Workbook

Sheet ENERO
P1: MES
B2: REPORTE DE AVANCE | P2: ENERO
B3: Fecha: 29/06/2022 | E3: Version: 01 | I3: GP-F-23
P4: FEBRERO
B5: Código Orden de servicio | P5: MARZO
P6: ABRIL
B7: Nombre del profesional (Reporta) | P7: MAYO
P8: JUNIO
B9: Mes a reportar | D9: ENERO | P9: JULIO
P10: AGOSTO
B11: Fecha reporte | D11: 46053 | P11: SEPTIEMBRE
P12: OCTUBRE
B13: Clasificación del servicio | H13: Reporte mes por servicio | J13: Reporte acumulado por servicio | P13: NOVIEMBRE
B14: Ítem general | C14: ítem actividad | D14: Descripción de la actividad | E14: Soporte | F14: Medio de entrega | G14: Días contratados | H14: Días | I14: % avance | J14: Días | K14: % avance | P14: DICIEMBRE
F15: Digital | G15: 0 | I15: =IFERROR(H15/G15,0) -> 0 | J15: =H15 -> 0 | K15: =IFERROR(J15/G15,0) -> 0
F16: Digital | G16: 0 | I16: =IFERROR(H16/G16,0) -> 0 | J16: =H16 -> 0 | K16: =IFERROR(J16/G16,0) -> 0
F17: Digital | G17: 0 | I17: =IFERROR(H17/G17,0) -> 0 | J17: =H17 -> 0 | K17: =IFERROR(J17/G17,0) -> 0
F18: Digital | G18: 0 | I18: =IFERROR(H18/G18,0) -> 0 | J18: =H18 -> 0 | K18: =IFERROR(J18/G18,0) -> 0
F19: Digital | G19: 0 | I19: =IFERROR(H19/G19,0) -> 0 | J19: =H19 -> 0 | K19: =IFERROR(J19/G19,0) -> 0
F20: Digital | G20: 0 | I20: =IFERROR(H20/G20,0) -> 0 | J20: =H20 -> 0 | K20: =IFERROR(J20/G20,0) -> 0
F21: Digital | G21: 0 | I21: =IFERROR(H21/G21,0) -> 0 | J21: =H21 -> 0 | K21: =IFERROR(J21/G21,0) -> 0
F22: Digital | G22: 0 | I22: =IFERROR(H22/G22,0) -> 0 | J22: =H22 -> 0 | K22: =IFERROR(J22/G22,0) -> 0
F23: Digital | G23: 0 | I23: =IFERROR(H23/G23,0) -> 0 | J23: =H23 -> 0 | K23: =IFERROR(J23/G23,0) -> 0
F24: Digital | G24: 0 | I24: =IFERROR(H24/G24,0) -> 0 | J24: =H24 -> 0 | K24: =IFERROR(J24/G24,0) -> 0
F25: Digital | G25: 0 | I25: =IFERROR(H25/G25,0) -> 0 | J25: =H25 -> 0 | K25: =IFERROR(J25/G25,0) -> 0
F26: Digital | G26: 0 | I26: =IFERROR(H26/G26,0) -> 0 | J26: =H26 -> 0 | K26: =IFERROR(J26/G26,0) -> 0
... F33: Digital | G33: 0 | I33: =IFERROR(H33/G33,0) -> 0 | J33: =H33 -> 0 | K33: =IFERROR(J33/G33,0) -> 0
G34: =+CONCATENATE("TOTAL A ",D9) -> TOTAL A ENERO | J34: TOTAL ACUMULADO
G35: =+SUM(G15:G33) -> 0 | H35: =+SUM(H15:H33) -> 0 | I35: =IFERROR(H35/G35,0) -> 0 | J35: =+SUM(J15:J33) -> 0 | K35: =IFERROR(J35/G35,0) -> 0
B37: Observaciones: | D37: Describa en este espacio su observación
B38: ¿Se presentó algún aspecto o situación que afecte la ejecución y calidad de los entregables? (Marque con una X)
B40: PROFESIONAL
B41: SI | D41: Describa en este espacio su observación
B42: NO
B43: ¿Se presentó algún aspecto o situación que afecte la ejecución y calidad de los entregables? (Marque con una X)
B45: INTERVENTOR O LIDER
B46: SI | D46: Describa en este espacio su observación
B47: NO
B51: Revisa: | G51: Interventor:
A83: MES
...

Sheet FEBRERO
P1: MES
B2: REPORTE DE AVANCE | P2: ENERO
B3: Fecha: 29/06/2022 | E3: Version: 01 | I3: GP-F-23
P4: FEBRERO
B5: Código Orden de servicio | P5: MARZO
P6: ABRIL
B7: Nombre del profesional (Reporta) | P7: MAYO
P8: JUNIO
B9: Mes a reportar | D9: FEBRERO | P9: JULIO
P10: AGOSTO
B11: Fecha reporte | D11: 46081 | P11: SEPTIEMBRE
P12: OCTUBRE
B13: Clasificación del servicio | H13: Reporte mes por servicio | J13: Reporte acumulado por servicio | P13: NOVIEMBRE
B14: Ítem general | C14: ítem actividad | D14: Descripción de la actividad | E14: Soporte | F14: Medio de entrega | G14: Días contratados | H14: Días | I14: % avance | J14: Días | K14: % avance | P14: DICIEMBRE
F15: Digital | G15: =ENERO!G15 -> 0 | I15: =IFERROR(H15/G15,0) -> 0 | J15: =H15+ENERO!J15 -> 0 | K15: =IFERROR(J15/G15,0) -> 0
F16: Digital | G16: =ENERO!G16 -> 0 | I16: =IFERROR(H16/G16,0) -> 0 | J16: =H16+ENERO!J16 -> 0 | K16: =IFERROR(J16/G16,0) -> 0
F17: Digital | G17: =ENERO!G17 -> 0 | I17: =IFERROR(H17/G17,0) -> 0 | J17: =H17+ENERO!J17 -> 0 | K17: =IFERROR(J17/G17,0) -> 0
F18: Digital | G18: =ENERO!G18 -> 0 | I18: =IFERROR(H18/G18,0) -> 0 | J18: =H18+ENERO!J18 -> 0 | K18: =IFERROR(J18/G18,0) -> 0
F19: Digital | G19: =ENERO!G19 -> 0 | I19: =IFERROR(H19/G19,0) -> 0 | J19: =H19+ENERO!J19 -> 0 | K19: =IFERROR(J19/G19,0) -> 0
F20: Digital | G20: =ENERO!G20 -> 0 | I20: =IFERROR(H20/G20,0) -> 0 | J20: =H20+ENERO!J20 -> 0 | K20: =IFERROR(J20/G20,0) -> 0
F21: Digital | G21: =ENERO!G21 -> 0 | I21: =IFERROR(H21/G21,0) -> 0 | J21: =H21+ENERO!J21 -> 0 | K21: =IFERROR(J21/G21,0) -> 0
F22: Digital | G22: =ENERO!G22 -> 0 | I22: =IFERROR(H22/G22,0) -> 0 | J22: =H22+ENERO!J22 -> 0 | K22: =IFERROR(J22/G22,0) -> 0
F23: Digital | G23: =ENERO!G23 -> 0 | I23: =IFERROR(H23/G23,0) -> 0 | J23: =H23+ENERO!J23 -> 0 | K23: =IFERROR(J23/G23,0) -> 0
F24: Digital | G24: =ENERO!G24 -> 0 | I24: =IFERROR(H24/G24,0) -> 0 | J24: =H24+ENERO!J24 -> 0 | K24: =IFERROR(J24/G24,0) -> 0
F25: Digital | G25: =ENERO!G25 -> 0 | I25: =IFERROR(H25/G25,0) -> 0 | J25: =H25+ENERO!J25 -> 0 | K25: =IFERROR(J25/G25,0) -> 0
F26: Digital | G26: =ENERO!G26 -> 0 | I26: =IFERROR(H26/G26,0) -> 0 | J26: =H26+ENERO!J26 -> 0 | K26: =IFERROR(J26/G26,0) -> 0
... F33: Digital | G33: =ENERO!G33 -> 0 | I33: =IFERROR(H33/G33,0) -> 0 | J33: =H33+ENERO!J33 -> 0 | K33: =IFERROR(J33/G33,0) -> 0
G34: =+CONCATENATE("TOTAL A ",D9) -> TOTAL A FEBRERO | J34: TOTAL ACUMULADO
G35: =+SUM(G15:G33) -> 0 | H35: =+SUM(H15:H33) -> 0 | I35: =IFERROR(H35/G35,0) -> 0 | J35: =+SUM(J15:J33) -> 0 | K35: =IFERROR(J35/G35,0) -> 0
B37: Observaciones: | D37: Describa en este espacio su observación
B38: ¿Se presentó algún aspecto o situación que afecte la ejecución y calidad de los entregables? (Marque con una X)
B40: PROFESIONAL
B41: SI | D41: Describa en este espacio su observación
B42: NO
B43: ¿Se presentó algún aspecto o situación que afecte la ejecución y calidad de los entregables? (Marque con una X)
B45: INTERVENTOR O LIDER
B46: SI | D46: Describa en este espacio su observación
B47: NO
B51: Revisa: | G51: Interventor:
A83: MES
...

Sheet MARZO
P1: MES
B2: REPORTE DE AVANCE | P2: ENERO
B3: Fecha: 29/06/2022 | E3: Version: 01 | I3: GP-F-23
P4: FEBRERO
B5: Código Orden de servicio | P5: MARZO
P6: ABRIL
B7: Nombre del profesional (Reporta) | P7: MAYO
P8: JUNIO
B9: Mes a reportar | D9: MARZO | P9: JULIO
P10: AGOSTO
B11: Fecha reporte | D11: 46112 | P11: SEPTIEMBRE
P12: OCTUBRE
B13: Clasificación del servicio | H13: Reporte mes por servicio | J13: Reporte acumulado por servicio | P13: NOVIEMBRE
B14: Ítem general | C14: ítem actividad | D14: Descripción de la actividad | E14: Soporte | F14: Medio de entrega | G14: Días contratados | H14: Días | I14: % avance | J14: Días | K14: % avance | P14: DICIEMBRE
F15: Digital | G15: =ENERO!G15 -> 0 | I15: =IFERROR(H15/G15,0) -> 0 | J15: =H15+FEBRERO!J15 -> 0 | K15: =IFERROR(J15/G15,0) -> 0
F16: Digital | G16: =ENERO!G16 -> 0 | I16: =IFERROR(H16/G16,0) -> 0 | J16: =H16+FEBRERO!J16 -> 0 | K16: =IFERROR(J16/G16,0) -> 0
F17: Digital | G17: =ENERO!G17 -> 0 | I17: =IFERROR(H17/G17,0) -> 0 | J17: =H17+FEBRERO!J17 -> 0 | K17: =IFERROR(J17/G17,0) -> 0
F18: Digital | G18: =ENERO!G18 -> 0 | I18: =IFERROR(H18/G18,0) -> 0 | J18: =H18+FEBRERO!J18 -> 0 | K18: =IFERROR(J18/G18,0) -> 0
F19: Digital | G19: =ENERO!G19 -> 0 | I19: =IFERROR(H19/G19,0) -> 0 | J19: =H19+FEBRERO!J19 -> 0 | K19: =IFERROR(J19/G19,0) -> 0
F20: Digital | G20: =ENERO!G20 -> 0 | I20: =IFERROR(H20/G20,0) -> 0 | J20: =H20+FEBRERO!J20 -> 0 | K20: =IFERROR(J20/G20,0) -> 0
F21: Digital | G21: =ENERO!G21 -> 0 | I21: =IFERROR(H21/G21,0) -> 0 | J21: =H21+FEBRERO!J21 -> 0 | K21: =IFERROR(J21/G21,0) -> 0
F22: Digital | G22: =ENERO!G22 -> 0 | I22: =IFERROR(H22/G22,0) -> 0 | J22: =H22+FEBRERO!J22 -> 0 | K22: =IFERROR(J22/G22,0) -> 0
F23: Digital | G23: =ENERO!G23 -> 0 | I23: =IFERROR(H23/G23,0) -> 0 | J23: =H23+FEBRERO!J23 -> 0 | K23: =IFERROR(J23/G23,0) -> 0
F24: Digital | G24: =ENERO!G24 -> 0 | I24: =IFERROR(H24/G24,0) -> 0 | J24: =H24+FEBRERO!J24 -> 0 | K24: =IFERROR(J24/G24,0) -> 0
F25: Digital | G25: =ENERO!G25 -> 0 | I25: =IFERROR(H25/G25,0) -> 0 | J25: =H25+FEBRERO!J25 -> 0 | K25: =IFERROR(J25/G25,0) -> 0
F26: Digital | G26: =ENERO!G26 -> 0 | I26: =IFERROR(H26/G26,0) -> 0 | J26: =H26+FEBRERO!J26 -> 0 | K26: =IFERROR(J26/G26,0) -> 0
... F33: Digital | G33: =ENERO!G33 -> 0 | I33: =IFERROR(H33/G33,0) -> 0 | J33: =H33+FEBRERO!J33 -> 0 | K33: =IFERROR(J33/G33,0) -> 0
G34: =+CONCATENATE("TOTAL A ",D9) -> TOTAL A MARZO | J34: TOTAL ACUMULADO
G35: =+SUM(G15:G33) -> 0 | H35: =+SUM(H15:H33) -> 0 | I35: =IFERROR(H35/G35,0) -> 0 | J35: =+SUM(J15:J33) -> 0 | K35: =IFERROR(J35/G35,0) -> 0
B37: Observaciones: | D37: Describa en este espacio su observación
B38: ¿Se presentó algún aspecto o situación que afecte la ejecución y calidad de los entregables? (Marque con una X)
B40: PROFESIONAL
B41: SI | D41: Describa en este espacio su observación
B42: NO
B43: ¿Se presentó algún aspecto o situación que afecte la ejecución y calidad de los entregables? (Marque con una X)
B45: INTERVENTOR O LIDER
B46: SI | D46: Describa en este espacio su observación
B47: NO
B51: Revisa: | G51: Interventor:
A83: MES
...

Sheet ABRIL
P1: MES
B2: REPORTE DE AVANCE | P2: ENERO
B3: Fecha: 29/06/2022 | E3: Version: 01 | I3: GP-F-23
P4: FEBRERO
B5: Código Orden de servicio | P5: MARZO
P6: ABRIL
B7: Nombre del profesional (Reporta) | P7: MAYO
P8: JUNIO
B9: Mes a reportar | D9: ABRIL | P9: JULIO
P10: AGOSTO
B11: Fecha reporte | D11: 46142 | P11: SEPTIEMBRE
P12: OCTUBRE
B13: Clasificación del servicio | H13: Reporte mes por servicio | J13: Reporte acumulado por servicio | P13: NOVIEMBRE
B14: Ítem general | C14: ítem actividad | D14: Descripción de la actividad | E14: Soporte | F14: Medio de entrega | G14: Días contratados | H14: Días | I14: % avance | J14: Días | K14: % avance | P14: DICIEMBRE
F15: Digital | G15: =ENERO!G15 -> 0 | I15: =IFERROR(H15/G15,0) -> 0 | J15: =H15+MARZO!J15 -> 0 | K15: =IFERROR(J15/G15,0) -> 0
F16: Digital | G16: =ENERO!G16 -> 0 | I16: =IFERROR(H16/G16,0) -> 0 | J16: =H16+MARZO!J16 -> 0 | K16: =IFERROR(J16/G16,0) -> 0
F17: Digital | G17: =ENERO!G17 -> 0 | I17: =IFERROR(H17/G17,0) -> 0 | J17: =H17+MARZO!J17 -> 0 | K17: =IFERROR(J17/G17,0) -> 0
F18: Digital | G18: =ENERO!G18 -> 0 | I18: =IFERROR(H18/G18,0) -> 0 | J18: =H18+MARZO!J18 -> 0 | K18: =IFERROR(J18/G18,0) -> 0
F19: Digital | G19: =ENERO!G19 -> 0 | I19: =IFERROR(H19/G19,0) -> 0 | J19: =H19+MARZO!J19 -> 0 | K19: =IFERROR(J19/G19,0) -> 0
F20: Digital | G20: =ENERO!G20 -> 0 | I20: =IFERROR(H20/G20,0) -> 0 | J20: =H20+MARZO!J20 -> 0 | K20: =IFERROR(J20/G20,0) -> 0
F21: Digital | G21: =ENERO!G21 -> 0 | I21: =IFERROR(H21/G21,0) -> 0 | J21: =H21+MARZO!J21 -> 0 | K21: =IFERROR(J21/G21,0) -> 0
F22: Digital | G22: =ENERO!G22 -> 0 | I22: =IFERROR(H22/G22,0) -> 0 | J22: =H22+MARZO!J22 -> 0 | K22: =IFERROR(J22/G22,0) -> 0
F23: Digital | G23: =ENERO!G23 -> 0 | I23: =IFERROR(H23/G23,0) -> 0 | J23: =H23+MARZO!J23 -> 0 | K23: =IFERROR(J23/G23,0) -> 0
F24: Digital | G24: =ENERO!G24 -> 0 | I24: =IFERROR(H24/G24,0) -> 0 | J24: =H24+MARZO!J24 -> 0 | K24: =IFERROR(J24/G24,0) -> 0
F25: Digital | G25: =ENERO!G25 -> 0 | I25: =IFERROR(H25/G25,0) -> 0 | J25: =H25+MARZO!J25 -> 0 | K25: =IFERROR(J25/G25,0) -> 0
F26: Digital | G26: =ENERO!G26 -> 0 | I26: =IFERROR(H26/G26,0) -> 0 | J26: =H26+MARZO!J26 -> 0 | K26: =IFERROR(J26/G26,0) -> 0
... F33: Digital | G33: =ENERO!G33 -> 0 | I33: =IFERROR(H33/G33,0) -> 0 | J33: =H33+MARZO!J33 -> 0 | K33: =IFERROR(J33/G33,0) -> 0
G34: =+CONCATENATE("TOTAL A ",D9) -> TOTAL A ABRIL | J34: TOTAL ACUMULADO
G35: =+SUM(G15:G33) -> 0 | H35: =+SUM(H15:H33) -> 0 | I35: =IFERROR(H35/G35,0) -> 0 | J35: =+SUM(J15:J33) -> 0 | K35: =IFERROR(J35/G35,0) -> 0
B37: Observaciones: | D37: Describa en este espacio su observación
B38: ¿Se presentó algún aspecto o situación que afecte la ejecución y calidad de los entregables? (Marque con una X)
B40: PROFESIONAL
B41: SI | D41: Describa en este espacio su observación
B42: NO
B43: ¿Se presentó algún aspecto o situación que afecte la ejecución y calidad de los entregables? (Marque con una X)
B45: INTERVENTOR O LIDER
B46: SI | D46: Describa en este espacio su observación
B47: NO
B51: Revisa: | G51: Interventor:
A83: MES
...

Sheet MAYO
P1: MES
B2: REPORTE DE AVANCE | P2: ENERO
B3: Fecha: 29/06/2022 | E3: Version: 01 | I3: GP-F-23
P4: FEBRERO
B5: Código Orden de servicio | P5: MARZO
P6: ABRIL
B7: Nombre del profesional (Reporta) | P7: MAYO
P8: JUNIO
B9: Mes a reportar | D9: MAYO | P9: JULIO
P10: AGOSTO
B11: Fecha reporte | D11: 46173 | P11: SEPTIEMBRE
P12: OCTUBRE
B13: Clasificación del servicio | H13: Reporte mes por servicio | J13: Reporte acumulado por servicio | P13: NOVIEMBRE
B14: Ítem general | C14: ítem actividad | D14: Descripción de la actividad | E14: Soporte | F14: Medio de entrega | G14: Días contratados | H14: Días | I14: % avance | J14: Días | K14: % avance | P14: DICIEMBRE
F15: Digital | G15: =ENERO!G15 -> 0 | I15: =IFERROR(H15/G15,0) -> 0 | J15: =H15+ABRIL!J15 -> 0 | K15: =IFERROR(J15/G15,0) -> 0
F16: Digital | G16: =ENERO!G16 -> 0 | I16: =IFERROR(H16/G16,0) -> 0 | J16: =H16+ABRIL!J16 -> 0 | K16: =IFERROR(J16/G16,0) -> 0
F17: Digital | G17: =ENERO!G17 -> 0 | I17: =IFERROR(H17/G17,0) -> 0 | J17: =H17+ABRIL!J17 -> 0 | K17: =IFERROR(J17/G17,0) -> 0
F18: Digital | G18: =ENERO!G18 -> 0 | I18: =IFERROR(H18/G18,0) -> 0 | J18: =H18+ABRIL!J18 -> 0 | K18: =IFERROR(J18/G18,0) -> 0
F19: Digital | G19: =ENERO!G19 -> 0 | I19: =IFERROR(H19/G19,0) -> 0 | J19: =H19+ABRIL!J19 -> 0 | K19: =IFERROR(J19/G19,0) -> 0
F20: Digital | G20: =ENERO!G20 -> 0 | I20: =IFERROR(H20/G20,0) -> 0 | J20: =H20+ABRIL!J20 -> 0 | K20: =IFERROR(J20/G20,0) -> 0
F21: Digital | G21: =ENERO!G21 -> 0 | I21: =IFERROR(H21/G21,0) -> 0 | J21: =H21+ABRIL!J21 -> 0 | K21: =IFERROR(J21/G21,0) -> 0
F22: Digital | G22: =ENERO!G22 -> 0 | I22: =IFERROR(H22/G22,0) -> 0 | J22: =H22+ABRIL!J22 -> 0 | K22: =IFERROR(J22/G22,0) -> 0
F23: Digital | G23: =ENERO!G23 -> 0 | I23: =IFERROR(H23/G23,0) -> 0 | J23: =H23+ABRIL!J23 -> 0 | K23: =IFERROR(J23/G23,0) -> 0
F24: Digital | G24: =ENERO!G24 -> 0 | I24: =IFERROR(H24/G24,0) -> 0 | J24: =H24+ABRIL!J24 -> 0 | K24: =IFERROR(J24/G24,0) -> 0
F25: Digital | G25: =ENERO!G25 -> 0 | I25: =IFERROR(H25/G25,0) -> 0 | J25: =H25+ABRIL!J25 -> 0 | K25: =IFERROR(J25/G25,0) -> 0
F26: Digital | G26: =ENERO!G26 -> 0 | I26: =IFERROR(H26/G26,0) -> 0 | J26: =H26+ABRIL!J26 -> 0 | K26: =IFERROR(J26/G26,0) -> 0
... F33: Digital | G33: =ENERO!G33 -> 0 | I33: =IFERROR(H33/G33,0) -> 0 | J33: =H33+ABRIL!J33 -> 0 | K33: =IFERROR(J33/G33,0) -> 0
G34: =+CONCATENATE("TOTAL A ",D9) -> TOTAL A MAYO | J34: TOTAL ACUMULADO
G35: =+SUM(G15:G33) -> 0 | H35: =+SUM(H15:H33) -> 0 | I35: =IFERROR(H35/G35,0) -> 0 | J35: =+SUM(J15:J33) -> 0 | K35: =IFERROR(J35/G35,0) -> 0
B37: Observaciones: | D37: Describa en este espacio su observación
B38: ¿Se presentó algún aspecto o situación que afecte la ejecución y calidad de los entregables? (Marque con una X)
B40: PROFESIONAL
B41: SI | D41: Describa en este espacio su observación
B42: NO
B43: ¿Se presentó algún aspecto o situación que afecte la ejecución y calidad de los entregables? (Marque con una X)
B45: INTERVENTOR O LIDER
B46: SI | D46: Describa en este espacio su observación
B47: NO
B51: Revisa: | G51: Interventor:
A83: MES
...

Sheet JUNIO
P1: MES
B2: REPORTE DE AVANCE | P2: ENERO
B3: Fecha: 29/06/2022 | E3: Version: 01 | I3: GP-F-23
P4: FEBRERO
B5: Código Orden de servicio | P5: MARZO
P6: ABRIL
B7: Nombre del profesional (Reporta) | P7: MAYO
P8: JUNIO
B9: Mes a reportar | D9: JUNIO | P9: JULIO
P10: AGOSTO
B11: Fecha reporte | D11: 46203 | P11: SEPTIEMBRE
P12: OCTUBRE
B13: Clasificación del servicio | H13: Reporte mes por servicio | J13: Reporte acumulado por servicio | P13: NOVIEMBRE
B14: Ítem general | C14: ítem actividad | D14: Descripción de la actividad | E14: Soporte | F14: Medio de entrega | G14: Días contratados | H14: Días | I14: % avance | J14: Días | K14: % avance | P14: DICIEMBRE
F15: Digital | G15: =ENERO!G15 -> 0 | I15: =IFERROR(H15/G15,0) -> 0 | J15: =H15+MAYO!J15 -> 0 | K15: =IFERROR(J15/G15,0) -> 0
F16: Digital | G16: =ENERO!G16 -> 0 | I16: =IFERROR(H16/G16,0) -> 0 | J16: =H16+MAYO!J16 -> 0 | K16: =IFERROR(J16/G16,0) -> 0
F17: Digital | G17: =ENERO!G17 -> 0 | I17: =IFERROR(H17/G17,0) -> 0 | J17: =H17+MAYO!J17 -> 0 | K17: =IFERROR(J17/G17,0) -> 0
F18: Digital | G18: =ENERO!G18 -> 0 | I18: =IFERROR(H18/G18,0) -> 0 | J18: =H18+MAYO!J18 -> 0 | K18: =IFERROR(J18/G18,0) -> 0
F19: Digital | G19: =ENERO!G19 -> 0 | I19: =IFERROR(H19/G19,0) -> 0 | J19: =H19+MAYO!J19 -> 0 | K19: =IFERROR(J19/G19,0) -> 0
F20: Digital | G20: =ENERO!G20 -> 0 | I20: =IFERROR(H20/G20,0) -> 0 | J20: =H20+MAYO!J20 -> 0 | K20: =IFERROR(J20/G20,0) -> 0
F21: Digital | G21: =ENERO!G21 -> 0 | I21: =IFERROR(H21/G21,0) -> 0 | J21: =H21+MAYO!J21 -> 0 | K21: =IFERROR(J21/G21,0) -> 0
F22: Digital | G22: =ENERO!G22 -> 0 | I22: =IFERROR(H22/G22,0) -> 0 | J22: =H22+MAYO!J22 -> 0 | K22: =IFERROR(J22/G22,0) -> 0
F23: Digital | G23: =ENERO!G23 -> 0 | I23: =IFERROR(H23/G23,0) -> 0 | J23: =H23+MAYO!J23 -> 0 | K23: =IFERROR(J23/G23,0) -> 0
F24: Digital | G24: =ENERO!G24 -> 0 | I24: =IFERROR(H24/G24,0) -> 0 | J24: =H24+MAYO!J24 -> 0 | K24: =IFERROR(J24/G24,0) -> 0
F25: Digital | G25: =ENERO!G25 -> 0 | I25: =IFERROR(H25/G25,0) -> 0 | J25: =H25+MAYO!J25 -> 0 | K25: =IFERROR(J25/G25,0) -> 0
F26: Digital | G26: =ENERO!G26 -> 0 | I26: =IFERROR(H26/G26,0) -> 0 | J26: =H26+MAYO!J26 -> 0 | K26: =IFERROR(J26/G26,0) -> 0
... F33: Digital | G33: =ENERO!G33 -> 0 | I33: =IFERROR(H33/G33,0) -> 0 | J33: =H33+MAYO!J33 -> 0 | K33: =IFERROR(J33/G33,0) -> 0
G34: =+CONCATENATE("TOTAL A ",D9) -> TOTAL A JUNIO | J34: TOTAL ACUMULADO
G35: =+SUM(G15:G33) -> 0 | H35: =+SUM(H15:H33) -> 0 | I35: =IFERROR(H35/G35,0) -> 0 | J35: =+SUM(J15:J33) -> 0 | K35: =IFERROR(J35/G35,0) -> 0
B37: Observaciones: | D37: Describa en este espacio su observación
B38: ¿Se presentó algún aspecto o situación que afecte la ejecución y calidad de los entregables? (Marque con una X)
B40: PROFESIONAL
B41: SI | D41: Describa en este espacio su observación
B42: NO
B43: ¿Se presentó algún aspecto o situación que afecte la ejecución y calidad de los entregables? (Marque con una X)
B45: INTERVENTOR O LIDER
B46: SI | D46: Describa en este espacio su observación
B47: NO
B51: Revisa: | G51: Interventor:
A83: MES
...

Sheet JULIO
P1: MES
B2: REPORTE DE AVANCE | P2: ENERO
B3: Fecha: 29/06/2022 | E3: Version: 01 | I3: GP-F-23
P4: FEBRERO
B5: Código Orden de servicio | P5: MARZO
P6: ABRIL
B7: Nombre del profesional (Reporta) | P7: MAYO
P8: JUNIO
B9: Mes a reportar | D9: JULIO | P9: JULIO
P10: AGOSTO
B11: Fecha reporte | D11: 46234 | P11: SEPTIEMBRE
P12: OCTUBRE
B13: Clasificación del servicio | H13: Reporte mes por servicio | J13: Reporte acumulado por servicio | P13: NOVIEMBRE
B14: Ítem general | C14: ítem actividad | D14: Descripción de la actividad | E14: Soporte | F14: Medio de entrega | G14: Días contratados | H14: Días | I14: % avance | J14: Días | K14: % avance | P14: DICIEMBRE
F15: Digital | G15: =ENERO!G15 -> 0 | I15: =IFERROR(H15/G15,0) -> 0 | J15: =H15+JUNIO!J15 -> 0 | K15: =IFERROR(J15/G15,0) -> 0
F16: Digital | G16: =ENERO!G16 -> 0 | I16: =IFERROR(H16/G16,0) -> 0 | J16: =H16+JUNIO!J16 -> 0 | K16: =IFERROR(J16/G16,0) -> 0
F17: Digital | G17: =ENERO!G17 -> 0 | I17: =IFERROR(H17/G17,0) -> 0 | J17: =H17+JUNIO!J17 -> 0 | K17: =IFERROR(J17/G17,0) -> 0
F18: Digital | G18: =ENERO!G18 -> 0 | I18: =IFERROR(H18/G18,0) -> 0 | J18: =H18+JUNIO!J18 -> 0 | K18: =IFERROR(J18/G18,0) -> 0
F19: Digital | G19: =ENERO!G19 -> 0 | I19: =IFERROR(H19/G19,0) -> 0 | J19: =H19+JUNIO!J19 -> 0 | K19: =IFERROR(J19/G19,0) -> 0
F20: Digital | G20: =ENERO!G20 -> 0 | I20: =IFERROR(H20/G20,0) -> 0 | J20: =H20+JUNIO!J20 -> 0 | K20: =IFERROR(J20/G20,0) -> 0
F21: Digital | G21: =ENERO!G21 -> 0 | I21: =IFERROR(H21/G21,0) -> 0 | J21: =H21+JUNIO!J21 -> 0 | K21: =IFERROR(J21/G21,0) -> 0
F22: Digital | G22: =ENERO!G22 -> 0 | I22: =IFERROR(H22/G22,0) -> 0 | J22: =H22+JUNIO!J22 -> 0 | K22: =IFERROR(J22/G22,0) -> 0
F23: Digital | G23: =ENERO!G23 -> 0 | I23: =IFERROR(H23/G23,0) -> 0 | J23: =H23+JUNIO!J23 -> 0 | K23: =IFERROR(J23/G23,0) -> 0
F24: Digital | G24: =ENERO!G24 -> 0 | I24: =IFERROR(H24/G24,0) -> 0 | J24: =H24+JUNIO!J24 -> 0 | K24: =IFERROR(J24/G24,0) -> 0
F25: Digital | G25: =ENERO!G25 -> 0 | I25: =IFERROR(H25/G25,0) -> 0 | J25: =H25+JUNIO!J25 -> 0 | K25: =IFERROR(J25/G25,0) -> 0
F26: Digital | G26: =ENERO!G26 -> 0 | I26: =IFERROR(H26/G26,0) -> 0 | J26: =H26+JUNIO!J26 -> 0 | K26: =IFERROR(J26/G26,0) -> 0
... F33: Digital | G33: =ENERO!G33 -> 0 | I33: =IFERROR(H33/G33,0) -> 0 | J33: =H33+JUNIO!J33 -> 0 | K33: =IFERROR(J33/G33,0) -> 0
G34: =+CONCATENATE("TOTAL A ",D9) -> TOTAL A JULIO | J34: TOTAL ACUMULADO
G35: =+SUM(G15:G33) -> 0 | H35: =+SUM(H15:H33) -> 0 | I35: =IFERROR(H35/G35,0) -> 0 | J35: =+SUM(J15:J33) -> 0 | K35: =IFERROR(J35/G35,0) -> 0
B37: Observaciones: | D37: Describa en este espacio su observación
B38: ¿Se presentó algún aspecto o situación que afecte la ejecución y calidad de los entregables? (Marque con una X)
B40: PROFESIONAL
B41: SI | D41: Describa en este espacio su observación
B42: NO
B43: ¿Se presentó algún aspecto o situación que afecte la ejecución y calidad de los entregables? (Marque con una X)
B45: INTERVENTOR O LIDER
B46: SI | D46: Describa en este espacio su observación
B47: NO
B51: Revisa: | G51: Interventor:
A83: MES
...

Sheet AGOSTO
P1: MES
B2: REPORTE DE AVANCE | P2: ENERO
B3: Fecha: 29/06/2022 | E3: Version: 01 | I3: GP-F-23
P4: FEBRERO
B5: Código Orden de servicio | P5: MARZO
P6: ABRIL
B7: Nombre del profesional (Reporta) | P7: MAYO
P8: JUNIO
B9: Mes a reportar | D9: AGOSTO | P9: JULIO
P10: AGOSTO
B11: Fecha reporte | D11: 46265 | P11: SEPTIEMBRE
P12: OCTUBRE
B13: Clasificación del servicio | H13: Reporte mes por servicio | J13: Reporte acumulado por servicio | P13: NOVIEMBRE
B14: Ítem general | C14: ítem actividad | D14: Descripción de la actividad | E14: Soporte | F14: Medio de entrega | G14: Días contratados | H14: Días | I14: % avance | J14: Días | K14: % avance | P14: DICIEMBRE
F15: Digital | G15: =ENERO!G15 -> 0 | I15: =IFERROR(H15/G15,0) -> 0 | J15: =H15+JULIO!J15 -> 0 | K15: =IFERROR(J15/G15,0) -> 0
F16: Digital | G16: =ENERO!G16 -> 0 | I16: =IFERROR(H16/G16,0) -> 0 | J16: =H16+JULIO!J16 -> 0 | K16: =IFERROR(J16/G16,0) -> 0
F17: Digital | G17: =ENERO!G17 -> 0 | I17: =IFERROR(H17/G17,0) -> 0 | J17: =H17+JULIO!J17 -> 0 | K17: =IFERROR(J17/G17,0) -> 0
F18: Digital | G18: =ENERO!G18 -> 0 | I18: =IFERROR(H18/G18,0) -> 0 | J18: =H18+JULIO!J18 -> 0 | K18: =IFERROR(J18/G18,0) -> 0
F19: Digital | G19: =ENERO!G19 -> 0 | I19: =IFERROR(H19/G19,0) -> 0 | J19: =H19+JULIO!J19 -> 0 | K19: =IFERROR(J19/G19,0) -> 0
F20: Digital | G20: =ENERO!G20 -> 0 | I20: =IFERROR(H20/G20,0) -> 0 | J20: =H20+JULIO!J20 -> 0 | K20: =IFERROR(J20/G20,0) -> 0
F21: Digital | G21: =ENERO!G21 -> 0 | I21: =IFERROR(H21/G21,0) -> 0 | J21: =H21+JULIO!J21 -> 0 | K21: =IFERROR(J21/G21,0) -> 0
F22: Digital | G22: =ENERO!G22 -> 0 | I22: =IFERROR(H22/G22,0) -> 0 | J22: =H22+JULIO!J22 -> 0 | K22: =IFERROR(J22/G22,0) -> 0
F23: Digital | G23: =ENERO!G23 -> 0 | I23: =IFERROR(H23/G23,0) -> 0 | J23: =H23+JULIO!J23 -> 0 | K23: =IFERROR(J23/G23,0) -> 0
F24: Digital | G24: =ENERO!G24 -> 0 | I24: =IFERROR(H24/G24,0) -> 0 | J24: =H24+JULIO!J24 -> 0 | K24: =IFERROR(J24/G24,0) -> 0
F25: Digital | G25: =ENERO!G25 -> 0 | I25: =IFERROR(H25/G25,0) -> 0 | J25: =H25+JULIO!J25 -> 0 | K25: =IFERROR(J25/G25,0) -> 0
F26: Digital | G26: =ENERO!G26 -> 0 | I26: =IFERROR(H26/G26,0) -> 0 | J26: =H26+JULIO!J26 -> 0 | K26: =IFERROR(J26/G26,0) -> 0
... F33: Digital | G33: =ENERO!G33 -> 0 | I33: =IFERROR(H33/G33,0) -> 0 | J33: =H33+JULIO!J33 -> 0 | K33: =IFERROR(J33/G33,0) -> 0
G34: =+CONCATENATE("TOTAL A ",D9) -> TOTAL A AGOSTO | J34: TOTAL ACUMULADO
G35: =+SUM(G15:G33) -> 0 | H35: =+SUM(H15:H33) -> 0 | I35: =IFERROR(H35/G35,0) -> 0 | J35: =+SUM(J15:J33) -> 0 | K35: =IFERROR(J35/G35,0) -> 0
B37: Observaciones: | D37: Describa en este espacio su observación
B38: ¿Se presentó algún aspecto o situación que afecte la ejecución y calidad de los entregables? (Marque con una X)
B40: PROFESIONAL
B41: SI | D41: Describa en este espacio su observación
B42: NO
B43: ¿Se presentó algún aspecto o situación que afecte la ejecución y calidad de los entregables? (Marque con una X)
B45: INTERVENTOR O LIDER
B46: SI | D46: Describa en este espacio su observación
B47: NO
B51: Revisa: | G51: Interventor:
A83: MES
...

Sheet SEPTIEMBRE
P1: MES
B2: REPORTE DE AVANCE | P2: ENERO
B3: Fecha: 29/06/2022 | E3: Version: 01 | I3: GP-F-23
P4: FEBRERO
B5: Código Orden de servicio | P5: MARZO
P6: ABRIL
B7: Nombre del profesional (Reporta) | P7: MAYO
P8: JUNIO
B9: Mes a reportar | D9: SEPTIEMBRE | P9: JULIO
P10: AGOSTO
B11: Fecha reporte | D11: 46295 | P11: SEPTIEMBRE
P12: OCTUBRE
B13: Clasificación del servicio | H13: Reporte mes por servicio | J13: Reporte acumulado por servicio | P13: NOVIEMBRE
B14: Ítem general | C14: ítem actividad | D14: Descripción de la actividad | E14: Soporte | F14: Medio de entrega | G14: Días contratados | H14: Días | I14: % avance | J14: Días | K14: % avance | P14: DICIEMBRE
F15: Digital | G15: =ENERO!G15 -> 0 | I15: =IFERROR(H15/G15,0) -> 0 | J15: =H15+AGOSTO!J15 -> 0 | K15: =IFERROR(J15/G15,0) -> 0
F16: Digital | G16: =ENERO!G16 -> 0 | I16: =IFERROR(H16/G16,0) -> 0 | J16: =H16+AGOSTO!J16 -> 0 | K16: =IFERROR(J16/G16,0) -> 0
F17: Digital | G17: =ENERO!G17 -> 0 | I17: =IFERROR(H17/G17,0) -> 0 | J17: =H17+AGOSTO!J17 -> 0 | K17: =IFERROR(J17/G17,0) -> 0
F18: Digital | G18: =ENERO!G18 -> 0 | I18: =IFERROR(H18/G18,0) -> 0 | J18: =H18+AGOSTO!J18 -> 0 | K18: =IFERROR(J18/G18,0) -> 0
F19: Digital | G19: =ENERO!G19 -> 0 | I19: =IFERROR(H19/G19,0) -> 0 | J19: =H19+AGOSTO!J19 -> 0 | K19: =IFERROR(J19/G19,0) -> 0
F20: Digital | G20: =ENERO!G20 -> 0 | I20: =IFERROR(H20/G20,0) -> 0 | J20: =H20+AGOSTO!J20 -> 0 | K20: =IFERROR(J20/G20,0) -> 0
F21: Digital | G21: =ENERO!G21 -> 0 | I21: =IFERROR(H21/G21,0) -> 0 | J21: =H21+AGOSTO!J21 -> 0 | K21: =IFERROR(J21/G21,0) -> 0
F22: Digital | G22: =ENERO!G22 -> 0 | I22: =IFERROR(H22/G22,0) -> 0 | J22: =H22+AGOSTO!J22 -> 0 | K22: =IFERROR(J22/G22,0) -> 0
F23: Digital | G23: =ENERO!G23 -> 0 | I23: =IFERROR(H23/G23,0) -> 0 | J23: =H23+AGOSTO!J23 -> 0 | K23: =IFERROR(J23/G23,0) -> 0
F24: Digital | G24: =ENERO!G24 -> 0 | I24: =IFERROR(H24/G24,0) -> 0 | J24: =H24+AGOSTO!J24 -> 0 | K24: =IFERROR(J24/G24,0) -> 0
F25: Digital | G25: =ENERO!G25 -> 0 | I25: =IFERROR(H25/G25,0) -> 0 | J25: =H25+AGOSTO!J25 -> 0 | K25: =IFERROR(J25/G25,0) -> 0
F26: Digital | G26: =ENERO!G26 -> 0 | I26: =IFERROR(H26/G26,0) -> 0 | J26: =H26+AGOSTO!J26 -> 0 | K26: =IFERROR(J26/G26,0) -> 0
... F33: Digital | G33: =ENERO!G33 -> 0 | I33: =IFERROR(H33/G33,0) -> 0 | J33: =H33+AGOSTO!J33 -> 0 | K33: =IFERROR(J33/G33,0) -> 0
G34: =+CONCATENATE("TOTAL A ",D9) -> TOTAL A SEPTIEMBRE | J34: TOTAL ACUMULADO
G35: =+SUM(G15:G33) -> 0 | H35: =+SUM(H15:H33) -> 0 | I35: =IFERROR(H35/G35,0) -> 0 | J35: =+SUM(J15:J33) -> 0 | K35: =IFERROR(J35/G35,0) -> 0
B37: Observaciones: | D37: Describa en este espacio su observación
B38: ¿Se presentó algún aspecto o situación que afecte la ejecución y calidad de los entregables? (Marque con una X)
B40: PROFESIONAL
B41: SI | D41: Describa en este espacio su observación
B42: NO
B43: ¿Se presentó algún aspecto o situación que afecte la ejecución y calidad de los entregables? (Marque con una X)
B45: INTERVENTOR O LIDER
B46: SI | D46: Describa en este espacio su observación
B47: NO
B51: Revisa: | G51: Interventor:
A83: MES
...

Sheet OCTUBRE
P1: MES
B2: REPORTE DE AVANCE | P2: ENERO
B3: Fecha: 29/06/2022 | E3: Version: 01 | I3: GP-F-23
P4: FEBRERO
B5: Código Orden de servicio | P5: MARZO
P6: ABRIL
B7: Nombre del profesional (Reporta) | P7: MAYO
P8: JUNIO
B9: Mes a reportar | D9: OCTUBRE | P9: JULIO
P10: AGOSTO
B11: Fecha reporte | D11: 46326 | P11: SEPTIEMBRE
P12: OCTUBRE
B13: Clasificación del servicio | H13: Reporte mes por servicio | J13: Reporte acumulado por servicio | P13: NOVIEMBRE
B14: Ítem general | C14: ítem actividad | D14: Descripción de la actividad | E14: Soporte | F14: Medio de entrega | G14: Días contratados | H14: Días | I14: % avance | J14: Días | K14: % avance | P14: DICIEMBRE
F15: Digital | G15: =ENERO!G15 -> 0 | I15: =IFERROR(H15/G15,0) -> 0 | J15: =H15+SEPTIEMBRE!J15 -> 0 | K15: =IFERROR(J15/G15,0) -> 0
F16: Digital | G16: =ENERO!G16 -> 0 | I16: =IFERROR(H16/G16,0) -> 0 | J16: =H16+SEPTIEMBRE!J16 -> 0 | K16: =IFERROR(J16/G16,0) -> 0
F17: Digital | G17: =ENERO!G17 -> 0 | I17: =IFERROR(H17/G17,0) -> 0 | J17: =H17+SEPTIEMBRE!J17 -> 0 | K17: =IFERROR(J17/G17,0) -> 0
F18: Digital | G18: =ENERO!G18 -> 0 | I18: =IFERROR(H18/G18,0) -> 0 | J18: =H18+SEPTIEMBRE!J18 -> 0 | K18: =IFERROR(J18/G18,0) -> 0
F19: Digital | G19: =ENERO!G19 -> 0 | I19: =IFERROR(H19/G19,0) -> 0 | J19: =H19+SEPTIEMBRE!J19 -> 0 | K19: =IFERROR(J19/G19,0) -> 0
F20: Digital | G20: =ENERO!G20 -> 0 | I20: =IFERROR(H20/G20,0) -> 0 | J20: =H20+SEPTIEMBRE!J20 -> 0 | K20: =IFERROR(J20/G20,0) -> 0
F21: Digital | G21: =ENERO!G21 -> 0 | I21: =IFERROR(H21/G21,0) -> 0 | J21: =H21+SEPTIEMBRE!J21 -> 0 | K21: =IFERROR(J21/G21,0) -> 0
F22: Digital | G22: =ENERO!G22 -> 0 | I22: =IFERROR(H22/G22,0) -> 0 | J22: =H22+SEPTIEMBRE!J22 -> 0 | K22: =IFERROR(J22/G22,0) -> 0
F23: Digital | G23: =ENERO!G23 -> 0 | I23: =IFERROR(H23/G23,0) -> 0 | J23: =H23+SEPTIEMBRE!J23 -> 0 | K23: =IFERROR(J23/G23,0) -> 0
F24: Digital | G24: =ENERO!G24 -> 0 | I24: =IFERROR(H24/G24,0) -> 0 | J24: =H24+SEPTIEMBRE!J24 -> 0 | K24: =IFERROR(J24/G24,0) -> 0
F25: Digital | G25: =ENERO!G25 -> 0 | I25: =IFERROR(H25/G25,0) -> 0 | J25: =H25+SEPTIEMBRE!J25 -> 0 | K25: =IFERROR(J25/G25,0) -> 0
F26: Digital | G26: =ENERO!G26 -> 0 | I26: =IFERROR(H26/G26,0) -> 0 | J26: =H26+SEPTIEMBRE!J26 -> 0 | K26: =IFERROR(J26/G26,0) -> 0
... F33: Digital | G33: =ENERO!G33 -> 0 | I33: =IFERROR(H33/G33,0) -> 0 | J33: =H33+SEPTIEMBRE!J33 -> 0 | K33: =IFERROR(J33/G33,0) -> 0
G34: =+CONCATENATE("TOTAL A ",D9) -> TOTAL A OCTUBRE | J34: TOTAL ACUMULADO
G35: =+SUM(G15:G33) -> 0 | H35: =+SUM(H15:H33) -> 0 | I35: =IFERROR(H35/G35,0) -> 0 | J35: =+SUM(J15:J33) -> 0 | K35: =IFERROR(J35/G35,0) -> 0
B37: Observaciones: | D37: Describa en este espacio su observación
B38: ¿Se presentó algún aspecto o situación que afecte la ejecución y calidad de los entregables? (Marque con una X)
B40: PROFESIONAL
B41: SI | D41: Describa en este espacio su observación
B42: NO
B43: ¿Se presentó algún aspecto o situación que afecte la ejecución y calidad de los entregables? (Marque con una X)
B45: INTERVENTOR O LIDER
B46: SI | D46: Describa en este espacio su observación
B47: NO
B51: Revisa: | G51: Interventor:
A83: MES
...

Sheet NOVIEMBRE
P1: MES
B2: REPORTE DE AVANCE | P2: ENERO
B3: Fecha: 29/06/2022 | E3: Version: 01 | I3: GP-F-23
P4: FEBRERO
B5: Código Orden de servicio | P5: MARZO
P6: ABRIL
B7: Nombre del profesional (Reporta) | P7: MAYO
P8: JUNIO
B9: Mes a reportar | D9: NOVIEMBRE | P9: JULIO
P10: AGOSTO
B11: Fecha reporte | D11: 46356 | P11: SEPTIEMBRE
P12: OCTUBRE
B13: Clasificación del servicio | H13: Reporte mes por servicio | J13: Reporte acumulado por servicio | P13: NOVIEMBRE
B14: Ítem general | C14: ítem actividad | D14: Descripción de la actividad | E14: Soporte | F14: Medio de entrega | G14: Días contratados | H14: Días | I14: % avance | J14: Días | K14: % avance | P14: DICIEMBRE
F15: Digital | G15: =ENERO!G15 -> 0 | I15: =IFERROR(H15/G15,0) -> 0 | J15: =H15+OCTUBRE!J15 -> 0 | K15: =IFERROR(J15/G15,0) -> 0
F16: Digital | G16: =ENERO!G16 -> 0 | I16: =IFERROR(H16/G16,0) -> 0 | J16: =H16+OCTUBRE!J16 -> 0 | K16: =IFERROR(J16/G16,0) -> 0
F17: Digital | G17: =ENERO!G17 -> 0 | I17: =IFERROR(H17/G17,0) -> 0 | J17: =H17+OCTUBRE!J17 -> 0 | K17: =IFERROR(J17/G17,0) -> 0
F18: Digital | G18: =ENERO!G18 -> 0 | I18: =IFERROR(H18/G18,0) -> 0 | J18: =H18+OCTUBRE!J18 -> 0 | K18: =IFERROR(J18/G18,0) -> 0
F19: Digital | G19: =ENERO!G19 -> 0 | I19: =IFERROR(H19/G19,0) -> 0 | J19: =H19+OCTUBRE!J19 -> 0 | K19: =IFERROR(J19/G19,0) -> 0
F20: Digital | G20: =ENERO!G20 -> 0 | I20: =IFERROR(H20/G20,0) -> 0 | J20: =H20+OCTUBRE!J20 -> 0 | K20: =IFERROR(J20/G20,0) -> 0
F21: Digital | G21: =ENERO!G21 -> 0 | I21: =IFERROR(H21/G21,0) -> 0 | J21: =H21+OCTUBRE!J21 -> 0 | K21: =IFERROR(J21/G21,0) -> 0
F22: Digital | G22: =ENERO!G22 -> 0 | I22: =IFERROR(H22/G22,0) -> 0 | J22: =H22+OCTUBRE!J22 -> 0 | K22: =IFERROR(J22/G22,0) -> 0
F23: Digital | G23: =ENERO!G23 -> 0 | I23: =IFERROR(H23/G23,0) -> 0 | J23: =H23+OCTUBRE!J23 -> 0 | K23: =IFERROR(J23/G23,0) -> 0
F24: Digital | G24: =ENERO!G24 -> 0 | I24: =IFERROR(H24/G24,0) -> 0 | J24: =H24+OCTUBRE!J24 -> 0 | K24: =IFERROR(J24/G24,0) -> 0
F25: Digital | G25: =ENERO!G25 -> 0 | I25: =IFERROR(H25/G25,0) -> 0 | J25: =H25+OCTUBRE!J25 -> 0 | K25: =IFERROR(J25/G25,0) -> 0
F26: Digital | G26: =ENERO!G26 -> 0 | I26: =IFERROR(H26/G26,0) -> 0 | J26: =H26+OCTUBRE!J26 -> 0 | K26: =IFERROR(J26/G26,0) -> 0
... F33: Digital | G33: =ENERO!G33 -> 0 | I33: =IFERROR(H33/G33,0) -> 0 | J33: =H33+OCTUBRE!J33 -> 0 | K33: =IFERROR(J33/G33,0) -> 0
G34: =+CONCATENATE("TOTAL A ",D9) -> TOTAL A NOVIEMBRE | J34: TOTAL ACUMULADO
G35: =+SUM(G15:G33) -> 0 | H35: =+SUM(H15:H33) -> 0 | I35: =IFERROR(H35/G35,0) -> 0 | J35: =+SUM(J15:J33) -> 0 | K35: =IFERROR(J35/G35,0) -> 0
B37: Observaciones: | D37: Describa en este espacio su observación
B38: ¿Se presentó algún aspecto o situación que afecte la ejecución y calidad de los entregables? (Marque con una X)
B40: PROFESIONAL
B41: SI | D41: Describa en este espacio su observación
B42: NO
B43: ¿Se presentó algún aspecto o situación que afecte la ejecución y calidad de los entregables? (Marque con una X)
B45: INTERVENTOR O LIDER
B46: SI | D46: Describa en este espacio su observación
B47: NO
B51: Revisa: | G51: Interventor:
A83: MES
...

Sheet DICIEMBRE
P1: MES
B2: REPORTE DE AVANCE | P2: ENERO
B3: Fecha: 29/06/2022 | E3: Version: 01 | I3: GP-F-23
P4: FEBRERO
B5: Código Orden de servicio | P5: MARZO
P6: ABRIL
B7: Nombre del profesional (Reporta) | P7: MAYO
P8: JUNIO
B9: Mes a reportar | D9: DICIEMBRE | P9: JULIO
P10: AGOSTO
B11: Fecha reporte | D11: 46387 | P11: SEPTIEMBRE
P12: OCTUBRE
B13: Clasificación del servicio | H13: Reporte mes por servicio | J13: Reporte acumulado por servicio | P13: NOVIEMBRE
B14: Ítem general | C14: ítem actividad | D14: Descripción de la actividad | E14: Soporte | F14: Medio de entrega | G14: Días contratados | H14: Días | I14: % avance | J14: Días | K14: % avance | P14: DICIEMBRE
F15: Digital | G15: =ENERO!G15 -> 0 | I15: =IFERROR(H15/G15,0) -> 0 | J15: =H15+NOVIEMBRE!J15 -> 0 | K15: =IFERROR(J15/G15,0) -> 0
F16: Digital | G16: =ENERO!G16 -> 0 | I16: =IFERROR(H16/G16,0) -> 0 | J16: =H16+NOVIEMBRE!J16 -> 0 | K16: =IFERROR(J16/G16,0) -> 0
F17: Digital | G17: =ENERO!G17 -> 0 | I17: =IFERROR(H17/G17,0) -> 0 | J17: =H17+NOVIEMBRE!J17 -> 0 | K17: =IFERROR(J17/G17,0) -> 0
F18: Digital | G18: =ENERO!G18 -> 0 | I18: =IFERROR(H18/G18,0) -> 0 | J18: =H18+NOVIEMBRE!J18 -> 0 | K18: =IFERROR(J18/G18,0) -> 0
F19: Digital | G19: =ENERO!G19 -> 0 | I19: =IFERROR(H19/G19,0) -> 0 | J19: =H19+NOVIEMBRE!J19 -> 0 | K19: =IFERROR(J19/G19,0) -> 0
F20: Digital | G20: =ENERO!G20 -> 0 | I20: =IFERROR(H20/G20,0) -> 0 | J20: =H20+NOVIEMBRE!J20 -> 0 | K20: =IFERROR(J20/G20,0) -> 0
F21: Digital | G21: =ENERO!G21 -> 0 | I21: =IFERROR(H21/G21,0) -> 0 | J21: =H21+NOVIEMBRE!J21 -> 0 | K21: =IFERROR(J21/G21,0) -> 0
F22: Digital | G22: =ENERO!G22 -> 0 | I22: =IFERROR(H22/G22,0) -> 0 | J22: =H22+NOVIEMBRE!J22 -> 0 | K22: =IFERROR(J22/G22,0) -> 0
F23: Digital | G23: =ENERO!G23 -> 0 | I23: =IFERROR(H23/G23,0) -> 0 | J23: =H23+NOVIEMBRE!J23 -> 0 | K23: =IFERROR(J23/G23,0) -> 0
F24: Digital | G24: =ENERO!G24 -> 0 | I24: =IFERROR(H24/G24,0) -> 0 | J24: =H24+NOVIEMBRE!J24 -> 0 | K24: =IFERROR(J24/G24,0) -> 0
F25: Digital | G25: =ENERO!G25 -> 0 | I25: =IFERROR(H25/G25,0) -> 0 | J25: =H25+NOVIEMBRE!J25 -> 0 | K25: =IFERROR(J25/G25,0) -> 0
F26: Digital | G26: =ENERO!G26 -> 0 | I26: =IFERROR(H26/G26,0) -> 0 | J26: =H26+NOVIEMBRE!J26 -> 0 | K26: =IFERROR(J26/G26,0) -> 0
... F33: Digital | G33: =ENERO!G33 -> 0 | I33: =IFERROR(H33/G33,0) -> 0 | J33: =H33+NOVIEMBRE!J33 -> 0 | K33: =IFERROR(J33/G33,0) -> 0
G34: =+CONCATENATE("TOTAL A ",D9) -> TOTAL A DICIEMBRE | J34: TOTAL ACUMULADO
G35: =+SUM(G15:G33) -> 0 | H35: =+SUM(H15:H33) -> 0 | I35: =IFERROR(H35/G35,0) -> 0 | J35: =+SUM(J15:J33) -> 0 | K35: =IFERROR(J35/G35,0) -> 0
B37: Observaciones: | D37: Describa en este espacio su observación
B38: ¿Se presentó algún aspecto o situación que afecte la ejecución y calidad de los entregables? (Marque con una X)
B40: PROFESIONAL
B41: SI | D41: Describa en este espacio su observación
B42: NO
B43: ¿Se presentó algún aspecto o situación que afecte la ejecución y calidad de los entregables? (Marque con una X)
B45: INTERVENTOR O LIDER
B46: SI | D46: Describa en este espacio su observación
B47: NO
B51: Revisa: | G51: Interventor:
A83: MES
...
