Workbook

Sheet ENERO
Q1: MES
B2: REPORTE DE AVANCE | Q2: ENERO
B3: Fecha: 29/06/2022 | F3: Version: 01 | J3: GP-F-23
Q4: FEBRERO
B5: Código Orden de servicio | D5: 90560321 | Q5: MARZO
Q6: ABRIL
B7: Mes a reportar | D7: ENERO | Q7: JULIO
Q8: AGOSTO
B9: Fecha reporte | D9: 46053 | Q9: SEPTIEMBRE
Q10: OCTUBRE
B11: Clasificación del servicio | I11: Reporte mes por servicio | K11: Reporte acumulado por servicio | Q11: NOVIEMBRE
B12: Ítem general | C12: ítem actividad | D12: Descripción de la actividad | E12: Profesional Responsable | F12: Soporte | G12: Medio de entrega | H12: Días contratados | I12: Días | J12: % avance | K12: Días | L12: % avance | Q12: DICIEMBRE
B13: 1 | C13: 1.24 | D13: Caracterización composicional de fluidos de hidrocarburos mediante técnicas geoquímicas. | E13: Adriana Patricia Dueñes Garces | F13: https://ecopetrol-my.sharepoint.com/:w:/r/personal/adrianapa_duenes_ecopetrol_com_co1/Documents/Informe%20Final_Llanito%2045-Integrado.docx?d=wa48a58a7ff874ec3a8e419c5fbd3780f&csf=1&web=1&e=kTiIiW | G13: Digital | H13: 110 | I13: 8 | J13: =IFERROR(I13/H13,0) -> 0.072727273 | K13: =I13 -> 8 | L13: =IFERROR(K13/H13,0) -> 0.072727273
B14: 1 | C14: 1.25 | D14: Análisis geoquímicos de Fingerprinting | F14: https://ecopetrol-my.sharepoint.com/:w:/r/personal/adrianapa_duenes_ecopetrol_com_co1/Documents/Informe%20Final_Llanito%2045-Integrado.docx?d=wa48a58a7ff874ec3a8e419c5fbd3780f&csf=1&web=1&e=kTiIiW | G14: Digital | H14: 115 | I14: 7 | J14: =IFERROR(I14/H14,0) -> 0.060869565 | K14: =I14 -> 7 | L14: =IFERROR(K14/H14,0) -> 0.060869565
B15: 1 | C15: 1.24 | D15: Caracterización composicional de fluidos de hidrocarburos mediante técnicas geoquímicas. | E15: Mario Augusto Moreno Castellanos | F15: Informe | G15: miguel.jimenezja@ecopetrol.com.co | H15: 35 | I15: 7 | J15: =IFERROR(I15/H15,0) -> 0.2 | K15: =I15 -> 7 | L15: =IFERROR(K15/H15,0) -> 0.2
B16: 1 | C16: 1.25 | D16: Análisis geoquímicos de Fingerprinting | F16: Informe | G16: miguel.jimenezja@ecopetrol.com.co | H16: 40 | I16: 8 | J16: =IFERROR(I16/H16,0) -> 0.2 | K16: =I16 -> 8 | L16: =IFERROR(K16/H16,0) -> 0.2
B17: 1 | C17: 1.24 | D17: Caracterización composicional de fluidos de hidrocarburos mediante técnicas geoquímicas. | E17: Julio Cesar Figueroa Vega | F17: Informe PDF recopilación de la informacion disponible para la caracterizacion de crudos en la cuenca del valle medio y llanos | G17: Digital, se envia por correo los respectivos formatos y el documento final | H17: 165 | I17: 15 | J17: =IFERROR(I17/H17,0) -> 0.090909091 | K17: =I17 -> 15 | L17: =IFERROR(K17/H17,0) -> 0.090909091
B18: 1 | C18: 1.24 | D18: Caracterización composicional de fluidos de hidrocarburos mediante técnicas geoquímicas. | E18: Jully Marcela Ortegon Barrera | F18: Informe - Estudio de Petroleómica aplicada a crudos alterados | G18: Archivo digital procesado | H18: 165 | I18: 15 | J18: =IFERROR(I18/H18,0) -> 0.090909091 | K18: =I18 -> 15 | L18: =IFERROR(K18/H18,0) -> 0.090909091
B19: 1 | C19: 1.25 | D19: Análisis geoquímicos de Fingerprinting | E19: Oscar Fabian Suarez Suarez | F19: Análisis geoquímico - Informe | G19: Digital enviado a miguel.jimenezja@ecopetrol.com.co | H19: 75 | I19: 15 | J19: =IFERROR(I19/H19,0) -> 0.2 | K19: =I19 -> 15 | L19: =IFERROR(K19/H19,0) -> 0.2
B20: 1 | C20: 1.25 | D20: Análisis geoquímicos de Fingerprinting | E20: Mauricio Andres Vasquez Pinto | F20: Análisis geoquímico - Informe | G20: Digital | H20: 75 | I20: 15 | J20: =IFERROR(I20/H20,0) -> 0.2 | K20: =I20 -> 15 | L20: =IFERROR(K20/H20,0) -> 0.2
B21: 1 | C21: 1.16 | D21: Georeferenciación de Mapas, pozos, Imágenes satélite, etc. y Definición de CRS (Cordinates Reference System) | E21: Jorge Eduardo Paiba Alzate | F21: Información georreferenciada | G21: Digital | H21: 75 | I21: 0 | J21: =IFERROR(I21/H21,0) -> 0 | K21: =I21 -> 0 | L21: =IFERROR(K21/H21,0) -> 0
B22: 1 | C22: 1.22 | D22: Modelos Digitales de Afloramiento a partir de fotogrametría | F22: Modelo digital 3D - Informe | G22: Digital | H22: 75 | I22: 0 | J22: =IFERROR(I22/H22,0) -> 0 | K22: =I22 -> 0 | L22: =IFERROR(K22/H22,0) -> 0
B23: 1 | C23: 1.26 | D23: Análisis e interpretación de imágenes de satélite | F23: Imagen clasificada - Informe | G23: Digital | H23: 75 | I23: 15 | J23: =IFERROR(I23/H23,0) -> 0.2 | K23: =I23 -> 15 | L23: =IFERROR(K23/H23,0) -> 0.2
B24: 1 | C24: 1.19 | D24: Procesamiento sísmico en tiempo y/o profundidad | E24: Sergio Fernando Poveda Salazar | F24: 2.1. • Correos enviados al equipo de sismología y correspondientes campos (Edwin Mayorga, Esteban Poveda, Nelson Pérez, campos monitoreados). 2.2. "…\OneDrive - Ecopetrol S.A\SFPS\MODFLOW\0 - CAÑO SUR ESTE\202601_pruebas_cse_calibracion" à Carpeta OneDrive compartida por Nelson Pérez 2.3. \\10.100.25.60\nfs\SISMOLOGIA\ENTREGABLES MERIDIAN\Sergio Poveda\2026\2026-01 - Enero - Entregables\seis_viewer_v2 2.4. \\10.100.25.60\nfs\SISMOLOGIA\ENTREGABLES MERIDIAN\Sergio Poveda\2026\2026-01 - Enero - Entregables\seismic_report_ecp | G24: Digital | H24: 225 | I24: 15 | J24: =IFERROR(I24/H24,0) -> 0.066666667 | K24: =I24 -> 15 | L24: =IFERROR(K24/H24,0) -> 0.066666667
B25: 1 | C25: 1.19 | D25: Procesamiento sísmico en tiempo y/o profundidad | E25: Edwin Fabian Mayorga Lopez | F25: Actualización de los catálogos de inyección y sismicidad para Rubiales, Quifa Y Caño Sur, hasta el 20 de enero 2026. Informe mensual relación entre la sismicidad y la inyección para los PAD3, PAD4 y PAD5 diciembre de 2025. Informe mensual relación sismicidad inyección para el PAD RB555 diciembre de 2025. Plan preliminar de trabajo durante 2026 con SeisComP. | G25: Digital en la carpeta de sismología: \\10.100.25.60\nfs\SISMOLOGIA\ENTREGABLES MERIDIAN\Edwin Mayorga\2026\enero\Entregables | H25: 225 | I25: 15 | J25: =IFERROR(I25/H25,0) -> 0.066666667 | K25: =I25 -> 15 | L25: =IFERROR(K25/H25,0) -> 0.066666667
H26: =+CONCATENATE("TOTAL A ",D7) -> TOTAL A ENERO | K26: TOTAL ACUMULADO
H27: =+SUM(H13:H25) -> 1455 | I27: =+SUM(I13:I25) -> 135 | J27: =IFERROR(I27/H27,0) -> 0.092783505 | K27: =+SUM(K13:K25) -> 135 | L27: =IFERROR(K27/H27,0) -> 0.092783505
B29: Observaciones: | D29: 1.24 1.25 Especialista (MM): * Informe de caracterización geoquímica de muestras a partir de cromatografía gaseosa (GC-FID) en fluidos circundantes al pozo la Cira-1625KRST-1 con el fin de determinar tendencias, familias o características propias del entorno, las cuales se compararán con la información de análisis geoquímicos que se obtendrán del pozo Cira-1625KRST-1.
D30: 1.24 1.25 Especialista (AD): * Se realizó la evaluación e integración de nuevos estudios y datos geoquímicos al IANR llanito-45 para dar respuesta a las autoridades por contaminación ambiental el los predios del Campo Llanito, se realiza la entrega por medio de SharePoint. * Se inició la interpretación de los datos obtenidos para el Barrio 25 de agosto
D31: 1.24 Senior (JF): El objeto central de este estudio es establecer una línea base geoquímica detallada de crudos frescos para luego evaluar, de manera sistemática y controlada, cómo los procesos de intemperismo (físicos, químicos y biológicos) modifican su composición molecular y propiedades fisicoquímicas.
D32: 1.16 1.22 1.26 Senior (JP): El trabajo realizado aportó al desarrollo de una de las actividades de la orden de servicio y seguira desarrollandose los siguientes meses.
D33: 1.2 Basico (SP) Este mes se generaron los reportes diarios de sismicidad y alertas sísmicas, además de colaborar con la actualización del visor de sismicidad de Dash y la rutina de generación de reportes diarios y alertas sísmicas, entre otras.
D34: 1.19 Junior (EM): * Actualización los catálogos de inyección y sismicidad para Rubiales, Quifa Y Caño Sur (20 enero 2026). * Informe mensual de la relación entre la sismicidad y la inyección para los PAD3, PAD4 y PAD5 de diciembre de 2025. * Informe mensual de la relación sismicidad inyección para el PAD RB555 de diciembre de 2025. * Plan preliminar de trabajo durante 2026 con SeisComP.
B35: ¿Se presentó algún aspecto o situación que afecte la ejecución y calidad de los entregables? (Marque con una X)
B37: PROFESIONAL
B38: SI | D38: Describa en este espacio su observación
B39: NO
B40: ¿Se presentó algún aspecto o situación que afecte la ejecución y calidad de los entregables? (Marque con una X)
B42: INTERVENTOR O LIDER
B43: SI | D43: Describa en este espacio su observación
...

Sheet FEBRERO
Q1: MES
B2: REPORTE DE AVANCE | Q2: ENERO
B3: Fecha: 29/06/2022 | F3: Version: 01 | J3: GP-F-23
Q4: FEBRERO
B5: Código Orden de servicio | D5: 90560321 | Q5: MARZO
Q6: ABRIL
B7: Mes a reportar | D7: FEBRERO | Q7: JULIO
Q8: AGOSTO
B9: Fecha reporte | D9: 46081 | Q9: SEPTIEMBRE
Q10: OCTUBRE
B11: Clasificación del servicio | I11: Reporte mes por servicio | K11: Reporte acumulado por servicio | Q11: NOVIEMBRE
B12: Ítem general | C12: ítem actividad | D12: Descripción de la actividad | E12: Profesional Responsable | F12: Soporte | G12: Medio de entrega | H12: Días contratados | I12: Días | J12: % avance | K12: Días | L12: % avance | Q12: DICIEMBRE
B13: 1 | C13: 1.24 | D13: Caracterización composicional de fluidos de hidrocarburos mediante técnicas geoquímicas. | E13: Adriana Patricia Dueñes Garces | F13: Informe a Miguel Jimenez por correo electrónico | G13: Digital | H13: 110 | I13: 15 | J13: =IFERROR(I13/H13,0) -> 0.13636364 | K13: =I13+ENERO!K13 -> 23 | L13: =IFERROR(K13/H13,0) -> 0.20909091
B14: 1 | C14: 1.25 | D14: Análisis geoquímicos de Fingerprinting | F14: Informe enviado a Miguel Jimenez por correo electrónico | G14: Digital | H14: 115 | I14: 15 | J14: =IFERROR(I14/H14,0) -> 0.13043478 | K14: =I14+ENERO!K14 -> 22 | L14: =IFERROR(K14/H14,0) -> 0.19130435
B15: 1 | C15: 1.24 | D15: Caracterización composicional de fluidos de hidrocarburos mediante técnicas geoquímicas. | E15: Mario Augusto Moreno Castellanos | F15: Informe | G15: miguel.jimenezja@ecopetrol.com.co | H15: 35 | I15: 15 | J15: =IFERROR(I15/H15,0) -> 0.42857143 | K15: =I15+ENERO!K15 -> 22 | L15: =IFERROR(K15/H15,0) -> 0.62857143
B16: 1 | C16: 1.25 | D16: Análisis geoquímicos de Fingerprinting | F16: Informe | G16: miguel.jimenezja@ecopetrol.com.co | H16: 40 | I16: 15 | J16: =IFERROR(I16/H16,0) -> 0.375 | K16: =I16+ENERO!K16 -> 23 | L16: =IFERROR(K16/H16,0) -> 0.575
B17: 1 | C17: 1.24 | D17: Caracterización composicional de fluidos de hidrocarburos mediante técnicas geoquímicas. | E17: Julio Cesar Figueroa Vega | F17: Informe PDF recopilación de la informacion disponible para la caracterizacion de crudos en la cuenca del valle medio y llanos | G17: Digital, se envia por correo los respectivos formatos y el documento final | H17: 165 | I17: 30 | J17: =IFERROR(I17/H17,0) -> 0.18181818 | K17: =I17+ENERO!K17 -> 45 | L17: =IFERROR(K17/H17,0) -> 0.27272727
B18: 1 | C18: 1.24 | D18: Caracterización composicional de fluidos de hidrocarburos mediante técnicas geoquímicas. | E18: Jully Marcela Ortegon Barrera | F18: Informe - Estudio de Petroleómica aplicada a crudos alterados | G18: Archivo digital procesado | H18: 165 | I18: 30 | J18: =IFERROR(I18/H18,0) -> 0.18181818 | K18: =I18+ENERO!K18 -> 45 | L18: =IFERROR(K18/H18,0) -> 0.27272727
B19: 1 | C19: 1.25 | D19: Análisis geoquímicos de Fingerprinting | E19: Oscar Fabian Suarez Suarez | F19: Análisis geoquímico - Informe | G19: Digital enviado a miguel.jimenezja@ecopetrol.com.co | H19: 75 | I19: 30 | J19: =IFERROR(I19/H19,0) -> 0.4 | K19: =I19+ENERO!K19 -> 45 | L19: =IFERROR(K19/H19,0) -> 0.6
B20: 1 | C20: 1.25 | D20: Análisis geoquímicos de Fingerprinting | E20: Mauricio Andres Vasquez Pinto | F20: Análisis geoquímico - Informe | G20: Digital | H20: 75 | I20: 30 | J20: =IFERROR(I20/H20,0) -> 0.4 | K20: =I20+ENERO!K20 -> 45 | L20: =IFERROR(K20/H20,0) -> 0.6
B21: 1 | C21: 1.16 | D21: Georeferenciación de Mapas, pozos, Imágenes satélite, etc. y Definición de CRS (Cordinates Reference System) | E21: Jorge Eduardo Paiba Alzate | F21: Información georreferenciada | G21: Digital | H21: 75 | I21: 10 | J21: =IFERROR(I21/H21,0) -> 0.13333333 | K21: =I21+ENERO!K21 -> 10 | L21: =IFERROR(K21/H21,0) -> 0.13333333
B22: 1 | C22: 1.22 | D22: Modelos Digitales de Afloramiento a partir de fotogrametría | F22: Modelo digital 3D - Informe | G22: Digital | H22: 75 | I22: 10 | J22: =IFERROR(I22/H22,0) -> 0.13333333 | K22: =I22+ENERO!K22 -> 10 | L22: =IFERROR(K22/H22,0) -> 0.13333333
B23: 1 | C23: 1.26 | D23: Análisis e interpretación de imágenes de satélite | F23: Imagen clasificada - Informe | G23: Digital | H23: 75 | I23: 10 | J23: =IFERROR(I23/H23,0) -> 0.13333333 | K23: =I23+ENERO!K23 -> 25 | L23: =IFERROR(K23/H23,0) -> 0.33333333
B24: 1 | C24: 1.19 | D24: Procesamiento sísmico en tiempo y/o profundidad | E24: Sergio Fernando Poveda Salazar | F24: * Turnos de vigilancia para alertas de sismicidad y reportes diarios de sismicidad (CA, RB, CSE, QF) * Visor de sismicidad – Aplicación Dash (RB, CA, QF, CSE, CH) * Rutina de código para reportes diarios y alertas sísmicas (RB, CSE, CA) * Reportes mensuales autoridades ambientales – RB555, PADs 3, 4 y 5 (RB) * Resumen mensual de sismicidad e inyección (CA) | G24: * Correos enviados al equipo de sismología y correspondientes campos (Edwin Mayorga, Esteban Poveda, Nelson Pérez, campos monitoreados). * \\10.100.25.60\nfs\SISMOLOGIA\ENTREGABLES MERIDIAN\Sergio Poveda\2026\2026-02 - Febrero - Entregables\seis_viewer_v2 * \\10.100.25.60\nfs\SISMOLOGIA\ENTREGABLES MERIDIAN\Sergio Poveda\2026\2026-02 - Febrero - Entregables\seismic_report * \\10.100.25.60\nfs\SISMOLOGIA\ENTREGABLES MERIDIAN\Sergio Poveda\2026\2026-02 - Febrero - Entregables\ 20260225_IS38_Ene_2026_RB555.doc \\10.100.25.60\nfs\SISMOLOGIA\ENTREGABLES MERIDIAN\Sergio Poveda\2026\2026-02 - Febrero - Entregables\ 20260225_IS93_Ene_2026_ANH_PAD3_4_5.doc * \\10.100.25.60\nfs\SISMOLOGIA\ENTREGABLES MERIDIAN\Sergio Poveda\2026\2026-02 - Febrero - Entregables\ 20260210_Seguimiento_inyeccion_Enero2026.ppt | H24: 225 | I24: 30 | J24: =IFERROR(I24/H24,0) -> 0.13333333 | K24: =I24+ENERO!K24 -> 45 | L24: =IFERROR(K24/H24,0) -> 0.2
B25: 1 | C25: 1.19 | D25: Procesamiento sísmico en tiempo y/o profundidad | E25: Edwin Fabian Mayorga Lopez | F25: Presentación de seguimiento de sismicidad inyección del 1° noviembre de 2025 al 9 de febrero para el campo Rubiales. Informe anual relación sismicidad inyección para el PAD RB555 durante 2025. Reportes semanales de la calidad de las estaciones de la red Rubiales y Cano Sur Este. Presentación semanal configuración del sistema SeisComP, conforme al plan de trabajo. | G25: Digital en la carpeta de sismología: \\10.100.25.60\nfs\SISMOLOGIA\ENTREGABLES MERIDIAN\Edwin Mayorga\2026\febrero\Entregables | H25: 225 | I25: 30 | J25: =IFERROR(I25/H25,0) -> 0.13333333 | K25: =I25+ENERO!K25 -> 45 | L25: =IFERROR(K25/H25,0) -> 0.2
H26: =+CONCATENATE("TOTAL A ",D7) -> TOTAL A FEBRERO | K26: TOTAL ACUMULADO
H27: =+SUM(H13:H25) -> 1455 | I27: =+SUM(I13:I25) -> 270 | J27: =IFERROR(I27/H27,0) -> 0.18556701 | K27: =+SUM(K13:K25) -> 405 | L27: =IFERROR(K27/H27,0) -> 0.27835052
B29: Observaciones: | D29: 1.24 1.25 Especialista (MM): Avance del Informe de caracterización geoquímica de muestras a partir de cromatografía gaseosa (GC-FID) en fluidos circundantes al pozo la Cira-1625KRST-1 con el fin de determinar tendencias, familias o características propias del entorno, las cuales se compararán con la información de análisis geoquímicos que se obtendrán del pozo Cira-1625KRST-1.
D30: 1.24 1.25 Especialista (AD): * Se realizó la evaluación e integración de la geoquímica para dar respuesta a las autoridades por contaminación ambiental del pozo de agua El Rodeo cercano al predio de Belkys en el Campo Llanito, se realiza la entrega por medio de correo electrónico. * Se realizó la interpretación geoquímica e integración de los datos de geología y estructuras asociadas a la manifestación de crudo en superficie en el área de Fortuna, Campo Lisama, para dar respuesta a las autoridades Ambientales por la presunta contaminación de los predios, se realiza la entrega por medio de correo electrónico.
D31: 1.24 Senior (JF): El objeto central de este estudio es establecer una línea base geoquímica detallada de crudos frescos para luego evaluar, de manera sistemática y controlada, cómo los procesos de intemperismo (físicos, químicos y biológicos) modifican su composición molecular y propiedades fisicoquímicas.
D32: 1.16 1.22 1.26 Senior (JP): El trabajo realizado aportó al desarrollo de las actividades de la orden de servicio y seguiran desarrollandose los siguientes meses.
D33: 1.2 Basico (SP) Este mes se generaron los reportes diarios de sismicidad y alertas sísmicas, además de colaborar con la actualización del visor de sismicidad de Dash, la rutina de generación de reportes diarios y alertas sísmicas, la creación del resumen de sismicidad e inyección, entre otras.
D34: 1.19 Junior (EM): En este periodo se elaboró: 1) Presentación de seguimiento de sismicidad inyección del 1° noviembre de 2025 al 9 de febrero para el campo Rubiales. 2) Informe anual de la relación sismicidad inyección para el PAD RB555 durante 2025. 3) Reportes semanales de la calidad de las estaciones de la red Rubiales y la red Cano Sur Este 4) Presentación sobre la configuración del sistema SeisComP, conforme al plan de trabajo.
B35: ¿Se presentó algún aspecto o situación que afecte la ejecución y calidad de los entregables? (Marque con una X)
B37: PROFESIONAL
B38: SI | D38: Describa en este espacio su observación
B39: NO
B40: ¿Se presentó algún aspecto o situación que afecte la ejecución y calidad de los entregables? (Marque con una X)
B42: INTERVENTOR O LIDER
B43: SI | D43: Describa en este espacio su observación
...
