Workbook

Sheet ENERO
P1: MES
B2: REPORTE DE AVANCE | P2: ENERO
B3: Fecha: 29/06/2022 | E3: Version: 01 | I3: GP-F-23
P4: FEBRERO
B5: Código Orden de servicio | D5: 90594501 | P5: MARZO
P6: JUNIO
B7: Mes a reportar | D7: ENERO | P7: JULIO
P8: AGOSTO
B9: Fecha reporte | D9: 46053 | P9: SEPTIEMBRE
P10: OCTUBRE
B11: Clasificación del servicio | H11: Reporte mes por servicio | J11: Reporte acumulado por servicio | P11: NOVIEMBRE
B12: Ítem general | C12: ítem actividad | D12: Descripción de la actividad | E12: Soporte | F12: Medio de entrega | G12: Días contratados | H12: Días | I12: % avance | J12: Días | K12: % avance | P12: DICIEMBRE
B13: 3 | C13: 3.1 | D13: Crear un modelo de simulación dinámica cuando esté disponible el modelo estático: identificación, organización, revisión y análisis del modelo estático, fluido, roca, producción, terminación y datos de laboratorio que sean válidos y representativos del reservorio que se está investigando. Realice el QA/QC del modelo estático y defina la incertidumbre principal en los parámetros de comparación de modelo e parámetros de ajuste histórico, trabaje en estrecha colaboración con el geomodelador para el upscaling del modelo estático al modelo de simulación, ajustar el modelo con los datos de producción e inyección y realizar el ajuste histórico. Realizar previsión y construir plan de desarrollo de campo | E13: - | F13: - | G13: 32 | H13: 0 | I13: =IFERROR(H13/G13,0) -> 0 | J13: =+H13 -> 0 | K13: =IFERROR(J13/G13,0) -> 0
B14: 3 | C14: 3.2 | D14: Realizar el ajuste histórico del modelo de simulación: realizar actividades de ajuste histórico con diferentes variables según la disponibilidad y la calidad de los datos. Llevar a cabo flujos de trabajo iterativos en los que los primeros esfuerzos de ajuste histórico sean con iteraciones con el modelo estático, la reconstrucción y el refinamiento del modelo, en lugar de simplemente realizar arreglos (multiplicadores de porosidad y permeabilidad) dentro del modelo a escala de simulación. El ajuste incluye, perfiles de producción e inyección, presiones totales inferiores, presión estática y perfiles de registro de inyección | E14: - | F14: - | G14: 20 | H14: 0 | I14: =IFERROR(H14/G14,0) -> 0 | J14: =+H14 -> 0 | K14: =IFERROR(J14/G14,0) -> 0
B15: 3 | C15: 3.3 | D15: Realice el plan de desarrollo de campo y los pronósticos: realizando todos los pronósticos de escenarios de simulación para llevar a cabo la planificación del desarrollo de campo, esto incluye investigar y realizar análisis de sensibilidad e incertidumbre de los principales parámetros coincidentes de la historia y las incógnitas y su efecto en el pronóstico. | E15: - | F15: - | G15: 15 | H15: 0 | I15: =IFERROR(H15/G15,0) -> 0 | J15: =+H15 -> 0 | K15: =IFERROR(J15/G15,0) -> 0
B16: 3 | C16: 3.7 | D16: Inventario y acceso a raw data de puntos de presión (Pre-Test) tomados con probadores de formación (RDT (Halliburton), MDT (Schlumberger), MFT (Weatherford), etc.). La raw data debe contener por profundidad probada: valores de presión, temperatura, caudales inducidos (cc/seg) y volúmenes asociados de cámara pre-test (cc). | E16: - | F16: - | G16: 8 | H16: 0 | I16: =IFERROR(H16/G16,0) -> 0 | J16: =+H16 -> 0 | K16: =IFERROR(J16/G16,0) -> 0
B17: 3 | C17: 3.11 | D17: Análisis de interpretación de datos de pruebas de presión - producción (DSTs, PBU, Pruebas Extendidas Producción, Gradientes Estáticos - Dinámicos PT, etc.) o de presión inyección (Inyectividad, SRT, FOT) aplicadas ya sea en tiempo real, memorizadas o con sarta temporal DST. Integración Probador Formación - registros Open Hole. | E17: - | F17: - | G17: 8 | H17: 0 | I17: =IFERROR(H17/G17,0) -> 0 | J17: =+H17 -> 0 | K17: =IFERROR(J17/G17,0) -> 0
B18: 3 | C18: 3.13 | D18: Generar base de datos de producción (OFM o la que se requiera) | E18: Actualización periódica (diaria) tablero de seguimiento Power BI con el comportamiento y producción de los pozos Capachos & Andina y Arauca (diaria) | F18: En ruta: VAS\31. GAN_ARAUCA\13. Arauca 2025\Seguimiento Desempeño Pozos y VAS\23. GAN_CAPACHOS-ANDINA\00. 2025\01 Seguimiento de Producción\02 Seguimiento desempeño pozos | G18: 32 | H18: 4 | I18: =IFERROR(H18/G18,0) -> 0.125 | J18: =+H18 -> 4 | K18: =IFERROR(J18/G18,0) -> 0.125
B19: 3 | C19: 3.15 | D19: Generar Balance de Materia por campo y/o por subunidad y/o por compartimiento | E19: - | F19: - | G19: 10 | H19: 0 | I19: =IFERROR(H19/G19,0) -> 0 | J19: =+H19 -> 0 | K19: =IFERROR(J19/G19,0) -> 0
B20: 3 | C20: 3.16 | D20: Análisis de Declinaciones por pozo y/o subunidad | E20: Revisión de volúmenes VT Plan 3 para el activo Arauca y Capachos, dichos volúmenes fueron migrados a Planning Space para corrida financiera de flujos de caja. | F20: Revisado en software ValNav y enviado correo a alejandro.lopezru@ecopetrol.com.co el 13 de enero y de Capachos a leydy.jerez@ecopetrol.com.co el 16 de enero | G20: 20 | H20: 6 | I20: =IFERROR(H20/G20,0) -> 0.3 | J20: =+H20 -> 6 | K20: =IFERROR(J20/G20,0) -> 0.3
B21: 3 | C21: 3.17 | D21: Analizar data histórica de producción, productividad y daño por pozo | E21: Revisión preliminar y final de flujos de caja corridos para los activos Capachos y Arauca, validando volúmenes de aceite y blancos (líquidos) y gas (ventas y consumos) para todas las categorías (Probadas, probables y posibles). | F21: Cargado en rutas: VAS\23. GAN_CAPACHOS-ANDINA\00. 2025\03 Auditoria IRR 2024 IMR 2025\07 Flujos de Caja auditoira 2025 y VAS\31. GAN_ARAUCA\13. Arauca 2025\Auditoria 2025\Flujos de caja 2025 | G21: 18 | H21: 6 | I21: =IFERROR(H21/G21,0) -> 0.33333333 | J21: =+H21 -> 6 | K21: =IFERROR(J21/G21,0) -> 0.33333333
B22: 3 | C22: 3.18 | D22: Generar perfiles de Producción por pozos para pozos existente en escenarios Bajo, Medio y Alto | E22: Generar perfiles de Producción por pozos para pozos existente en escenarios Bajo, Medio y Alto | F22: Trabajado en ppt Teams directamente en grupo de trabajo: Andina Limon GET | G22: 10 | H22: 2 | I22: =IFERROR(H22/G22,0) -> 0.2 | J22: =+H22 -> 2 | K22: =IFERROR(J22/G22,0) -> 0.2
B23: 5 | C23: 5.1 | D23: Generar bases de datos de Eventos de pozos | E23: - | F23: - | G23: 10 | H23: 0 | I23: =IFERROR(H23/G23,0) -> 0 | J23: =+H23 -> 0 | K23: =IFERROR(J23/G23,0) -> 0
B24: 5 | C24: 5.3 | D24: Estimar restricciones de Presión y tasas para la generación de perfiles de producción | E24: Generación de declaratoria de gas preliminar para los activos Capachos y Arauca visión Ecopetrol. | F24: Enviado a mail Alba.Calderon@ecopetrol.com.co el 19 de enero | G24: 10 | H24: 2 | I24: =IFERROR(H24/G24,0) -> 0.2 | J24: =+H24 -> 2 | K24: =IFERROR(J24/G24,0) -> 0.2
... B28: 5 | C28: 5.10 | D28: Adelantar en análisis y evaluación de datos enfocada a la ejecución de estudios de daño de formación | E28: - | F28: - | G28: 10 | H28: 0 | I28: =IFERROR(H28/G28,0) -> 0 | J28: =+H28 -> 0 | K28: =IFERROR(J28/G28,0) -> 0
G29: =+CONCATENATE("TOTAL A ",D7) -> TOTAL A ENERO | J29: TOTAL ACUMULADO
G30: =+SUM(G13:G28) -> 233 | H30: =+SUM(H13:H28) -> 23 | I30: =IFERROR(H30/G30,0) -> 0.098712446 | J30: =+SUM(J13:J28) -> 23 | K30: =IFERROR(J30/G30,0) -> 0.098712446
B32: Observaciones: | D32: * Actualización periódica (diaria) tablero de seguimiento Power BI con el comportamiento y producción de los pozos Capachos & Andina y Arauca (diaria) * Revisión de volúmenes VT Plan 3 para el activo Arauca y Capachos, dichos volúmenes fueron migrados a Planning Space para corrida financiera de flujos de caja. * Revisión preliminar y final de flujos de caja corridos para los activos Capachos y Arauca, validando volúmenes de aceite y blancos (líquidos) y gas (ventas y consumos) para todas las categorías (Probadas, probables y posibles). * Generar perfiles de Producción por pozos para pozos existente en escenarios Bajo, Medio y Alto * Generación de declaratoria de gas preliminar para los activos Capachos y Arauca visión Ecopetrol. * Revisión status pozo Andina Norte-2 con especialistas de daño de Ecopetrol y equipo técnico de Parex definiendo el plan de mejora de producción del pozo.
B33: ¿Se presentó algún aspecto o situación que afecte la ejecución y calidad de los entregables? (Marque con una X)
B35: PROFESIONAL
B36: SI | D36: Describa en este espacio su observación
B37: NO
B38: ¿Se presentó algún aspecto o situación que afecte la ejecución y calidad de los entregables? (Marque con una X)
B40: INTERVENTOR O LIDER
B41: SI | D41: Describa en este espacio su observación
B42: NO
B46: Revisa: | G46: Interventor: | H46: Mauricio Casanova Angarita
A78: MES
A79: ENERO
A80: FEBRERO
...

Sheet FEBRERO
P1: MES
B2: REPORTE DE AVANCE | P2: ENERO
B3: Fecha: 29/06/2022 | E3: Version: 01 | I3: GP-F-23
P4: FEBRERO
B5: Código Orden de servicio | D5: 90594501 | P5: MARZO
P6: JUNIO
B7: Mes a reportar | D7: FEBRERO | P7: JULIO
P8: AGOSTO
B9: Fecha reporte | D9: 46081 | P9: SEPTIEMBRE
P10: OCTUBRE
B11: Clasificación del servicio | H11: Reporte mes por servicio | J11: Reporte acumulado por servicio | P11: NOVIEMBRE
B12: Ítem general | C12: ítem actividad | D12: Descripción de la actividad | E12: Soporte | F12: Medio de entrega | G12: Días contratados | H12: Días | I12: % avance | J12: Días | K12: % avance | P12: DICIEMBRE
B13: 3 | C13: 3.1 | D13: Crear un modelo de simulación dinámica cuando esté disponible el modelo estático: identificación, organización, revisión y análisis del modelo estático, fluido, roca, producción, terminación y datos de laboratorio que sean válidos y representativos del reservorio que se está investigando. Realice el QA/QC del modelo estático y defina la incertidumbre principal en los parámetros de comparación de modelo e parámetros de ajuste histórico, trabaje en estrecha colaboración con el geomodelador para el upscaling del modelo estático al modelo de simulación, ajustar el modelo con los datos de producción e inyección y realizar el ajuste histórico. Realizar previsión y construir plan de desarrollo de campo | E13: Construcción del modelo dinámico de Andina y Capachos, para este mes se recopiló información de petrofísica validando los modelos utilizados en el modelo estático, además de información PVT para la construcción del modelo de fluidos. | F13: Cargado en sharepoint ruta: https://ecopetrol.sharepoint.com/sites/GerenciadeDesarrollo/PIDs/Forms/AllItems.aspx?e=5%3A5ef524e97cf54db4b669f603c52f1be8&sharingv2=true&fromShare=true&at=9&CT=1770823340471&OR=OWA%2DNT%2DMail&CID=0d13fa69%2Dd771%2D98ab%2De9e8%2D3e9adb96ab41&FolderCTID=0x0120006131DF9D7F194942ABC8C695DEB8E61A&id=%2Fsites%2FGerenciadeDesarrollo%2FPIDs%2FAndina%20%2D%20Capachos%202026&xsdata=MDV8MDJ8fDVkNWU5MmNkY2FjMjQzYTEyMTI1MDhkZTc2MTExZTAxfGE0MzA1OTg3Y2Y3ODRmOTM5ZDY0YmYxOGFmNjUzOTdifDB8MHw2MzkwNzgwMTMwMjMxMDEyMjF8VW5rbm93bnxWR1ZoYlhOVFpXTjFjbWwwZVZObGNuWnBZMlY4ZXlKRFFTSTZJbFJsWVcxelgwRlVVRk5sY25acFkyVmZVMUJQVEU5R0lpd2lWaUk2SWpBdU1DNHdNREF3SWl3aVVDSTZJbGRwYmpNeUlpd2lRVTRpT2lKUGRHaGxjaUlzSWxkVUlqb3hNWDA9fDF8TDJOb1lYUnpMekU1T20xbFpYUnBibWRmVDBSRmVFNXFiR2hhYW1kMFRUSk9hVTE1TURCYWFsSnRURlJvYlUxNlozUk9hbFY1VFhwVmVrNXFaM2hQVjBVMVFIUm9jbVZoWkM1Mk1pOXRaWE56WVdkbGN5OHhOemN5TWpBME5UQXdNekE1fGIxMWY1ODhkNDkxMDQxYTk4NDkyMDhkZTc2MTExZTAwfDRkNjgwZmQ5ZTFiYTRjNzc5MDJhZGU1MDFiZGE4OTQ1&sdata=ZG05N3VGa0VVeGkyY3BRY0wvM01UckdhNitVUjhXbDdIUEpQSEZFQVFFUT0%3D&ovuser=a4305987-cf78-4f93-9d64-bf18af65397b%2Cdiego.castilloba%40ecopetrol.com.co | G13: 32 | H13: 4 | I13: =IFERROR(H13/G13,0) -> 0.125 | J13: =+H13+ENERO!J13 -> 4 | K13: =IFERROR(J13/G13,0) -> 0.125
B14: 3 | C14: 3.2 | D14: Realizar el ajuste histórico del modelo de simulación: realizar actividades de ajuste histórico con diferentes variables según la disponibilidad y la calidad de los datos. Llevar a cabo flujos de trabajo iterativos en los que los primeros esfuerzos de ajuste histórico sean con iteraciones con el modelo estático, la reconstrucción y el refinamiento del modelo, en lugar de simplemente realizar arreglos (multiplicadores de porosidad y permeabilidad) dentro del modelo a escala de simulación. El ajuste incluye, perfiles de producción e inyección, presiones totales inferiores, presión estática y perfiles de registro de inyección | E14: - | F14: - | G14: 20 | H14: 0 | I14: =IFERROR(H14/G14,0) -> 0 | J14: =+H14+ENERO!J14 -> 0 | K14: =IFERROR(J14/G14,0) -> 0
B15: 3 | C15: 3.3 | D15: Realice el plan de desarrollo de campo y los pronósticos: realizando todos los pronósticos de escenarios de simulación para llevar a cabo la planificación del desarrollo de campo, esto incluye investigar y realizar análisis de sensibilidad e incertidumbre de los principales parámetros coincidentes de la historia y las incógnitas y su efecto en el pronóstico. | E15: - | F15: - | G15: 15 | H15: 0 | I15: =IFERROR(H15/G15,0) -> 0 | J15: =+H15+ENERO!J15 -> 0 | K15: =IFERROR(J15/G15,0) -> 0
B16: 3 | C16: 3.7 | D16: Inventario y acceso a raw data de puntos de presión (Pre-Test) tomados con probadores de formación (RDT (Halliburton), MDT (Schlumberger), MFT (Weatherford), etc.). La raw data debe contener por profundidad probada: valores de presión, temperatura, caudales inducidos (cc/seg) y volúmenes asociados de cámara pre-test (cc). | E16: Revisión de ecuación de estado para el activo Capachos generado por equipo encargado de caracterización de fluidos del departamento de servicios petrotécnicos, el cual es input del modelo dinámico a construir. | F16: Cargado en sharepoint ruta: https://ecopetrol.sharepoint.com/sites/GerenciadeDesarrollo/PIDs/Forms/AllItems.aspx?e=5%3A5ef524e97cf54db4b669f603c52f1be8&sharingv2=true&fromShare=true&at=9&CT=1770823340471&OR=OWA%2DNT%2DMail&CID=0d13fa69%2Dd771%2D98ab%2De9e8%2D3e9adb96ab41&FolderCTID=0x0120006131DF9D7F194942ABC8C695DEB8E61A&id=%2Fsites%2FGerenciadeDesarrollo%2FPIDs%2FAndina%20%2D%20Capachos%202026&xsdata=MDV8MDJ8fDVkNWU5MmNkY2FjMjQzYTEyMTI1MDhkZTc2MTExZTAxfGE0MzA1OTg3Y2Y3ODRmOTM5ZDY0YmYxOGFmNjUzOTdifDB8MHw2MzkwNzgwMTMwMjMxMDEyMjF8VW5rbm93bnxWR1ZoYlhOVFpXTjFjbWwwZVZObGNuWnBZMlY4ZXlKRFFTSTZJbFJsWVcxelgwRlVVRk5sY25acFkyVmZVMUJQVEU5R0lpd2lWaUk2SWpBdU1DNHdNREF3SWl3aVVDSTZJbGRwYmpNeUlpd2lRVTRpT2lKUGRHaGxjaUlzSWxkVUlqb3hNWDA9fDF8TDJOb1lYUnpMekU1T20xbFpYUnBibWRmVDBSRmVFNXFiR2hhYW1kMFRUSk9hVTE1TURCYWFsSnRURlJvYlUxNlozUk9hbFY1VFhwVmVrNXFaM2hQVjBVMVFIUm9jbVZoWkM1Mk1pOXRaWE56WVdkbGN5OHhOemN5TWpBME5UQXdNekE1fGIxMWY1ODhkNDkxMDQxYTk4NDkyMDhkZTc2MTExZTAwfDRkNjgwZmQ5ZTFiYTRjNzc5MDJhZGU1MDFiZGE4OTQ1&sdata=ZG05N3VGa0VVeGkyY3BRY0wvM01UckdhNitVUjhXbDdIUEpQSEZFQVFFUT0%3D&ovuser=a4305987-cf78-4f93-9d64-bf18af65397b%2Cdiego.castilloba%40ecopetrol.com.co | G16: 8 | H16: 2 | I16: =IFERROR(H16/G16,0) -> 0.25 | J16: =+H16+ENERO!J16 -> 2 | K16: =IFERROR(J16/G16,0) -> 0.25
B17: 3 | C17: 3.11 | D17: Análisis de interpretación de datos de pruebas de presión - producción (DSTs, PBU, Pruebas Extendidas Producción, Gradientes Estáticos - Dinámicos PT, etc.) o de presión inyección (Inyectividad, SRT, FOT) aplicadas ya sea en tiempo real, memorizadas o con sarta temporal DST. Integración Probador Formación - registros Open Hole. | E17: Entendimiento de los activos recibidos Aguas Blancas y Boranda, se agendaron sesiones para la entrega formal de los activos y entendimiento y estatus de cada activo. | F17: En ruta: VA\32. GAN_BORANDA\4. ING YTOS Y PRODUCCIÓN\RESERVAS Y RECURSOS\2025 y VAS\15. GAN_AGUAS BLANCAS\5. ING DE YTOS Y PROD\1. RESERVAS Y RECURSOS\2025 | G17: 8 | H17: 3 | I17: =IFERROR(H17/G17,0) -> 0.375 | J17: =+H17+ENERO!J17 -> 3 | K17: =IFERROR(J17/G17,0) -> 0.375
B18: 3 | C18: 3.13 | D18: Generar base de datos de producción (OFM o la que se requiera) | E18: Actualización periódica (diaria) tablero de seguimiento Power BI con el comportamiento y producción de los pozos Capachos & Andina y Arauca (diaria) | F18: En ruta: VAS\31. GAN_ARAUCA\13. Arauca 2025\Seguimiento Desempeño Pozos y VAS\23. GAN_CAPACHOS-ANDINA\00. 2025\01 Seguimiento de Producción\02 Seguimiento desempeño pozos | G18: 32 | H18: 4 | I18: =IFERROR(H18/G18,0) -> 0.125 | J18: =+H18+ENERO!J18 -> 8 | K18: =IFERROR(J18/G18,0) -> 0.25
B19: 3 | C19: 3.15 | D19: Generar Balance de Materia por campo y/o por subunidad y/o por compartimiento | E19: Análisis y justificación de volúmenes en Ecovol de los Campos Capachos, Capachos Sur y Arauca para reservas y recursos contingentes en aceite, gas y blancos. | F19: Cargado directamente en software interno Ecovol | G19: 10 | H19: 4 | I19: =IFERROR(H19/G19,0) -> 0.4 | J19: =+H19+ENERO!J19 -> 4 | K19: =IFERROR(J19/G19,0) -> 0.4
B20: 3 | C20: 3.16 | D20: Análisis de Declinaciones por pozo y/o subunidad | E20: - | F20: - | G20: 20 | H20: 0 | I20: =IFERROR(H20/G20,0) -> 0 | J20: =+H20+ENERO!J20 -> 6 | K20: =IFERROR(J20/G20,0) -> 0.3
B21: 3 | C21: 3.17 | D21: Analizar data histórica de producción, productividad y daño por pozo | E21: - | F21: - | G21: 18 | H21: 0 | I21: =IFERROR(H21/G21,0) -> 0 | J21: =+H21+ENERO!J21 -> 6 | K21: =IFERROR(J21/G21,0) -> 0.33333333
B22: 3 | C22: 3.18 | D22: Generar perfiles de Producción por pozos para pozos existente en escenarios Bajo, Medio y Alto | E22: - | F22: - | G22: 10 | H22: 0 | I22: =IFERROR(H22/G22,0) -> 0 | J22: =+H22+ENERO!J22 -> 2 | K22: =IFERROR(J22/G22,0) -> 0.2
B23: 5 | C23: 5.1 | D23: Generar bases de datos de Eventos de pozos | E23: Generación de nuevo perfil Arauca-8 de acuerdo con el comportamiento de presión en cabeza del pozo, además del incremento de corte de agua y revisión conjunta con el equipo Parex. | F23: Enviado a correo al mail: Edwin.Loaiza@ecopetrol.com.co el 17 de febrero de 2026 | G23: 10 | H23: 2 | I23: =IFERROR(H23/G23,0) -> 0.2 | J23: =+H23+ENERO!J23 -> 2 | K23: =IFERROR(J23/G23,0) -> 0.2
B24: 5 | C24: 5.3 | D24: Estimar restricciones de Presión y tasas para la generación de perfiles de producción | E24: Revisión final declaratorias de gas de los activos Capachos, Arauca, Boranda y aguas Blancas compartidos por Parex posterior a los ajustes solicitados. | F24: En ruta: VAS\23. GAN_CAPACHOS-ANDINA\00. 2025\17. Declaratoria de gas\2026 y VAS:\31. GAN_ARAUCA\13. Arauca 2025\Declaratoria de gas\2026 | G24: 10 | H24: 3 | I24: =IFERROR(H24/G24,0) -> 0.3 | J24: =+H24+ENERO!J24 -> 5 | K24: =IFERROR(J24/G24,0) -> 0.5
... B28: 5 | C28: 5.10 | D28: Adelantar en análisis y evaluación de datos enfocada a la ejecución de estudios de daño de formación | E28: Comparativo de declaratoria de gas equipos técnicos ECP – PRX que permitieron identificar diferencias en el Activo Arauca y en los Campos Capachos y Capachos Sur, los cuales fueron ajustados y enviados posteriormente por Parex. | F28: Enviado a correo al mail: manuel.gutierrez@parexresources.com, Santiago.olivos@parexresources.com, Jose.Redondo@parexresources.com por parte de Parex con copia a carlos.monzon@ecopetrol.com.co, Dora.Restrepo@ecopetrol.com.co por parte de ECP | G28: 10 | H28: 3 | I28: =IFERROR(H28/G28,0) -> 0.3 | J28: =+H28+ENERO!J28 -> 3 | K28: =IFERROR(J28/G28,0) -> 0.3
G29: =+CONCATENATE("TOTAL A ",D7) -> TOTAL A FEBRERO | J29: TOTAL ACUMULADO
G30: =+SUM(G13:G28) -> 233 | H30: =+SUM(H13:H28) -> 30 | I30: =IFERROR(H30/G30,0) -> 0.12875536 | J30: =+SUM(J13:J28) -> 53 | K30: =IFERROR(J30/G30,0) -> 0.22746781
B32: Observaciones: | D32: * Construcción del modelo dinámico de Andina y Capachos, para este mes se recopiló información de petrofísica validando los modelos utilizados en el modelo estático, además de información PVT para la construcción del modelo de fluidos. * Revisión de ecuación de estado para el activo Capachos generado por equipo encargado de caracterización de fluidos del departamento de servicios petrotécnicos, el cual es input del modelo dinámico a construir. * Entendimiento de los activos recibidos Aguas Blancas y Boranda, se agendaron sesiones para la entrega formal de los activos y entendimiento y estatus de cada activo. * Actualización periódica (diaria) tablero de seguimiento Power BI con el comportamiento y producción de los pozos Capachos & Andina y Arauca (diaria) * Análisis y justificación de volúmenes en Ecovol de los Campos Capachos, Capachos Sur y Arauca para reservas y recursos contingentes en aceite, gas y blancos. * Generación de nuevo perfil Arauca-8 de acuerdo con el comportamiento de presión en cabeza del pozo, además del incremento de corte de agua y revisión conjunta con el equipo Parex. * Revisión final declaratorias de gas de los activos Capachos, Arauca, Boranda y aguas Blancas compartidos por Parex posterior a los ajustes solicitados. * Revisión preliminar de volúmenes técnicos de auditoría de reservas enviados por parte de Parex para los campos Arauca, Capachos y Andina. * Análisis de perfil de Andina-4, comparando 3 perfiles para evaluación financiera: i) Perfil inicial de AR (Fm Barco+Guad+ALS), ii) Perfil ajustado con entrada de pozo (Fm Mir + ALS) y iii) Perfil final posterior a instalación de BES (Fm Mir+Bar+Guad+ALS). * Comparativo de declaratoria de gas equipos técnicos ECP – PRX que permitieron identificar diferencias en el Activo Arauca y en los Campos Capachos y Capachos Sur, los cuales fueron ajustados y enviados posteriormente por Parex.
B33: ¿Se presentó algún aspecto o situación que afecte la ejecución y calidad de los entregables? (Marque con una X)
B35: PROFESIONAL
B36: SI | D36: Describa en este espacio su observación
B37: NO
B38: ¿Se presentó algún aspecto o situación que afecte la ejecución y calidad de los entregables? (Marque con una X)
B40: INTERVENTOR O LIDER
B41: SI | D41: Describa en este espacio su observación
B42: NO
B46: Revisa: | G46: Interventor: | H46: Mauricio Casanova Angarita
A78: MES
A79: ENERO
A80: FEBRERO
...
