Workbook

Sheet ABRIL 2025
Q1: MES
B2: REPORTE DE AVANCE | Q2: ENERO
B3: Fecha: 29/06/2022 | F3: Version: 01 | J3: GP-F-23
Q4: FEBRERO
B5: Código Orden de servicio | D5: 90141005 | Q5: MARZO
Q6: JUNIO
B7: Mes a reportar | D7: ABRIL | Q7: JULIO
Q8: AGOSTO
B9: Fecha reporte | D9: 45777 | Q9: SEPTIEMBRE
Q10: OCTUBRE
B11: Clasificación del servicio | I11: Reporte mes por servicio | K11: Reporte acumulado por servicio | Q11: NOVIEMBRE
B12: Ítem general | C12: ítem actividad | D12: Descripción de la actividad | E12: Profesional a cargo | F12: Soporte | G12: Medio de entrega | H12: Días contratados | I12: Días | J12: % avance | K12: Días | L12: % avance | Q12: DICIEMBRE
B13: 3 | C13: 3.6 | D13: Generar Modelo analítico del yacimiento integrando la información disponible en un software específico | E13: Alejandro D López | F13: Cambio en los cronogramas y perfiles del modelo analítico en ARPS para los perfiles de producción para el campo Akasias en para las etapas de ANE y Tinamu | G13: ACCESS - PLP 2024 - Todos los documentos (sharepoint.com) | H13: 20 | I13: 7 | J13: =IFERROR(I13/H13,0) -> 0.35 | K13: =+I13 -> 7 | L13: =IFERROR(K13/H13,0) -> 0.35
B14: 3 | C14: 3.13 | D14: Generar base de datos de producción (OFM o la que se requiera) | F14: Generar archivos de carga de productores, inyectores y allocacion para el campo Tinamu. Se realizó control de calidad a los archivos que se subieron al ARPS | G14: https://ecopetrol.sharepoint.com/sites/EquipoDesarrolloCPO-9/Documentos%20compartidos/Forms/AllItems.aspx?id=%2Fsites%2FEquipoDesarrolloCPO%2D9%2FDocumentos%20compartidos%2FGeneral%2F04%2DExploratorio%2FExploratorios%20CPO%2D9&viewid=0e96c994%2D47e1%2D4e99%2D93c0%2D37826753815c | H14: 10 | I14: 8 | J14: =IFERROR(I14/H14,0) -> 0.8 | K14: =+I14 -> 8 | L14: =IFERROR(K14/H14,0) -> 0.8
B15: 3 | C15: 3.16 | D15: Análisis de Declinaciones por pozo y/o subunidad | F15: Se generó un establecio la configuracion de allocacion de primeras y segundas lineas por RWA para el campo Akacias en la etapa de desarrollo temprano | G15: ACCESS - PLP 2024 - Todos los documentos (sharepoint.com) | H15: 10 | I15: 2 | J15: =IFERROR(I15/H15,0) -> 0.2 | K15: =+I15 -> 2 | L15: =IFERROR(K15/H15,0) -> 0.2
B16: 3 | C16: 3.17 | D16: Analizar data histórica de producción, productividad y daño por pozo | F16: Base de Datos - Informe de la Evaluación | G16: ACCESS - PLP 2024 - Todos los documentos (sharepoint.com) | H16: 10 | I16: 4 | J16: =IFERROR(I16/H16,0) -> 0.4 | K16: =+I16 -> 4 | L16: =IFERROR(K16/H16,0) -> 0.4
B17: 3 | C17: 3.18 | D17: Generar perfiles de Producción por pozos para pozos existente en escenarios Bajo, Medio y Alto | F17: Se generó un archivo parcial de analisis de produccion de los pozos de cercanos y perforados del campo Tinamu para usar su produccion como referencia para los futuros pozos del campo | G17: ACCESS - PLP 2024 - Todos los documentos (sharepoint.com) | H17: 10 | I17: 2 | J17: =IFERROR(I17/H17,0) -> 0.2 | K17: =+I17 -> 2 | L17: =IFERROR(K17/H17,0) -> 0.2
B18: 5 | C18: 5.2 | D18: Generación de oportunidades de intervención a Pozos | F18: Base de Datos - Informe de la Evaluación | G18: ACCESS - Frontera - Todos los documentos | H18: 10 | I18: 3 | J18: =IFERROR(I18/H18,0) -> 0.3 | K18: =+I18 -> 3 | L18: =IFERROR(K18/H18,0) -> 0.3
B19: 5 | C19: 5.9 | D19: Realizar el seguimiento de producción/ inyección de pozos intervenidos con base en los comportamientos de producción previo y posterior a la intervención | F19: Entrega de perfiles de la etapa de Tinamu para proyectos | G19: ACCESS - Tinamu - Todos los documentos | H19: 10 | I19: 1 | J19: =IFERROR(I19/H19,0) -> 0.1 | K19: =+I19 -> 1 | L19: =IFERROR(K19/H19,0) -> 0.1
B20: 8 | C20: 8.2 | D20: Carga de datos, procesamiento de datos, Análisis Estadístico descriptivo considerando hipótesis desde la teoría, y análisis descriptivo considerando hipótesis generadas desde la misma data (pasos 1, 2 y 3 teoría CRISP-DM). | F20: Informe, con estadísticas descriptivas, histogramas, pruebas de ajuste, etc. | G20: Informe de reservas Campo Akacias 2022 - Inicio (sharepoint.com) | H20: 10 | I20: 3 | J20: =IFERROR(I20/H20,0) -> 0.3 | K20: =+I20 -> 3 | L20: =IFERROR(K20/H20,0) -> 0.3
B21: 3 | C21: 3.6 | D21: Generar Modelo analítico del yacimiento integrando la información disponible en un software específico | E21: Jhon H Carreño | F21: 1. Actualización semanal del modelo estático y dinámico del yacimiento y pozos del campo Akacias, mediante el proyecto Sahara Abr-2024 (Cargadores y modelo final) | G21: 1. X:\CHICHIMENE\INFORMACIÓN_CAMPO_CHICHIMENE\23.-Inyeccion de Agua\10. MONITOREO\09. Proyecto Sahara\2025\04. Abril 2. W:\2.- Ingeniería de Yacimientos\1.MONITOREO\1.Sahara\2025\4. Abril | H21: 10 | I21: 3 | J21: =IFERROR(I21/H21,0) -> 0.3 | K21: =+I21 -> 3 | L21: =IFERROR(K21/H21,0) -> 0.3
B22: 3 | C22: 3.13 | D22: Generar base de datos de producción (OFM o la que se requiera) | F22: 1. Actualización de la producción por proyecto y tipo de recobro en los Tableros 2.1 y las bases de datos de Molinos de viento de los pozos | G22: 1. https://ecopetrol.sharepoint.com/:f:/s/IAAKACIAS/EgCqFNT0rW9HqaUHUJ2Rl9QBCvS0kt0UAmo5iqfzicBI0Q?e=Qh9MOi 2. https://ecopetrol.sharepoint.com/:f:/s/IAAKACIAS/ErHM_OfTGKZLmCPrT3bK8O8BcnNF3UxaQIY023A7wFXXZg?e=2Qvz45 | H22: 10 | I22: 3 | J22: =IFERROR(I22/H22,0) -> 0.3 | K22: =+I22 -> 3 | L22: =IFERROR(K22/H22,0) -> 0.3
B23: 3 | C23: 3.14 | D23: Generar Distribución de Producción por sub- unidades (allocation) | F23: 1. Distribución de la producción asociada a la implementación del WF en los patrones de inyección del campo AK por medio del metodo RWA con la información a cierre de Mar-2025 | G23: 1. https://ecopetrol.sharepoint.com/:f:/s/IAAKACIAS/EtPNskxPDDlCgotsjtO3ZMgBdz_yBC_z0GJdAK8Dr4LYNA?e=M3WzO2 | H23: 10 | I23: 3 | J23: =IFERROR(I23/H23,0) -> 0.3 | K23: =+I23 -> 3 | L23: =IFERROR(K23/H23,0) -> 0.3
B24: 3 | C24: 3.16 | D24: Análisis de Declinaciones por pozo y/o subunidad | F24: 1. Elaboración y seguimiento a la estrategía de mitigación a la canalización presentada en los pozos AK-139 y AK-77 por el AK-26 2. Priorización de actividades para el POP del primer trimestre 2025 | G24: 1. https://ecopetrol.sharepoint.com/:p:/s/IAAKACIAS/EeE9kgAR8AxPn4UfJlXD_fAB2TJrx9FZPJU3F2Ddx2eXqQ?e=OQOaIb 2. https://ecopetrol.sharepoint.com/:x:/r/sites/IAAKACIAS/Documentos%20compartidos/34.%20POP%202024-2025/2025/ACT%20-%2011%2004%202025/POP_Vs_P50_RETO_11042025.xlsx?d=w0dc02f860ec24a6087e089a015726a66&csf=1&web=1&e=Z1XrGc | H24: 10 | I24: 4 | J24: =IFERROR(I24/H24,0) -> 0.4 | K24: =+I24 -> 4 | L24: =IFERROR(K24/H24,0) -> 0.4
B25: 3 | C25: 3.17 | D25: Analizar data histórica de producción, productividad y daño por pozo | F25: 1. Interpretación del PBU AK-156 2. Corrida de nodales para ver efecto de la petrofísica en la afectación de la productividad 3. Ajuste en la visualización de la pestaña de productividad en el tablero 2.6 para visualizar la data historica posterior a la entrada de la estación Orotoy | G25: 1. https://ecopetrol.sharepoint.com/:p:/s/IAAKACIAS/ETSl4EzNkxNCkKTkU5P7IlkBDiDfVPy--BoTL_sWcDdiPQ?e=SP4KAX 2. W:\2.- Ingeniería de Yacimientos\1.MONITOREO\3. Nodales\Analisis Nodal AK-153 3. https://ecopetrol.sharepoint.com/:u:/s/SeguimientoIAChichimeneECP/Ed09N9_VW1ZKvB1ao5Awy-gB2QfQA2HA2vexqLo-aLJh9g?e=nnAQQx | H25: 10 | I25: 3 | J25: =IFERROR(I25/H25,0) -> 0.3 | K25: =+I25 -> 3 | L25: =IFERROR(K25/H25,0) -> 0.3
B26: 3 | C26: 3.18 | D26: Generar perfiles de Producción por pozos para pozos existente en escenarios Bajo, Medio y Alto | F26: 1. Corrida del Resnode para el 2Q del 2025 | G26: 1. https://ecopetrol.sharepoint.com/:f:/s/IAAKACIAS/EqoG8uZYFsJNspSJS8-rSVwBZAlMrsbUA1Y20jTltnDz9g?e=OEg0Ft | H26: 10 | I26: 3 | J26: =IFERROR(I26/H26,0) -> 0.3 | K26: =+I26 -> 3 | L26: =IFERROR(K26/H26,0) -> 0.3
B27: 5 | C27: 5.2 | D27: Generación de oportunidades de intervención a Pozos | F27: 1. Intervención y análisis para reactivación de los pozos NE-3 y AK-153 2. Aplicación de la metodología planteada para selección de candidatos de CAF | G27: 1. https://ecopetrol.sharepoint.com/:p:/s/IAAKACIAS/EVyNiCrA7vJLvqXNF7yt4XUBTSxOfZlIpPCElt9CI5_Q4A?e=nxAcRe 2. https://ecopetrol.sharepoint.com/:p:/s/IAAKACIAS/EUKgWHePs4lCu3t20r0UTf8BODOHQh_ioXZYeBUMqFqrmw?e=jNtCfN 3. https://ecopetrol.sharepoint.com/:f:/s/IAAKACIAS/EkNgGC2v_1BCrY4XoGinTtkBsvHzYHtlrhuRMyD9NgJ5Jg?e=mvoKQM | H27: 10 | I27: 5 | J27: =IFERROR(I27/H27,0) -> 0.5 | K27: =+I27 -> 5 | L27: =IFERROR(K27/H27,0) -> 0.5
B28: 5 | C28: 5.9 | D28: Realizar el seguimiento de producción/ inyección de pozos intervenidos con base en los comportamientos de producción previo y posterior a la intervención | F28: 1. Definición y arranque del proyecto frontera ChiAk 2. Elaboración del docuemento para solicitud de producción temprana de los pozos Tejón-1 y Guamal profundo-1 | G28: 1. https://ecopetrol.sharepoint.com/:p:/r/sites/SeguimientoIAChichimeneECP/Documentos%20compartidos/36.%20Pozos%20Frontera/Protocolo%20Frontera.pptx?d=w93ed7554ac204e7e8a8bd69117896fad&csf=1&web=1&e=6JB57S 2. https://ecopetrol.sharepoint.com/:w:/s/IAAKACIAS/ESeATH2EI_xHiKHHxQYxEA0BmDMgLNeivKiYl9dRPYtigw?e=RqhYlH | H28: 10 | I28: 3 | J28: =IFERROR(I28/H28,0) -> 0.3 | K28: =+I28 -> 3 | L28: =IFERROR(K28/H28,0) -> 0.3
B29: 8 | C29: 8.2 | D29: Carga de datos, procesamiento de datos, Análisis Estadístico descriptivo considerando hipótesis desde la teoría, y análisis descriptivo considerando hipótesis generadas desde la misma data (pasos 1, 2 y 3 teoría CRISP-DM). | F29: 1/2/3. Soporte en la carga semanal y análisis de datos en repositorios de bases de datos correspondientes al campo Akacias (proyecto Sahara, AVM, tableros de producción, molinos de viento y control de proyectos, WellMeeting. | G29: 2. W:\2.- Ingeniería de Yacimientos\1.MONITOREO\22.Well Meeting\2025\4. Abril | H29: 10 | I29: 3 | J29: =IFERROR(I29/H29,0) -> 0.3 | K29: =+I29 -> 3 | L29: =IFERROR(K29/H29,0) -> 0.3
B30: 1 | C30: 1.2 | D30: Generación Bases de Datos de Pozos (Registros, Topes e información disponible) | E30: Julian A Hernández | F30: 1) Actualización con la base de datos con información final para los pozos CH-234, AK-145, CH-239. Planes direccionales pozos AK-214, CHSW94 y CH-236. | G30: \\10.100.25.35\pgtrabajodigital\JAH\Proyecto groups21\akacias\2.- Ingeniería de Yacimientos\1.MONITOREO | H30: 15 | I30: 4 | J30: =IFERROR(I30/H30,0) -> 0.26666667 | K30: =+I30 -> 4 | L30: =IFERROR(K30/H30,0) -> 0.26666667
B31: 1 | C31: 1.3 | D31: Interpretación Sísmica | F31: 1) Revisón de información sismica para los pozos pertencientes a los patrones de inyección para identificar estructuras y establecer conectividades en los patrones de inyección. En busqueda del mejoramiento del factor de conectividad geológico. 2) Revisión información sísmica para identificar fallas o estrucutras en los patrones de inyección en pro de actualziar el factor de conectividad geológica para el campo Akacias. 3) Revisión en conjunto con el área de geofísica de la informaicón sismica para los pozos nuevos a perforar en el campo Akacias. | G31: \\10.100.25.35\pgtrabajodigital\JAH\Proyecto Z:\akacias\2.- Ingeniería de Yacimientos\1.MONITOREO\19.Sistematica WF Akacias\2025\04.Abril | H31: 8 | I31: 2 | J31: =IFERROR(I31/H31,0) -> 0.25 | K31: =+I31 -> 2 | L31: =IFERROR(K31/H31,0) -> 0.25
B32: 1 | C32: 1.5 | D32: Digitalización, digitación y/o captura de información geológica (Mapas, Raw Data, topes, etc.) | F32: 1) Generación mapas, cortes y correalciones para hacer seguimiento a los patrones de inyección del campo y monitoreo a los pozos productores. 2) Cargue informaicón final de los pozos CH-234, AK-145, CH-23 (registros e interpretación petrofísica). 3) Actualización y cargue de los planes direccionales finales para los pozos AK-214, CHSW94 y CH-236. | G32: \\10.100.25.35\pgtrabajodigital\JAH\Proyecto | H32: 10 | I32: 2 | J32: =IFERROR(I32/H32,0) -> 0.2 | K32: =+I32 -> 2 | L32: =IFERROR(K32/H32,0) -> 0.2
B33: 1 | C33: 1.8 | D33: Balanceo de Secciones | F33: 1) Contrucción en petrel de secciones que permitan observar la continuidad horizontal de los ciclos estratigráficos en pro de establecer la conectividad geológica en los patrones de inyección, en el monitoreo del WF para el campo Akacias. 2) Generación de secciones estructurales que permitan observar el comportamiento areal del yacimiento para monitorear el comportamiento de pozos productores y conectividades en patrones de inyección. 3) Generación de secciones que permitan evaluar la continuidad lateral del yacimiento en el análisis de los pozos con baja inyectividad del campo Akacias. Adicionalmente, contrucción del material dentro del análisis de conectividad del patron del pozo AK-26 en el área de Nueva Esperanza. | G33: \\10.100.25.35\pgtrabajodigital\JAH\Proyecto | H33: 8 | I33: 3 | J33: =IFERROR(I33/H33,0) -> 0.375 | K33: =+I33 -> 3 | L33: =IFERROR(K33/H33,0) -> 0.375
B34: 1 | C34: 1.9 | D34: Análisis de sellos de fallas | F34: 1) Revisión del modelo estrucutural para el análisis de los patrones de inyección y así establecer la comunicación entre Inyec-produc durantes las sesiones de WF Akacias. 2) Revisión de los posibles sellos estructurales que condicionen el factor falla involucrado en la determinación del factor de conectividad geológico y continuar con la actualización de los tableros de conectividad geológica. 3) Análisis de las fallas dentro del estudio para identificar la influencia del acuífero en el campo a nivel CHIAK. 4) Actualziación de la interpretación estructural e inicio del análisis de conectividad en los patrones de inyección del campo. | G34: \\10.100.25.35\pgtrabajodigital\JAH\Proyecto Z:\akacias\2.- Ingeniería de Yacimientos\1.MONITOREO\19.Sistematica WF Akacias\2025\04.Abril | H34: 10 | I34: 5 | J34: =IFERROR(I34/H34,0) -> 0.5 | K34: =+I34 -> 5 | L34: =IFERROR(K34/H34,0) -> 0.5
B35: 1 | C35: 1.10 | D35: Amarre Sísmica Pozo | F35: 1) Revisión de la información sismíca con la trayectoria en las trayectorias entre pozos inyectores y porductores para identicar el Factor falla involucrado dentro del factor de conectividad geológica, insumo para actualizar el factor de conectividad geológico y el mapa de conectividad. 2) Revisión de las fallas interpretadas en las zonas de los pozos próximos a perforar para identificar los posibles riesgos geológicos y geofísicos. | G35: \\10.100.25.35\pgtrabajodigital\JAH\Proyecto groups21\akacias\5. Información de pozos | H35: 8 | I35: 3 | J35: =IFERROR(I35/H35,0) -> 0.375 | K35: =+I35 -> 3 | L35: =IFERROR(K35/H35,0) -> 0.375
B36: 1 | C36: 1.12 | D36: Generación de mapas de facies | F36: 1) Continua la elaboración de la base de datos para la actualización de los tableros G&G CHIAK. 2) Hacer seguimiento áreal de las facies para identificar los cambios laterales de facies que puedan indicar el comportamiento de arenas yto en los pozos productores. | G36: \\10.100.25.35\pgtrabajodigital\JAH\Proyecto | H36: 8 | I36: 2 | J36: =IFERROR(I36/H36,0) -> 0.25 | K36: =+I36 -> 2 | L36: =IFERROR(K36/H36,0) -> 0.25
B37: 1 | C37: 1.15 | D37: Carga de información para poblar el modelo geocelular (direccionales, coordenadas, surveys, topes, data de presión, estados mecánicos, evento de pozos, etc.) | F37: 1) Actualización final pozos CH-234, AK-145, CH-239 y actualización de los planes direccionales pozos AK-214, CHSW94 y CH-236. 2) Cargue de últimos planes direccionales aprobados para los pozos de la Etapa ANE y Frontera. | G37: ruta: \\10.100.25.35\pgtrabajodigital\JAH\Proyecto | H37: 15 | I37: 4 | J37: =IFERROR(I37/H37,0) -> 0.26666667 | K37: =+I37 -> 4 | L37: =IFERROR(K37/H37,0) -> 0.26666667
B38: 1 | C38: 1.25 | D38: Análisis geoquímicos de Fingerprinting | F38: 1) Continua: Análisis de la posible influencia del acuífero a nivel CHIAK actualización del mapa con datos a corte del segundo semestre de 2024, a partir de la integración de información de análisis fisicoquímicos, continuidad estratigráfica, rasgos estructurales, resultados de PLTs e ILTs, BSW y Ql en los pozos de los campos Chichimene y Akacias. | G38: ruta: \\10.100.25.35\pgtrabajodigital\JAH\Proyecto | H38: 8 | I38: 5 | J38: =IFERROR(I38/H38,0) -> 0.625 | K38: =+I38 -> 5 | L38: =IFERROR(K38/H38,0) -> 0.625
B39: 3 | C39: 3.6 | D39: Generar Modelo analítico del yacimiento integrando la información disponible en un software específico | E39: Milton J Gualteros | F39: Actualización modelo analítico de yacimientos ARPS (Frontera y Desarrollo Postrerios) | G39: Microsoft Teams, Email, Sharepoint Y:\akacias\37. Archivos | H39: 12 | I39: 3 | J39: =IFERROR(I39/H39,0) -> 0.25 | K39: =+I39 -> 3 | L39: =IFERROR(K39/H39,0) -> 0.25
B40: 3 | C40: 3.13 | D40: Generar base de datos de producción (OFM o la que se requiera) | F40: Generación base de datos y construcción perfiles de producción campaña WO | G40: Microsoft Teams, Email, Sharepoint Y:\akacias\37. Archivos | H40: 11 | I40: 3 | J40: =IFERROR(I40/H40,0) -> 0.27272727 | K40: =+I40 -> 3 | L40: =IFERROR(K40/H40,0) -> 0.27272727
...

Sheet MAYO 2025
Q1: MES
B2: REPORTE DE AVANCE | Q2: ENERO
B3: Fecha: 29/06/2022 | F3: Version: 01 | J3: GP-F-23
Q4: FEBRERO
B5: Código Orden de servicio | D5: 90141005 | Q5: MARZO
Q6: JUNIO
B7: Mes a reportar | D7: MAYO | Q7: JULIO
Q8: AGOSTO
B9: Fecha reporte | D9: 45808 | Q9: SEPTIEMBRE
Q10: OCTUBRE
B11: Clasificación del servicio | I11: Reporte mes por servicio | K11: Reporte acumulado por servicio | Q11: NOVIEMBRE
B12: Ítem general | C12: ítem actividad | D12: Descripción de la actividad | E12: Profesional a cargo | F12: Soporte | G12: Medio de entrega | H12: Días contratados | I12: Días | J12: % avance | K12: Días | L12: % avance | Q12: DICIEMBRE
B13: 3 | C13: 3.6 | D13: Generar Modelo analítico del yacimiento integrando la información disponible en un software específico | E13: Alejandro D López | F13: Cambio en los cronogramas y perfiles del modelo analítico en ARPS para los perfiles de producción para el campo Akasias en para las etapas de ANE y Tinamu | G13: ACCESS - PLP 2024 - Todos los documentos (sharepoint.com) | H13: 20 | I13: 7 | J13: =IFERROR(I13/H13,0) -> 0.35 | K13: =+I13+'ABRIL 2025'!K13 -> 14 | L13: =IFERROR(K13/H13,0) -> 0.7
B14: 3 | C14: 3.13 | D14: Generar base de datos de producción (OFM o la que se requiera) | F14: Generar archivos de carga de productores, inyectores y allocacion para el campo Tinamu. Se realizó control de calidad a los archivos que se subieron al ARPS | G14: https://ecopetrol.sharepoint.com/sites/EquipoDesarrolloCPO-9/Documentos%20compartidos/Forms/AllItems.aspx?id=%2Fsites%2FEquipoDesarrolloCPO%2D9%2FDocumentos%20compartidos%2FGeneral%2F04%2DExploratorio%2FExploratorios%20CPO%2D9&viewid=0e96c994%2D47e1%2D4e99%2D93c0%2D37826753815c | H14: 10 | I14: 2 | J14: =IFERROR(I14/H14,0) -> 0.2 | K14: =+I14+'ABRIL 2025'!K14 -> 10 | L14: =IFERROR(K14/H14,0) -> 1
B15: 3 | C15: 3.16 | D15: Análisis de Declinaciones por pozo y/o subunidad | F15: Se generó un establecio la configuracion de allocacion de primeras y segundas lineas por RWA para el campo Akacias en la etapa de desarrollo temprano | G15: ACCESS - PLP 2024 - Todos los documentos (sharepoint.com) | H15: 10 | I15: 2 | J15: =IFERROR(I15/H15,0) -> 0.2 | K15: =+I15+'ABRIL 2025'!K15 -> 4 | L15: =IFERROR(K15/H15,0) -> 0.4
B16: 3 | C16: 3.17 | D16: Analizar data histórica de producción, productividad y daño por pozo | F16: Base de Datos - Informe de la Evaluación | G16: ACCESS - PLP 2024 - Todos los documentos (sharepoint.com) | H16: 10 | I16: 4 | J16: =IFERROR(I16/H16,0) -> 0.4 | K16: =+I16+'ABRIL 2025'!K16 -> 8 | L16: =IFERROR(K16/H16,0) -> 0.8
B17: 3 | C17: 3.18 | D17: Generar perfiles de Producción por pozos para pozos existente en escenarios Bajo, Medio y Alto | F17: Se generó un archivo parcial de analisis de produccion de los pozos de cercanos y perforados del campo Tinamu para usar su produccion como referencia para los futuros pozos del campo | G17: ACCESS - PLP 2024 - Todos los documentos (sharepoint.com) | H17: 10 | I17: 2 | J17: =IFERROR(I17/H17,0) -> 0.2 | K17: =+I17+'ABRIL 2025'!K17 -> 4 | L17: =IFERROR(K17/H17,0) -> 0.4
B18: 5 | C18: 5.2 | D18: Generación de oportunidades de intervención a Pozos | F18: Base de Datos - Informe de la Evaluación | G18: ACCESS - Frontera - Todos los documentos | H18: 10 | I18: 3 | J18: =IFERROR(I18/H18,0) -> 0.3 | K18: =+I18+'ABRIL 2025'!K18 -> 6 | L18: =IFERROR(K18/H18,0) -> 0.6
B19: 5 | C19: 5.9 | D19: Realizar el seguimiento de producción/ inyección de pozos intervenidos con base en los comportamientos de producción previo y posterior a la intervención | F19: Entrega de perfiles de la etapa de Tinamu para proyectos | G19: ACCESS - Tinamu - Todos los documentos | H19: 10 | I19: 4 | J19: =IFERROR(I19/H19,0) -> 0.4 | K19: =+I19+'ABRIL 2025'!K19 -> 5 | L19: =IFERROR(K19/H19,0) -> 0.5
B20: 8 | C20: 8.2 | D20: Carga de datos, procesamiento de datos, Análisis Estadístico descriptivo considerando hipótesis desde la teoría, y análisis descriptivo considerando hipótesis generadas desde la misma data (pasos 1, 2 y 3 teoría CRISP-DM). | F20: Informe, con estadísticas descriptivas, histogramas, pruebas de ajuste, etc. | G20: Informe de reservas Campo Akacias 2022 - Inicio (sharepoint.com) | H20: 10 | I20: 6 | J20: =IFERROR(I20/H20,0) -> 0.6 | K20: =+I20+'ABRIL 2025'!K20 -> 9 | L20: =IFERROR(K20/H20,0) -> 0.9
B21: 3 | C21: 3.6 | D21: Generar Modelo analítico del yacimiento integrando la información disponible en un software específico | E21: Jhon H Carreño | F21: 1. Actualización semanal del modelo estático y dinámico del yacimiento y pozos del campo Akacias, mediante el proyecto Sahara Mayo-2025 (Cargadores y modelo final) | G21: 1. X:\CHICHIMENE\INFORMACIÓN_CAMPO_CHICHIMENE\23.-Inyeccion de Agua\10. MONITOREO\09. Proyecto Sahara\2025\05.Mayo 2. W:\2.- Ingeniería de Yacimientos\1.MONITOREO\1.Sahara\2025\5. Mayo | H21: 10 | I21: 4 | J21: =IFERROR(I21/H21,0) -> 0.4 | K21: =+I21+'ABRIL 2025'!K21 -> 7 | L21: =IFERROR(K21/H21,0) -> 0.7
B22: 3 | C22: 3.13 | D22: Generar base de datos de producción (OFM o la que se requiera) | F22: 1. Actualización de la producción por proyecto y tipo de recobro en los Tableros 2.1 y las bases de datos de Molinos de viento de los pozos con la información del mes de abril de 2025 | G22: 1. W:\2.- Ingeniería de Yacimientos\1.MONITOREO\9.Tablero Power BI 2.1\2025\4. Abril 2. W:\2.- Ingeniería de Yacimientos\1.MONITOREO\14.Molinos de Viento\Cargadores\Real\2025\04. Abril | H22: 10 | I22: 3 | J22: =IFERROR(I22/H22,0) -> 0.3 | K22: =+I22+'ABRIL 2025'!K22 -> 6 | L22: =IFERROR(K22/H22,0) -> 0.6
B23: 3 | C23: 3.14 | D23: Generar Distribución de Producción por sub- unidades (allocation) | F23: 1. Distribución de la producción asociada a la implementación del WF en los patrones de inyección del campo AK por medio del metodo RWA con la información a cierre de Abr-2025 | G23: 1. W:\2.- Ingeniería de Yacimientos\1.MONITOREO\16.RWA\AKACIAS\2025\4. Abril | H23: 10 | I23: 3 | J23: =IFERROR(I23/H23,0) -> 0.3 | K23: =+I23+'ABRIL 2025'!K23 -> 6 | L23: =IFERROR(K23/H23,0) -> 0.6
B24: 3 | C24: 3.16 | D24: Análisis de Declinaciones por pozo y/o subunidad | F24: 1. Participación en el taller plan cierre de brechas a fin de establecer las actividades aprobadas y definir las bases para el plan de inversiones | G24: 1. https://ecopetrol.sharepoint.com/:p:/s/IAAKACIAS/ERuRkXh3wQNPus0uGyB1N9UB7yXfOj7XEmce1gOnmCt4Cg?e=3IEjmr | H24: 10 | I24: 3 | J24: =IFERROR(I24/H24,0) -> 0.3 | K24: =+I24+'ABRIL 2025'!K24 -> 7 | L24: =IFERROR(K24/H24,0) -> 0.7
B25: 3 | C25: 3.17 | D25: Analizar data histórica de producción, productividad y daño por pozo | F25: 1. Presentación del efecto de la inyección en la zona NE, comportamiento de presiones | G25: 1. W:\2.- Ingeniería de Yacimientos\1.MONITOREO\7.Presiones\2025\1_Semestre | H25: 10 | I25: 3 | J25: =IFERROR(I25/H25,0) -> 0.3 | K25: =+I25+'ABRIL 2025'!K25 -> 6 | L25: =IFERROR(K25/H25,0) -> 0.6
B26: 3 | C26: 3.18 | D26: Generar perfiles de Producción por pozos para pozos existente en escenarios Bajo, Medio y Alto | F26: 1. Elaboración del programa de evaluación de los pozos Tejón-1 y Guamal profundo-1 bajo el esquema de producción temprana 2. Ajuste de declinación y PDI para corrida de RWA en la PDP | G26: 1. W:\34.- Exploratorios CPO-09\Producción temprana Guamal 2. https://ecopetrol.sharepoint.com/:x:/r/sites/IAAKACIAS/Documentos%20compartidos/21.%20Portafolio/2025/4.-%20PDI%202025/1.-%20B%C3%A1sica/DCA/AT%20Dnm%20Template.xlsx?d=w728cdf274b4946b9addc4b9b6feb6ec8&csf=1&web=1&e=1X7h1Y | H26: 10 | I26: 4 | J26: =IFERROR(I26/H26,0) -> 0.4 | K26: =+I26+'ABRIL 2025'!K26 -> 7 | L26: =IFERROR(K26/H26,0) -> 0.7
B27: 5 | C27: 5.2 | D27: Generación de oportunidades de intervención a Pozos | F27: 1. Análisis de información previa y necesidad de adquisición de presiones para el AK-153 a fin de verificar la conexión con el bloque principal. 2. Análisis en Saphir para realizar una prueba de interferencia entre el AK-139 y AK-153 | G27: 1. W:\2.- Ingeniería de Yacimientos\1.MONITOREO\19.Sistematica WF Akacias\2025\04. Abril 2. W:\2.- Ingeniería de Yacimientos\1.MONITOREO\19.Sistematica WF Akacias\2025\05. Mayo | H27: 10 | I27: 3 | J27: =IFERROR(I27/H27,0) -> 0.3 | K27: =+I27+'ABRIL 2025'!K27 -> 8 | L27: =IFERROR(K27/H27,0) -> 0.8
B28: 5 | C28: 5.9 | D28: Realizar el seguimiento de producción/ inyección de pozos intervenidos con base en los comportamientos de producción previo y posterior a la intervención | F28: 1. Estrategía y escenarios de perdida de producción durante apagados de los pozos del CL-NE para evitar afectación en los pozos del patrón AK-26 | G28: 1. https://ecopetrol.sharepoint.com/:p:/s/IAAKACIAS/Eb1baMERUeNEjoPL3ygdW7oBXSSC67Fti9iIakUSZ0N6tw?e=b0S10l 2. https://ecopetrol.sharepoint.com/:x:/s/IAAKACIAS/EZdMvxsKHBNHmGIiwYOoHYEBZrEZrqxKMrOkARzdtJNFCw?e=GehYyk | H28: 10 | I28: 3 | J28: =IFERROR(I28/H28,0) -> 0.3 | K28: =+I28+'ABRIL 2025'!K28 -> 6 | L28: =IFERROR(K28/H28,0) -> 0.6
B29: 8 | C29: 8.2 | D29: Carga de datos, procesamiento de datos, Análisis Estadístico descriptivo considerando hipótesis desde la teoría, y análisis descriptivo considerando hipótesis generadas desde la misma data (pasos 1, 2 y 3 teoría CRISP-DM). | F29: 1. Registro de las actividades pendientes para el inyector frontera AK-147 en Wellmeeting 2. Registro de acciones especificas para los pozos Akacias | G29: 1 y 2. W:\2.- Ingeniería de Yacimientos\1.MONITOREO\22.Well Meeting\2025\5. Mayo | H29: 10 | I29: 4 | J29: =IFERROR(I29/H29,0) -> 0.4 | K29: =+I29+'ABRIL 2025'!K29 -> 7 | L29: =IFERROR(K29/H29,0) -> 0.7
B30: 1 | C30: 1.2 | D30: Generación Bases de Datos de Pozos (Registros, Topes e información disponible) | E30: Julian A Hernández | F30: 1) Actualización con la base de datos con información final para el pozo AK-147 y AK-221. Planes direccionales pozos AK-150 y AK-158 | G30: \\10.100.25.35\pgtrabajodigital\JAH\Proyecto groups21\akacias\2.- Ingeniería de Yacimientos\1.MONITOREO | H30: 15 | I30: 5 | J30: =IFERROR(I30/H30,0) -> 0.33333333 | K30: =+I30+'ABRIL 2025'!K30 -> 9 | L30: =IFERROR(K30/H30,0) -> 0.6
B31: 1 | C31: 1.3 | D31: Interpretación Sísmica | F31: 1) Revisón de información sismica para los pozos pertencientes a los patrones de inyección para identificar estructuras y establecer conectividades en los patrones de inyección. En busqueda del mejoramiento del factor de conectividad geológico. 2) Revisión información sísmica para identificar fallas o estrucutras en los patrones de inyección en pro de actualziar el factor de conectividad geológica para el campo Akacias. 3) Revisión en conjunto con el área de geofísica de la informaicón sismica para los pozos nuevos a perforar en el campo Akacias. | G31: \\10.100.25.35\pgtrabajodigital\JAH\Proyecto Z:\akacias\2.- Ingeniería de Yacimientos\1.MONITOREO\19.Sistematica WF Akacias\2025\05.Mayo | H31: 8 | I31: 3 | J31: =IFERROR(I31/H31,0) -> 0.375 | K31: =+I31+'ABRIL 2025'!K31 -> 5 | L31: =IFERROR(K31/H31,0) -> 0.625
B32: 1 | C32: 1.5 | D32: Digitalización, digitación y/o captura de información geológica (Mapas, Raw Data, topes, etc.) | F32: 1) Generación mapas, cortes y correalciones para hacer seguimiento a los patrones de inyección del campo y monitoreo a los pozos productores. 2) Cargue informaicón final de los pozos AK-147 y AK-221 (registros e interpretación petrofísica). 3) Actualización y cargue de los planes direccionales finales para los pozos AK-150 y AK-158. | G32: \\10.100.25.35\pgtrabajodigital\JAH\Proyecto | H32: 10 | I32: 3 | J32: =IFERROR(I32/H32,0) -> 0.3 | K32: =+I32+'ABRIL 2025'!K32 -> 5 | L32: =IFERROR(K32/H32,0) -> 0.5
B33: 1 | C33: 1.8 | D33: Balanceo de Secciones | F33: 1) Contrucción en petrel de secciones que permitan observar la continuidad horizontal de los ciclos estratigráficos en pro de establecer la conectividad geológica en los patrones de inyección, en el monitoreo del WF para el campo Akacias. 2) Generación de secciones estructurales que permitan observar el comportamiento areal del yacimiento para monitorear el comportamiento de pozos productores y conectividades en patrones de inyección. | G33: \\10.100.25.35\pgtrabajodigital\JAH\Proyecto | H33: 8 | I33: 2 | J33: =IFERROR(I33/H33,0) -> 0.25 | K33: =+I33+'ABRIL 2025'!K33 -> 5 | L33: =IFERROR(K33/H33,0) -> 0.625
B34: 1 | C34: 1.9 | D34: Análisis de sellos de fallas | F34: 1) Revisión del modelo estrucutural para el análisis de los patrones de inyección y así establecer la comunicación entre Inyec-produc durantes las sesiones de WF Akacias. 2) Revisión de los posibles sellos estructurales que condicionen el factor falla involucrado en la determinación del factor de conectividad geológico y continuar con la actualización de los tableros de conectividad geológica. 3) Análisis de las fallas dentro del estudio para identificar la influencia del acuífero en el campo a nivel CHIAK. 4) Continua la actualziación de la interpretación estructural e inicio del análisis de conectividad en los patrones de inyección del campo. | G34: \\10.100.25.35\pgtrabajodigital\JAH\Proyecto Z:\akacias\2.- Ingeniería de Yacimientos\1.MONITOREO\19.Sistematica WF Akacias\2025\05.Mayo | H34: 10 | I34: 3 | J34: =IFERROR(I34/H34,0) -> 0.3 | K34: =+I34+'ABRIL 2025'!K34 -> 8 | L34: =IFERROR(K34/H34,0) -> 0.8
B35: 1 | C35: 1.10 | D35: Amarre Sísmica Pozo | F35: 1) Revisión de la información sismíca con la trayectoria en las trayectorias entre pozos inyectores y porductores para identicar el Factor falla involucrado dentro del factor de conectividad geológica, insumo para actualizar el factor de conectividad geológico y el mapa de conectividad. 2) Revisión de las fallas interpretadas en las zonas de los pozos próximos a perforar para identificar los posibles riesgos geológicos y geofísicos, incolucrando la nueva información estructural. | G35: \\10.100.25.35\pgtrabajodigital\JAH\Proyecto groups21\akacias\5. Información de pozos | H35: 8 | I35: 3 | J35: =IFERROR(I35/H35,0) -> 0.375 | K35: =+I35+'ABRIL 2025'!K35 -> 6 | L35: =IFERROR(K35/H35,0) -> 0.75
B36: 1 | C36: 1.12 | D36: Generación de mapas de facies | F36: 1) Continua la elaboración de la base de datos para la actualización de los tableros G&G CHIAK. 2) Hacer seguimiento áreal de las facies para identificar los cambios laterales de facies que puedan indicar el comportamiento de arenas yto en los pozos productores. | G36: \\10.100.25.35\pgtrabajodigital\JAH\Proyecto | H36: 8 | I36: 3 | J36: =IFERROR(I36/H36,0) -> 0.375 | K36: =+I36+'ABRIL 2025'!K36 -> 5 | L36: =IFERROR(K36/H36,0) -> 0.625
B37: 1 | C37: 1.15 | D37: Carga de información para poblar el modelo geocelular (direccionales, coordenadas, surveys, topes, data de presión, estados mecánicos, evento de pozos, etc.) | F37: 1) Actualización final pozos AK-147 y AK-221 y actualización de los planes direccionales pozos AK-150 y AK-158. 2) Continua cargue de últimos planes direccionales aprobados para los pozos de la Etapa ANE y Frontera para la elaboración de los archivos RMS. | G37: ruta: \\10.100.25.35\pgtrabajodigital\JAH\Proyecto | H37: 15 | I37: 5 | J37: =IFERROR(I37/H37,0) -> 0.33333333 | K37: =+I37+'ABRIL 2025'!K37 -> 9 | L37: =IFERROR(K37/H37,0) -> 0.6
B38: 1 | C38: 1.25 | D38: Análisis geoquímicos de Fingerprinting | F38: 1) Continua: Análisis de la posible influencia del acuífero a nivel CHIAK actualización del mapa con datos a corte del segundo semestre de 2024, a partir de la integración de información de análisis fisicoquímicos, continuidad estratigráfica, rasgos estructurales, resultados de PLTs e ILTs, BSW y Ql en los pozos de los campos Chichimene y Akacias. | G38: ruta: \\10.100.25.35\pgtrabajodigital\JAH\Proyecto | H38: 8 | I38: 3 | J38: =IFERROR(I38/H38,0) -> 0.375 | K38: =+I38+'ABRIL 2025'!K38 -> 8 | L38: =IFERROR(K38/H38,0) -> 1
B39: 3 | C39: 3.6 | D39: Generar Modelo analítico del yacimiento integrando la información disponible en un software específico | E39: Milton J Gualteros | F39: Actualización modelo analítico de yacimientos ARPS (Frontera, ANE, A3's) | G39: Microsoft Teams, Email, Sharepoint Y:\akacias\37. Archivos | H39: 12 | I39: 5 | J39: =IFERROR(I39/H39,0) -> 0.41666667 | K39: =+I39+'ABRIL 2025'!K39 -> 8 | L39: =IFERROR(K39/H39,0) -> 0.66666667
B40: 3 | C40: 3.13 | D40: Generar base de datos de producción (OFM o la que se requiera) | F40: Generación base de datos y construcción perfiles proyecto inyección norte CHIAK | G40: Microsoft Teams, Email, Sharepoint Y:\akacias\37. Archivos | H40: 11 | I40: 4 | J40: =IFERROR(I40/H40,0) -> 0.36363636 | K40: =+I40+'ABRIL 2025'!K40 -> 7 | L40: =IFERROR(K40/H40,0) -> 0.63636364
...

Sheet JUNIO 2025
Q1: MES
B2: REPORTE DE AVANCE | Q2: ENERO
B3: Fecha: 29/06/2022 | F3: Version: 01 | J3: GP-F-23
Q4: FEBRERO
B5: Código Orden de servicio | D5: 90141005 | Q5: MARZO
Q6: JUNIO
B7: Mes a reportar | D7: JUNIO | Q7: JULIO
Q8: AGOSTO
B9: Fecha reporte | D9: 45838 | Q9: SEPTIEMBRE
Q10: OCTUBRE
B11: Clasificación del servicio | I11: Reporte mes por servicio | K11: Reporte acumulado por servicio | Q11: NOVIEMBRE
B12: Ítem general | C12: ítem actividad | D12: Descripción de la actividad | E12: Profesional a cargo | F12: Soporte | G12: Medio de entrega | H12: Días contratados | I12: Días | J12: % avance | K12: Días | L12: % avance | Q12: DICIEMBRE
B13: 3 | C13: 3.6 | D13: Generar Modelo analítico del yacimiento integrando la información disponible en un software específico | E13: Alejandro D López | F13: Cambio en los cronogramas y perfiles del modelo analítico en ARPS para los perfiles de producción para el campo Akasias en para las etapas de ANE y Tinamu | G13: ACCESS - PLP 2024 - Todos los documentos (sharepoint.com) | H13: 33 | I13: 6 | J13: =IFERROR(I13/H13,0) -> 0.18181818 | K13: =+I13+'MAYO 2025'!K13 -> 20 | L13: =IFERROR(K13/H13,0) -> 0.60606061
B14: 3 | C14: 3.13 | D14: Generar base de datos de producción (OFM o la que se requiera) | F14: - | G14: - | H14: 39 | I14: 0 | J14: =IFERROR(I14/H14,0) -> 0 | K14: =+I14+'MAYO 2025'!K14 -> 10 | L14: =IFERROR(K14/H14,0) -> 0.25641026
B15: 3 | C15: 3.16 | D15: Análisis de Declinaciones por pozo y/o subunidad | F15: Se generó un establecio la configuracion de allocacion de primeras y segundas lineas por RWA para el campo Akacias en la etapa de desarrollo temprano | G15: ACCESS - PLP 2024 - Todos los documentos (sharepoint.com) | H15: 33 | I15: 6 | J15: =IFERROR(I15/H15,0) -> 0.18181818 | K15: =+I15+'MAYO 2025'!K15 -> 10 | L15: =IFERROR(K15/H15,0) -> 0.3030303
B16: 3 | C16: 3.17 | D16: Analizar data histórica de producción, productividad y daño por pozo | F16: Base de Datos - Informe de la Evaluación | G16: ACCESS - PLP 2024 - Todos los documentos (sharepoint.com) | H16: 33 | I16: 2 | J16: =IFERROR(I16/H16,0) -> 0.060606061 | K16: =+I16+'MAYO 2025'!K16 -> 10 | L16: =IFERROR(K16/H16,0) -> 0.3030303
B17: 3 | C17: 3.18 | D17: Generar perfiles de Producción por pozos para pozos existente en escenarios Bajo, Medio y Alto | F17: Se generó un archivo parcial de analisis de produccion de los pozos de cercanos y perforados del campo Tinamu para usar su produccion como referencia para los futuros pozos del campo | G17: ACCESS - PLP 2024 - Todos los documentos (sharepoint.com) | H17: 33 | I17: 6 | J17: =IFERROR(I17/H17,0) -> 0.18181818 | K17: =+I17+'MAYO 2025'!K17 -> 10 | L17: =IFERROR(K17/H17,0) -> 0.3030303
B18: 5 | C18: 5.2 | D18: Generación de oportunidades de intervención a Pozos | F18: Base de Datos - Informe de la Evaluación | G18: ACCESS - Frontera - Todos los documentos | H18: 33 | I18: 4 | J18: =IFERROR(I18/H18,0) -> 0.12121212 | K18: =+I18+'MAYO 2025'!K18 -> 10 | L18: =IFERROR(K18/H18,0) -> 0.3030303
B19: 5 | C19: 5.9 | D19: Realizar el seguimiento de producción/ inyección de pozos intervenidos con base en los comportamientos de producción previo y posterior a la intervención | F19: Entrega de perfiles de la etapa de Tinamu para proyectos | G19: ACCESS - Tinamu - Todos los documentos | H19: 33 | I19: 5 | J19: =IFERROR(I19/H19,0) -> 0.15151515 | K19: =+I19+'MAYO 2025'!K19 -> 10 | L19: =IFERROR(K19/H19,0) -> 0.3030303
B20: 8 | C20: 8.2 | D20: Carga de datos, procesamiento de datos, Análisis Estadístico descriptivo considerando hipótesis desde la teoría, y análisis descriptivo considerando hipótesis generadas desde la misma data (pasos 1, 2 y 3 teoría CRISP-DM). | F20: Informe, con estadísticas descriptivas, histogramas, pruebas de ajuste, etc. | G20: Informe de reservas Campo Akacias 2022 - Inicio (sharepoint.com) | H20: 33 | I20: 1 | J20: =IFERROR(I20/H20,0) -> 0.03030303 | K20: =+I20+'MAYO 2025'!K20 -> 10 | L20: =IFERROR(K20/H20,0) -> 0.3030303
B21: 3 | C21: 3.6 | D21: Generar Modelo analítico del yacimiento integrando la información disponible en un software específico | E21: Jhon H Carreño | F21: 1. Actualización semanal del modelo estático y dinámico del yacimiento y pozos del campo Akacias, mediante el proyecto Sahara Junio-2025 (Cargadores y modelo final) | G21: X:\CHICHIMENE\INFORMACIÓN_CAMPO_CHICHIMENE\23.-Inyeccion de Agua\10. MONITOREO\09. Proyecto Sahara\2025\06. Junio W:\2.- Ingeniería de Yacimientos\1.MONITOREO\1.Sahara\2025\6. Junio | H21: 30 | I21: 3 | J21: =IFERROR(I21/H21,0) -> 0.1 | K21: =+I21+'MAYO 2025'!K21 -> 10 | L21: =IFERROR(K21/H21,0) -> 0.33333333
B22: 3 | C22: 3.13 | D22: Generar base de datos de producción (OFM o la que se requiera) | F22: 1. Actualización de la producción por proyecto y tipo de recobro en los Tableros 2.1 y los cargadores para la bases de datos de Molinos de viento de los pozos con la información del mes de mayo de 2025 | G22: W:\2.- Ingeniería de Yacimientos\1.MONITOREO\9.Tablero Power BI 2.1\2025 W:\2.- Ingeniería de Yacimientos\1.MONITOREO\14.Molinos de Viento\Cargadores\Real\2025 | H22: 30 | I22: 4 | J22: =IFERROR(I22/H22,0) -> 0.13333333 | K22: =+I22+'MAYO 2025'!K22 -> 10 | L22: =IFERROR(K22/H22,0) -> 0.33333333
B23: 3 | C23: 3.14 | D23: Generar Distribución de Producción por sub- unidades (allocation) | F23: 1. Distribución de la producción asociada a la implementación del WF en los patrones de inyección del campo AK por medio del metodo RWA con la información a cierre de May-2025 | G23: W:\2.- Ingeniería de Yacimientos\1.MONITOREO\16.RWA\AKACIAS\2025\5. Mayo | H23: 30 | I23: 4 | J23: =IFERROR(I23/H23,0) -> 0.13333333 | K23: =+I23+'MAYO 2025'!K23 -> 10 | L23: =IFERROR(K23/H23,0) -> 0.33333333
B24: 3 | C24: 3.16 | D24: Análisis de Declinaciones por pozo y/o subunidad | F24: 1. Análisis de la delcinación post BT en la generación de las curvas CC, distribución de la producción incremental para los trabajos de WO, OPT y OPEX bajo la metodología RWA para el plan de inversiones | G24: https://ecopetrol.sharepoint.com/:x:/s/IAAKACIAS/EXxBMXZqPrBMv9-HmsMp444BQgL9qkjBseaENWHbk4w31g?e=wfBNQM C:\Users\c109868u\Ecopetrol S.A\I&A AKACIAS - Documentos\21. Portafolio\2025\4.- PDI 2025\2. NPs\1. CCs\3. CCs | H24: 30 | I24: 3 | J24: =IFERROR(I24/H24,0) -> 0.1 | K24: =+I24+'MAYO 2025'!K24 -> 10 | L24: =IFERROR(K24/H24,0) -> 0.33333333
B25: 3 | C25: 3.17 | D25: Analizar data histórica de producción, productividad y daño por pozo | F25: 1. Interpretación y análisis de la influencia en inyección del productor de segunda línea AK-90ST con el inyector AK-135i por medio de presiones | G25: W:\2.- Ingeniería de Yacimientos\1.MONITOREO\7.Presiones\2025\1_Semestre\4. AK-90ST https://ecopetrol.sharepoint.com/:p:/r/sites/IAAKACIAS/Documentos%20compartidos/03.Sistem%C3%A1tica%20WF%20Akacias/2025/05.%20Mayo/Sistem%C3%A1tica%20WF-%20Akac%C3%ADas%2021.05.20251.pptx?d=wc1685bbd511144e38e83cbdf281d5bba&csf=1&web=1&e=w6J5DN | H25: 30 | I25: 4 | J25: =IFERROR(I25/H25,0) -> 0.13333333 | K25: =+I25+'MAYO 2025'!K25 -> 10 | L25: =IFERROR(K25/H25,0) -> 0.33333333
B26: 3 | C26: 3.18 | D26: Generar perfiles de Producción por pozos para pozos existente en escenarios Bajo, Medio y Alto | F26: 1. Construcción y arme de las curvas caracteristicas para los pozos de la zona NE y Frontera del campo Akacias incluyendo los escenarios de control de cambios A2.2 y modificación del VRR | G26: https://ecopetrol.sharepoint.com/:x:/s/IAAKACIAS/Eeu5b4fKMIRIn-TWjqiJSWIBlMASlQTwnfDNZqXLCPkh5w?e=0CfOjy | H26: 30 | I26: 3 | J26: =IFERROR(I26/H26,0) -> 0.1 | K26: =+I26+'MAYO 2025'!K26 -> 10 | L26: =IFERROR(K26/H26,0) -> 0.33333333
B27: 5 | C27: 5.2 | D27: Generación de oportunidades de intervención a Pozos | F27: 1. Diseño de caudales objetivos y estimación de propiedades por intervalo/zona para el pozo inyector AK-145i del proyecto frontera | G27: https://ecopetrol.sharepoint.com/:x:/s/IAAKACIAS/EVktu4yXZU9AoSJ9Rx6GnHMB_emfaXyqnG-lwIQPuxelWQ?e=2V1Hf5 | H27: 30 | I27: 2 | J27: =IFERROR(I27/H27,0) -> 0.066666667 | K27: =+I27+'MAYO 2025'!K27 -> 10 | L27: =IFERROR(K27/H27,0) -> 0.33333333
B28: 5 | C28: 5.9 | D28: Realizar el seguimiento de producción/ inyección de pozos intervenidos con base en los comportamientos de producción previo y posterior a la intervención | F28: 1. Descripción de causas en el seguimiento de los proyectos en ejecución para el campo Akacias | G28: https://ecopetrol.sharepoint.com/:x:/s/IAAKACIAS/Eeu5b4fKMIRIn-TWjqiJSWIBlMASlQTwnfDNZqXLCPkh5w?e=0CfOjy | H28: 30 | I28: 4 | J28: =IFERROR(I28/H28,0) -> 0.13333333 | K28: =+I28+'MAYO 2025'!K28 -> 10 | L28: =IFERROR(K28/H28,0) -> 0.33333333
B29: 8 | C29: 8.2 | D29: Carga de datos, procesamiento de datos, Análisis Estadístico descriptivo considerando hipótesis desde la teoría, y análisis descriptivo considerando hipótesis generadas desde la misma data (pasos 1, 2 y 3 teoría CRISP-DM). | F29: Actualización de las diferentes bases de datos para la actualización de tableros y distintas visuales | G29: https://ecopetrol.sharepoint.com/:f:/s/IAAKACIAS/EoI_hVXr9Q5FtD_ADjltMeYB1mxxF9WpklMtD9QXGgqRTA?e=FXnE5b | H29: 30 | I29: 3 | J29: =IFERROR(I29/H29,0) -> 0.1 | K29: =+I29+'MAYO 2025'!K29 -> 10 | L29: =IFERROR(K29/H29,0) -> 0.33333333
B30: 1 | C30: 1.2 | D30: Generación Bases de Datos de Pozos (Registros, Topes e información disponible) | E30: Julian A Hernández | F30: 1) Actualización con la base de datos con información preliminar para los pozos de la etapa ANE. | G30: \\10.100.25.35\pgtrabajodigital\JAH\Proyecto groups21\akacias\2.- Ingeniería de Yacimientos\1.MONITOREO | H30: 55 | I30: 6 | J30: =IFERROR(I30/H30,0) -> 0.10909091 | K30: =+I30+'MAYO 2025'!K30 -> 15 | L30: =IFERROR(K30/H30,0) -> 0.27272727
B31: 1 | C31: 1.3 | D31: Interpretación Sísmica | F31: 1) Revisón de información sismica para los pozos pertencientes a los patrones de inyección para identificar estructuras y establecer conectividades en los patrones de inyección. En busqueda del mejoramiento del factor de conectividad geológico. 2) Revisión información sísmica para identificar fallas o estrucutras en los patrones de inyección en pro de actualziar el factor de conectividad geológica para el campo Akacias. 3) Revisión en conjunto con el área de geofísica de la informaicón sismica para los pozos nuevos a perforar en el campo Akacias. | G31: \\10.100.25.35\pgtrabajodigital\JAH\Proyecto Z:\akacias\2.- Ingeniería de Yacimientos\1.MONITOREO\19.Sistematica WF Akacias\2025\06.Junio | H31: 20 | I31: 3 | J31: =IFERROR(I31/H31,0) -> 0.15 | K31: =+I31+'MAYO 2025'!K31 -> 8 | L31: =IFERROR(K31/H31,0) -> 0.4
B32: 1 | C32: 1.5 | D32: Digitalización, digitación y/o captura de información geológica (Mapas, Raw Data, topes, etc.) | F32: 1) Generación mapas, cortes y correalciones para hacer seguimiento a los patrones de inyección del campo y monitoreo a los pozos productores. 2) Cargue informaicón preliminar para los pozos de la etapa ANE. | G32: \\10.100.25.35\pgtrabajodigital\JAH\Proyecto | H32: 30 | I32: 5 | J32: =IFERROR(I32/H32,0) -> 0.16666667 | K32: =+I32+'MAYO 2025'!K32 -> 10 | L32: =IFERROR(K32/H32,0) -> 0.33333333
B33: 1 | C33: 1.8 | D33: Balanceo de Secciones | F33: 1) Contrucción en petrel de secciones que permitan observar la continuidad horizontal de los ciclos estratigráficos en pro de establecer la conectividad geológica en los patrones de inyección, en el monitoreo del WF para el campo Akacias. 2) Generación de secciones estructurales que permitan observar el comportamiento areal del yacimiento para monitorear el comportamiento de pozos productores y conectividades en patrones de inyección. | G33: \\10.100.25.35\pgtrabajodigital\JAH\Proyecto | H33: 25 | I33: 3 | J33: =IFERROR(I33/H33,0) -> 0.12 | K33: =+I33+'MAYO 2025'!K33 -> 8 | L33: =IFERROR(K33/H33,0) -> 0.32
B34: 1 | C34: 1.9 | D34: Análisis de sellos de fallas | F34: 1) Revisión del modelo estrucutural para el análisis de los patrones de inyección y así establecer la comunicación entre Inyec-produc durantes las sesiones de WF Akacias. 2) Revisión de los posibles sellos estructurales que condicionen el factor falla involucrado en la determinación del factor de conectividad geológico y continuar con la actualización de los tableros de conectividad geológica. 3) Análisis de las fallas dentro del estudio para identificar la influencia del acuífero en el campo a nivel CHIAK. 4) Continua la actualziación de la interpretación estructural e inicio del análisis de conectividad en los patrones de inyección del campo. | G34: \\10.100.25.35\pgtrabajodigital\JAH\Proyecto Z:\akacias\2.- Ingeniería de Yacimientos\1.MONITOREO\19.Sistematica WF Akacias\2025\06.Junio | H34: 30 | I34: 2 | J34: =IFERROR(I34/H34,0) -> 0.066666667 | K34: =+I34+'MAYO 2025'!K34 -> 10 | L34: =IFERROR(K34/H34,0) -> 0.33333333
B35: 1 | C35: 1.10 | D35: Amarre Sísmica Pozo | F35: 1) Revisión de la información sismíca con la trayectoria en las trayectorias entre pozos inyectores y porductores para identicar el Factor falla involucrado dentro del factor de conectividad geológica, insumo para actualizar el factor de conectividad geológico y el mapa de conectividad. 2) Revisión de las fallas interpretadas en las zonas de los pozos próximos a perforar para identificar los posibles riesgos geológicos y geofísicos, involucrando la nueva información estructural. Información que se usa como insumo para contrucción de los documentos RMS elaborados para los próximos pozos a perforar (etapas ANE y Frontera). | G35: \\10.100.25.35\pgtrabajodigital\JAH\Proyecto groups21\akacias\5. Información de pozos | H35: 20 | I35: 2 | J35: =IFERROR(I35/H35,0) -> 0.1 | K35: =+I35+'MAYO 2025'!K35 -> 8 | L35: =IFERROR(K35/H35,0) -> 0.4
B36: 1 | C36: 1.12 | D36: Generación de mapas de facies | F36: 1) Continua la elaboración de la base de datos para la actualización de los tableros G&G CHIAK. 2) Hacer seguimiento áreal de las facies para identificar los cambios laterales de facies que puedan indicar el comportamiento de arenas yto en los pozos productores. | G36: \\10.100.25.35\pgtrabajodigital\JAH\Proyecto | H36: 20 | I36: 3 | J36: =IFERROR(I36/H36,0) -> 0.15 | K36: =+I36+'MAYO 2025'!K36 -> 8 | L36: =IFERROR(K36/H36,0) -> 0.4
B37: 1 | C37: 1.15 | D37: Carga de información para poblar el modelo geocelular (direccionales, coordenadas, surveys, topes, data de presión, estados mecánicos, evento de pozos, etc.) | F37: 1) Actualización última información aprobada para los pozos de la etapa ANE y Frontera para la elaboración de los archivos RMS. | G37: ruta: \\10.100.25.35\pgtrabajodigital\JAH\Proyecto | H37: 50 | I37: 6 | J37: =IFERROR(I37/H37,0) -> 0.12 | K37: =+I37+'MAYO 2025'!K37 -> 15 | L37: =IFERROR(K37/H37,0) -> 0.3
B38: 1 | C38: 1.25 | D38: Análisis geoquímicos de Fingerprinting | F38: - | G38: - | H38: 20 | I38: 0 | J38: =IFERROR(I38/H38,0) -> 0 | K38: =+I38+'MAYO 2025'!K38 -> 8 | L38: =IFERROR(K38/H38,0) -> 0.4
B39: 3 | C39: 3.6 | D39: Generar Modelo analítico del yacimiento integrando la información disponible en un software específico | E39: Milton J Gualteros | F39: Actualización modelo analítico de yacimientos ARPS PDI2025 ESC3 - Frontera, ANE, Etapa 3, Inyección norte CHIAK | G39: Microsoft Teams, Email, Sharepoint Y:\akacias\37. Archivos | H39: 35 | I39: 4 | J39: =IFERROR(I39/H39,0) -> 0.11428571 | K39: =+I39+'MAYO 2025'!K39 -> 12 | L39: =IFERROR(K39/H39,0) -> 0.34285714
B40: 3 | C40: 3.13 | D40: Generar base de datos de producción (OFM o la que se requiera) | F40: Generación base de datos y construcción perfiles proyectos Desarrollo Posterior | G40: Microsoft Teams, Email, Sharepoint Y:\akacias\37. Archivos | H40: 33 | I40: 4 | J40: =IFERROR(I40/H40,0) -> 0.12121212 | K40: =+I40+'MAYO 2025'!K40 -> 11 | L40: =IFERROR(K40/H40,0) -> 0.33333333
...

Sheet JULIO 2025
Q1: MES
B2: REPORTE DE AVANCE | Q2: ENERO
B3: Fecha: 29/06/2022 | F3: Version: 01 | J3: GP-F-23
Q4: FEBRERO
B5: Código Orden de servicio | D5: 90141005 | Q5: MARZO
Q6: JUNIO
B7: Mes a reportar | D7: JULIO | Q7: JULIO
Q8: AGOSTO
B9: Fecha reporte | D9: 45869 | Q9: SEPTIEMBRE
Q10: OCTUBRE
B11: Clasificación del servicio | I11: Reporte mes por servicio | K11: Reporte acumulado por servicio | Q11: NOVIEMBRE
B12: Ítem general | C12: ítem actividad | D12: Descripción de la actividad | E12: Profesional a cargo | F12: Soporte | G12: Medio de entrega | H12: Días contratados | I12: Días | J12: % avance | K12: Días | L12: % avance | Q12: DICIEMBRE
B13: 3 | C13: 3.6 | D13: Generar Modelo analítico del yacimiento integrando la información disponible en un software específico | E13: Alejandro D López | F13: Cambio en los cronogramas y perfiles del modelo analítico en ARPS para los perfiles de producción para el campo Akasias en para las etapas de ANE y Tinamu | G13: ACCESS - PLP 2024 - Todos los documentos (sharepoint.com) | H13: 33 | I13: 6 | J13: =IFERROR(I13/H13,0) -> 0.18181818 | K13: =+I13+'JUNIO 2025'!K13 -> 26 | L13: =IFERROR(K13/H13,0) -> 0.78787879
B14: 3 | C14: 3.13 | D14: Generar base de datos de producción (OFM o la que se requiera) | F14: Generar archivos de carga de productores, inyectores y allocacion para el campo Tinamu. Se realizó control de calidad a los archivos que se subieron al ARPS | G14: https://ecopetrol.sharepoint.com/sites/EquipoDesarrolloCPO-9/Documentos%20compartidos/Forms/AllItems.aspx?id=%2Fsites%2FEquipoDesarrolloCPO%2D9%2FDocumentos%20compartidos%2FGeneral%2F04%2DExploratorio%2FExploratorios%20CPO%2D9&viewid=0e96c994%2D47e1%2D4e99%2D93c0%2D37826753815c | H14: 39 | I14: 0 | J14: =IFERROR(I14/H14,0) -> 0 | K14: =+I14+'JUNIO 2025'!K14 -> 10 | L14: =IFERROR(K14/H14,0) -> 0.25641026
B15: 3 | C15: 3.16 | D15: Análisis de Declinaciones por pozo y/o subunidad | F15: Se generó un establecio la configuracion de allocacion de primeras y segundas lineas por RWA para el campo Akacias en la etapa de desarrollo temprano | G15: ACCESS - PLP 2024 - Todos los documentos (sharepoint.com) | H15: 33 | I15: 6 | J15: =IFERROR(I15/H15,0) -> 0.18181818 | K15: =+I15+'JUNIO 2025'!K15 -> 16 | L15: =IFERROR(K15/H15,0) -> 0.48484848
B16: 3 | C16: 3.17 | D16: Analizar data histórica de producción, productividad y daño por pozo | F16: Base de Datos - Informe de la Evaluación | G16: ACCESS - PLP 2024 - Todos los documentos (sharepoint.com) | H16: 33 | I16: 2 | J16: =IFERROR(I16/H16,0) -> 0.060606061 | K16: =+I16+'JUNIO 2025'!K16 -> 12 | L16: =IFERROR(K16/H16,0) -> 0.36363636
B17: 3 | C17: 3.18 | D17: Generar perfiles de Producción por pozos para pozos existente en escenarios Bajo, Medio y Alto | F17: Se generó un archivo parcial de analisis de produccion de los pozos de cercanos y perforados del campo Tinamu para usar su produccion como referencia para los futuros pozos del campo | G17: ACCESS - PLP 2024 - Todos los documentos (sharepoint.com) | H17: 33 | I17: 6 | J17: =IFERROR(I17/H17,0) -> 0.18181818 | K17: =+I17+'JUNIO 2025'!K17 -> 16 | L17: =IFERROR(K17/H17,0) -> 0.48484848
B18: 5 | C18: 5.2 | D18: Generación de oportunidades de intervención a Pozos | F18: Base de Datos - Informe de la Evaluación | G18: ACCESS - Frontera - Todos los documentos | H18: 33 | I18: 4 | J18: =IFERROR(I18/H18,0) -> 0.12121212 | K18: =+I18+'JUNIO 2025'!K18 -> 14 | L18: =IFERROR(K18/H18,0) -> 0.42424242
B19: 5 | C19: 5.9 | D19: Realizar el seguimiento de producción/ inyección de pozos intervenidos con base en los comportamientos de producción previo y posterior a la intervención | F19: Entrega de perfiles de la etapa de Tinamu para proyectos | G19: ACCESS - Tinamu - Todos los documentos | H19: 33 | I19: 5 | J19: =IFERROR(I19/H19,0) -> 0.15151515 | K19: =+I19+'JUNIO 2025'!K19 -> 15 | L19: =IFERROR(K19/H19,0) -> 0.45454545
B20: 8 | C20: 8.2 | D20: Carga de datos, procesamiento de datos, Análisis Estadístico descriptivo considerando hipótesis desde la teoría, y análisis descriptivo considerando hipótesis generadas desde la misma data (pasos 1, 2 y 3 teoría CRISP-DM). | F20: Informe, con estadísticas descriptivas, histogramas, pruebas de ajuste, etc. | G20: Informe de reservas Campo Akacias 2022 - Inicio (sharepoint.com) | H20: 33 | I20: 1 | J20: =IFERROR(I20/H20,0) -> 0.03030303 | K20: =+I20+'JUNIO 2025'!K20 -> 11 | L20: =IFERROR(K20/H20,0) -> 0.33333333
B21: 3 | C21: 3.6 | D21: Generar Modelo analítico del yacimiento integrando la información disponible en un software específico | E21: Jhon H Carreño | F21: Actualización semanal del modelo estático y dinámico del yacimiento y pozos del campo Akacias, mediante el proyecto Sahara Junio-2025 (Cargadores y modelo final) | G21: X:\CHICHIMENE\INFORMACIÓN_CAMPO_CHICHIMENE\23.-Inyeccion de Agua\10. MONITOREO\09. Proyecto Sahara\2025 W:\2.- Ingeniería de Yacimientos\1.MONITOREO\1.Sahara\2025\7. Julio | H21: 30 | I21: 3 | J21: =IFERROR(I21/H21,0) -> 0.1 | K21: =+I21+'JUNIO 2025'!K21 -> 13 | L21: =IFERROR(K21/H21,0) -> 0.43333333
B22: 3 | C22: 3.13 | D22: Generar base de datos de producción (OFM o la que se requiera) | F22: Actualización de la producción con base a la información de las formas ministeriales para las base de datos (molinos de viento) de producción mensual y cargue trimestral y seguimiento a proyectos en tableros de seguimiento | G22: W:\2.- Ingeniería de Yacimientos\1.MONITOREO\9.Tablero Power BI 2.1\2025 W:\2.- Ingeniería de Yacimientos\1.MONITOREO\14.Molinos de Viento\Cargadores\Real\2025 | H22: 30 | I22: 4 | J22: =IFERROR(I22/H22,0) -> 0.13333333 | K22: =+I22+'JUNIO 2025'!K22 -> 14 | L22: =IFERROR(K22/H22,0) -> 0.46666667
B23: 3 | C23: 3.14 | D23: Generar Distribución de Producción por sub- unidades (allocation) | F23: Distribución de la producción asociada a la implementación del WF en los patrones de inyección del campo AK por medio del metodo RWA con la información a cierre de Jun-2025 y distribución de la inyección de agua por medio de factores de alocación usando como información base los registros ILT adquiridos | G23: W:\2.- Ingeniería de Yacimientos\1.MONITOREO\9.Tablero Power BI 2.1\2025\6. Junio W:\2.- Ingeniería de Yacimientos\1.MONITOREO\14.Molinos de Viento\Cargadores\Real\2025\06. Junio | H23: 30 | I23: 4 | J23: =IFERROR(I23/H23,0) -> 0.13333333 | K23: =+I23+'JUNIO 2025'!K23 -> 14 | L23: =IFERROR(K23/H23,0) -> 0.46666667
B24: 3 | C24: 3.16 | D24: Análisis de Declinaciones por pozo y/o subunidad | F24: Definición del efecto de inyección del AK-135i sobre los productores AK-133 y 137. Construcción de líneas base en Sahara | G24: X:\CHICHIMENE\INFORMACIÓN_CAMPO_CHICHIMENE\23.-Inyeccion de Agua\10. MONITOREO\09. Proyecto Sahara\2025 | H24: 30 | I24: 3 | J24: =IFERROR(I24/H24,0) -> 0.1 | K24: =+I24+'JUNIO 2025'!K24 -> 13 | L24: =IFERROR(K24/H24,0) -> 0.43333333
B25: 3 | C25: 3.17 | D25: Analizar data histórica de producción, productividad y daño por pozo | F25: Interpretación del cierre para los pozos AK-79, AK-96, AK-127, AK-155 y AK-156 del sector Nueva Esperanza para determinar el grado de recuperación de presión por efecto de la inyección en el AK-26i, AK-147i y CH-235i del proyecto frontera | G25: W:\2.- Ingeniería de Yacimientos\1.MONITOREO\7.Presiones\2025\1_Semestre\Información de presión Jun2025 NE | H25: 30 | I25: 4 | J25: =IFERROR(I25/H25,0) -> 0.13333333 | K25: =+I25+'JUNIO 2025'!K25 -> 14 | L25: =IFERROR(K25/H25,0) -> 0.46666667
B26: 3 | C26: 3.18 | D26: Generar perfiles de Producción por pozos para pozos existente en escenarios Bajo, Medio y Alto | F26: Actualización del coeficiente de eficiencia veritical para seguimiento de los patrones de inyección del campo Akacias | G26: W:\2.- Ingeniería de Yacimientos\1.MONITOREO\37. Coeficientes de eficiencia vertical\2025\3. Junio | H26: 30 | I26: 3 | J26: =IFERROR(I26/H26,0) -> 0.1 | K26: =+I26+'JUNIO 2025'!K26 -> 13 | L26: =IFERROR(K26/H26,0) -> 0.43333333
B27: 5 | C27: 5.2 | D27: Generación de oportunidades de intervención a Pozos | F27: Interpretación del gradiente estático adquirido en el AK-153 del sector Nueva esperanza a fin de conocer el grado de conexión con los pozos del patrón, además de verificar el incremeto de presión en el tiempo | G27: W:\2.- Ingeniería de Yacimientos\1.MONITOREO\7.Presiones\2025\1_Semestre\5. AK-153 | H27: 30 | I27: 3 | J27: =IFERROR(I27/H27,0) -> 0.1 | K27: =+I27+'JUNIO 2025'!K27 -> 13 | L27: =IFERROR(K27/H27,0) -> 0.43333333
B28: 5 | C28: 5.9 | D28: Realizar el seguimiento de producción/ inyección de pozos intervenidos con base en los comportamientos de producción previo y posterior a la intervención | F28: Seguimiento a la intervención de WO de los pozos AK-35i, AK-33 y AK-05 | G28: W:\2.- Ingeniería de Yacimientos\1.MONITOREO\4. Inyectores\Etapa A2.2\AK-35\2025 https://ecopetrol.sharepoint.com/:p:/s/IAAKACIAS/EVKgMF0gGsVHtQBEs1cOyrwBuReCBoJh1yvlEMqX3lTqHw?e=79vEVM | H28: 30 | I28: 3 | J28: =IFERROR(I28/H28,0) -> 0.1 | K28: =+I28+'JUNIO 2025'!K28 -> 13 | L28: =IFERROR(K28/H28,0) -> 0.43333333
B29: 8 | C29: 8.2 | D29: Carga de datos, procesamiento de datos, Análisis Estadístico descriptivo considerando hipótesis desde la teoría, y análisis descriptivo considerando hipótesis generadas desde la misma data (pasos 1, 2 y 3 teoría CRISP-DM). | F29: Actualización de las diferentes bases de datos para la actualización de tableros y distintas visuales | G29: https://ecopetrol.sharepoint.com/:f:/s/IAAKACIAS/EoI_hVXr9Q5FtD_ADjltMeYB1mxxF9WpklMtD9QXGgqRTA?e=FXnE5b | H29: 30 | I29: 3 | J29: =IFERROR(I29/H29,0) -> 0.1 | K29: =+I29+'JUNIO 2025'!K29 -> 13 | L29: =IFERROR(K29/H29,0) -> 0.43333333
B30: 1 | C30: 1.2 | D30: Generación Bases de Datos de Pozos (Registros, Topes e información disponible) | E30: Julian A Hernández | F30: 1) Actualización con la base de datos con información de pozos inyectores del campo y la información preliminar aprobada para los pozos AK222 y AK99. | G30: \\10.100.25.35\pgtrabajodigital\JAH\Proyecto groups21\akacias\2.- Ingeniería de Yacimientos\1.MONITOREO | H30: 55 | I30: 7 | J30: =IFERROR(I30/H30,0) -> 0.12727273 | K30: =+I30+'JUNIO 2025'!K30 -> 22 | L30: =IFERROR(K30/H30,0) -> 0.4
