Workbook

Sheet ABRIL
P1: MES
B2: REPORTE DE AVANCE | P2: ENERO
B3: Fecha: 29/06/2022 | E3: Version: 01 | I3: GP-F-23
P4: FEBRERO
B5: Código Orden de servicio | D5: 90172266 | P5: MARZO
P6: JUNIO
B7: Mes a reportar | D7: ABRIL | P7: JULIO
P8: AGOSTO
B9: Fecha reporte | D9: 45777 | P9: SEPTIEMBRE
P10: OCTUBRE
B11: Clasificación del servicio | H11: Reporte mes por servicio | J11: Reporte acumulado por servicio | P11: NOVIEMBRE
B12: Ítem general | C12: ítem actividad | D12: Descripción de la actividad | E12: Soporte | F12: Medio de entrega | G12: Días contratados | H12: Días | I12: % avance | J12: Días | K12: % avance | P12: DICIEMBRE
B13: 3 | C13: 3.6 | D13: Generar Modelo analítico del yacimiento integrando la información disponible en un software específico | E13: - | F13: - | G13: 10 | H13: 0 | I13: =IFERROR(H13/G13,0) -> 0 | J13: =+H13 -> 0 | K13: =IFERROR(J13/G13,0) -> 0
B14: 3 | C14: 3.11 | D14: Análisis e interpretación de datos de pruebas de presión-producción (DSTs, PBU, Pruebas Extendidas Producción, Gradientes Estáticos-Dinámicos PT, etc.) o de presión inyección (Inyectividad, SRT, FOT) aplicadas ya sea en tiempo real, memorizadas o con sarta temporal DST. Integración Probador Formación – Registros Open Hole. | E14: - | F14: - | G14: 5 | H14: 0 | I14: =IFERROR(H14/G14,0) -> 0 | J14: =+H14 -> 0 | K14: =IFERROR(J14/G14,0) -> 0
B15: 3 | C15: 3.13 | D15: Generar base de datos de producción (OFM o la que se requiera) | E15: - | F15: - | G15: 13 | H15: 0 | I15: =IFERROR(H15/G15,0) -> 0 | J15: =+H15 -> 0 | K15: =IFERROR(J15/G15,0) -> 0
B16: 3 | C16: 3.14 | D16: Generar Distribución de Producción por sub- unidades (allocation) | E16: - | F16: - | G16: 20 | H16: 0 | I16: =IFERROR(H16/G16,0) -> 0 | J16: =+H16 -> 0 | K16: =IFERROR(J16/G16,0) -> 0
B17: 3 | C17: 3.15 | D17: Generar Balance de Materia por campo y/o por subunidad y/o por compartimiento | E17: - | F17: - | G17: 10 | H17: 0 | I17: =IFERROR(H17/G17,0) -> 0 | J17: =+H17 -> 0 | K17: =IFERROR(J17/G17,0) -> 0
B18: 3 | C18: 3.16 | D18: Análisis de Declinaciones por pozo y/o subunidad | E18: Base de Datos – Perfiles Generados – Informe del análisis | F18: Digital | G18: 20 | H18: 3 | I18: =IFERROR(H18/G18,0) -> 0.15 | J18: =+H18 -> 3 | K18: =IFERROR(J18/G18,0) -> 0.15
B19: 3 | C19: 3.17 | D19: Analizar data histórica de producción, productividad y daño por pozo | E19: Base de Datos - Informe de la Evaluación | F19: Digital | G19: 20 | H19: 3 | I19: =IFERROR(H19/G19,0) -> 0.15 | J19: =+H19 -> 3 | K19: =IFERROR(J19/G19,0) -> 0.15
B20: 3 | C20: 3.18 | D20: Generar perfiles de Producción por pozos para pozos existente en escenarios Bajo, Medio y Alto. | E20: - | F20: - | G20: 20 | H20: 0 | I20: =IFERROR(H20/G20,0) -> 0 | J20: =+H20 -> 0 | K20: =IFERROR(J20/G20,0) -> 0
B21: 5 | C21: 5.2 | D21: Generación de oportunidades de intervención a Pozos | E21: - | F21: - | G21: 13 | H21: 0 | I21: =IFERROR(H21/G21,0) -> 0 | J21: =+H21 -> 0 | K21: =IFERROR(J21/G21,0) -> 0
B22: 5 | C22: 5.3 | D22: Estimar restricciones de Presión y tasas para la generación de perfiles de producción | E22: - | F22: - | G22: 20 | H22: 0 | I22: =IFERROR(H22/G22,0) -> 0 | J22: =+H22 -> 0 | K22: =IFERROR(J22/G22,0) -> 0
B23: 5 | C23: 5.4 | D23: Generar modelo de Pozos | E23: - | F23: - | G23: 13 | H23: 0 | I23: =IFERROR(H23/G23,0) -> 0 | J23: =+H23 -> 0 | K23: =IFERROR(J23/G23,0) -> 0
B24: 5 | C24: 5.5 | D24: Adelantar la evaluación e interpretación de datos enfocada a candidatización de actividades de reacondicionamiento y optimización de productividad en los activos | E24: - | F24: - | G24: 13 | H24: 0 | I24: =IFERROR(H24/G24,0) -> 0 | J24: =+H24 -> 0 | K24: =IFERROR(J24/G24,0) -> 0
... B30: 5 | C30: 5.11 | D30: Generar los análisis asociados a la ejecución de estudios de daño de formación empleando simulación numérica (análisis nodal y single well model, análisis de aguas, análisis de crudos, entre otros) | E30: - | F30: - | G30: 8 | H30: 0 | I30: =IFERROR(H30/G30,0) -> 0 | J30: =+H30 -> 0 | K30: =IFERROR(J30/G30,0) -> 0
G31: =+CONCATENATE("TOTAL A ",D7) -> TOTAL A ABRIL | J31: TOTAL ACUMULADO
G32: =+SUM(G13:G30) -> 249 | H32: =+SUM(H13:H30) -> 9 | I32: =IFERROR(H32/G32,0) -> 0.036144578 | J32: =+SUM(J13:J30) -> 9 | K32: =IFERROR(J32/G32,0) -> 0.036144578
B34: Observaciones: | D34: En el formato GP-F-25 se detallan las actividades realizadas y los enlaces a los sitios/archivos donde se ha cargado la información. https://ecopetrol.sharepoint.com/:x:/r/sites/OptimizacinInyeccin-ProduccinSanFrancisco/Documentos compartidos/Optimizaci%C3%B3n proceso de Inyecci%C3%B3n - Producci%C3%B3n/Inyecci%C3%B3n/RWA SF Ene-Feb_2025.xlsx?d=w35503fe905534d0aaae8e60e91bf1271&csf=1&web=1&e=0S7rIt https://ecopetrol.sharepoint.com/:x:/r/sites/OptimizacinInyeccin-ProduccinSanFrancisco/Documentos compartidos/Optimizaci%C3%B3n proceso de Inyecci%C3%B3n - Producci%C3%B3n/Actas Well Meeting/Notas de Reuni%C3%B3n para Wellmeeting San Francisco.xlsx?d=we77180250ac949cca611943521a15487&csf=1&web=1&e=YoV2Bj
B35: ¿Se presentó algún aspecto o situación que afecte la ejecución y calidad de los entregables? (Marque con una X)
B37: PROFESIONAL
B38: SI | D38: Describa en este espacio su observación
B39: NO
B40: ¿Se presentó algún aspecto o situación que afecte la ejecución y calidad de los entregables? (Marque con una X)
B42: INTERVENTOR O LIDER
B43: SI | D43: Describa en este espacio su observación
B44: NO
B48: Revisa: | G48: Interventor: | H48: Luisa Margarita Uribe
A72: MES
A73: ENERO
A74: FEBRERO
...

Sheet MAYO
P1: MES
B2: REPORTE DE AVANCE | P2: ENERO
B3: Fecha: 29/06/2022 | E3: Version: 01 | I3: GP-F-23
P4: FEBRERO
B5: Código Orden de servicio | D5: 90172266 | P5: MARZO
P6: JUNIO
B7: Mes a reportar | D7: MAYO | P7: JULIO
P8: AGOSTO
B9: Fecha reporte | D9: 45808 | P9: SEPTIEMBRE
P10: OCTUBRE
B11: Clasificación del servicio | H11: Reporte mes por servicio | J11: Reporte acumulado por servicio | P11: NOVIEMBRE
B12: Ítem general | C12: ítem actividad | D12: Descripción de la actividad | E12: Soporte | F12: Medio de entrega | G12: Días contratados | H12: Días | I12: % avance | J12: Días | K12: % avance | P12: DICIEMBRE
B13: 3 | C13: 3.6 | D13: Generar Modelo analítico del yacimiento integrando la información disponible en un software específico | E13: - | F13: - | G13: 10 | H13: 0 | I13: =IFERROR(H13/G13,0) -> 0 | J13: =+H13+ABRIL!J13 -> 0 | K13: =IFERROR(J13/G13,0) -> 0
B14: 3 | C14: 3.11 | D14: Análisis e interpretación de datos de pruebas de presión-producción (DSTs, PBU, Pruebas Extendidas Producción, Gradientes Estáticos-Dinámicos PT, etc.) o de presión inyección (Inyectividad, SRT, FOT) aplicadas ya sea en tiempo real, memorizadas o con sarta temporal DST. Integración Probador Formación – Registros Open Hole. | E14: - | F14: - | G14: 5 | H14: 0 | I14: =IFERROR(H14/G14,0) -> 0 | J14: =+H14+ABRIL!J14 -> 0 | K14: =IFERROR(J14/G14,0) -> 0
B15: 3 | C15: 3.13 | D15: Generar base de datos de producción (OFM o la que se requiera) | E15: Base de Datos | F15: Digital | G15: 13 | H15: 2 | I15: =IFERROR(H15/G15,0) -> 0.15384615 | J15: =+H15+ABRIL!J15 -> 2 | K15: =IFERROR(J15/G15,0) -> 0.15384615
B16: 3 | C16: 3.14 | D16: Generar Distribución de Producción por sub- unidades (allocation) | E16: - | F16: - | G16: 20 | H16: 0 | I16: =IFERROR(H16/G16,0) -> 0 | J16: =+H16+ABRIL!J16 -> 0 | K16: =IFERROR(J16/G16,0) -> 0
B17: 3 | C17: 3.15 | D17: Generar Balance de Materia por campo y/o por subunidad y/o por compartimiento | E17: - | F17: - | G17: 10 | H17: 0 | I17: =IFERROR(H17/G17,0) -> 0 | J17: =+H17+ABRIL!J17 -> 0 | K17: =IFERROR(J17/G17,0) -> 0
B18: 3 | C18: 3.16 | D18: Análisis de Declinaciones por pozo y/o subunidad | E18: Base de Datos – Perfiles Generados – Informe del análisis | F18: Digital | G18: 20 | H18: 6 | I18: =IFERROR(H18/G18,0) -> 0.3 | J18: =+H18+ABRIL!J18 -> 9 | K18: =IFERROR(J18/G18,0) -> 0.45
B19: 3 | C19: 3.17 | D19: Analizar data histórica de producción, productividad y daño por pozo | E19: Base de Datos - Informe de la Evaluación | F19: Digital | G19: 20 | H19: 6 | I19: =IFERROR(H19/G19,0) -> 0.3 | J19: =+H19+ABRIL!J19 -> 9 | K19: =IFERROR(J19/G19,0) -> 0.45
B20: 3 | C20: 3.18 | D20: Generar perfiles de Producción por pozos para pozos existente en escenarios Bajo, Medio y Alto. | E20: Base de Datos – Informe de la Evaluación | F20: Digital | G20: 20 | H20: 6 | I20: =IFERROR(H20/G20,0) -> 0.3 | J20: =+H20+ABRIL!J20 -> 6 | K20: =IFERROR(J20/G20,0) -> 0.3
B21: 5 | C21: 5.2 | D21: Generación de oportunidades de intervención a Pozos | E21: Base de Datos - Informe de la Evaluación | F21: Digital | G21: 13 | H21: 2 | I21: =IFERROR(H21/G21,0) -> 0.15384615 | J21: =+H21+ABRIL!J21 -> 2 | K21: =IFERROR(J21/G21,0) -> 0.15384615
B22: 5 | C22: 5.3 | D22: Estimar restricciones de Presión y tasas para la generación de perfiles de producción | E22: Base de Datos – Informe de la Evaluación | F22: Digital | G22: 20 | H22: 2 | I22: =IFERROR(H22/G22,0) -> 0.1 | J22: =+H22+ABRIL!J22 -> 2 | K22: =IFERROR(J22/G22,0) -> 0.1
B23: 5 | C23: 5.4 | D23: Generar modelo de Pozos | E23: - | F23: - | G23: 13 | H23: 0 | I23: =IFERROR(H23/G23,0) -> 0 | J23: =+H23+ABRIL!J23 -> 0 | K23: =IFERROR(J23/G23,0) -> 0
B24: 5 | C24: 5.5 | D24: Adelantar la evaluación e interpretación de datos enfocada a candidatización de actividades de reacondicionamiento y optimización de productividad en los activos | E24: Base de Datos – Informe de la Evaluación | F24: Digital | G24: 13 | H24: 2 | I24: =IFERROR(H24/G24,0) -> 0.15384615 | J24: =+H24+ABRIL!J24 -> 2 | K24: =IFERROR(J24/G24,0) -> 0.15384615
... B30: 5 | C30: 5.11 | D30: Generar los análisis asociados a la ejecución de estudios de daño de formación empleando simulación numérica (análisis nodal y single well model, análisis de aguas, análisis de crudos, entre otros) | E30: Base de Datos – Informe de la Evaluación | F30: Digital | G30: 8 | H30: 1 | I30: =IFERROR(H30/G30,0) -> 0.125 | J30: =+H30+ABRIL!J30 -> 1 | K30: =IFERROR(J30/G30,0) -> 0.125
G31: =+CONCATENATE("TOTAL A ",D7) -> TOTAL A MAYO | J31: TOTAL ACUMULADO
G32: =+SUM(G13:G30) -> 249 | H32: =+SUM(H13:H30) -> 30 | I32: =IFERROR(H32/G32,0) -> 0.12048193 | J32: =+SUM(J13:J30) -> 39 | K32: =IFERROR(J32/G32,0) -> 0.15662651
B34: Observaciones: | D34: En el formato GP-F-25 se detallan las actividades realizadas y los enlaces a los sitios/archivos donde se ha cargado la información.
B35: ¿Se presentó algún aspecto o situación que afecte la ejecución y calidad de los entregables? (Marque con una X)
B37: PROFESIONAL
B38: SI | D38: Describa en este espacio su observación
B39: NO
B40: ¿Se presentó algún aspecto o situación que afecte la ejecución y calidad de los entregables? (Marque con una X)
B42: INTERVENTOR O LIDER
B43: SI | D43: Describa en este espacio su observación
B44: NO
B48: Revisa: | G48: Interventor: | H48: Luisa Margarita Uribe
A72: MES
A73: ENERO
A74: FEBRERO
...

Sheet JUNIO
P1: MES
B2: REPORTE DE AVANCE | P2: ENERO
B3: Fecha: 29/06/2022 | E3: Version: 01 | I3: GP-F-23
P4: FEBRERO
B5: Código Orden de servicio | D5: 90172266 | P5: MARZO
P6: JUNIO
B7: Mes a reportar | D7: JUNIO | P7: JULIO
P8: AGOSTO
B9: Fecha reporte | D9: 45838 | P9: SEPTIEMBRE
P10: OCTUBRE
B11: Clasificación del servicio | H11: Reporte mes por servicio | J11: Reporte acumulado por servicio | P11: NOVIEMBRE
B12: Ítem general | C12: ítem actividad | D12: Descripción de la actividad | E12: Soporte | F12: Medio de entrega | G12: Días contratados | H12: Días | I12: % avance | J12: Días | K12: % avance | P12: DICIEMBRE
B13: 3 | C13: 3.6 | D13: Generar Modelo analítico del yacimiento integrando la información disponible en un software específico | E13: Modelo Analítico – Perfiles de Producción – Informe del modelo | F13: Digital | G13: 10 | H13: 2 | I13: =IFERROR(H13/G13,0) -> 0.2 | J13: =+H13+MAYO!J13 -> 2 | K13: =IFERROR(J13/G13,0) -> 0.2
B14: 3 | C14: 3.11 | D14: Análisis e interpretación de datos de pruebas de presión-producción (DSTs, PBU, Pruebas Extendidas Producción, Gradientes Estáticos-Dinámicos PT, etc.) o de presión inyección (Inyectividad, SRT, FOT) aplicadas ya sea en tiempo real, memorizadas o con sarta temporal DST. Integración Probador Formación – Registros Open Hole. | E14: Informe del análisis por pozo o prueba | F14: Digital | G14: 5 | H14: 2 | I14: =IFERROR(H14/G14,0) -> 0.4 | J14: =+H14+MAYO!J14 -> 2 | K14: =IFERROR(J14/G14,0) -> 0.4
B15: 3 | C15: 3.13 | D15: Generar base de datos de producción (OFM o la que se requiera) | E15: Base de Datos | F15: Digital | G15: 13 | H15: 2 | I15: =IFERROR(H15/G15,0) -> 0.15384615 | J15: =+H15+MAYO!J15 -> 4 | K15: =IFERROR(J15/G15,0) -> 0.30769231
B16: 3 | C16: 3.14 | D16: Generar Distribución de Producción por sub- unidades (allocation) | E16: Base de Datos | F16: Digital | G16: 20 | H16: 2 | I16: =IFERROR(H16/G16,0) -> 0.1 | J16: =+H16+MAYO!J16 -> 2 | K16: =IFERROR(J16/G16,0) -> 0.1
B17: 3 | C17: 3.15 | D17: Generar Balance de Materia por campo y/o por subunidad y/o por compartimiento | E17: - | F17: - | G17: 10 | H17: 0 | I17: =IFERROR(H17/G17,0) -> 0 | J17: =+H17+MAYO!J17 -> 0 | K17: =IFERROR(J17/G17,0) -> 0
B18: 3 | C18: 3.16 | D18: Análisis de Declinaciones por pozo y/o subunidad | E18: Base de Datos – Perfiles Generados – Informe del análisis | F18: Digital | G18: 20 | H18: 4 | I18: =IFERROR(H18/G18,0) -> 0.2 | J18: =+H18+MAYO!J18 -> 13 | K18: =IFERROR(J18/G18,0) -> 0.65
B19: 3 | C19: 3.17 | D19: Analizar data histórica de producción, productividad y daño por pozo | E19: Base de Datos - Informe de la Evaluación | F19: Digital | G19: 20 | H19: 3 | I19: =IFERROR(H19/G19,0) -> 0.15 | J19: =+H19+MAYO!J19 -> 12 | K19: =IFERROR(J19/G19,0) -> 0.6
B20: 3 | C20: 3.18 | D20: Generar perfiles de Producción por pozos para pozos existente en escenarios Bajo, Medio y Alto. | E20: Base de Datos – Informe de la Evaluación | F20: Digital | G20: 20 | H20: 4 | I20: =IFERROR(H20/G20,0) -> 0.2 | J20: =+H20+MAYO!J20 -> 10 | K20: =IFERROR(J20/G20,0) -> 0.5
B21: 5 | C21: 5.2 | D21: Generación de oportunidades de intervención a Pozos | E21: Base de Datos - Informe de la Evaluación | F21: Digital | G21: 13 | H21: 2 | I21: =IFERROR(H21/G21,0) -> 0.15384615 | J21: =+H21+MAYO!J21 -> 4 | K21: =IFERROR(J21/G21,0) -> 0.30769231
B22: 5 | C22: 5.3 | D22: Estimar restricciones de Presión y tasas para la generación de perfiles de producción | E22: Base de Datos – Informe de la Evaluación | F22: Digital | G22: 20 | H22: 2 | I22: =IFERROR(H22/G22,0) -> 0.1 | J22: =+H22+MAYO!J22 -> 4 | K22: =IFERROR(J22/G22,0) -> 0.2
B23: 5 | C23: 5.4 | D23: Generar modelo de Pozos | E23: - | F23: - | G23: 13 | H23: 0 | I23: =IFERROR(H23/G23,0) -> 0 | J23: =+H23+MAYO!J23 -> 0 | K23: =IFERROR(J23/G23,0) -> 0
B24: 5 | C24: 5.5 | D24: Adelantar la evaluación e interpretación de datos enfocada a candidatización de actividades de reacondicionamiento y optimización de productividad en los activos | E24: Base de Datos – Informe de la Evaluación | F24: Digital | G24: 13 | H24: 2 | I24: =IFERROR(H24/G24,0) -> 0.15384615 | J24: =+H24+MAYO!J24 -> 4 | K24: =IFERROR(J24/G24,0) -> 0.30769231
... B30: 5 | C30: 5.11 | D30: Generar los análisis asociados a la ejecución de estudios de daño de formación empleando simulación numérica (análisis nodal y single well model, análisis de aguas, análisis de crudos, entre otros) | E30: Base de Datos – Informe de la Evaluación | F30: Digital | G30: 8 | H30: 1 | I30: =IFERROR(H30/G30,0) -> 0.125 | J30: =+H30+MAYO!J30 -> 2 | K30: =IFERROR(J30/G30,0) -> 0.25
G31: =+CONCATENATE("TOTAL A ",D7) -> TOTAL A JUNIO | J31: TOTAL ACUMULADO
G32: =+SUM(G13:G30) -> 249 | H32: =+SUM(H13:H30) -> 30 | I32: =IFERROR(H32/G32,0) -> 0.12048193 | J32: =+SUM(J13:J30) -> 69 | K32: =IFERROR(J32/G32,0) -> 0.27710843
B34: Observaciones: | D34: En el formato GP-F-25 se detallan las actividades realizadas y los enlaces a los sitios/archivos donde se ha cargado la información.
B35: ¿Se presentó algún aspecto o situación que afecte la ejecución y calidad de los entregables? (Marque con una X)
B37: PROFESIONAL
B38: SI | D38: Describa en este espacio su observación
B39: NO
B40: ¿Se presentó algún aspecto o situación que afecte la ejecución y calidad de los entregables? (Marque con una X)
B42: INTERVENTOR O LIDER
B43: SI | D43: Describa en este espacio su observación
B44: NO
B48: Revisa: | G48: Interventor: | H48: Luisa Margarita Uribe
A72: MES
A73: ENERO
A74: FEBRERO
...

Sheet JULIO
P1: MES
B2: REPORTE DE AVANCE | P2: ENERO
B3: Fecha: 29/06/2022 | E3: Version: 01 | I3: GP-F-23
P4: FEBRERO
B5: Código Orden de servicio | D5: 90172266 | P5: MARZO
P6: JUNIO
B7: Mes a reportar | D7: JULIO | P7: JULIO
P8: AGOSTO
B9: Fecha reporte | D9: 45869 | P9: SEPTIEMBRE
P10: OCTUBRE
B11: Clasificación del servicio | H11: Reporte mes por servicio | J11: Reporte acumulado por servicio | P11: NOVIEMBRE
B12: Ítem general | C12: ítem actividad | D12: Descripción de la actividad | E12: Soporte | F12: Medio de entrega | G12: Días contratados | H12: Días | I12: % avance | J12: Días | K12: % avance | P12: DICIEMBRE
B13: 3 | C13: 3.6 | D13: Generar Modelo analítico del yacimiento integrando la información disponible en un software específico | E13: Modelo Analítico – Perfiles de Producción – Informe del modelo | F13: Digital | G13: 10 | H13: 2 | I13: =IFERROR(H13/G13,0) -> 0.2 | J13: =+H13+JUNIO!J13 -> 4 | K13: =IFERROR(J13/G13,0) -> 0.4
B14: 3 | C14: 3.11 | D14: Análisis e interpretación de datos de pruebas de presión-producción (DSTs, PBU, Pruebas Extendidas Producción, Gradientes Estáticos-Dinámicos PT, etc.) o de presión inyección (Inyectividad, SRT, FOT) aplicadas ya sea en tiempo real, memorizadas o con sarta temporal DST. Integración Probador Formación – Registros Open Hole. | E14: Informe del análisis por pozo o prueba | F14: Digital | G14: 5 | H14: 1 | I14: =IFERROR(H14/G14,0) -> 0.2 | J14: =+H14+JUNIO!J14 -> 3 | K14: =IFERROR(J14/G14,0) -> 0.6
B15: 3 | C15: 3.13 | D15: Generar base de datos de producción (OFM o la que se requiera) | E15: Base de Datos | F15: Digital | G15: 13 | H15: 2 | I15: =IFERROR(H15/G15,0) -> 0.15384615 | J15: =+H15+JUNIO!J15 -> 6 | K15: =IFERROR(J15/G15,0) -> 0.46153846
B16: 3 | C16: 3.14 | D16: Generar Distribución de Producción por sub- unidades (allocation) | E16: Base de Datos | F16: Digital | G16: 20 | H16: 3 | I16: =IFERROR(H16/G16,0) -> 0.15 | J16: =+H16+JUNIO!J16 -> 5 | K16: =IFERROR(J16/G16,0) -> 0.25
B17: 3 | C17: 3.15 | D17: Generar Balance de Materia por campo y/o por subunidad y/o por compartimiento | E17: Base de Datos - Modelo de Balance - Informe del modelo | F17: Digital | G17: 10 | H17: 2 | I17: =IFERROR(H17/G17,0) -> 0.2 | J17: =+H17+JUNIO!J17 -> 2 | K17: =IFERROR(J17/G17,0) -> 0.2
B18: 3 | C18: 3.16 | D18: Análisis de Declinaciones por pozo y/o subunidad | E18: Base de Datos – Perfiles Generados – Informe del análisis | F18: Digital | G18: 20 | I18: =IFERROR(H18/G18,0) -> 0 | J18: =+H18+JUNIO!J18 -> 13 | K18: =IFERROR(J18/G18,0) -> 0.65
B19: 3 | C19: 3.17 | D19: Analizar data histórica de producción, productividad y daño por pozo | E19: Base de Datos - Informe de la Evaluación | F19: Digital | G19: 20 | I19: =IFERROR(H19/G19,0) -> 0 | J19: =+H19+JUNIO!J19 -> 12 | K19: =IFERROR(J19/G19,0) -> 0.6
B20: 3 | C20: 3.18 | D20: Generar perfiles de Producción por pozos para pozos existente en escenarios Bajo, Medio y Alto. | E20: Base de Datos – Informe de la Evaluación | F20: Digital | G20: 20 | H20: 2 | I20: =IFERROR(H20/G20,0) -> 0.1 | J20: =+H20+JUNIO!J20 -> 12 | K20: =IFERROR(J20/G20,0) -> 0.6
B21: 5 | C21: 5.2 | D21: Generación de oportunidades de intervención a Pozos | E21: Base de Datos - Informe de la Evaluación | F21: Digital | G21: 13 | H21: 2 | I21: =IFERROR(H21/G21,0) -> 0.15384615 | J21: =+H21+JUNIO!J21 -> 6 | K21: =IFERROR(J21/G21,0) -> 0.46153846
B22: 5 | C22: 5.3 | D22: Estimar restricciones de Presión y tasas para la generación de perfiles de producción | E22: Base de Datos – Informe de la Evaluación | F22: Digital | G22: 20 | H22: 2 | I22: =IFERROR(H22/G22,0) -> 0.1 | J22: =+H22+JUNIO!J22 -> 6 | K22: =IFERROR(J22/G22,0) -> 0.3
B23: 5 | C23: 5.4 | D23: Generar modelo de Pozos | E23: Base de Datos – Informe de la Evaluación | F23: Digital | G23: 13 | H23: 2 | I23: =IFERROR(H23/G23,0) -> 0.15384615 | J23: =+H23+JUNIO!J23 -> 2 | K23: =IFERROR(J23/G23,0) -> 0.15384615
B24: 5 | C24: 5.5 | D24: Adelantar la evaluación e interpretación de datos enfocada a candidatización de actividades de reacondicionamiento y optimización de productividad en los activos | E24: Base de Datos – Informe de la Evaluación | F24: Digital | G24: 13 | H24: 2 | I24: =IFERROR(H24/G24,0) -> 0.15384615 | J24: =+H24+JUNIO!J24 -> 6 | K24: =IFERROR(J24/G24,0) -> 0.46153846
B25: 5 | C25: 5.6 | D25: Generar los análisis asociados a candidatización de pozos para optimización de la producción empleando simulación numérica (análisis nodal) de productividad de pozos | E25: Base de Datos – Informe de la Evaluación | F25: Digital | G25: 13 | H25: 2 | I25: =IFERROR(H25/G25,0) -> 0.15384615 | J25: =+H25+JUNIO!J25 -> 4 | K25: =IFERROR(J25/G25,0) -> 0.30769231
B26: 5 | C26: 5.7 | D26: Generar reportes de soporte en la ejecución de trabajos ejecutados, tales como estimulaciones, fracturamientos hidráulicos, recañoneos, entre otros. | E26: Base de Datos – Informe de la Evaluación | F26: Digital | G26: 13 | H26: 3 | I26: =IFERROR(H26/G26,0) -> 0.23076923 | J26: =+H26+JUNIO!J26 -> 3 | K26: =IFERROR(J26/G26,0) -> 0.23076923
B27: 5 | C27: 5.8 | D27: Generar reportes de evaluación de los tratamientos de estimulación y optimización de producción implementados en la vigencia respectiva | E27: Base de Datos – Informe de la Evaluación | F27: Digital | G27: 10 | H27: 2 | I27: =IFERROR(H27/G27,0) -> 0.2 | J27: =+H27+JUNIO!J27 -> 2 | K27: =IFERROR(J27/G27,0) -> 0.2
B28: 5 | C28: 5.9 | D28: Realizar el seguimiento de producción/inyección de pozos intervenidos con base en los comportamientos de producción previo y posterior a la intervención | E28: Base de Datos – Informe de la Evaluación | F28: Digital | G28: 20 | H28: 1 | I28: =IFERROR(H28/G28,0) -> 0.05 | J28: =+H28+JUNIO!J28 -> 8 | K28: =IFERROR(J28/G28,0) -> 0.4
B29: 5 | C29: 5.10 | D29: Adelantar en análisis y evaluación de datos enfocada a la ejecución de estudios de daño de formación | E29: Base de Datos – Informe de la Evaluación | F29: Digital | G29: 8 | H29: 1 | I29: =IFERROR(H29/G29,0) -> 0.125 | J29: =+H29+JUNIO!J29 -> 2 | K29: =IFERROR(J29/G29,0) -> 0.25
B30: 5 | C30: 5.11 | D30: Generar los análisis asociados a la ejecución de estudios de daño de formación empleando simulación numérica (análisis nodal y single well model, análisis de aguas, análisis de crudos, entre otros) | E30: Base de Datos – Informe de la Evaluación | F30: Digital | G30: 8 | H30: 1 | I30: =IFERROR(H30/G30,0) -> 0.125 | J30: =+H30+JUNIO!J30 -> 3 | K30: =IFERROR(J30/G30,0) -> 0.375
G31: =+CONCATENATE("TOTAL A ",D7) -> TOTAL A JULIO | J31: TOTAL ACUMULADO
G32: =+SUM(G13:G30) -> 249 | H32: =+SUM(H13:H30) -> 30 | I32: =IFERROR(H32/G32,0) -> 0.12048193 | J32: =+SUM(J13:J30) -> 99 | K32: =IFERROR(J32/G32,0) -> 0.39759036
B34: Observaciones: | D34: En el formato GP-F-25 se detallan las actividades realizadas y los enlaces a los sitios/archivos donde se ha cargado la información.
B35: ¿Se presentó algún aspecto o situación que afecte la ejecución y calidad de los entregables? (Marque con una X)
B37: PROFESIONAL
B38: SI | D38: Describa en este espacio su observación
B39: NO
B40: ¿Se presentó algún aspecto o situación que afecte la ejecución y calidad de los entregables? (Marque con una X)
B42: INTERVENTOR O LIDER
B43: SI | D43: Describa en este espacio su observación
...

Sheet AGOSTO
P1: MES
B2: REPORTE DE AVANCE | P2: ENERO
B3: Fecha: 29/06/2022 | E3: Version: 01 | I3: GP-F-23
P4: FEBRERO
B5: Código Orden de servicio | D5: 90172266 | P5: MARZO
P6: JUNIO
B7: Mes a reportar | D7: AGOSTO | P7: JULIO
P8: AGOSTO
B9: Fecha reporte | D9: 45900 | P9: SEPTIEMBRE
P10: OCTUBRE
B11: Clasificación del servicio | H11: Reporte mes por servicio | J11: Reporte acumulado por servicio | P11: NOVIEMBRE
B12: Ítem general | C12: ítem actividad | D12: Descripción de la actividad | E12: Soporte | F12: Medio de entrega | G12: Días contratados | H12: Días | I12: % avance | J12: Días | K12: % avance | P12: DICIEMBRE
B13: 3 | C13: 3.6 | D13: Generar Modelo analítico del yacimiento integrando la información disponible en un software específico | E13: Modelo Analítico – Perfiles de Producción – Informe del modelo | F13: Digital | G13: 10 | H13: 2 | I13: =IFERROR(H13/G13,0) -> 0.2 | J13: =+H13+JULIO!J13 -> 6 | K13: =IFERROR(J13/G13,0) -> 0.6
B14: 3 | C14: 3.11 | D14: Análisis e interpretación de datos de pruebas de presión-producción (DSTs, PBU, Pruebas Extendidas Producción, Gradientes Estáticos-Dinámicos PT, etc.) o de presión inyección (Inyectividad, SRT, FOT) aplicadas ya sea en tiempo real, memorizadas o con sarta temporal DST. Integración Probador Formación – Registros Open Hole. | E14: - | F14: - | G14: 5 | H14: 0 | I14: =IFERROR(H14/G14,0) -> 0 | J14: =+H14+JULIO!J14 -> 3 | K14: =IFERROR(J14/G14,0) -> 0.6
B15: 3 | C15: 3.13 | D15: Generar base de datos de producción (OFM o la que se requiera) | E15: Base de Datos | F15: Digital | G15: 13 | H15: 2 | I15: =IFERROR(H15/G15,0) -> 0.15384615 | J15: =+H15+JULIO!J15 -> 8 | K15: =IFERROR(J15/G15,0) -> 0.61538462
B16: 3 | C16: 3.14 | D16: Generar Distribución de Producción por sub- unidades (allocation) | E16: Base de Datos | F16: Digital | G16: 20 | H16: 3 | I16: =IFERROR(H16/G16,0) -> 0.15 | J16: =+H16+JULIO!J16 -> 8 | K16: =IFERROR(J16/G16,0) -> 0.4
B17: 3 | C17: 3.15 | D17: Generar Balance de Materia por campo y/o por subunidad y/o por compartimiento | E17: Base de Datos - Modelo de Balance - Informe del modelo | F17: Digital | G17: 10 | H17: 2 | I17: =IFERROR(H17/G17,0) -> 0.2 | J17: =+H17+JULIO!J17 -> 4 | K17: =IFERROR(J17/G17,0) -> 0.4
B18: 3 | C18: 3.16 | D18: Análisis de Declinaciones por pozo y/o subunidad | E18: - | F18: - | G18: 20 | H18: 0 | I18: =IFERROR(H18/G18,0) -> 0 | J18: =+H18+JULIO!J18 -> 13 | K18: =IFERROR(J18/G18,0) -> 0.65
B19: 3 | C19: 3.17 | D19: Analizar data histórica de producción, productividad y daño por pozo | E19: - | F19: - | G19: 20 | H19: 0 | I19: =IFERROR(H19/G19,0) -> 0 | J19: =+H19+JULIO!J19 -> 12 | K19: =IFERROR(J19/G19,0) -> 0.6
B20: 3 | C20: 3.18 | D20: Generar perfiles de Producción por pozos para pozos existente en escenarios Bajo, Medio y Alto. | E20: Base de Datos – Informe de la Evaluación | F20: Digital | G20: 20 | H20: 1 | I20: =IFERROR(H20/G20,0) -> 0.05 | J20: =+H20+JULIO!J20 -> 13 | K20: =IFERROR(J20/G20,0) -> 0.65
B21: 5 | C21: 5.2 | D21: Generación de oportunidades de intervención a Pozos | E21: Base de Datos - Informe de la Evaluación | F21: Digital | G21: 13 | H21: 2 | I21: =IFERROR(H21/G21,0) -> 0.15384615 | J21: =+H21+JULIO!J21 -> 8 | K21: =IFERROR(J21/G21,0) -> 0.61538462
B22: 5 | C22: 5.3 | D22: Estimar restricciones de Presión y tasas para la generación de perfiles de producción | E22: Base de Datos – Informe de la Evaluación | F22: Digital | G22: 20 | H22: 3 | I22: =IFERROR(H22/G22,0) -> 0.15 | J22: =+H22+JULIO!J22 -> 9 | K22: =IFERROR(J22/G22,0) -> 0.45
B23: 5 | C23: 5.4 | D23: Generar modelo de Pozos | E23: Base de Datos – Informe de la Evaluación | F23: Digital | G23: 13 | H23: 3 | I23: =IFERROR(H23/G23,0) -> 0.23076923 | J23: =+H23+JULIO!J23 -> 5 | K23: =IFERROR(J23/G23,0) -> 0.38461538
B24: 5 | C24: 5.5 | D24: Adelantar la evaluación e interpretación de datos enfocada a candidatización de actividades de reacondicionamiento y optimización de productividad en los activos | E24: Base de Datos – Informe de la Evaluación | F24: Digital | G24: 13 | H24: 2 | I24: =IFERROR(H24/G24,0) -> 0.15384615 | J24: =+H24+JULIO!J24 -> 8 | K24: =IFERROR(J24/G24,0) -> 0.61538462
... B30: 5 | C30: 5.11 | D30: Generar los análisis asociados a la ejecución de estudios de daño de formación empleando simulación numérica (análisis nodal y single well model, análisis de aguas, análisis de crudos, entre otros) | E30: Base de Datos – Informe de la Evaluación | F30: Digital | G30: 8 | H30: 1 | I30: =IFERROR(H30/G30,0) -> 0.125 | J30: =+H30+JULIO!J30 -> 4 | K30: =IFERROR(J30/G30,0) -> 0.5
G31: =+CONCATENATE("TOTAL A ",D7) -> TOTAL A AGOSTO | J31: TOTAL ACUMULADO
G32: =+SUM(G13:G30) -> 249 | H32: =+SUM(H13:H30) -> 30 | I32: =IFERROR(H32/G32,0) -> 0.12048193 | J32: =+SUM(J13:J30) -> 129 | K32: =IFERROR(J32/G32,0) -> 0.51807229
B34: Observaciones: | D34: En el formato GP-F-25 se detallan las actividades realizadas y los enlaces a los sitios/archivos donde se ha cargado la información.
B35: ¿Se presentó algún aspecto o situación que afecte la ejecución y calidad de los entregables? (Marque con una X)
B37: PROFESIONAL
B38: SI | D38: Describa en este espacio su observación
B39: NO
B40: ¿Se presentó algún aspecto o situación que afecte la ejecución y calidad de los entregables? (Marque con una X)
B42: INTERVENTOR O LIDER
B43: SI | D43: Describa en este espacio su observación
B44: NO
B48: Revisa: | G48: Interventor: | H48: Luisa Margarita Uribe
A72: MES
A73: ENERO
A74: FEBRERO
...

Sheet SEPTIEMBRE
P1: MES
B2: REPORTE DE AVANCE | P2: ENERO
B3: Fecha: 29/06/2022 | E3: Version: 01 | I3: GP-F-23
P4: FEBRERO
B5: Código Orden de servicio | D5: 90172266 | P5: MARZO
P6: JUNIO
B7: Mes a reportar | D7: SEPTIEMBRE | P7: JULIO
P8: AGOSTO
B9: Fecha reporte | D9: 45930 | P9: SEPTIEMBRE
P10: OCTUBRE
B11: Clasificación del servicio | H11: Reporte mes por servicio | J11: Reporte acumulado por servicio | P11: NOVIEMBRE
B12: Ítem general | C12: ítem actividad | D12: Descripción de la actividad | E12: Soporte | F12: Medio de entrega | G12: Días contratados | H12: Días | I12: % avance | J12: Días | K12: % avance | P12: DICIEMBRE
B13: 3 | C13: 3.6 | D13: Generar Modelo analítico del yacimiento integrando la información disponible en un software específico | E13: Modelo Analítico – Perfiles de Producción – Informe del modelo | F13: Digital | G13: 10 | H13: 1 | I13: =IFERROR(H13/G13,0) -> 0.1 | J13: =+H13+AGOSTO!J13 -> 7 | K13: =IFERROR(J13/G13,0) -> 0.7
B14: 3 | C14: 3.11 | D14: Análisis e interpretación de datos de pruebas de presión-producción (DSTs, PBU, Pruebas Extendidas Producción, Gradientes Estáticos-Dinámicos PT, etc.) o de presión inyección (Inyectividad, SRT, FOT) aplicadas ya sea en tiempo real, memorizadas o con sarta temporal DST. Integración Probador Formación – Registros Open Hole. | E14: - | F14: - | G14: 5 | H14: 0 | I14: =IFERROR(H14/G14,0) -> 0 | J14: =+H14+AGOSTO!J14 -> 3 | K14: =IFERROR(J14/G14,0) -> 0.6
B15: 3 | C15: 3.13 | D15: Generar base de datos de producción (OFM o la que se requiera) | E15: Base de Datos | F15: Digital | G15: 13 | H15: 2 | I15: =IFERROR(H15/G15,0) -> 0.15384615 | J15: =+H15+AGOSTO!J15 -> 10 | K15: =IFERROR(J15/G15,0) -> 0.76923077
B16: 3 | C16: 3.14 | D16: Generar Distribución de Producción por sub- unidades (allocation) | E16: Base de Datos | F16: Digital | G16: 20 | H16: 3 | I16: =IFERROR(H16/G16,0) -> 0.15 | J16: =+H16+AGOSTO!J16 -> 11 | K16: =IFERROR(J16/G16,0) -> 0.55
B17: 3 | C17: 3.15 | D17: Generar Balance de Materia por campo y/o por subunidad y/o por compartimiento | E17: Base de Datos - Modelo de Balance - Informe del modelo | F17: Digital | G17: 10 | H17: 2 | I17: =IFERROR(H17/G17,0) -> 0.2 | J17: =+H17+AGOSTO!J17 -> 6 | K17: =IFERROR(J17/G17,0) -> 0.6
B18: 3 | C18: 3.16 | D18: Análisis de Declinaciones por pozo y/o subunidad | E18: - | F18: - | G18: 20 | H18: 0 | I18: =IFERROR(H18/G18,0) -> 0 | J18: =+H18+AGOSTO!J18 -> 13 | K18: =IFERROR(J18/G18,0) -> 0.65
B19: 3 | C19: 3.17 | D19: Analizar data histórica de producción, productividad y daño por pozo | E19: - | F19: - | G19: 20 | H19: 0 | I19: =IFERROR(H19/G19,0) -> 0 | J19: =+H19+AGOSTO!J19 -> 12 | K19: =IFERROR(J19/G19,0) -> 0.6
B20: 3 | C20: 3.18 | D20: Generar perfiles de Producción por pozos para pozos existente en escenarios Bajo, Medio y Alto. | E20: Base de Datos – Informe de la Evaluación | F20: Digital | G20: 20 | H20: 1 | I20: =IFERROR(H20/G20,0) -> 0.05 | J20: =+H20+AGOSTO!J20 -> 14 | K20: =IFERROR(J20/G20,0) -> 0.7
B21: 5 | C21: 5.2 | D21: Generación de oportunidades de intervención a Pozos | E21: Base de Datos - Informe de la Evaluación | F21: Digital | G21: 13 | H21: 2 | I21: =IFERROR(H21/G21,0) -> 0.15384615 | J21: =+H21+AGOSTO!J21 -> 10 | K21: =IFERROR(J21/G21,0) -> 0.76923077
B22: 5 | C22: 5.3 | D22: Estimar restricciones de Presión y tasas para la generación de perfiles de producción | E22: Base de Datos – Informe de la Evaluación | F22: Digital | G22: 20 | H22: 3 | I22: =IFERROR(H22/G22,0) -> 0.15 | J22: =+H22+AGOSTO!J22 -> 12 | K22: =IFERROR(J22/G22,0) -> 0.6
B23: 5 | C23: 5.4 | D23: Generar modelo de Pozos | E23: Base de Datos – Informe de la Evaluación | F23: Digital | G23: 13 | H23: 3 | I23: =IFERROR(H23/G23,0) -> 0.23076923 | J23: =+H23+AGOSTO!J23 -> 8 | K23: =IFERROR(J23/G23,0) -> 0.61538462
B24: 5 | C24: 5.5 | D24: Adelantar la evaluación e interpretación de datos enfocada a candidatización de actividades de reacondicionamiento y optimización de productividad en los activos | E24: Base de Datos – Informe de la Evaluación | F24: Digital | G24: 13 | H24: 2 | I24: =IFERROR(H24/G24,0) -> 0.15384615 | J24: =+H24+AGOSTO!J24 -> 10 | K24: =IFERROR(J24/G24,0) -> 0.76923077
... B30: 5 | C30: 5.11 | D30: Generar los análisis asociados a la ejecución de estudios de daño de formación empleando simulación numérica (análisis nodal y single well model, análisis de aguas, análisis de crudos, entre otros) | E30: Base de Datos – Informe de la Evaluación | F30: Digital | G30: 8 | H30: 1 | I30: =IFERROR(H30/G30,0) -> 0.125 | J30: =+H30+AGOSTO!J30 -> 5 | K30: =IFERROR(J30/G30,0) -> 0.625
G31: =+CONCATENATE("TOTAL A ",D7) -> TOTAL A SEPTIEMBRE | J31: TOTAL ACUMULADO
G32: =+SUM(G13:G30) -> 249 | H32: =+SUM(H13:H30) -> 30 | I32: =IFERROR(H32/G32,0) -> 0.12048193 | J32: =+SUM(J13:J30) -> 159 | K32: =IFERROR(J32/G32,0) -> 0.63855422
B34: Observaciones: | D34: En el formato GP-F-25 se detallan las actividades realizadas y los enlaces a los sitios/archivos donde se ha cargado la información.
B35: ¿Se presentó algún aspecto o situación que afecte la ejecución y calidad de los entregables? (Marque con una X)
B37: PROFESIONAL
B38: SI | D38: Describa en este espacio su observación
B39: NO
B40: ¿Se presentó algún aspecto o situación que afecte la ejecución y calidad de los entregables? (Marque con una X)
B42: INTERVENTOR O LIDER
B43: SI | D43: Describa en este espacio su observación
B44: NO
B48: Revisa: | G48: Interventor: | H48: Luisa Margarita Uribe
A72: MES
A73: ENERO
A74: FEBRERO
...

Sheet OCTUBRE
P1: MES
B2: REPORTE DE AVANCE | P2: ENERO
B3: Fecha: 29/06/2022 | E3: Version: 01 | I3: GP-F-23
P4: FEBRERO
B5: Código Orden de servicio | D5: 90172266 | P5: MARZO
P6: JUNIO
B7: Mes a reportar | D7: OCTUBRE | P7: JULIO
P8: AGOSTO
B9: Fecha reporte | D9: 45961 | P9: SEPTIEMBRE
P10: OCTUBRE
B11: Clasificación del servicio | H11: Reporte mes por servicio | J11: Reporte acumulado por servicio | P11: NOVIEMBRE
B12: Ítem general | C12: ítem actividad | D12: Descripción de la actividad | E12: Soporte | F12: Medio de entrega | G12: Días contratados | H12: Días | I12: % avance | J12: Días | K12: % avance | P12: DICIEMBRE
B13: 3 | C13: 3.6 | D13: Generar Modelo analítico del yacimiento integrando la información disponible en un software específico | E13: Modelo Analítico – Perfiles de Producción – Informe del modelo | F13: Digital | G13: 10 | H13: 1 | I13: =IFERROR(H13/G13,0) -> 0.1 | J13: =+H13+SEPTIEMBRE!J13 -> 8 | K13: =IFERROR(J13/G13,0) -> 0.8
B14: 3 | C14: 3.11 | D14: Análisis e interpretación de datos de pruebas de presión-producción (DSTs, PBU, Pruebas Extendidas Producción, Gradientes Estáticos-Dinámicos PT, etc.) o de presión inyección (Inyectividad, SRT, FOT) aplicadas ya sea en tiempo real, memorizadas o con sarta temporal DST. Integración Probador Formación – Registros Open Hole. | E14: - | F14: - | G14: 5 | H14: 1 | I14: =IFERROR(H14/G14,0) -> 0.2 | J14: =+H14+SEPTIEMBRE!J14 -> 4 | K14: =IFERROR(J14/G14,0) -> 0.8
B15: 3 | C15: 3.13 | D15: Generar base de datos de producción (OFM o la que se requiera) | E15: Base de Datos | F15: Digital | G15: 13 | H15: 1 | I15: =IFERROR(H15/G15,0) -> 0.076923077 | J15: =+H15+SEPTIEMBRE!J15 -> 11 | K15: =IFERROR(J15/G15,0) -> 0.84615385
B16: 3 | C16: 3.14 | D16: Generar Distribución de Producción por sub- unidades (allocation) | E16: Base de Datos | F16: Digital | G16: 20 | H16: 3 | I16: =IFERROR(H16/G16,0) -> 0.15 | J16: =+H16+SEPTIEMBRE!J16 -> 14 | K16: =IFERROR(J16/G16,0) -> 0.7
B17: 3 | C17: 3.15 | D17: Generar Balance de Materia por campo y/o por subunidad y/o por compartimiento | E17: Base de Datos - Modelo de Balance - Informe del modelo | F17: Digital | G17: 10 | H17: 2 | I17: =IFERROR(H17/G17,0) -> 0.2 | J17: =+H17+SEPTIEMBRE!J17 -> 8 | K17: =IFERROR(J17/G17,0) -> 0.8
B18: 3 | C18: 3.16 | D18: Análisis de Declinaciones por pozo y/o subunidad | E18: - | F18: - | G18: 20 | H18: 1 | I18: =IFERROR(H18/G18,0) -> 0.05 | J18: =+H18+SEPTIEMBRE!J18 -> 14 | K18: =IFERROR(J18/G18,0) -> 0.7
B19: 3 | C19: 3.17 | D19: Analizar data histórica de producción, productividad y daño por pozo | E19: - | F19: - | G19: 20 | I19: =IFERROR(H19/G19,0) -> 0 | J19: =+H19+SEPTIEMBRE!J19 -> 12 | K19: =IFERROR(J19/G19,0) -> 0.6
B20: 3 | C20: 3.18 | D20: Generar perfiles de Producción por pozos para pozos existente en escenarios Bajo, Medio y Alto. | E20: Base de Datos – Informe de la Evaluación | F20: Digital | G20: 20 | H20: 1 | I20: =IFERROR(H20/G20,0) -> 0.05 | J20: =+H20+SEPTIEMBRE!J20 -> 15 | K20: =IFERROR(J20/G20,0) -> 0.75
B21: 5 | C21: 5.2 | D21: Generación de oportunidades de intervención a Pozos | E21: Base de Datos - Informe de la Evaluación | F21: Digital | G21: 13 | H21: 1 | I21: =IFERROR(H21/G21,0) -> 0.076923077 | J21: =+H21+SEPTIEMBRE!J21 -> 11 | K21: =IFERROR(J21/G21,0) -> 0.84615385
B22: 5 | C22: 5.3 | D22: Estimar restricciones de Presión y tasas para la generación de perfiles de producción | E22: Base de Datos – Informe de la Evaluación | F22: Digital | G22: 20 | H22: 3 | I22: =IFERROR(H22/G22,0) -> 0.15 | J22: =+H22+SEPTIEMBRE!J22 -> 15 | K22: =IFERROR(J22/G22,0) -> 0.75
B23: 5 | C23: 5.4 | D23: Generar modelo de Pozos | E23: Base de Datos – Informe de la Evaluación | F23: Digital | G23: 13 | H23: 3 | I23: =IFERROR(H23/G23,0) -> 0.23076923 | J23: =+H23+SEPTIEMBRE!J23 -> 11 | K23: =IFERROR(J23/G23,0) -> 0.84615385
B24: 5 | C24: 5.5 | D24: Adelantar la evaluación e interpretación de datos enfocada a candidatización de actividades de reacondicionamiento y optimización de productividad en los activos | E24: Base de Datos – Informe de la Evaluación | F24: Digital | G24: 13 | H24: 2 | I24: =IFERROR(H24/G24,0) -> 0.15384615 | J24: =+H24+SEPTIEMBRE!J24 -> 12 | K24: =IFERROR(J24/G24,0) -> 0.92307692
B25: 5 | C25: 5.6 | D25: Generar los análisis asociados a candidatización de pozos para optimización de la producción empleando simulación numérica (análisis nodal) de productividad de pozos | E25: Base de Datos – Informe de la Evaluación | F25: Digital | G25: 13 | H25: 2 | I25: =IFERROR(H25/G25,0) -> 0.15384615 | J25: =+H25+SEPTIEMBRE!J25 -> 10 | K25: =IFERROR(J25/G25,0) -> 0.76923077
B26: 5 | C26: 5.7 | D26: Generar reportes de soporte en la ejecución de trabajos ejecutados, tales como estimulaciones, fracturamientos hidráulicos, recañoneos, entre otros. | E26: Base de Datos – Informe de la Evaluación | F26: Digital | G26: 13 | H26: 3 | I26: =IFERROR(H26/G26,0) -> 0.23076923 | J26: =+H26+SEPTIEMBRE!J26 -> 12 | K26: =IFERROR(J26/G26,0) -> 0.92307692
B27: 5 | C27: 5.8 | D27: Generar reportes de evaluación de los tratamientos de estimulación y optimización de producción implementados en la vigencia respectiva | E27: Base de Datos – Informe de la Evaluación | F27: Digital | G27: 10 | H27: 2 | I27: =IFERROR(H27/G27,0) -> 0.2 | J27: =+H27+SEPTIEMBRE!J27 -> 8 | K27: =IFERROR(J27/G27,0) -> 0.8
B28: 5 | C28: 5.9 | D28: Realizar el seguimiento de producción/inyección de pozos intervenidos con base en los comportamientos de producción previo y posterior a la intervención | E28: Base de Datos – Informe de la Evaluación | F28: Digital | G28: 20 | H28: 2 | I28: =IFERROR(H28/G28,0) -> 0.1 | J28: =+H28+SEPTIEMBRE!J28 -> 13 | K28: =IFERROR(J28/G28,0) -> 0.65
B29: 5 | C29: 5.10 | D29: Adelantar en análisis y evaluación de datos enfocada a la ejecución de estudios de daño de formación | E29: Base de Datos – Informe de la Evaluación | F29: Digital | G29: 8 | H29: 1 | I29: =IFERROR(H29/G29,0) -> 0.125 | J29: =+H29+SEPTIEMBRE!J29 -> 5 | K29: =IFERROR(J29/G29,0) -> 0.625
B30: 5 | C30: 5.11 | D30: Generar los análisis asociados a la ejecución de estudios de daño de formación empleando simulación numérica (análisis nodal y single well model, análisis de aguas, análisis de crudos, entre otros) | E30: Base de Datos – Informe de la Evaluación | F30: Digital | G30: 8 | H30: 1 | I30: =IFERROR(H30/G30,0) -> 0.125 | J30: =+H30+SEPTIEMBRE!J30 -> 6 | K30: =IFERROR(J30/G30,0) -> 0.75
G31: =+CONCATENATE("TOTAL A ",D7) -> TOTAL A OCTUBRE | J31: TOTAL ACUMULADO
G32: =+SUM(G13:G30) -> 249 | H32: =+SUM(H13:H30) -> 30 | I32: =IFERROR(H32/G32,0) -> 0.12048193 | J32: =+SUM(J13:J30) -> 189 | K32: =IFERROR(J32/G32,0) -> 0.75903614
B34: Observaciones: | D34: En el formato GP-F-25 se detallan las actividades realizadas y los enlaces a los sitios/archivos donde se ha cargado la información.
B35: ¿Se presentó algún aspecto o situación que afecte la ejecución y calidad de los entregables? (Marque con una X)
B37: PROFESIONAL
B38: SI | D38: Describa en este espacio su observación
B39: NO
B40: ¿Se presentó algún aspecto o situación que afecte la ejecución y calidad de los entregables? (Marque con una X)
B42: INTERVENTOR O LIDER
B43: SI | D43: Describa en este espacio su observación
...

Sheet NOVIEMBRE
P1: MES
B2: REPORTE DE AVANCE | P2: ENERO
B3: Fecha: 29/06/2022 | E3: Version: 01 | I3: GP-F-23
P4: FEBRERO
B5: Código Orden de servicio | D5: 90172266 | P5: MARZO
P6: JUNIO
B7: Mes a reportar | D7: NOVIEMBRE | P7: JULIO
P8: AGOSTO
B9: Fecha reporte | D9: 45991 | P9: SEPTIEMBRE
P10: OCTUBRE
B11: Clasificación del servicio | H11: Reporte mes por servicio | J11: Reporte acumulado por servicio | P11: NOVIEMBRE
B12: Ítem general | C12: ítem actividad | D12: Descripción de la actividad | E12: Soporte | F12: Medio de entrega | G12: Días contratados | H12: Días | I12: % avance | J12: Días | K12: % avance | P12: DICIEMBRE
B13: 3 | C13: 3.6 | D13: Generar Modelo analítico del yacimiento integrando la información disponible en un software específico | E13: Modelo Analítico – Perfiles de Producción – Informe del modelo | F13: Digital | G13: 10 | H13: 1 | I13: =IFERROR(H13/G13,0) -> 0.1 | J13: =+H13+OCTUBRE!J13 -> 9 | K13: =IFERROR(J13/G13,0) -> 0.9
B14: 3 | C14: 3.11 | D14: Análisis e interpretación de datos de pruebas de presión-producción (DSTs, PBU, Pruebas Extendidas Producción, Gradientes Estáticos-Dinámicos PT, etc.) o de presión inyección (Inyectividad, SRT, FOT) aplicadas ya sea en tiempo real, memorizadas o con sarta temporal DST. Integración Probador Formación – Registros Open Hole. | E14: Informe del análisis por pozo o prueba | F14: Digital | G14: 5 | H14: 1 | I14: =IFERROR(H14/G14,0) -> 0.2 | J14: =+H14+OCTUBRE!J14 -> 5 | K14: =IFERROR(J14/G14,0) -> 1
B15: 3 | C15: 3.13 | D15: Generar base de datos de producción (OFM o la que se requiera) | E15: Base de Datos | F15: Digital | G15: 13 | H15: 1 | I15: =IFERROR(H15/G15,0) -> 0.076923077 | J15: =+H15+OCTUBRE!J15 -> 12 | K15: =IFERROR(J15/G15,0) -> 0.92307692
B16: 3 | C16: 3.14 | D16: Generar Distribución de Producción por sub- unidades (allocation) | E16: Base de Datos | F16: Digital | G16: 20 | H16: 3 | I16: =IFERROR(H16/G16,0) -> 0.15 | J16: =+H16+OCTUBRE!J16 -> 17 | K16: =IFERROR(J16/G16,0) -> 0.85
B17: 3 | C17: 3.15 | D17: Generar Balance de Materia por campo y/o por subunidad y/o por compartimiento | E17: Base de Datos - Modelo de Balance - Informe del modelo | F17: Digital | G17: 10 | H17: 1 | I17: =IFERROR(H17/G17,0) -> 0.1 | J17: =+H17+OCTUBRE!J17 -> 9 | K17: =IFERROR(J17/G17,0) -> 0.9
B18: 3 | C18: 3.16 | D18: Análisis de Declinaciones por pozo y/o subunidad | E18: Base de Datos – Perfiles Generados – Informe del análisis | F18: Digital | G18: 20 | H18: 2 | I18: =IFERROR(H18/G18,0) -> 0.1 | J18: =+H18+OCTUBRE!J18 -> 16 | K18: =IFERROR(J18/G18,0) -> 0.8
B19: 3 | C19: 3.17 | D19: Analizar data histórica de producción, productividad y daño por pozo | E19: Base de Datos - Informe de la Evaluación | F19: Digital | G19: 20 | H19: 4 | I19: =IFERROR(H19/G19,0) -> 0.2 | J19: =+H19+OCTUBRE!J19 -> 16 | K19: =IFERROR(J19/G19,0) -> 0.8
B20: 3 | C20: 3.18 | D20: Generar perfiles de Producción por pozos para pozos existente en escenarios Bajo, Medio y Alto. | E20: Base de Datos – Informe de la Evaluación | F20: Digital | G20: 20 | H20: 2 | I20: =IFERROR(H20/G20,0) -> 0.1 | J20: =+H20+OCTUBRE!J20 -> 17 | K20: =IFERROR(J20/G20,0) -> 0.85
B21: 5 | C21: 5.2 | D21: Generación de oportunidades de intervención a Pozos | E21: Base de Datos - Informe de la Evaluación | F21: Digital | G21: 13 | H21: 1 | I21: =IFERROR(H21/G21,0) -> 0.076923077 | J21: =+H21+OCTUBRE!J21 -> 12 | K21: =IFERROR(J21/G21,0) -> 0.92307692
B22: 5 | C22: 5.3 | D22: Estimar restricciones de Presión y tasas para la generación de perfiles de producción | E22: Base de Datos – Informe de la Evaluación | F22: Digital | G22: 20 | H22: 3 | I22: =IFERROR(H22/G22,0) -> 0.15 | J22: =+H22+OCTUBRE!J22 -> 18 | K22: =IFERROR(J22/G22,0) -> 0.9
B23: 5 | C23: 5.4 | D23: Generar modelo de Pozos | E23: Base de Datos – Informe de la Evaluación | F23: Digital | G23: 13 | H23: 1 | I23: =IFERROR(H23/G23,0) -> 0.076923077 | J23: =+H23+OCTUBRE!J23 -> 12 | K23: =IFERROR(J23/G23,0) -> 0.92307692
B24: 5 | C24: 5.5 | D24: Adelantar la evaluación e interpretación de datos enfocada a candidatización de actividades de reacondicionamiento y optimización de productividad en los activos | E24: Base de Datos – Informe de la Evaluación | F24: Digital | G24: 13 | H24: 1 | I24: =IFERROR(H24/G24,0) -> 0.076923077 | J24: =+H24+OCTUBRE!J24 -> 13 | K24: =IFERROR(J24/G24,0) -> 1
... B30: 5 | C30: 5.11 | D30: Generar los análisis asociados a la ejecución de estudios de daño de formación empleando simulación numérica (análisis nodal y single well model, análisis de aguas, análisis de crudos, entre otros) | E30: Base de Datos – Informe de la Evaluación | F30: Digital | G30: 8 | H30: 1 | I30: =IFERROR(H30/G30,0) -> 0.125 | J30: =+H30+OCTUBRE!J30 -> 7 | K30: =IFERROR(J30/G30,0) -> 0.875
G31: =+CONCATENATE("TOTAL A ",D7) -> TOTAL A NOVIEMBRE | J31: TOTAL ACUMULADO
G32: =+SUM(G13:G30) -> 249 | H32: =+SUM(H13:H30) -> 30 | I32: =IFERROR(H32/G32,0) -> 0.12048193 | J32: =+SUM(J13:J30) -> 219 | K32: =IFERROR(J32/G32,0) -> 0.87951807
B34: Observaciones: | D34: En el formato GP-F-25 se detallan las actividades realizadas y los enlaces a los sitios/archivos donde se ha cargado la información.
B35: ¿Se presentó algún aspecto o situación que afecte la ejecución y calidad de los entregables? (Marque con una X)
B37: PROFESIONAL
B38: SI | D38: Describa en este espacio su observación
B39: NO
B40: ¿Se presentó algún aspecto o situación que afecte la ejecución y calidad de los entregables? (Marque con una X)
B42: INTERVENTOR O LIDER
B43: SI | D43: Describa en este espacio su observación
B44: NO
B48: Revisa: | G48: Interventor: | H48: Luisa Margarita Uribe
A72: MES
A73: ENERO
A74: FEBRERO
...

Sheet DICIEMBRE
P1: MES
B2: REPORTE DE AVANCE | P2: ENERO
B3: Fecha: 29/06/2022 | E3: Version: 01 | I3: GP-F-23
P4: FEBRERO
B5: Código Orden de servicio | D5: 90172266 | P5: MARZO
P6: JUNIO
B7: Mes a reportar | D7: DICIEMBRE | P7: JULIO
P8: AGOSTO
B9: Fecha reporte | D9: 46022 | P9: SEPTIEMBRE
P10: OCTUBRE
B11: Clasificación del servicio | H11: Reporte mes por servicio | J11: Reporte acumulado por servicio | P11: NOVIEMBRE
B12: Ítem general | C12: ítem actividad | D12: Descripción de la actividad | E12: Soporte | F12: Medio de entrega | G12: Días contratados | H12: Días | I12: % avance | J12: Días | K12: % avance | P12: DICIEMBRE
B13: 3 | C13: 3.6 | D13: Generar Modelo analítico del yacimiento integrando la información disponible en un software específico | E13: Modelo Analítico – Perfiles de Producción – Informe del modelo | F13: Digital | G13: 10 | H13: 1 | I13: =IFERROR(H13/G13,0) -> 0.1 | J13: =+H13+NOVIEMBRE!J13 -> 10 | K13: =IFERROR(J13/G13,0) -> 1
B14: 3 | C14: 3.11 | D14: Análisis e interpretación de datos de pruebas de presión-producción (DSTs, PBU, Pruebas Extendidas Producción, Gradientes Estáticos-Dinámicos PT, etc.) o de presión inyección (Inyectividad, SRT, FOT) aplicadas ya sea en tiempo real, memorizadas o con sarta temporal DST. Integración Probador Formación – Registros Open Hole. | E14: Informe del análisis por pozo o prueba | F14: Digital | G14: 5 | H14: 0 | I14: =IFERROR(H14/G14,0) -> 0 | J14: =+H14+NOVIEMBRE!J14 -> 5 | K14: =IFERROR(J14/G14,0) -> 1
B15: 3 | C15: 3.13 | D15: Generar base de datos de producción (OFM o la que se requiera) | E15: Base de Datos | F15: Digital | G15: 13 | H15: 1 | I15: =IFERROR(H15/G15,0) -> 0.076923077 | J15: =+H15+NOVIEMBRE!J15 -> 13 | K15: =IFERROR(J15/G15,0) -> 1
B16: 3 | C16: 3.14 | D16: Generar Distribución de Producción por sub- unidades (allocation) | E16: Base de Datos | F16: Digital | G16: 20 | H16: 3 | I16: =IFERROR(H16/G16,0) -> 0.15 | J16: =+H16+NOVIEMBRE!J16 -> 20 | K16: =IFERROR(J16/G16,0) -> 1
B17: 3 | C17: 3.15 | D17: Generar Balance de Materia por campo y/o por subunidad y/o por compartimiento | E17: Base de Datos - Modelo de Balance - Informe del modelo | F17: Digital | G17: 10 | H17: 1 | I17: =IFERROR(H17/G17,0) -> 0.1 | J17: =+H17+NOVIEMBRE!J17 -> 10 | K17: =IFERROR(J17/G17,0) -> 1
B18: 3 | C18: 3.16 | D18: Análisis de Declinaciones por pozo y/o subunidad | E18: Base de Datos – Perfiles Generados – Informe del análisis | F18: Digital | G18: 20 | H18: 4 | I18: =IFERROR(H18/G18,0) -> 0.2 | J18: =+H18+NOVIEMBRE!J18 -> 20 | K18: =IFERROR(J18/G18,0) -> 1
B19: 3 | C19: 3.17 | D19: Analizar data histórica de producción, productividad y daño por pozo | E19: Base de Datos - Informe de la Evaluación | F19: Digital | G19: 20 | H19: 4 | I19: =IFERROR(H19/G19,0) -> 0.2 | J19: =+H19+NOVIEMBRE!J19 -> 20 | K19: =IFERROR(J19/G19,0) -> 1
B20: 3 | C20: 3.18 | D20: Generar perfiles de Producción por pozos para pozos existente en escenarios Bajo, Medio y Alto. | E20: Base de Datos – Informe de la Evaluación | F20: Digital | G20: 20 | H20: 3 | I20: =IFERROR(H20/G20,0) -> 0.15 | J20: =+H20+NOVIEMBRE!J20 -> 20 | K20: =IFERROR(J20/G20,0) -> 1
B21: 5 | C21: 5.2 | D21: Generación de oportunidades de intervención a Pozos | E21: Base de Datos - Informe de la Evaluación | F21: Digital | G21: 13 | H21: 1 | I21: =IFERROR(H21/G21,0) -> 0.076923077 | J21: =+H21+NOVIEMBRE!J21 -> 13 | K21: =IFERROR(J21/G21,0) -> 1
B22: 5 | C22: 5.3 | D22: Estimar restricciones de Presión y tasas para la generación de perfiles de producción | E22: Base de Datos – Informe de la Evaluación | F22: Digital | G22: 20 | H22: 2 | I22: =IFERROR(H22/G22,0) -> 0.1 | J22: =+H22+NOVIEMBRE!J22 -> 20 | K22: =IFERROR(J22/G22,0) -> 1
B23: 5 | C23: 5.4 | D23: Generar modelo de Pozos | E23: Base de Datos – Informe de la Evaluación | F23: Digital | G23: 13 | H23: 1 | I23: =IFERROR(H23/G23,0) -> 0.076923077 | J23: =+H23+NOVIEMBRE!J23 -> 13 | K23: =IFERROR(J23/G23,0) -> 1
B24: 5 | C24: 5.5 | D24: Adelantar la evaluación e interpretación de datos enfocada a candidatización de actividades de reacondicionamiento y optimización de productividad en los activos | E24: Base de Datos – Informe de la Evaluación | F24: Digital | G24: 13 | H24: 0 | I24: =IFERROR(H24/G24,0) -> 0 | J24: =+H24+NOVIEMBRE!J24 -> 13 | K24: =IFERROR(J24/G24,0) -> 1
... B30: 5 | C30: 5.11 | D30: Generar los análisis asociados a la ejecución de estudios de daño de formación empleando simulación numérica (análisis nodal y single well model, análisis de aguas, análisis de crudos, entre otros) | E30: Base de Datos – Informe de la Evaluación | F30: Digital | G30: 8 | H30: 1 | I30: =IFERROR(H30/G30,0) -> 0.125 | J30: =+H30+NOVIEMBRE!J30 -> 8 | K30: =IFERROR(J30/G30,0) -> 1
G31: =+CONCATENATE("TOTAL A ",D7) -> TOTAL A DICIEMBRE | J31: TOTAL ACUMULADO
G32: =+SUM(G13:G30) -> 249 | H32: =+SUM(H13:H30) -> 30 | I32: =IFERROR(H32/G32,0) -> 0.12048193 | J32: =+SUM(J13:J30) -> 249 | K32: =IFERROR(J32/G32,0) -> 1
B34: Observaciones: | D34: En el formato GP-F-25 se detallan las actividades realizadas y los enlaces a los sitios/archivos donde se ha cargado la información.
B35: ¿Se presentó algún aspecto o situación que afecte la ejecución y calidad de los entregables? (Marque con una X)
B37: PROFESIONAL
B38: SI | D38: Describa en este espacio su observación
B39: NO
B40: ¿Se presentó algún aspecto o situación que afecte la ejecución y calidad de los entregables? (Marque con una X)
B42: INTERVENTOR O LIDER
B43: SI | D43: Describa en este espacio su observación
B44: NO
B48: Revisa: | G48: Interventor: | H48: Luisa Margarita Uribe
A72: MES
A73: ENERO
A74: FEBRERO
...

Sheet ENERO
P1: MES
B2: REPORTE DE AVANCE | P2: ENERO
B3: Fecha: 29/06/2022 | E3: Version: 01 | I3: GP-F-23
P4: FEBRERO
B5: Código Orden de servicio | D5: 90172266 | P5: MARZO
P6: JUNIO
B7: Mes a reportar | D7: ENERO | P7: JULIO
P8: AGOSTO
B9: Fecha reporte | D9: 46053 | P9: SEPTIEMBRE
P10: OCTUBRE
B11: Clasificación del servicio | H11: Reporte mes por servicio | J11: Reporte acumulado por servicio | P11: NOVIEMBRE
B12: Ítem general | C12: ítem actividad | D12: Descripción de la actividad | E12: Soporte | F12: Medio de entrega | G12: Días contratados | H12: Días | I12: % avance | J12: Días | K12: % avance | P12: DICIEMBRE
B13: 3 | C13: 3.6 | D13: Generar Modelo analítico del yacimiento integrando la información disponible en un software específico | E13: Modelo Analítico – Perfiles de Producción – Informe del modelo | F13: Digital | G13: 14 | H13: 1 | I13: =IFERROR(H13/G13,0) -> 0.071428571 | J13: =+H13+DICIEMBRE!J13 -> 11 | K13: =IFERROR(J13/G13,0) -> 0.78571429
B14: 3 | C14: 3.11 | D14: Análisis e interpretación de datos de pruebas de presión-producción (DSTs, PBU, Pruebas Extendidas Producción, Gradientes Estáticos-Dinámicos PT, etc.) o de presión inyección (Inyectividad, SRT, FOT) aplicadas ya sea en tiempo real, memorizadas o con sarta temporal DST. Integración Probador Formación – Registros Open Hole. | E14: Informe del análisis por pozo o prueba | F14: Digital | G14: 7 | H14: 1 | I14: =IFERROR(H14/G14,0) -> 0.14285714 | J14: =+H14+DICIEMBRE!J14 -> 6 | K14: =IFERROR(J14/G14,0) -> 0.85714286
B15: 3 | C15: 3.13 | D15: Generar base de datos de producción (OFM o la que se requiera) | E15: Base de Datos | F15: Digital | G15: 18 | H15: 1 | I15: =IFERROR(H15/G15,0) -> 0.055555556 | J15: =+H15+DICIEMBRE!J15 -> 14 | K15: =IFERROR(J15/G15,0) -> 0.77777778
B16: 3 | C16: 3.14 | D16: Generar Distribución de Producción por sub- unidades (allocation) | E16: Base de Datos | F16: Digital | G16: 26 | H16: 3 | I16: =IFERROR(H16/G16,0) -> 0.11538462 | J16: =+H16+DICIEMBRE!J16 -> 23 | K16: =IFERROR(J16/G16,0) -> 0.88461538
B17: 3 | C17: 3.15 | D17: Generar Balance de Materia por campo y/o por subunidad y/o por compartimiento | E17: Base de Datos - Modelo de Balance - Informe del modelo | F17: Digital | G17: 14 | H17: 1 | I17: =IFERROR(H17/G17,0) -> 0.071428571 | J17: =+H17+DICIEMBRE!J17 -> 11 | K17: =IFERROR(J17/G17,0) -> 0.78571429
B18: 3 | C18: 3.16 | D18: Análisis de Declinaciones por pozo y/o subunidad | E18: Base de Datos – Perfiles Generados – Informe del análisis | F18: Digital | G18: 27 | H18: 4 | I18: =IFERROR(H18/G18,0) -> 0.14814815 | J18: =+H18+DICIEMBRE!J18 -> 24 | K18: =IFERROR(J18/G18,0) -> 0.88888889
B19: 3 | C19: 3.17 | D19: Analizar data histórica de producción, productividad y daño por pozo | E19: Base de Datos - Informe de la Evaluación | F19: Digital | G19: 26 | H19: 3 | I19: =IFERROR(H19/G19,0) -> 0.11538462 | J19: =+H19+DICIEMBRE!J19 -> 23 | K19: =IFERROR(J19/G19,0) -> 0.88461538
B20: 3 | C20: 3.18 | D20: Generar perfiles de Producción por pozos para pozos existente en escenarios Bajo, Medio y Alto. | E20: Base de Datos – Informe de la Evaluación | F20: Digital | G20: 27 | H20: 3 | I20: =IFERROR(H20/G20,0) -> 0.11111111 | J20: =+H20+DICIEMBRE!J20 -> 23 | K20: =IFERROR(J20/G20,0) -> 0.85185185
B21: 5 | C21: 5.2 | D21: Generación de oportunidades de intervención a Pozos | E21: Base de Datos - Informe de la Evaluación | F21: Digital | G21: 18 | H21: 1 | I21: =IFERROR(H21/G21,0) -> 0.055555556 | J21: =+H21+DICIEMBRE!J21 -> 14 | K21: =IFERROR(J21/G21,0) -> 0.77777778
B22: 5 | C22: 5.3 | D22: Estimar restricciones de Presión y tasas para la generación de perfiles de producción | E22: Base de Datos – Informe de la Evaluación | F22: Digital | G22: 27 | H22: 2 | I22: =IFERROR(H22/G22,0) -> 0.074074074 | J22: =+H22+DICIEMBRE!J22 -> 22 | K22: =IFERROR(J22/G22,0) -> 0.81481481
B23: 5 | C23: 5.4 | D23: Generar modelo de Pozos | E23: Base de Datos – Informe de la Evaluación | F23: Digital | G23: 18 | H23: 1 | I23: =IFERROR(H23/G23,0) -> 0.055555556 | J23: =+H23+DICIEMBRE!J23 -> 14 | K23: =IFERROR(J23/G23,0) -> 0.77777778
B24: 5 | C24: 5.5 | D24: Adelantar la evaluación e interpretación de datos enfocada a candidatización de actividades de reacondicionamiento y optimización de productividad en los activos | E24: Base de Datos – Informe de la Evaluación | F24: Digital | G24: 18 | H24: 0 | I24: =IFERROR(H24/G24,0) -> 0 | J24: =+H24+DICIEMBRE!J24 -> 13 | K24: =IFERROR(J24/G24,0) -> 0.72222222
... B30: 5 | C30: 5.11 | D30: Generar los análisis asociados a la ejecución de estudios de daño de formación empleando simulación numérica (análisis nodal y single well model, análisis de aguas, análisis de crudos, entre otros) | E30: Base de Datos – Informe de la Evaluación | F30: Digital | G30: 11 | H30: 1 | I30: =IFERROR(H30/G30,0) -> 0.090909091 | J30: =+H30+DICIEMBRE!J30 -> 9 | K30: =IFERROR(J30/G30,0) -> 0.81818182
G31: =+CONCATENATE("TOTAL A ",D7) -> TOTAL A ENERO | J31: TOTAL ACUMULADO
G32: =+SUM(G13:G30) -> 339 | H32: =+SUM(H13:H30) -> 30 | I32: =IFERROR(H32/G32,0) -> 0.088495575 | J32: =+SUM(J13:J30) -> 279 | K32: =IFERROR(J32/G32,0) -> 0.82300885
B34: Observaciones: | D34: En el formato GP-F-25 se detallan las actividades realizadas y los enlaces a los sitios/archivos donde se ha cargado la información.
B35: ¿Se presentó algún aspecto o situación que afecte la ejecución y calidad de los entregables? (Marque con una X)
B37: PROFESIONAL
B38: SI | D38: Describa en este espacio su observación
B39: NO
B40: ¿Se presentó algún aspecto o situación que afecte la ejecución y calidad de los entregables? (Marque con una X)
B42: INTERVENTOR O LIDER
B43: SI | D43: Describa en este espacio su observación
B44: NO
B48: Revisa: | G48: Interventor: | H48: Luisa Margarita Uribe
A72: MES
A73: ENERO
A74: FEBRERO
...

Sheet FEBRERO
P1: MES
B2: REPORTE DE AVANCE | P2: ENERO
B3: Fecha: 29/06/2022 | E3: Version: 01 | I3: GP-F-23
P4: FEBRERO
B5: Código Orden de servicio | D5: 90172266 | P5: MARZO
P6: JUNIO
B7: Mes a reportar | D7: FEBRERO | P7: JULIO
P8: AGOSTO
B9: Fecha reporte | D9: 46081 | P9: SEPTIEMBRE
P10: OCTUBRE
B11: Clasificación del servicio | H11: Reporte mes por servicio | J11: Reporte acumulado por servicio | P11: NOVIEMBRE
B12: Ítem general | C12: ítem actividad | D12: Descripción de la actividad | E12: Soporte | F12: Medio de entrega | G12: Días contratados | H12: Días | I12: % avance | J12: Días | K12: % avance | P12: DICIEMBRE
B13: 3 | C13: 3.6 | D13: Generar Modelo analítico del yacimiento integrando la información disponible en un software específico | E13: Modelo Analítico – Perfiles de Producción – Informe del modelo | F13: Digital | G13: 14 | H13: 1 | I13: =IFERROR(H13/G13,0) -> 0.071428571 | J13: =+H13+ENERO!J13 -> 12 | K13: =IFERROR(J13/G13,0) -> 0.85714286
