Workbook

Sheet ENERO
Q1: MES
B2: REPORTE DE AVANCE | Q2: ENERO
B3: Fecha: 29/06/2022 | F3: Version: 01 | J3: GP-F-23
Q4: FEBRERO
B5: Código Orden de servicio | D5: 90578295 | Q5: MARZO
Q6: JUNIO
B7: Mes a reportar | D7: ENERO | Q7: JULIO
Q8: AGOSTO
B9: Fecha reporte | D9: 46053 | Q9: SEPTIEMBRE
Q10: OCTUBRE
B11: Clasificación del servicio | I11: Reporte mes por servicio | K11: Reporte acumulado por servicio | Q11: NOVIEMBRE
B12: Ítem general | C12: ítem actividad | D12: Descripción de la actividad | E12: Profesional a cargo | F12: Soporte | G12: Medio de entrega | H12: Días contratados | I12: Días | J12: % avance | K12: Días | L12: % avance | Q12: DICIEMBRE
B13: 3 | C13: 3.6 | D13: Generar Modelo analítico del yacimiento integrando la información disponible en un software específico | E13: Christian Mauricio Pardo Carranza | F13: Se generó modelo analítico del yacimiento para para revisión de auditoría 2025 de reservas y recursos contingentes. | G13: \\10.100.25.60\sya\GEC\Ariari\67. ENTREGAS DE CARGO\ING. DE PORTAFOLIO\CMPC\Christian Pardo\ENTREGABLES 2026\01. ENERO | H13: 11 | I13: 3 | J13: =IFERROR(I13/H13,0) -> 0.27272727 | K13: =+I13 -> 3 | L13: =IFERROR(K13/H13,0) -> 0.27272727
B14: 3 | C14: 3.13 | D14: Generar base de datos de producción (OFM o la que se requiera) | F14: Se generó base de datos de OFM para análisis histórico de producción para revisión de auditoría 2025 de reservas y recursos contingentes. | G14: \\10.100.25.60\sya\GEC\Ariari\67. ENTREGAS DE CARGO\ING. DE PORTAFOLIO\CMPC\Christian Pardo\ENTREGABLES 2026\01. ENERO | H14: 12 | I14: 3 | J14: =IFERROR(I14/H14,0) -> 0.25 | K14: =+I14 -> 3 | L14: =IFERROR(K14/H14,0) -> 0.25
B15: 3 | C15: 3.14 | D15: Generar Distribución de Producción por sub- unidades (allocation) | F15: Se generó distribución de producción por sub-unidades para revisión de auditoría 2025 de reservas y recursos contingentes. | G15: \\10.100.25.60\sya\GEC\Ariari\67. ENTREGAS DE CARGO\ING. DE PORTAFOLIO\CMPC\Christian Pardo\ENTREGABLES 2026\01. ENERO | H15: 11 | I15: 4 | J15: =IFERROR(I15/H15,0) -> 0.36363636 | K15: =+I15 -> 4 | L15: =IFERROR(K15/H15,0) -> 0.36363636
B16: 3 | C16: 3.16 | D16: Análisis de Declinaciones por pozo y/o subunidad | F16: Se analizó declinación de pozos para revisión de auditoría 2025 de reservas y recursos contingentes. | G16: \\10.100.25.60\sya\GEC\Ariari\67. ENTREGAS DE CARGO\ING. DE PORTAFOLIO\CMPC\Christian Pardo\ENTREGABLES 2026\01. ENERO | H16: 11 | I16: 4 | J16: =IFERROR(I16/H16,0) -> 0.36363636 | K16: =+I16 -> 4 | L16: =IFERROR(K16/H16,0) -> 0.36363636
B17: 3 | C17: 3.17 | D17: Analizar data histórica de producción, productividad y daño por pozo | F17: Se analizó data histórica de producción para revisión de auditoría 2025 de reservas y recursos contingentes. | G17: \\10.100.25.60\sya\GEC\Ariari\67. ENTREGAS DE CARGO\ING. DE PORTAFOLIO\CMPC\Christian Pardo\ENTREGABLES 2026\01. ENERO | H17: 11 | I17: 4 | J17: =IFERROR(I17/H17,0) -> 0.36363636 | K17: =+I17 -> 4 | L17: =IFERROR(K17/H17,0) -> 0.36363636
B18: 3 | C18: 3.18 | D18: Generar perfiles de Producción por pozos para pozos existente en escenarios Bajo, Medio y Alto | F18: Se calcularon los perfiles para cada uno de los escenarios bajo, base y alto para revisión de auditoría 2025 de reservas y recursos contingentes. | G18: \\10.100.25.60\sya\GEC\Ariari\67. ENTREGAS DE CARGO\ING. DE PORTAFOLIO\CMPC\Christian Pardo\ENTREGABLES 2026\01. ENERO | H18: 11 | I18: 4 | J18: =IFERROR(I18/H18,0) -> 0.36363636 | K18: =+I18 -> 4 | L18: =IFERROR(K18/H18,0) -> 0.36363636
B19: 5 | C19: 5.2 | D19: Generación de oportunidades de intervención a Pozos | F19: Se generaron oportunidades de intervención a pozos para proyecto ET-2. | G19: \\10.100.25.60\sya\GEC\Ariari\67. ENTREGAS DE CARGO\ING. DE PORTAFOLIO\CMPC\Christian Pardo\ENTREGABLES 2026\01. ENERO | H19: 11 | I19: 4 | J19: =IFERROR(I19/H19,0) -> 0.36363636 | K19: =+I19 -> 4 | L19: =IFERROR(K19/H19,0) -> 0.36363636
B20: 8 | C20: 8.2 | D20: Carga de datos, procesamiento de datos, Análisis Estadístico descriptivo considerando hipótesis desde la teoría, y análisis descriptivo considerando hipótesis generadas desde la misma data (pasos 1, 2 y 3 teoría CRISP-DM). | F20: Se realizó archivo con perfiles visión certificador de campo pachaquiaro para análisis de robustez. Se realizó balance de incorporación de reservas para el bloque Apiay-ariari. Se revisó P-50 por pozo para meta de producción. Se realizó balance de agua para P-50 JD. Se cargó en PBI volúmenes certificados. Se cargo factor geológico en tablero 2.6. Se inició con RWA para seguimiento a secundaria. Se realizó reporte de producción e inyección semanal. Se inició con entrega de cargo ingeniero de portafolio y reservas. Se inició con entrega de cargo ingeniero de implementación y aseguramiento I&A. Se inició con informe técnico anual ITA 2025. Se inició con justificación de reservas 1P. | G20: \\10.100.25.60\sya\GEC\Ariari\67. ENTREGAS DE CARGO\ING. DE PORTAFOLIO\CMPC\Christian Pardo\ENTREGABLES 2026\01. ENERO | H20: 12 | I20: 4 | J20: =IFERROR(I20/H20,0) -> 0.33333333 | K20: =+I20 -> 4 | L20: =IFERROR(K20/H20,0) -> 0.33333333
B21: 3 | C21: 3.6 | D21: Generar Modelo analítico del yacimiento integrando la información disponible en un software específico | E21: Nubia Solanlly Reyes Ávila | F21: Modelo Analítico - Perfiles de Producción - Informe del modelo | G21: Digital | H21: 9 | I21: 3 | J21: =IFERROR(I21/H21,0) -> 0.33333333 | K21: =+I21 -> 3 | L21: =IFERROR(K21/H21,0) -> 0.33333333
B22: 3 | C22: 3.12 | D22: Generar Modelo de Presiones partiendo de las pruebas previamente validadas e interpretadas | F22: Base de Datos | G22: Digital | H22: 8 | I22: 2 | J22: =IFERROR(I22/H22,0) -> 0.25 | K22: =+I22 -> 2 | L22: =IFERROR(K22/H22,0) -> 0.25
B23: 3 | C23: 3.13 | D23: Generar base de datos de producción (OFM o la que se requiera) | F23: Base de Datos | G23: Digital | H23: 8 | I23: 3 | J23: =IFERROR(I23/H23,0) -> 0.375 | K23: =+I23 -> 3 | L23: =IFERROR(K23/H23,0) -> 0.375
B24: 3 | C24: 3.14 | D24: Generar Distribución de Producción por sub- unidades (allocation) | F24: Base de Datos | G24: Digital | H24: 8 | I24: 2 | J24: =IFERROR(I24/H24,0) -> 0.25 | K24: =+I24 -> 2 | L24: =IFERROR(K24/H24,0) -> 0.25
B25: 3 | C25: 3.16 | D25: Análisis de Declinaciones por pozo y/o subunidad | F25: Base de Datos - Perfiles Generados - Informe del análisis | G25: Digital | H25: 9 | I25: 3 | J25: =IFERROR(I25/H25,0) -> 0.33333333 | K25: =+I25 -> 3 | L25: =IFERROR(K25/H25,0) -> 0.33333333
B26: 3 | C26: 3.17 | D26: Analizar data histórica de producción, productividad y daño por pozo | F26: Base de Datos - Informe de la Evaluación | G26: Digital | H26: 8 | I26: 3 | J26: =IFERROR(I26/H26,0) -> 0.375 | K26: =+I26 -> 3 | L26: =IFERROR(K26/H26,0) -> 0.375
B27: 3 | C27: 3.18 | D27: Generar perfiles de Producción por pozos para pozos existente en escenarios Bajo, Medio y Alto | F27: Base de Datos - Informe de la Evaluación | G27: Digital | H27: 8 | I27: 3 | J27: =IFERROR(I27/H27,0) -> 0.375 | K27: =+I27 -> 3 | L27: =IFERROR(K27/H27,0) -> 0.375
B28: 5 | C28: 5.1 | D28: Generar bases de datos de Eventos de pozos | F28: Base de Datos | G28: Digital | H28: 8 | I28: 2 | J28: =IFERROR(I28/H28,0) -> 0.25 | K28: =+I28 -> 2 | L28: =IFERROR(K28/H28,0) -> 0.25
B29: 5 | C29: 5.2 | D29: Generación de oportunidades de intervención a Pozos | F29: Base de Datos - Informe de la Evaluación | G29: Digital | H29: 8 | I29: 3 | J29: =IFERROR(I29/H29,0) -> 0.375 | K29: =+I29 -> 3 | L29: =IFERROR(K29/H29,0) -> 0.375
B30: 5 | C30: 5.9 | D30: Realizar el seguimiento de producción/ inyección de pozos intervenidos con base en los comportamientos de producción previo y posterior a la intervención | F30: Base de Datos - Informe de la Evaluación | G30: Digital | H30: 8 | I30: 3 | J30: =IFERROR(I30/H30,0) -> 0.375 | K30: =+I30 -> 3 | L30: =IFERROR(K30/H30,0) -> 0.375
B31: 8 | C31: 8.2 | D31: Carga de datos, procesamiento de datos, Análisis Estadístico descriptivo considerando hipótesis desde la teoría, y análisis descriptivo considerando hipótesis generadas desde la misma data (pasos 1, 2 y 3 teoría CRISP-DM). | F31: Informe, con estadísticas descriptivas, histogramas, pruebas de ajuste, etc. | G31: Digital | H31: 8 | I31: 3 | J31: =IFERROR(I31/H31,0) -> 0.375 | K31: =+I31 -> 3 | L31: =IFERROR(K31/H31,0) -> 0.375
B32: 2 | C32: 2.2 | D32: Generación Modelo Petrofísico | E32: Maria Alejandra Mojica Arciniegas | F32: Modelo petrofisica Suria IFT | G32: Digital | H32: 11 | I32: 7 | J32: =IFERROR(I32/H32,0) -> 0.63636364 | K32: =+I32 -> 7 | L32: =IFERROR(K32/H32,0) -> 0.63636364
B33: 2 | C33: 2.3 | D33: Definir Contactos de Fluidos, Arena neta, Net pay, por pozo y por zona | F33: Modelo petrofisico Suria K1-Poro_Perm | G33: Digital | H33: 11 | I33: 6 | J33: =IFERROR(I33/H33,0) -> 0.54545455 | K33: =+I33 -> 6 | L33: =IFERROR(K33/H33,0) -> 0.54545455
B34: 2 | C34: 2.4 | D34: Realizar inventario y análisis de información petrofísica | F34: Analisis / interpretacion registros pozo LBN5 | G34: Digital | H34: 12 | I34: 4 | J34: =IFERROR(I34/H34,0) -> 0.33333333 | K34: =+I34 -> 4 | L34: =IFERROR(K34/H34,0) -> 0.33333333
B35: 2 | C35: 2.5 | D35: Realizar caracterización Scal (interpretación) | F35: - | G35: - | H35: 11 | I35: 0 | J35: =IFERROR(I35/H35,0) -> 0 | K35: =+I35 -> 0 | L35: =IFERROR(K35/H35,0) -> 0
B36: 2 | C36: 2.6 | D36: Realizar la digitalización de registros, normalización de curvas, edición y corrección de curvas | F36: - | G36: - | H36: 11 | I36: 0 | J36: =IFERROR(I36/H36,0) -> 0 | K36: =+I36 -> 0 | L36: =IFERROR(K36/H36,0) -> 0
B37: 2 | C37: 2.9 | D37: Generar tipos de roca / unidades de flujo por yacimiento y/o campo | F37: Analisis de K_H de pozos de correlacion para pozo Villavicencio | G37: Digital | H37: 11 | I37: 4 | J37: =IFERROR(I37/H37,0) -> 0.36363636 | K37: =+I37 -> 4 | L37: =IFERROR(K37/H37,0) -> 0.36363636
B38: 2 | C38: 2.10 | D38: Generar base de datos petrofísicos | F38: Evaluacion informacion formacion T1 campo Apiay | G38: Digital | H38: 11 | I38: 4 | J38: =IFERROR(I38/H38,0) -> 0.36363636 | K38: =+I38 -> 4 | L38: =IFERROR(K38/H38,0) -> 0.36363636
B39: 2 | C39: 2.11 | D39: Generación de Modelos de Física de Rocas | F39: Modelo TR K1_Suria | G39: Digital | H39: 12 | I39: 5 | J39: =IFERROR(I39/H39,0) -> 0.41666667 | K39: =+I39 -> 5 | L39: =IFERROR(K39/H39,0) -> 0.41666667
B40: 3 | C40: 3.6 | D40: Generar Modelo analítico del yacimiento integrando la información disponible en un software específico | E40: Jaime José Martínez Vertel | F40: Construcción de modelo en Sahara con la información del activo Apiay - Ariari exportado desde Petrel | G40: Comparativo Saharas.xlsx | H40: 10 | I40: 4 | J40: =IFERROR(I40/H40,0) -> 0.4 | K40: =+I40 -> 4 | L40: =IFERROR(K40/H40,0) -> 0.4
...

Sheet FEBRERO
Q1: MES
B2: REPORTE DE AVANCE | Q2: ENERO
B3: Fecha: 29/06/2022 | F3: Version: 01 | J3: GP-F-23
Q4: FEBRERO
B5: Código Orden de servicio | D5: 90578295 | Q5: MARZO
Q6: JUNIO
B7: Mes a reportar | D7: FEBRERO | Q7: JULIO
Q8: AGOSTO
B9: Fecha reporte | D9: 46081 | Q9: SEPTIEMBRE
Q10: OCTUBRE
B11: Clasificación del servicio | I11: Reporte mes por servicio | K11: Reporte acumulado por servicio | Q11: NOVIEMBRE
B12: Ítem general | C12: ítem actividad | D12: Descripción de la actividad | E12: Profesional a cargo | F12: Soporte | G12: Medio de entrega | H12: Días contratados | I12: Días | J12: % avance | K12: Días | L12: % avance | Q12: DICIEMBRE
B13: 3 | C13: 3.6 | D13: Generar Modelo analítico del yacimiento integrando la información disponible en un software específico | E13: Christian Mauricio Pardo Carranza | F13: Se generó modelo analítico del yacimiento en Sahara para seguimiento de producción y variables operacionales: Se cargó producciones y diferidas. Se cargó análisis fisicoquímicos. Actualización de estado de pozos. Actualización estados mecánicos. Generación de líneas base. Se cargó PLT y ILT. Se cargó PWF y parámetros. Se cargó pruebas de producción. | G13: \\10.100.25.60\sya\GEC\Ariari\67. ENTREGAS DE CARGO\I&A GDA\2026\3. CMPC\02. FEBRERO | H13: 11 | I13: 3 | J13: =IFERROR(I13/H13,0) -> 0.27272727 | K13: =+I13+ENERO!K13 -> 6 | L13: =IFERROR(K13/H13,0) -> 0.54545455
B14: 3 | C14: 3.13 | D14: Generar base de datos de producción (OFM o la que se requiera) | F14: Se generó base de datos de OFM para análisis histórico de producción para: Cálculo de EUR por pozo. Cargue de producciones Sahara y PBI. | G14: \\10.100.25.60\sya\GEC\Ariari\67. ENTREGAS DE CARGO\I&A GDA\2026\3. CMPC\02. FEBRERO | H14: 12 | I14: 3 | J14: =IFERROR(I14/H14,0) -> 0.25 | K14: =+I14+ENERO!K14 -> 6 | L14: =IFERROR(K14/H14,0) -> 0.5
B15: 3 | C15: 3.14 | D15: Generar Distribución de Producción por sub- unidades (allocation) | F15: Se generó distribución de producción por sub-unidades para: Cargue de producciones Sahara y PBI. | G15: \\10.100.25.60\sya\GEC\Ariari\67. ENTREGAS DE CARGO\I&A GDA\2026\3. CMPC\02. FEBRERO | H15: 11 | I15: 4 | J15: =IFERROR(I15/H15,0) -> 0.36363636 | K15: =+I15+ENERO!K15 -> 8 | L15: =IFERROR(K15/H15,0) -> 0.72727273
B16: 3 | C16: 3.16 | D16: Análisis de Declinaciones por pozo y/o subunidad | F16: Se analizó declinación de pozos para: Cálculo de líneas base pozos M-11. Archivo de Excel con proyecciones de Gas. Archivo de Excel con volúmenes del proyecto ET-1 y ET-4.1 para evaluación financiera. | G16: \\10.100.25.60\sya\GEC\Ariari\67. ENTREGAS DE CARGO\I&A GDA\2026\3. CMPC\02. FEBRERO | H16: 11 | I16: 4 | J16: =IFERROR(I16/H16,0) -> 0.36363636 | K16: =+I16+ENERO!K16 -> 8 | L16: =IFERROR(K16/H16,0) -> 0.72727273
B17: 3 | C17: 3.17 | D17: Analizar data histórica de producción, productividad y daño por pozo | F17: Se analizó data histórica de producción para: Cargue de producciones Sahara y PBI. Cálculo de EUR por pozo. Archivo de Excel con proyecciones de Gas. Archivo de Excel con volúmenes del proyecto ET-1 y ET-4.1 para evaluación financiera. | G17: \\10.100.25.60\sya\GEC\Ariari\67. ENTREGAS DE CARGO\I&A GDA\2026\3. CMPC\02. FEBRERO | H17: 11 | I17: 4 | J17: =IFERROR(I17/H17,0) -> 0.36363636 | K17: =+I17+ENERO!K17 -> 8 | L17: =IFERROR(K17/H17,0) -> 0.72727273
B18: 3 | C18: 3.18 | D18: Generar perfiles de Producción por pozos para pozos existente en escenarios Bajo, Medio y Alto | F18: Se calcularon los perfiles para cada uno de los escenarios bajo, base y alto para: Archivo de Excel con proyecciones de Gas. Archivo de Excel con volúmenes del proyecto ET-1 y ET-4.1 para evaluación financiera. | G18: \\10.100.25.60\sya\GEC\Ariari\67. ENTREGAS DE CARGO\I&A GDA\2026\3. CMPC\02. FEBRERO | H18: 11 | I18: 4 | J18: =IFERROR(I18/H18,0) -> 0.36363636 | K18: =+I18+ENERO!K18 -> 8 | L18: =IFERROR(K18/H18,0) -> 0.72727273
B19: 5 | C19: 5.2 | D19: Generación de oportunidades de intervención a Pozos | F19: Se generaron oportunidades de intervención a pozos para: Maduración del proyecto ET-2. Reactivaciones por WSV. | G19: \\10.100.25.60\sya\GEC\Ariari\67. ENTREGAS DE CARGO\I&A GDA\2026\3. CMPC\02. FEBRERO | H19: 11 | I19: 4 | J19: =IFERROR(I19/H19,0) -> 0.36363636 | K19: =+I19+ENERO!K19 -> 8 | L19: =IFERROR(K19/H19,0) -> 0.72727273
B20: 8 | C20: 8.2 | D20: Carga de datos, procesamiento de datos, Análisis Estadístico descriptivo considerando hipótesis desde la teoría, y análisis descriptivo considerando hipótesis generadas desde la misma data (pasos 1, 2 y 3 teoría CRISP-DM). | F20: Se realizó actualización de informe ITA para el proyecto Modulo 12. Se cargó factor geológico y conectividades tablero 2.6. Se generó proyección de vertimiento para los campos Apiay y Suria con base en perfiles PDI 1. Se revisaron caudales de pozos del proyecto ET-4.2 de básica e incremental de P-50. Se realizó justificación de reservas 1P. Se realizó justificación de recursos contingentes. Se realizó reporte semanal. Se realizó informe de seguimiento a ruta WO y WSV. Se consolidó información para proyecto Maxpro. Se realizó entrega de cargo ingeniero de portafolio. Se realizó actualización en informe de recursos contingentes pozos excluidos de reservas M-12. Se realizó archivo con perfiles de básica para ICO protección de la básica con base en PDI 1. Se cargó P-50 y Real en PBI para comparación mes a mes de P-50 y AUD 2025 con respecto al real. | G20: \\10.100.25.60\sya\GEC\Ariari\67. ENTREGAS DE CARGO\I&A GDA\2026\3. CMPC\02. FEBRERO | H20: 12 | I20: 4 | J20: =IFERROR(I20/H20,0) -> 0.33333333 | K20: =+I20+ENERO!K20 -> 8 | L20: =IFERROR(K20/H20,0) -> 0.66666667
B21: 3 | C21: 3.6 | D21: Generar Modelo analítico del yacimiento integrando la información disponible en un software específico | E21: Nubia Solanlly Reyes Ávila | F21: Modelo Analítico - Perfiles de Producción - Informe del modelo | G21: Digital | H21: 9 | I21: 3 | J21: =IFERROR(I21/H21,0) -> 0.33333333 | K21: =+I21+ENERO!K21 -> 6 | L21: =IFERROR(K21/H21,0) -> 0.66666667
B22: 3 | C22: 3.12 | D22: Generar Modelo de Presiones partiendo de las pruebas previamente validadas e interpretadas | F22: Base de Datos | G22: Digital | H22: 8 | I22: 3 | J22: =IFERROR(I22/H22,0) -> 0.375 | K22: =+I22+ENERO!K22 -> 5 | L22: =IFERROR(K22/H22,0) -> 0.625
B23: 3 | C23: 3.13 | D23: Generar base de datos de producción (OFM o la que se requiera) | F23: Base de Datos | G23: Digital | H23: 8 | I23: 2 | J23: =IFERROR(I23/H23,0) -> 0.25 | K23: =+I23+ENERO!K23 -> 5 | L23: =IFERROR(K23/H23,0) -> 0.625
B24: 3 | C24: 3.14 | D24: Generar Distribución de Producción por sub- unidades (allocation) | F24: Base de Datos | G24: Digital | H24: 8 | I24: 3 | J24: =IFERROR(I24/H24,0) -> 0.375 | K24: =+I24+ENERO!K24 -> 5 | L24: =IFERROR(K24/H24,0) -> 0.625
B25: 3 | C25: 3.16 | D25: Análisis de Declinaciones por pozo y/o subunidad | F25: Base de Datos - Perfiles Generados - Informe del análisis | G25: Digital | H25: 9 | I25: 3 | J25: =IFERROR(I25/H25,0) -> 0.33333333 | K25: =+I25+ENERO!K25 -> 6 | L25: =IFERROR(K25/H25,0) -> 0.66666667
B26: 3 | C26: 3.17 | D26: Analizar data histórica de producción, productividad y daño por pozo | F26: Base de Datos - Informe de la Evaluación | G26: Digital | H26: 8 | I26: 2 | J26: =IFERROR(I26/H26,0) -> 0.25 | K26: =+I26+ENERO!K26 -> 5 | L26: =IFERROR(K26/H26,0) -> 0.625
B27: 3 | C27: 3.18 | D27: Generar perfiles de Producción por pozos para pozos existente en escenarios Bajo, Medio y Alto | F27: Base de Datos - Informe de la Evaluación | G27: Digital | H27: 8 | I27: 3 | J27: =IFERROR(I27/H27,0) -> 0.375 | K27: =+I27+ENERO!K27 -> 6 | L27: =IFERROR(K27/H27,0) -> 0.75
B28: 5 | C28: 5.1 | D28: Generar bases de datos de Eventos de pozos | F28: Base de Datos | G28: Digital | H28: 8 | I28: 3 | J28: =IFERROR(I28/H28,0) -> 0.375 | K28: =+I28+ENERO!K28 -> 5 | L28: =IFERROR(K28/H28,0) -> 0.625
B29: 5 | C29: 5.2 | D29: Generación de oportunidades de intervención a Pozos | F29: Base de Datos - Informe de la Evaluación | G29: Digital | H29: 8 | I29: 2 | J29: =IFERROR(I29/H29,0) -> 0.25 | K29: =+I29+ENERO!K29 -> 5 | L29: =IFERROR(K29/H29,0) -> 0.625
B30: 5 | C30: 5.9 | D30: Realizar el seguimiento de producción/ inyección de pozos intervenidos con base en los comportamientos de producción previo y posterior a la intervención | F30: Base de Datos - Informe de la Evaluación | G30: Digital | H30: 8 | I30: 3 | J30: =IFERROR(I30/H30,0) -> 0.375 | K30: =+I30+ENERO!K30 -> 6 | L30: =IFERROR(K30/H30,0) -> 0.75
B31: 8 | C31: 8.2 | D31: Carga de datos, procesamiento de datos, Análisis Estadístico descriptivo considerando hipótesis desde la teoría, y análisis descriptivo considerando hipótesis generadas desde la misma data (pasos 1, 2 y 3 teoría CRISP-DM). | F31: Informe, con estadísticas descriptivas, histogramas, pruebas de ajuste, etc. | G31: Digital | H31: 8 | I31: 3 | J31: =IFERROR(I31/H31,0) -> 0.375 | K31: =+I31+ENERO!K31 -> 6 | L31: =IFERROR(K31/H31,0) -> 0.75
B32: 2 | C32: 2.2 | D32: Generación Modelo Petrofísico | E32: Maria Alejandra Mojica Arciniegas | F32: Modelo petrofisico Suria | G32: Digital | H32: 11 | I32: 4 | J32: =IFERROR(I32/H32,0) -> 0.36363636 | K32: =+I32+ENERO!K32 -> 11 | L32: =IFERROR(K32/H32,0) -> 1
B33: 2 | C33: 2.3 | D33: Definir Contactos de Fluidos, Arena neta, Net pay, por pozo y por zona | F33: Pozos WO-Etapa 2 | G33: Digital | H33: 11 | I33: 5 | J33: =IFERROR(I33/H33,0) -> 0.45454545 | K33: =+I33+ENERO!K33 -> 11 | L33: =IFERROR(K33/H33,0) -> 1
B34: 2 | C34: 2.4 | D34: Realizar inventario y análisis de información petrofísica | F34: Modelo petrofisico T1 | G34: Digital | H34: 12 | I34: 8 | J34: =IFERROR(I34/H34,0) -> 0.66666667 | K34: =+I34+ENERO!K34 -> 12 | L34: =IFERROR(K34/H34,0) -> 1
B35: 2 | C35: 2.5 | D35: Realizar caracterización Scal (interpretación) | F35: Modelo petrofisico Suria - T1 | G35: Digital | H35: 11 | I35: 5 | J35: =IFERROR(I35/H35,0) -> 0.45454545 | K35: =+I35+ENERO!K35 -> 5 | L35: =IFERROR(K35/H35,0) -> 0.45454545
B36: 2 | C36: 2.6 | D36: Realizar la digitalización de registros, normalización de curvas, edición y corrección de curvas | F36: Modelo petrofisica T1 | G36: Digital | H36: 11 | I36: 2 | J36: =IFERROR(I36/H36,0) -> 0.18181818 | K36: =+I36+ENERO!K36 -> 2 | L36: =IFERROR(K36/H36,0) -> 0.18181818
B37: 2 | C37: 2.9 | D37: Generar tipos de roca / unidades de flujo por yacimiento y/o campo | F37: Soporte equipo corto plazo | G37: Digital | H37: 11 | I37: 2 | J37: =IFERROR(I37/H37,0) -> 0.18181818 | K37: =+I37+ENERO!K37 -> 6 | L37: =IFERROR(K37/H37,0) -> 0.54545455
B38: 2 | C38: 2.10 | D38: Generar base de datos petrofísicos | F38: Informe ITA campos del activo Apiay -Ariari | G38: Digital | H38: 11 | I38: 2 | J38: =IFERROR(I38/H38,0) -> 0.18181818 | K38: =+I38+ENERO!K38 -> 6 | L38: =IFERROR(K38/H38,0) -> 0.54545455
B39: 2 | C39: 2.11 | D39: Generación de Modelos de Física de Rocas | F39: Informe IRR campos del activo Apiay -Ariari | G39: Digital | H39: 12 | I39: 2 | J39: =IFERROR(I39/H39,0) -> 0.16666667 | K39: =+I39+ENERO!K39 -> 7 | L39: =IFERROR(K39/H39,0) -> 0.58333333
B40: 3 | C40: 3.6 | D40: Generar Modelo analítico del yacimiento integrando la información disponible en un software específico | E40: Jaime José Martínez Vertel | F40: Construcción de modelo en Sahara con la información del activo Apiay - Ariari exportado desde Petrel | G40: Comparativo Saharas.xlsx | H40: 10 | I40: 4 | J40: =IFERROR(I40/H40,0) -> 0.4 | K40: =+I40+ENERO!K40 -> 8 | L40: =IFERROR(K40/H40,0) -> 0.8
...
