Workbook

Sheet ENERO 2026
Q1: MES
B2: REPORTE DE AVANCE | Q2: ENERO
B3: Fecha: 29/06/2022 | F3: Version: 01 | J3: GP-F-23
Q4: FEBRERO
B5: Código Orden de servicio | D5: 90577770 | Q5: MARZO
Q6: JUNIO
B7: Mes a reportar | D7: ENERO | Q7: JULIO
Q8: AGOSTO
B9: Fecha reporte | D9: 46053 | Q9: SEPTIEMBRE
Q10: OCTUBRE
B11: Clasificación del servicio | I11: Reporte mes por servicio | K11: Reporte acumulado por servicio | Q11: NOVIEMBRE
B12: Ítem general | C12: ítem actividad | D12: Descripción de la actividad | E12: Profesional a cargo | F12: Soporte | G12: Medio de entrega | H12: Días contratados Acta de Inicio | I12: Días | J12: % avance | K12: Días | L12: % avance | Q12: DICIEMBRE
B13: 1 | C13: 1.1 | D13: Generar Modelo Estático del yacimiento integrando la información disponible. | E13: Ximena Alejandra Rodriguez Florez | F13: Modelo Estático - Informe de Modelo - Cálculo de Volúmenes in Place | G13: Digital | H13: 60 | I13: 10 | J13: =IFERROR(I13/H13,0) -> 0.16666667 | K13: =I13 -> 10 | L13: =IFERROR(K13/H13,0) -> 0.16666667
B14: 1 | C14: 1.2 | D14: Generación de Bases de datos de Pozos (Registros, Topes e Información disponible) | F14: Bases de Datos | G14: Digital | H14: 20 | I14: 6 | J14: =IFERROR(I14/H14,0) -> 0.3 | K14: =I14 -> 6 | L14: =IFERROR(K14/H14,0) -> 0.3
B15: 1 | C15: 1.4 | D15: Generación Modelo estructural. | F15: Modelo estructural - Informe del Modelo | G15: Digital | H15: 45 | I15: 2 | J15: =IFERROR(I15/H15,0) -> 0.044444444 | K15: =I15 -> 2 | L15: =IFERROR(K15/H15,0) -> 0.044444444
B16: 1 | C16: 1.5 | D16: Digitalización, digitación y/o captura de información geológica (Mapas, Raw Data, topes, etc.) | F16: Mapas en formato digital | G16: Digital | H16: 20 | I16: 4 | J16: =IFERROR(I16/H16,0) -> 0.2 | K16: =I16 -> 4 | L16: =IFERROR(K16/H16,0) -> 0.2
B17: 1 | C17: 1.7 | D17: Generación Modelo Geocelular. | F17: Modelo Geocelular - Informe del Modelo | G17: Digital | H17: 30 | I17: 1 | J17: =IFERROR(I17/H17,0) -> 0.033333333 | K17: =I17 -> 1 | L17: =IFERROR(K17/H17,0) -> 0.033333333
B18: 1 | C18: 1.15 | D18: Carga de información para poblar el modelo geocelular (direccionales,coordenadas, surveys, topes, data de presión, estados mecánicos, evento de pozos, etc.) | F18: Modelo poblado | G18: Digital | H18: 20 | I18: 1 | J18: =IFERROR(I18/H18,0) -> 0.05 | K18: =I18 -> 1 | L18: =IFERROR(K18/H18,0) -> 0.05
B19: 1 | C19: 1.16 | D19: Georeferenciación de Mapas, pozos, Imágenes satélite, etc. y Definición de CRS (Cordinates Reference System) | F19: Información georeferenciada | G19: Digital | H19: 20 | I19: 2 | J19: =IFERROR(I19/H19,0) -> 0.1 | K19: =I19 -> 2 | L19: =IFERROR(K19/H19,0) -> 0.1
B20: 1 | C20: 1.17 | D20: Calculo probabilístico de Volúmenes In situ. | F20: - | G20: - | H20: 21 | I20: 0 | J20: =IFERROR(I20/H20,0) -> 0 | K20: =I20 -> 0 | L20: =IFERROR(K20/H20,0) -> 0
B21: 5 | C21: 5.1 | D21: Generar bases de datos de Eventos de pozos | E21: Jhon Abelardo Cuesta Asprilla | F21: Base de Datos | G21: Digital | H21: 30 | I21: 3 | J21: =IFERROR(I21/H21,0) -> 0.1 | K21: =I21 -> 3 | L21: =IFERROR(K21/H21,0) -> 0.1
B22: 5 | C22: 5.2 | D22: Generación de oportunidades de intervención a Pozos | F22: Base de Datos - Informe de la Evaluación | G22: Digital | H22: 30 | I22: 3 | J22: =IFERROR(I22/H22,0) -> 0.1 | K22: =I22 -> 3 | L22: =IFERROR(K22/H22,0) -> 0.1
B23: 5 | C23: 5.3 | D23: Estimar restricciones de Presión y tasas para la generación de perfiles de producción | F23: Base de Datos - Informe de la Evaluación | G23: Digital | H23: 30 | I23: 3 | J23: =IFERROR(I23/H23,0) -> 0.1 | K23: =I23 -> 3 | L23: =IFERROR(K23/H23,0) -> 0.1
B24: 5 | C24: 5.4 | D24: Generar modelo de Pozos | F24: Base de Datos - Informe de la Evaluación | G24: Digital | H24: 30 | I24: 3 | J24: =IFERROR(I24/H24,0) -> 0.1 | K24: =I24 -> 3 | L24: =IFERROR(K24/H24,0) -> 0.1
B25: 5 | C25: 5.5 | D25: Adelantar la evaluación e interpretación de datos enfocada a candidatización de actividades de reacondicionamiento y optimización de productividad en los activos | F25: Base de Datos - Informe de la Evaluación | G25: Digital | H25: 29 | I25: 4 | J25: =IFERROR(I25/H25,0) -> 0.13793103 | K25: =I25 -> 4 | L25: =IFERROR(K25/H25,0) -> 0.13793103
B26: 5 | C26: 5.6 | D26: Generar los análisis asociados a candidatización de pozos para optimización de la producción empleando simulación numérica (análisis nodal) de productividad de pozos | F26: Base de Datos - Informe de la Evaluación | G26: Digital | H26: 29 | I26: 4 | J26: =IFERROR(I26/H26,0) -> 0.13793103 | K26: =I26 -> 4 | L26: =IFERROR(K26/H26,0) -> 0.13793103
B27: 5 | C27: 5.9 | D27: Realizar el seguimiento de producción/ inyección de pozos intervenidos con base en los comportamientos de producción previo y posterior a la intervención | F27: Base de Datos - Informe de la Evaluación | G27: Digital | H27: 29 | I27: 3 | J27: =IFERROR(I27/H27,0) -> 0.10344828 | K27: =I27 -> 3 | L27: =IFERROR(K27/H27,0) -> 0.10344828
B28: 5 | C28: 5.10 | D28: Adelantar en análisis y evaluación de datos enfocada a la ejecución de estudios de daño de formación | F28: Base de Datos - Informe de la Evaluación | G28: Digital | H28: 29 | I28: 3 | J28: =IFERROR(I28/H28,0) -> 0.10344828 | K28: =I28 -> 3 | L28: =IFERROR(K28/H28,0) -> 0.10344828
B29: 5 | C29: 5.1 | D29: Generar bases de datos de Eventos de pozos | E29: Andres Fabian Amaya Hernandez | F29: Actualización de Tableros PBI con información de producción, inyección e intervenciones | G29: Sharepoint: https://ecopetrol.sharepoint.com/sites/TablerosdeSeguimientoYR-CG/Shared%20Documents/Forms/AllItems.aspx | H29: 30 | I29: 3.25 | J29: =IFERROR(I29/H29,0) -> 0.10833333 | K29: =I29 -> 3.25 | L29: =IFERROR(K29/H29,0) -> 0.10833333
B30: 5 | C30: 5.2 | D30: Generación de oportunidades de intervención a Pozos | F30: Reuniones sistemáticas para el seguimiento y monitoreo de la producción/inyección del Campo yariguí, y así identificar pozos candidatos para trabajos de WO y mejorar el índice de productividad e inyectividad | G30: Actas en medio digital: https://wellmeeting.ecopetrol.com.co/ | H30: 30 | I30: 3.25 | J30: =IFERROR(I30/H30,0) -> 0.10833333 | K30: =I30 -> 3.25 | L30: =IFERROR(K30/H30,0) -> 0.10833333
B31: 5 | C31: 5.3 | D31: Estimar restricciones de Presión y tasas para la generación de perfiles de producción | F31: Revisión de perfiles FID certificados y Flujos de Caja del campo yariguí-Cantagallo. Estimación de justificación de reservas 1P del Campo Yariguí | G31: Sharepoint: https://ecopetrol.sharepoint.com/sites/TablerosdeSeguimientoYR-CG/Shared%20Documents/Forms/AllItems.aspx Ruta compartida: \\10.11.46.150\groups07\01_YR-CG\04_PROYECTOS\26_PIC\2026 Ruta compartida: \\10.11.46.150\groups07\01_YR-CG\02_Modelo Dinámico\02_Yacimientos\07_Auditoria de Reservas | H31: 30 | I31: 3.25 | J31: =IFERROR(I31/H31,0) -> 0.10833333 | K31: =I31 -> 3.25 | L31: =IFERROR(K31/H31,0) -> 0.10833333
B32: 5 | C32: 5.4 | D32: Generar modelo de Pozos | F32: Base de Datos - Informe de la Evaluación | G32: Digital | H32: 30 | I32: 3.25 | J32: =IFERROR(I32/H32,0) -> 0.10833333 | K32: =I32 -> 3.25 | L32: =IFERROR(K32/H32,0) -> 0.10833333
B33: 5 | C33: 5.5 | D33: Adelantar la evaluación e interpretación de datos enfocada a candidatización de actividades de reacondicionamiento y optimización de productividad en los activos | F33: Actualización de Tableros PBI creados para el seguimiento de producción/inyección, gráficos de Lorenz de pozos inyectores, balance de presiones y revisión de reservas certificadas | G33: Sharepoint: https://ecopetrol.sharepoint.com/sites/TablerosdeSeguimientoYR-CG/Shared%20Documents/Forms/AllItems.aspx | H33: 30 | I33: 3.25 | J33: =IFERROR(I33/H33,0) -> 0.10833333 | K33: =I33 -> 3.25 | L33: =IFERROR(K33/H33,0) -> 0.10833333
B34: 5 | C34: 5.6 | D34: Generar los análisis asociados a candidatización de pozos para optimización de la producción empleando simulación numérica (análisis nodal) de productividad de pozos | F34: Reuniones sistemáticas para el seguimiento y monitoreo de la producción/inyección del Campo yariguí, y así identificar pozos con oportunidades de optimización de la presión de fondo manteniendo el balance de presiones del patrón | G34: Actas en medio digital: https://wellmeeting.ecopetrol.com.co/ Sharepoint: https://ecopetrol.sharepoint.com/sites/TablerosdeSeguimientoYR-CG/Shared%20Documents/Forms/AllItems.aspx | H34: 30 | I34: 3.25 | J34: =IFERROR(I34/H34,0) -> 0.10833333 | K34: =I34 -> 3.25 | L34: =IFERROR(K34/H34,0) -> 0.10833333
B35: 5 | C35: 5.9 | D35: Realizar el seguimiento de producción/ inyección de pozos intervenidos con base en los comportamientos de producción previo y posterior a la intervención | F35: Reuniones sistemáticas para el seguimiento y monitoreo de la producción/inyección del Campo yariguí | G35: Actas en medio digital: https://wellmeeting.ecopetrol.com.co/ | H35: 28 | I35: 3.25 | J35: =IFERROR(I35/H35,0) -> 0.11607143 | K35: =I35 -> 3.25 | L35: =IFERROR(K35/H35,0) -> 0.11607143
B36: 5 | C36: 5.10 | D36: Adelantar en análisis y evaluación de datos enfocada a la ejecución de estudios de daño de formación | F36: Actualización de Tableros PBI creados para el balance de presiones y poder identificar condiciones actuales de los pozos como Pwf actuales, Pwf límite, índice de productividad y condición de daño | G36: Sharepoint: https://ecopetrol.sharepoint.com/sites/TablerosdeSeguimientoYR-CG/Shared%20Documents/Forms/AllItems.aspx | H36: 28 | I36: 3.25 | J36: =IFERROR(I36/H36,0) -> 0.11607143 | K36: =I36 -> 3.25 | L36: =IFERROR(K36/H36,0) -> 0.11607143
B37: 3 | C37: 3.3 | D37: Realice el plan de desarrollo de campo y los pronósticos: realizando todos los pronósticos de escenarios de simulación para llevar a cabo la planificación del desarrollo de campo, esto incluye investigar y realizar análisis de sensibilidad e incertidumbre de los principales parámetros coincidentes de la historia y las incógnitas y su efecto en el pronóstico. La predicción se basaría en el plan de desarrollo de campo, las ubicaciones de perforación de relleno, el análisis de patrones, la optimización de la inyección de agua, la tasa de inyección óptima y el proceso de recuperación terciaria (química y térmica). Realizar evaluaciones económicas y evaluaciones de cada proceso y presentar la mejor solución óptima. Generar Modelo analítico del yacimiento integrando la información disponible en un software específico. | E37: Jose Carlos Garcia Rueda | F37: Modelo Dinámico -Perfiles de Producción -Informe. | G37: Digital | H37: 78 | I37: 14 | J37: =IFERROR(I37/H37,0) -> 0.17948718 | K37: =I37 -> 14 | L37: =IFERROR(K37/H37,0) -> 0.17948718
B38: 3 | C38: 3.13 | D38: Generar base de datos de producción (OFM o la que se requiera) | F38: Base de Datos | G38: Digital | H38: 34 | I38: 2 | J38: =IFERROR(I38/H38,0) -> 0.058823529 | K38: =I38 -> 2 | L38: =IFERROR(K38/H38,0) -> 0.058823529
B39: 3 | C39: 3.14 | D39: Generar Distribución de Producción por sub- unidades (allocation) | F39: - | G39: - | H39: 30 | I39: 0 | J39: =IFERROR(I39/H39,0) -> 0 | K39: =I39 -> 0 | L39: =IFERROR(K39/H39,0) -> 0
B40: 3 | C40: 3.16 | D40: Análisis de Declinaciones por pozo y/o subunidad | F40: - | G40: - | H40: 30 | I40: 0 | J40: =IFERROR(I40/H40,0) -> 0 | K40: =I40 -> 0 | L40: =IFERROR(K40/H40,0) -> 0
...

Sheet FEBRERO 2026
Q1: MES
B2: REPORTE DE AVANCE | Q2: ENERO
B3: Fecha: 29/06/2022 | F3: Version: 01 | J3: GP-F-23
Q4: FEBRERO
B5: Código Orden de servicio | D5: 90577770 | Q5: MARZO
Q6: JUNIO
B7: Mes a reportar | D7: FEBRERO | Q7: JULIO
Q8: AGOSTO
B9: Fecha reporte | D9: 46081 | Q9: SEPTIEMBRE
Q10: OCTUBRE
B11: Clasificación del servicio | I11: Reporte mes por servicio | K11: Reporte acumulado por servicio | Q11: NOVIEMBRE
B12: Ítem general | C12: ítem actividad | D12: Descripción de la actividad | E12: Profesional a cargo | F12: Soporte | G12: Medio de entrega | H12: Días contratados Acta de Inicio | I12: Días | J12: % avance | K12: Días | L12: % avance | Q12: DICIEMBRE
B13: 1 | C13: 1.1 | D13: Generar Modelo Estático del yacimiento integrando la información disponible. | E13: Ximena Alejandra Rodriguez Florez | F13: Modelo Estático - Informe de Modelo - Cálculo de Volúmenes in Place | G13: Digital | H13: 60 | I13: 5 | J13: =IFERROR(I13/H13,0) -> 0.083333333 | K13: =I13+'ENERO 2026'!K13 -> 15 | L13: =IFERROR(K13/H13,0) -> 0.25
B14: 1 | C14: 1.2 | D14: Generación de Bases de datos de Pozos (Registros, Topes e Información disponible) | F14: Bases de Datos | G14: Digital | H14: 20 | I14: 7 | J14: =IFERROR(I14/H14,0) -> 0.35 | K14: =I14+'ENERO 2026'!K14 -> 13 | L14: =IFERROR(K14/H14,0) -> 0.65
B15: 1 | C15: 1.4 | D15: Generación Modelo estructural. | F15: Modelo estructural - Informe del Modelo | G15: Digital | H15: 45 | I15: 3 | J15: =IFERROR(I15/H15,0) -> 0.066666667 | K15: =I15+'ENERO 2026'!K15 -> 5 | L15: =IFERROR(K15/H15,0) -> 0.11111111
B16: 1 | C16: 1.5 | D16: Digitalización, digitación y/o captura de información geológica (Mapas, Raw Data, topes, etc.) | F16: Mapas en formato digital | G16: Digital | H16: 20 | I16: 5 | J16: =IFERROR(I16/H16,0) -> 0.25 | K16: =I16+'ENERO 2026'!K16 -> 9 | L16: =IFERROR(K16/H16,0) -> 0.45
B17: 1 | C17: 1.7 | D17: Generación Modelo Geocelular. | F17: Modelo Geocelular - Informe del Modelo | G17: Digital | H17: 30 | I17: 0 | J17: =IFERROR(I17/H17,0) -> 0 | K17: =I17+'ENERO 2026'!K17 -> 1 | L17: =IFERROR(K17/H17,0) -> 0.033333333
B18: 1 | C18: 1.15 | D18: Carga de información para poblar el modelo geocelular (direccionales,coordenadas, surveys, topes, data de presión, estados mecánicos, evento de pozos, etc.) | F18: Modelo poblado | G18: Digital | H18: 20 | I18: 5 | J18: =IFERROR(I18/H18,0) -> 0.25 | K18: =I18+'ENERO 2026'!K18 -> 6 | L18: =IFERROR(K18/H18,0) -> 0.3
B19: 1 | C19: 1.16 | D19: Georeferenciación de Mapas, pozos, Imágenes satélite, etc. y Definición de CRS (Cordinates Reference System) | F19: Información georeferenciada | G19: Digital | H19: 20 | I19: 5 | J19: =IFERROR(I19/H19,0) -> 0.25 | K19: =I19+'ENERO 2026'!K19 -> 7 | L19: =IFERROR(K19/H19,0) -> 0.35
B20: 1 | C20: 1.17 | D20: Calculo probabilístico de Volúmenes In situ. | F20: Calculo Volumétrico - Bases de Datos | G20: Digital | H20: 21 | I20: 0 | J20: =IFERROR(I20/H20,0) -> 0 | K20: =I20+'ENERO 2026'!K20 -> 0 | L20: =IFERROR(K20/H20,0) -> 0
B21: 5 | C21: 5.1 | D21: Generar bases de datos de Eventos de pozos | E21: Jhon Abelardo Cuesta Asprilla | F21: Base de Datos | G21: Digital | H21: 30 | I21: 3 | J21: =IFERROR(I21/H21,0) -> 0.1 | K21: =I21+'ENERO 2026'!K21 -> 6 | L21: =IFERROR(K21/H21,0) -> 0.2
B22: 5 | C22: 5.2 | D22: Generación de oportunidades de intervención a Pozos | F22: Base de Datos - Informe de la Evaluación | G22: Digital | H22: 30 | I22: 4 | J22: =IFERROR(I22/H22,0) -> 0.13333333 | K22: =I22+'ENERO 2026'!K22 -> 7 | L22: =IFERROR(K22/H22,0) -> 0.23333333
B23: 5 | C23: 5.3 | D23: Estimar restricciones de Presión y tasas para la generación de perfiles de producción | F23: Base de Datos - Informe de la Evaluación | G23: Digital | H23: 30 | I23: 4 | J23: =IFERROR(I23/H23,0) -> 0.13333333 | K23: =I23+'ENERO 2026'!K23 -> 7 | L23: =IFERROR(K23/H23,0) -> 0.23333333
B24: 5 | C24: 5.4 | D24: Generar modelo de Pozos | F24: Base de Datos - Informe de la Evaluación | G24: Digital | H24: 30 | I24: 4 | J24: =IFERROR(I24/H24,0) -> 0.13333333 | K24: =I24+'ENERO 2026'!K24 -> 7 | L24: =IFERROR(K24/H24,0) -> 0.23333333
B25: 5 | C25: 5.5 | D25: Adelantar la evaluación e interpretación de datos enfocada a candidatización de actividades de reacondicionamiento y optimización de productividad en los activos | F25: Base de Datos - Informe de la Evaluación | G25: Digital | H25: 29 | I25: 4 | J25: =IFERROR(I25/H25,0) -> 0.13793103 | K25: =I25+'ENERO 2026'!K25 -> 8 | L25: =IFERROR(K25/H25,0) -> 0.27586207
B26: 5 | C26: 5.6 | D26: Generar los análisis asociados a candidatización de pozos para optimización de la producción empleando simulación numérica (análisis nodal) de productividad de pozos | F26: Base de Datos - Informe de la Evaluación | G26: Digital | H26: 29 | I26: 4 | J26: =IFERROR(I26/H26,0) -> 0.13793103 | K26: =I26+'ENERO 2026'!K26 -> 8 | L26: =IFERROR(K26/H26,0) -> 0.27586207
B27: 5 | C27: 5.9 | D27: Realizar el seguimiento de producción/ inyección de pozos intervenidos con base en los comportamientos de producción previo y posterior a la intervención | F27: Base de Datos - Informe de la Evaluación | G27: Digital | H27: 29 | I27: 4 | J27: =IFERROR(I27/H27,0) -> 0.13793103 | K27: =I27+'ENERO 2026'!K27 -> 7 | L27: =IFERROR(K27/H27,0) -> 0.24137931
B28: 5 | C28: 5.10 | D28: Adelantar en análisis y evaluación de datos enfocada a la ejecución de estudios de daño de formación | F28: Base de Datos - Informe de la Evaluación | G28: Digital | H28: 29 | I28: 3 | J28: =IFERROR(I28/H28,0) -> 0.10344828 | K28: =I28+'ENERO 2026'!K28 -> 6 | L28: =IFERROR(K28/H28,0) -> 0.20689655
B29: 5 | C29: 5.1 | D29: Generar bases de datos de Eventos de pozos | E29: Andres Fabian Amaya Hernandez | F29: Actualización de Tableros PBI con información de producción, inyección e intervenciones | G29: Sharepoint: https://ecopetrol.sharepoint.com/sites/TablerosdeSeguimientoYR-CG/Shared%20Documents/Forms/AllItems.aspx | H29: 30 | I29: 3.75 | J29: =IFERROR(I29/H29,0) -> 0.125 | K29: =I29+'ENERO 2026'!K29 -> 7 | L29: =IFERROR(K29/H29,0) -> 0.23333333
B30: 5 | C30: 5.2 | D30: Generación de oportunidades de intervención a Pozos | F30: Reuniones sistemáticas para el seguimiento y monitoreo de la producción/inyección del Campo yariguí, y así identificar pozos candidatos para trabajos de WO y mejorar el índice de productividad e inyectividad | G30: Actas en medio digital: https://wellmeeting.ecopetrol.com.co/ | H30: 30 | I30: 3.75 | J30: =IFERROR(I30/H30,0) -> 0.125 | K30: =I30+'ENERO 2026'!K30 -> 7 | L30: =IFERROR(K30/H30,0) -> 0.23333333
B31: 5 | C31: 5.3 | D31: Estimar restricciones de Presión y tasas para la generación de perfiles de producción | F31: Estimación de justificación de reservas 1P del Campo Yariguí. Diligenciamiento de Formato F20 sobre la conversión de reservas PND del Campo Yariguí-Cantagallo | G31: Sharepoint: https://ecopetrol.sharepoint.com/sites/TablerosdeSeguimientoYR-CG/Shared%20Documents/Forms/AllItems.aspx Ruta compartida: \\10.11.46.150\groups07\01_YR-CG\04_PROYECTOS\26_PIC\2026 Ruta compartida: \\10.11.46.150\groups07\01_YR-CG\02_Modelo Dinámico\02_Yacimientos\07_Auditoria de Reservas | H31: 30 | I31: 3.75 | J31: =IFERROR(I31/H31,0) -> 0.125 | K31: =I31+'ENERO 2026'!K31 -> 7 | L31: =IFERROR(K31/H31,0) -> 0.23333333
B32: 5 | C32: 5.4 | D32: Generar modelo de Pozos | F32: Base de Datos - Informe de la Evaluación | G32: Digital | H32: 30 | I32: 3.75 | J32: =IFERROR(I32/H32,0) -> 0.125 | K32: =I32+'ENERO 2026'!K32 -> 7 | L32: =IFERROR(K32/H32,0) -> 0.23333333
B33: 5 | C33: 5.5 | D33: Adelantar la evaluación e interpretación de datos enfocada a candidatización de actividades de reacondicionamiento y optimización de productividad en los activos | F33: Actualización de Tableros PBI creados para el seguimiento de producción/inyección, gráficos de Lorenz de pozos inyectores, balance de presiones y revisión de reservas certificadas | G33: Sharepoint: https://ecopetrol.sharepoint.com/sites/TablerosdeSeguimientoYR-CG/Shared%20Documents/Forms/AllItems.aspx | H33: 30 | I33: 3.75 | J33: =IFERROR(I33/H33,0) -> 0.125 | K33: =I33+'ENERO 2026'!K33 -> 7 | L33: =IFERROR(K33/H33,0) -> 0.23333333
B34: 5 | C34: 5.6 | D34: Generar los análisis asociados a candidatización de pozos para optimización de la producción empleando simulación numérica (análisis nodal) de productividad de pozos | F34: Reuniones sistemáticas para el seguimiento y monitoreo de la producción/inyección del Campo yariguí, y así identificar pozos con oportunidades de optimización de la presión de fondo manteniendo el balance de presiones del patrón | G34: Actas en medio digital: https://wellmeeting.ecopetrol.com.co/ Sharepoint: https://ecopetrol.sharepoint.com/sites/TablerosdeSeguimientoYR-CG/Shared%20Documents/Forms/AllItems.aspx | H34: 30 | I34: 3.75 | J34: =IFERROR(I34/H34,0) -> 0.125 | K34: =I34+'ENERO 2026'!K34 -> 7 | L34: =IFERROR(K34/H34,0) -> 0.23333333
B35: 5 | C35: 5.9 | D35: Realizar el seguimiento de producción/ inyección de pozos intervenidos con base en los comportamientos de producción previo y posterior a la intervención | F35: Reuniones sistemáticas para el seguimiento y monitoreo de la producción/inyección del Campo yariguí | G35: Actas en medio digital: https://wellmeeting.ecopetrol.com.co/ | H35: 28 | I35: 3.75 | J35: =IFERROR(I35/H35,0) -> 0.13392857 | K35: =I35+'ENERO 2026'!K35 -> 7 | L35: =IFERROR(K35/H35,0) -> 0.25
B36: 5 | C36: 5.10 | D36: Adelantar en análisis y evaluación de datos enfocada a la ejecución de estudios de daño de formación | F36: Actualización de Tableros PBI creados para el balance de presiones y poder identificar condiciones actuales de los pozos como Pwf actuales, Pwf límite, índice de productividad y condición de daño | G36: Sharepoint: https://ecopetrol.sharepoint.com/sites/TablerosdeSeguimientoYR-CG/Shared%20Documents/Forms/AllItems.aspx | H36: 28 | I36: 3.75 | J36: =IFERROR(I36/H36,0) -> 0.13392857 | K36: =I36+'ENERO 2026'!K36 -> 7 | L36: =IFERROR(K36/H36,0) -> 0.25
B37: 3 | C37: 3.3 | D37: Realice el plan de desarrollo de campo y los pronósticos: realizando todos los pronósticos de escenarios de simulación para llevar a cabo la planificación del desarrollo de campo, esto incluye investigar y realizar análisis de sensibilidad e incertidumbre de los principales parámetros coincidentes de la historia y las incógnitas y su efecto en el pronóstico. La predicción se basaría en el plan de desarrollo de campo, las ubicaciones de perforación de relleno, el análisis de patrones, la optimización de la inyección de agua, la tasa de inyección óptima y el proceso de recuperación terciaria (química y térmica). Realizar evaluaciones económicas y evaluaciones de cada proceso y presentar la mejor solución óptima. Generar Modelo analítico del yacimiento integrando la información disponible en un software específico. | E37: Jose Carlos Garcia Rueda | F37: Modelo Dinámico -Perfiles de Producción -Informe. | G37: Digital | H37: 78 | I37: 12 | J37: =IFERROR(I37/H37,0) -> 0.15384615 | K37: =I37+'ENERO 2026'!K37 -> 26 | L37: =IFERROR(K37/H37,0) -> 0.33333333
B38: 3 | C38: 3.13 | D38: Generar base de datos de producción (OFM o la que se requiera) | F38: Base de Datos | G38: Digital | H38: 34 | I38: 6 | J38: =IFERROR(I38/H38,0) -> 0.17647059 | K38: =I38+'ENERO 2026'!K38 -> 8 | L38: =IFERROR(K38/H38,0) -> 0.23529412
B39: 3 | C39: 3.14 | D39: Generar Distribución de Producción por sub- unidades (allocation) | F39: Base de Datos | G39: Digital | H39: 30 | I39: 6 | J39: =IFERROR(I39/H39,0) -> 0.2 | K39: =I39+'ENERO 2026'!K39 -> 6 | L39: =IFERROR(K39/H39,0) -> 0.2
B40: 3 | C40: 3.16 | D40: Análisis de Declinaciones por pozo y/o subunidad | F40: - | G40: - | H40: 30 | I40: 0 | J40: =IFERROR(I40/H40,0) -> 0 | K40: =I40+'ENERO 2026'!K40 -> 0 | L40: =IFERROR(K40/H40,0) -> 0
...
