Workbook

Sheet JUNIO
P1: MES
B2: REPORTE DE AVANCE | P2: ENERO
B3: Fecha: 29/06/2022 | E3: Version: 01 | I3: GP-F-23
P4: FEBRERO
B5: Código Orden de servicio | D5: 90227898 | P5: MARZO
P6: ABRIL
B7: Mes a reportar | D7: JUNIO | P7: JULIO
P8: AGOSTO
B9: Fecha reporte | D9: 45838 | P9: SEPTIEMBRE
P10: OCTUBRE
B11: Clasificación del servicio | H11: Reporte mes por servicio | J11: Reporte acumulado por servicio | P11: NOVIEMBRE
B12: Ítem general | C12: ítem actividad | D12: Descripción de la actividad | E12: Soporte | F12: Medio de entrega | G12: Días contratados | H12: Días | I12: % avance | J12: Días | K12: % avance | P12: DICIEMBRE
B13: 3 | C13: 3.6 | D13: Generar Modelo analítico del yacimiento integrando la información disponible en un software específico | E13: Modelo Analítico – Perfiles de Producción – Informe del modelo | F13: Digital | G13: 11 | H13: 1 | I13: =IFERROR(H13/G13,0) -> 0.090909091 | J13: =+H13 -> 1 | K13: =IFERROR(J13/G13,0) -> 0.090909091
B14: 3 | C14: 3.11 | D14: Análisis e interpretación de datos de pruebas de presión-producción (DSTs, PBU, Pruebas Extendidas Producción, Gradientes Estáticos-Dinámicos PT, etc.) o de presión inyección (Inyectividad, SRT, FOT) aplicadas ya sea en tiempo real, memorizadas o con sarta temporal DST. Integración Probador Formación – Registros Open Hole. | E14: - | F14: - | G14: 11 | H14: 0 | I14: =IFERROR(H14/G14,0) -> 0 | J14: =+H14 -> 0 | K14: =IFERROR(J14/G14,0) -> 0
B15: 3 | C15: 3.13 | D15: Generar base de datos de producción (OFM o la que se requiera) | E15: Base de Datos | F15: Digital | G15: 11 | H15: 1 | I15: =IFERROR(H15/G15,0) -> 0.090909091 | J15: =+H15 -> 1 | K15: =IFERROR(J15/G15,0) -> 0.090909091
B16: 3 | C16: 3.14 | D16: Generar Distribución de Producción por sub- unidades (allocation) | E16: Base de Datos | F16: Digital | G16: 11 | H16: 1 | I16: =IFERROR(H16/G16,0) -> 0.090909091 | J16: =+H16 -> 1 | K16: =IFERROR(J16/G16,0) -> 0.090909091
B17: 3 | C17: 3.15 | D17: Generar Balance de Materia por campo y/o por subunidad y/o por compartimiento | E17: Base de Datos - Modelo de Balance - Informe del modelo | F17: Digital | G17: 11 | H17: 1 | I17: =IFERROR(H17/G17,0) -> 0.090909091 | J17: =+H17 -> 1 | K17: =IFERROR(J17/G17,0) -> 0.090909091
B18: 3 | C18: 3.16 | D18: Análisis de Declinaciones por pozo y/o subunidad | E18: Base de Datos – Perfiles Generados – Informe del análisis | F18: Digital | G18: 11 | H18: 1 | I18: =IFERROR(H18/G18,0) -> 0.090909091 | J18: =+H18 -> 1 | K18: =IFERROR(J18/G18,0) -> 0.090909091
B19: 3 | C19: 3.17 | D19: Analizar data histórica de producción, productividad y daño por pozo | E19: Base de Datos - Informe de la Evaluación | F19: Digital | G19: 11 | H19: 2 | I19: =IFERROR(H19/G19,0) -> 0.18181818 | J19: =+H19 -> 2 | K19: =IFERROR(J19/G19,0) -> 0.18181818
B20: 3 | C20: 3.18 | D20: Generar perfiles de Producción por pozos para pozos existente en escenarios Bajo, Medio y Alto. | E20: Base de Datos – Informe de la Evaluación | F20: Digital | G20: 11 | H20: 1 | I20: =IFERROR(H20/G20,0) -> 0.090909091 | J20: =+H20 -> 1 | K20: =IFERROR(J20/G20,0) -> 0.090909091
B21: 5 | C21: 5.2 | D21: Generación de oportunidades de intervención a Pozos | E21: Base de Datos - Informe de la Evaluación | F21: Digital | G21: 11 | H21: 1 | I21: =IFERROR(H21/G21,0) -> 0.090909091 | J21: =+H21 -> 1 | K21: =IFERROR(J21/G21,0) -> 0.090909091
B22: 5 | C22: 5.3 | D22: Estimar restricciones de Presión y tasas para la generación de perfiles de producción | E22: Base de Datos – Informe de la Evaluación | F22: Digital | G22: 11 | H22: 1 | I22: =IFERROR(H22/G22,0) -> 0.090909091 | J22: =+H22 -> 1 | K22: =IFERROR(J22/G22,0) -> 0.090909091
B23: 5 | C23: 5.4 | D23: Generar modelo de Pozos | E23: - | F23: - | G23: 11 | H23: 0 | I23: =IFERROR(H23/G23,0) -> 0 | J23: =+H23 -> 0 | K23: =IFERROR(J23/G23,0) -> 0
B24: 5 | C24: 5.5 | D24: Adelantar la evaluación e interpretación de datos enfocada a candidatización de actividades de reacondicionamiento y optimización de productividad en los activos | E24: Base de Datos – Informe de la Evaluación | F24: Digital | G24: 11 | H24: 2 | I24: =IFERROR(H24/G24,0) -> 0.18181818 | J24: =+H24 -> 2 | K24: =IFERROR(J24/G24,0) -> 0.18181818
... B30: 5 | C30: 5.11 | D30: Generar los análisis asociados a la ejecución de estudios de daño de formación empleando simulación numérica (análisis nodal y single well model, análisis de aguas, análisis de crudos, entre otros) | E30: - | F30: - | G30: 11 | H30: 0 | I30: =IFERROR(H30/G30,0) -> 0 | J30: =+H30 -> 0 | K30: =IFERROR(J30/G30,0) -> 0
G31: =+CONCATENATE("TOTAL A ",D7) -> TOTAL A JUNIO | J31: TOTAL ACUMULADO
G32: =+SUM(G13:G30) -> 198 | H32: =+SUM(H13:H30) -> 18 | I32: =IFERROR(H32/G32,0) -> 0.090909091 | J32: =+SUM(J13:J30) -> 18 | K32: =IFERROR(J32/G32,0) -> 0.090909091
B34: Observaciones: | D34: Describa en este espacio su observación
B35: ¿Se presentó algún aspecto o situación que afecte la ejecución y calidad de los entregables? (Marque con una X)
B37: PROFESIONAL
B38: SI | D38: Describa en este espacio su observación
B39: NO
B40: ¿Se presentó algún aspecto o situación que afecte la ejecución y calidad de los entregables? (Marque con una X)
B42: INTERVENTOR O LIDER
B43: SI | D43: Describa en este espacio su observación
B44: NO
B48: Revisa: | G48: Interventor: | H48: Luisa Margarita Uribe Corrales
A95: MES
A96: ENERO
A97: FEBRERO
...

Sheet JULIO
P1: MES
B2: REPORTE DE AVANCE | P2: ENERO
B3: Fecha: 29/06/2022 | E3: Version: 01 | I3: GP-F-23
P4: FEBRERO
B5: Código Orden de servicio | D5: 90227898 | P5: MARZO
P6: ABRIL
B7: Mes a reportar | D7: JULIO | P7: JULIO
P8: AGOSTO
B9: Fecha reporte | D9: 45869 | P9: SEPTIEMBRE
P10: OCTUBRE
B11: Clasificación del servicio | H11: Reporte mes por servicio | J11: Reporte acumulado por servicio | P11: NOVIEMBRE
B12: Ítem general | C12: ítem actividad | D12: Descripción de la actividad | E12: Soporte | F12: Medio de entrega | G12: Días contratados | H12: Días | I12: % avance | J12: Días | K12: % avance | P12: DICIEMBRE
B13: 3 | C13: 3.6 | D13: Generar Modelo analítico del yacimiento integrando la información disponible en un software específico | E13: Modelo Analítico – Perfiles de Producción – Informe del modelo | F13: Digital | G13: 11 | H13: 2 | I13: =IFERROR(H13/G13,0) -> 0.18181818 | J13: =+H13+JUNIO!J13 -> 3 | K13: =IFERROR(J13/G13,0) -> 0.27272727
B14: 3 | C14: 3.11 | D14: Análisis e interpretación de datos de pruebas de presión-producción (DSTs, PBU, Pruebas Extendidas Producción, Gradientes Estáticos-Dinámicos PT, etc.) o de presión inyección (Inyectividad, SRT, FOT) aplicadas ya sea en tiempo real, memorizadas o con sarta temporal DST. Integración Probador Formación – Registros Open Hole. | E14: Informe del análisis por pozo o prueba | F14: Digital | G14: 11 | H14: 2 | I14: =IFERROR(H14/G14,0) -> 0.18181818 | J14: =+H14+JUNIO!J14 -> 2 | K14: =IFERROR(J14/G14,0) -> 0.18181818
B15: 3 | C15: 3.13 | D15: Generar base de datos de producción (OFM o la que se requiera) | E15: Base de Datos | F15: Digital | G15: 11 | H15: 2 | I15: =IFERROR(H15/G15,0) -> 0.18181818 | J15: =+H15+JUNIO!J15 -> 3 | K15: =IFERROR(J15/G15,0) -> 0.27272727
B16: 3 | C16: 3.14 | D16: Generar Distribución de Producción por sub- unidades (allocation) | E16: Base de Datos | F16: Digital | G16: 11 | H16: 2 | I16: =IFERROR(H16/G16,0) -> 0.18181818 | J16: =+H16+JUNIO!J16 -> 3 | K16: =IFERROR(J16/G16,0) -> 0.27272727
B17: 3 | C17: 3.15 | D17: Generar Balance de Materia por campo y/o por subunidad y/o por compartimiento | E17: Base de Datos - Modelo de Balance - Informe del modelo | F17: Digital | G17: 11 | H17: 1 | I17: =IFERROR(H17/G17,0) -> 0.090909091 | J17: =+H17+JUNIO!J17 -> 2 | K17: =IFERROR(J17/G17,0) -> 0.18181818
B18: 3 | C18: 3.16 | D18: Análisis de Declinaciones por pozo y/o subunidad | E18: Base de Datos – Perfiles Generados – Informe del análisis | F18: Digital | G18: 11 | H18: 2 | I18: =IFERROR(H18/G18,0) -> 0.18181818 | J18: =+H18+JUNIO!J18 -> 3 | K18: =IFERROR(J18/G18,0) -> 0.27272727
B19: 3 | C19: 3.17 | D19: Analizar data histórica de producción, productividad y daño por pozo | E19: Base de Datos - Informe de la Evaluación | F19: Digital | G19: 11 | H19: 2 | I19: =IFERROR(H19/G19,0) -> 0.18181818 | J19: =+H19+JUNIO!J19 -> 4 | K19: =IFERROR(J19/G19,0) -> 0.36363636
B20: 3 | C20: 3.18 | D20: Generar perfiles de Producción por pozos para pozos existente en escenarios Bajo, Medio y Alto. | E20: Base de Datos – Informe de la Evaluación | F20: Digital | G20: 11 | H20: 2 | I20: =IFERROR(H20/G20,0) -> 0.18181818 | J20: =+H20+JUNIO!J20 -> 3 | K20: =IFERROR(J20/G20,0) -> 0.27272727
B21: 5 | C21: 5.2 | D21: Generación de oportunidades de intervención a Pozos | E21: Base de Datos - Informe de la Evaluación | F21: Digital | G21: 11 | H21: 1 | I21: =IFERROR(H21/G21,0) -> 0.090909091 | J21: =+H21+JUNIO!J21 -> 2 | K21: =IFERROR(J21/G21,0) -> 0.18181818
B22: 5 | C22: 5.3 | D22: Estimar restricciones de Presión y tasas para la generación de perfiles de producción | E22: Base de Datos – Informe de la Evaluación | F22: Digital | G22: 11 | H22: 2 | I22: =IFERROR(H22/G22,0) -> 0.18181818 | J22: =+H22+JUNIO!J22 -> 3 | K22: =IFERROR(J22/G22,0) -> 0.27272727
B23: 5 | C23: 5.4 | D23: Generar modelo de Pozos | E23: Base de Datos – Informe de la Evaluación | F23: Digital | G23: 11 | H23: 2 | I23: =IFERROR(H23/G23,0) -> 0.18181818 | J23: =+H23+JUNIO!J23 -> 2 | K23: =IFERROR(J23/G23,0) -> 0.18181818
B24: 5 | C24: 5.5 | D24: Adelantar la evaluación e interpretación de datos enfocada a candidatización de actividades de reacondicionamiento y optimización de productividad en los activos | E24: Base de Datos – Informe de la Evaluación | F24: Digital | G24: 11 | H24: 1 | I24: =IFERROR(H24/G24,0) -> 0.090909091 | J24: =+H24+JUNIO!J24 -> 3 | K24: =IFERROR(J24/G24,0) -> 0.27272727
... B30: 5 | C30: 5.11 | D30: Generar los análisis asociados a la ejecución de estudios de daño de formación empleando simulación numérica (análisis nodal y single well model, análisis de aguas, análisis de crudos, entre otros) | E30: Base de Datos – Informe de la Evaluación | F30: Digital | G30: 11 | H30: 1 | I30: =IFERROR(H30/G30,0) -> 0.090909091 | J30: =+H30+JUNIO!J30 -> 1 | K30: =IFERROR(J30/G30,0) -> 0.090909091
G31: =+CONCATENATE("TOTAL A ",D7) -> TOTAL A JULIO | J31: TOTAL ACUMULADO
G32: =+SUM(G13:G30) -> 198 | H32: =+SUM(H13:H30) -> 30 | I32: =IFERROR(H32/G32,0) -> 0.15151515 | J32: =+SUM(J13:J30) -> 48 | K32: =IFERROR(J32/G32,0) -> 0.24242424
B34: Observaciones: | D34: Describa en este espacio su observación
B35: ¿Se presentó algún aspecto o situación que afecte la ejecución y calidad de los entregables? (Marque con una X)
B37: PROFESIONAL
B38: SI | D38: Describa en este espacio su observación
B39: NO
B40: ¿Se presentó algún aspecto o situación que afecte la ejecución y calidad de los entregables? (Marque con una X)
B42: INTERVENTOR O LIDER
B43: SI | D43: Describa en este espacio su observación
B44: NO
B48: Revisa: | G48: Interventor: | H48: Luisa Margarita Uribe Corrales
A95: MES
A96: ENERO
A97: FEBRERO
...

Sheet AGOSTO
P1: MES
B2: REPORTE DE AVANCE | P2: ENERO
B3: Fecha: 29/06/2022 | E3: Version: 01 | I3: GP-F-23
P4: FEBRERO
B5: Código Orden de servicio | D5: 90227898 | P5: MARZO
P6: ABRIL
B7: Mes a reportar | D7: AGOSTO | P7: JULIO
P8: AGOSTO
B9: Fecha reporte | D9: 45900 | P9: SEPTIEMBRE
P10: OCTUBRE
B11: Clasificación del servicio | H11: Reporte mes por servicio | J11: Reporte acumulado por servicio | P11: NOVIEMBRE
B12: Ítem general | C12: ítem actividad | D12: Descripción de la actividad | E12: Soporte | F12: Medio de entrega | G12: Días contratados | H12: Días | I12: % avance | J12: Días | K12: % avance | P12: DICIEMBRE
B13: 3 | C13: 3.6 | D13: Generar Modelo analítico del yacimiento integrando la información disponible en un software específico | E13: Modelo Analítico – Perfiles de Producción – Informe del modelo | F13: Digital | G13: 11 | H13: 2 | I13: =IFERROR(H13/G13,0) -> 0.18181818 | J13: =+H13+JULIO!J13 -> 5 | K13: =IFERROR(J13/G13,0) -> 0.45454545
B14: 3 | C14: 3.11 | D14: Análisis e interpretación de datos de pruebas de presión-producción (DSTs, PBU, Pruebas Extendidas Producción, Gradientes Estáticos-Dinámicos PT, etc.) o de presión inyección (Inyectividad, SRT, FOT) aplicadas ya sea en tiempo real, memorizadas o con sarta temporal DST. Integración Probador Formación – Registros Open Hole. | E14: Informe del análisis por pozo o prueba | F14: Digital | G14: 11 | H14: 2 | I14: =IFERROR(H14/G14,0) -> 0.18181818 | J14: =+H14+JULIO!J14 -> 4 | K14: =IFERROR(J14/G14,0) -> 0.36363636
B15: 3 | C15: 3.13 | D15: Generar base de datos de producción (OFM o la que se requiera) | E15: Base de Datos | F15: Digital | G15: 11 | H15: 2 | I15: =IFERROR(H15/G15,0) -> 0.18181818 | J15: =+H15+JULIO!J15 -> 5 | K15: =IFERROR(J15/G15,0) -> 0.45454545
B16: 3 | C16: 3.14 | D16: Generar Distribución de Producción por sub- unidades (allocation) | E16: Base de Datos | F16: Digital | G16: 11 | H16: 2 | I16: =IFERROR(H16/G16,0) -> 0.18181818 | J16: =+H16+JULIO!J16 -> 5 | K16: =IFERROR(J16/G16,0) -> 0.45454545
B17: 3 | C17: 3.15 | D17: Generar Balance de Materia por campo y/o por subunidad y/o por compartimiento | E17: Base de Datos - Modelo de Balance - Informe del modelo | F17: Digital | G17: 11 | H17: 1 | I17: =IFERROR(H17/G17,0) -> 0.090909091 | J17: =+H17+JULIO!J17 -> 3 | K17: =IFERROR(J17/G17,0) -> 0.27272727
B18: 3 | C18: 3.16 | D18: Análisis de Declinaciones por pozo y/o subunidad | E18: Base de Datos – Perfiles Generados – Informe del análisis | F18: Digital | G18: 11 | H18: 2 | I18: =IFERROR(H18/G18,0) -> 0.18181818 | J18: =+H18+JULIO!J18 -> 5 | K18: =IFERROR(J18/G18,0) -> 0.45454545
B19: 3 | C19: 3.17 | D19: Analizar data histórica de producción, productividad y daño por pozo | E19: Base de Datos - Informe de la Evaluación | F19: Digital | G19: 11 | H19: 2 | I19: =IFERROR(H19/G19,0) -> 0.18181818 | J19: =+H19+JULIO!J19 -> 6 | K19: =IFERROR(J19/G19,0) -> 0.54545455
B20: 3 | C20: 3.18 | D20: Generar perfiles de Producción por pozos para pozos existente en escenarios Bajo, Medio y Alto. | E20: Base de Datos – Informe de la Evaluación | F20: Digital | G20: 11 | H20: 2 | I20: =IFERROR(H20/G20,0) -> 0.18181818 | J20: =+H20+JULIO!J20 -> 5 | K20: =IFERROR(J20/G20,0) -> 0.45454545
B21: 5 | C21: 5.2 | D21: Generación de oportunidades de intervención a Pozos | E21: Base de Datos - Informe de la Evaluación | F21: Digital | G21: 11 | H21: 1 | I21: =IFERROR(H21/G21,0) -> 0.090909091 | J21: =+H21+JULIO!J21 -> 3 | K21: =IFERROR(J21/G21,0) -> 0.27272727
B22: 5 | C22: 5.3 | D22: Estimar restricciones de Presión y tasas para la generación de perfiles de producción | E22: Base de Datos – Informe de la Evaluación | F22: Digital | G22: 11 | H22: 2 | I22: =IFERROR(H22/G22,0) -> 0.18181818 | J22: =+H22+JULIO!J22 -> 5 | K22: =IFERROR(J22/G22,0) -> 0.45454545
B23: 5 | C23: 5.4 | D23: Generar modelo de Pozos | E23: Base de Datos – Informe de la Evaluación | F23: Digital | G23: 11 | H23: 2 | I23: =IFERROR(H23/G23,0) -> 0.18181818 | J23: =+H23+JULIO!J23 -> 4 | K23: =IFERROR(J23/G23,0) -> 0.36363636
B24: 5 | C24: 5.5 | D24: Adelantar la evaluación e interpretación de datos enfocada a candidatización de actividades de reacondicionamiento y optimización de productividad en los activos | E24: Base de Datos – Informe de la Evaluación | F24: Digital | G24: 11 | H24: 1 | I24: =IFERROR(H24/G24,0) -> 0.090909091 | J24: =+H24+JULIO!J24 -> 4 | K24: =IFERROR(J24/G24,0) -> 0.36363636
... B30: 5 | C30: 5.11 | D30: Generar los análisis asociados a la ejecución de estudios de daño de formación empleando simulación numérica (análisis nodal y single well model, análisis de aguas, análisis de crudos, entre otros) | E30: Base de Datos – Informe de la Evaluación | F30: Digital | G30: 11 | H30: 1 | I30: =IFERROR(H30/G30,0) -> 0.090909091 | J30: =+H30+JULIO!J30 -> 2 | K30: =IFERROR(J30/G30,0) -> 0.18181818
G31: =+CONCATENATE("TOTAL A ",D7) -> TOTAL A AGOSTO | J31: TOTAL ACUMULADO
G32: =+SUM(G13:G30) -> 198 | H32: =+SUM(H13:H30) -> 30 | I32: =IFERROR(H32/G32,0) -> 0.15151515 | J32: =+SUM(J13:J30) -> 78 | K32: =IFERROR(J32/G32,0) -> 0.39393939
B34: Observaciones: | D34: Describa en este espacio su observación
B35: ¿Se presentó algún aspecto o situación que afecte la ejecución y calidad de los entregables? (Marque con una X)
B37: PROFESIONAL
B38: SI | D38: Describa en este espacio su observación
B39: NO
B40: ¿Se presentó algún aspecto o situación que afecte la ejecución y calidad de los entregables? (Marque con una X)
B42: INTERVENTOR O LIDER
B43: SI | D43: Describa en este espacio su observación
B44: NO
B48: Revisa: | G48: Interventor: | H48: Luisa Margarita Uribe Corrales
A95: MES
A96: ENERO
A97: FEBRERO
...

Sheet SEPTIEMBRE
P1: MES
B2: REPORTE DE AVANCE | P2: ENERO
B3: Fecha: 29/06/2022 | E3: Version: 01 | I3: GP-F-23
P4: FEBRERO
B5: Código Orden de servicio | D5: 90227898 | P5: MARZO
P6: ABRIL
B7: Mes a reportar | D7: SEPTIEMBRE | P7: JULIO
P8: AGOSTO
B9: Fecha reporte | D9: 45930 | P9: SEPTIEMBRE
P10: OCTUBRE
B11: Clasificación del servicio | H11: Reporte mes por servicio | J11: Reporte acumulado por servicio | P11: NOVIEMBRE
B12: Ítem general | C12: ítem actividad | D12: Descripción de la actividad | E12: Soporte | F12: Medio de entrega | G12: Días contratados | H12: Días | I12: % avance | J12: Días | K12: % avance | P12: DICIEMBRE
B13: 3 | C13: 3.6 | D13: Generar Modelo analítico del yacimiento integrando la información disponible en un software específico | E13: Modelo Analítico – Perfiles de Producción – Informe del modelo | F13: Digital | G13: 11 | H13: 2 | I13: =IFERROR(H13/G13,0) -> 0.18181818 | J13: =+H13+AGOSTO!J13 -> 7 | K13: =IFERROR(J13/G13,0) -> 0.63636364
B14: 3 | C14: 3.11 | D14: Análisis e interpretación de datos de pruebas de presión-producción (DSTs, PBU, Pruebas Extendidas Producción, Gradientes Estáticos-Dinámicos PT, etc.) o de presión inyección (Inyectividad, SRT, FOT) aplicadas ya sea en tiempo real, memorizadas o con sarta temporal DST. Integración Probador Formación – Registros Open Hole. | E14: Informe del análisis por pozo o prueba | F14: Digital | G14: 11 | H14: 2 | I14: =IFERROR(H14/G14,0) -> 0.18181818 | J14: =+H14+AGOSTO!J14 -> 6 | K14: =IFERROR(J14/G14,0) -> 0.54545455
B15: 3 | C15: 3.13 | D15: Generar base de datos de producción (OFM o la que se requiera) | E15: Base de Datos | F15: Digital | G15: 11 | H15: 2 | I15: =IFERROR(H15/G15,0) -> 0.18181818 | J15: =+H15+AGOSTO!J15 -> 7 | K15: =IFERROR(J15/G15,0) -> 0.63636364
B16: 3 | C16: 3.14 | D16: Generar Distribución de Producción por sub- unidades (allocation) | E16: Base de Datos | F16: Digital | G16: 11 | H16: 2 | I16: =IFERROR(H16/G16,0) -> 0.18181818 | J16: =+H16+AGOSTO!J16 -> 7 | K16: =IFERROR(J16/G16,0) -> 0.63636364
B17: 3 | C17: 3.15 | D17: Generar Balance de Materia por campo y/o por subunidad y/o por compartimiento | E17: Base de Datos - Modelo de Balance - Informe del modelo | F17: Digital | G17: 11 | H17: 1 | I17: =IFERROR(H17/G17,0) -> 0.090909091 | J17: =+H17+AGOSTO!J17 -> 4 | K17: =IFERROR(J17/G17,0) -> 0.36363636
B18: 3 | C18: 3.16 | D18: Análisis de Declinaciones por pozo y/o subunidad | E18: Base de Datos – Perfiles Generados – Informe del análisis | F18: Digital | G18: 11 | H18: 2 | I18: =IFERROR(H18/G18,0) -> 0.18181818 | J18: =+H18+AGOSTO!J18 -> 7 | K18: =IFERROR(J18/G18,0) -> 0.63636364
B19: 3 | C19: 3.17 | D19: Analizar data histórica de producción, productividad y daño por pozo | E19: Base de Datos - Informe de la Evaluación | F19: Digital | G19: 11 | H19: 2 | I19: =IFERROR(H19/G19,0) -> 0.18181818 | J19: =+H19+AGOSTO!J19 -> 8 | K19: =IFERROR(J19/G19,0) -> 0.72727273
B20: 3 | C20: 3.18 | D20: Generar perfiles de Producción por pozos para pozos existente en escenarios Bajo, Medio y Alto. | E20: Base de Datos – Informe de la Evaluación | F20: Digital | G20: 11 | H20: 2 | I20: =IFERROR(H20/G20,0) -> 0.18181818 | J20: =+H20+AGOSTO!J20 -> 7 | K20: =IFERROR(J20/G20,0) -> 0.63636364
B21: 5 | C21: 5.2 | D21: Generación de oportunidades de intervención a Pozos | E21: Base de Datos - Informe de la Evaluación | F21: Digital | G21: 11 | H21: 1 | I21: =IFERROR(H21/G21,0) -> 0.090909091 | J21: =+H21+AGOSTO!J21 -> 4 | K21: =IFERROR(J21/G21,0) -> 0.36363636
B22: 5 | C22: 5.3 | D22: Estimar restricciones de Presión y tasas para la generación de perfiles de producción | E22: Base de Datos – Informe de la Evaluación | F22: Digital | G22: 11 | H22: 2 | I22: =IFERROR(H22/G22,0) -> 0.18181818 | J22: =+H22+AGOSTO!J22 -> 7 | K22: =IFERROR(J22/G22,0) -> 0.63636364
B23: 5 | C23: 5.4 | D23: Generar modelo de Pozos | E23: Base de Datos – Informe de la Evaluación | F23: Digital | G23: 11 | H23: 2 | I23: =IFERROR(H23/G23,0) -> 0.18181818 | J23: =+H23+AGOSTO!J23 -> 6 | K23: =IFERROR(J23/G23,0) -> 0.54545455
B24: 5 | C24: 5.5 | D24: Adelantar la evaluación e interpretación de datos enfocada a candidatización de actividades de reacondicionamiento y optimización de productividad en los activos | E24: Base de Datos – Informe de la Evaluación | F24: Digital | G24: 11 | H24: 1 | I24: =IFERROR(H24/G24,0) -> 0.090909091 | J24: =+H24+AGOSTO!J24 -> 5 | K24: =IFERROR(J24/G24,0) -> 0.45454545
... B30: 5 | C30: 5.11 | D30: Generar los análisis asociados a la ejecución de estudios de daño de formación empleando simulación numérica (análisis nodal y single well model, análisis de aguas, análisis de crudos, entre otros) | E30: Base de Datos – Informe de la Evaluación | F30: Digital | G30: 11 | H30: 1 | I30: =IFERROR(H30/G30,0) -> 0.090909091 | J30: =+H30+AGOSTO!J30 -> 3 | K30: =IFERROR(J30/G30,0) -> 0.27272727
G31: =+CONCATENATE("TOTAL A ",D7) -> TOTAL A SEPTIEMBRE | J31: TOTAL ACUMULADO
G32: =+SUM(G13:G30) -> 198 | H32: =+SUM(H13:H30) -> 30 | I32: =IFERROR(H32/G32,0) -> 0.15151515 | J32: =+SUM(J13:J30) -> 108 | K32: =IFERROR(J32/G32,0) -> 0.54545455
B34: Observaciones: | D34: Describa en este espacio su observación
B35: ¿Se presentó algún aspecto o situación que afecte la ejecución y calidad de los entregables? (Marque con una X)
B37: PROFESIONAL
B38: SI | D38: Describa en este espacio su observación
B39: NO
B40: ¿Se presentó algún aspecto o situación que afecte la ejecución y calidad de los entregables? (Marque con una X)
B42: INTERVENTOR O LIDER
B43: SI | D43: Describa en este espacio su observación
B44: NO
B48: Revisa: | G48: Interventor: | H48: Luisa Margarita Uribe Corrales
A95: MES
A96: ENERO
A97: FEBRERO
...

Sheet OCTUBRE
P1: MES
B2: REPORTE DE AVANCE | P2: ENERO
B3: Fecha: 29/06/2022 | E3: Version: 01 | I3: GP-F-23
P4: FEBRERO
B5: Código Orden de servicio | D5: 90227898 | P5: MARZO
P6: ABRIL
B7: Mes a reportar | D7: OCTUBRE | P7: JULIO
P8: AGOSTO
B9: Fecha reporte | D9: 45961 | P9: SEPTIEMBRE
P10: OCTUBRE
B11: Clasificación del servicio | H11: Reporte mes por servicio | J11: Reporte acumulado por servicio | P11: NOVIEMBRE
B12: Ítem general | C12: ítem actividad | D12: Descripción de la actividad | E12: Soporte | F12: Medio de entrega | G12: Días contratados | H12: Días | I12: % avance | J12: Días | K12: % avance | P12: DICIEMBRE
B13: 3 | C13: 3.6 | D13: Generar Modelo analítico del yacimiento integrando la información disponible en un software específico | E13: Modelo Analítico – Perfiles de Producción – Informe del modelo | F13: Digital | G13: 11 | H13: 1 | I13: =IFERROR(H13/G13,0) -> 0.090909091 | J13: =+H13+SEPTIEMBRE!J13 -> 8 | K13: =IFERROR(J13/G13,0) -> 0.72727273
B14: 3 | C14: 3.11 | D14: Análisis e interpretación de datos de pruebas de presión-producción (DSTs, PBU, Pruebas Extendidas Producción, Gradientes Estáticos-Dinámicos PT, etc.) o de presión inyección (Inyectividad, SRT, FOT) aplicadas ya sea en tiempo real, memorizadas o con sarta temporal DST. Integración Probador Formación – Registros Open Hole. | E14: Informe del análisis por pozo o prueba | F14: Digital | G14: 11 | H14: 2 | I14: =IFERROR(H14/G14,0) -> 0.18181818 | J14: =+H14+SEPTIEMBRE!J14 -> 8 | K14: =IFERROR(J14/G14,0) -> 0.72727273
B15: 3 | C15: 3.13 | D15: Generar base de datos de producción (OFM o la que se requiera) | E15: Base de Datos | F15: Digital | G15: 11 | H15: 2 | I15: =IFERROR(H15/G15,0) -> 0.18181818 | J15: =+H15+SEPTIEMBRE!J15 -> 9 | K15: =IFERROR(J15/G15,0) -> 0.81818182
B16: 3 | C16: 3.14 | D16: Generar Distribución de Producción por sub- unidades (allocation) | E16: Base de Datos | F16: Digital | G16: 11 | H16: 1 | I16: =IFERROR(H16/G16,0) -> 0.090909091 | J16: =+H16+SEPTIEMBRE!J16 -> 8 | K16: =IFERROR(J16/G16,0) -> 0.72727273
B17: 3 | C17: 3.15 | D17: Generar Balance de Materia por campo y/o por subunidad y/o por compartimiento | E17: Base de Datos - Modelo de Balance - Informe del modelo | F17: Digital | G17: 11 | H17: 3 | I17: =IFERROR(H17/G17,0) -> 0.27272727 | J17: =+H17+SEPTIEMBRE!J17 -> 7 | K17: =IFERROR(J17/G17,0) -> 0.63636364
B18: 3 | C18: 3.16 | D18: Análisis de Declinaciones por pozo y/o subunidad | E18: Base de Datos – Perfiles Generados – Informe del análisis | F18: Digital | G18: 11 | H18: 1 | I18: =IFERROR(H18/G18,0) -> 0.090909091 | J18: =+H18+SEPTIEMBRE!J18 -> 8 | K18: =IFERROR(J18/G18,0) -> 0.72727273
B19: 3 | C19: 3.17 | D19: Analizar data histórica de producción, productividad y daño por pozo | E19: Base de Datos - Informe de la Evaluación | F19: Digital | G19: 11 | H19: 1 | I19: =IFERROR(H19/G19,0) -> 0.090909091 | J19: =+H19+SEPTIEMBRE!J19 -> 9 | K19: =IFERROR(J19/G19,0) -> 0.81818182
B20: 3 | C20: 3.18 | D20: Generar perfiles de Producción por pozos para pozos existente en escenarios Bajo, Medio y Alto. | E20: Base de Datos – Informe de la Evaluación | F20: Digital | G20: 11 | H20: 1 | I20: =IFERROR(H20/G20,0) -> 0.090909091 | J20: =+H20+SEPTIEMBRE!J20 -> 8 | K20: =IFERROR(J20/G20,0) -> 0.72727273
B21: 5 | C21: 5.2 | D21: Generación de oportunidades de intervención a Pozos | E21: Base de Datos - Informe de la Evaluación | F21: Digital | G21: 11 | H21: 2 | I21: =IFERROR(H21/G21,0) -> 0.18181818 | J21: =+H21+SEPTIEMBRE!J21 -> 6 | K21: =IFERROR(J21/G21,0) -> 0.54545455
B22: 5 | C22: 5.3 | D22: Estimar restricciones de Presión y tasas para la generación de perfiles de producción | E22: Base de Datos – Informe de la Evaluación | F22: Digital | G22: 11 | H22: 1 | I22: =IFERROR(H22/G22,0) -> 0.090909091 | J22: =+H22+SEPTIEMBRE!J22 -> 8 | K22: =IFERROR(J22/G22,0) -> 0.72727273
B23: 5 | C23: 5.4 | D23: Generar modelo de Pozos | E23: Base de Datos – Informe de la Evaluación | F23: Digital | G23: 11 | H23: 2 | I23: =IFERROR(H23/G23,0) -> 0.18181818 | J23: =+H23+SEPTIEMBRE!J23 -> 8 | K23: =IFERROR(J23/G23,0) -> 0.72727273
B24: 5 | C24: 5.5 | D24: Adelantar la evaluación e interpretación de datos enfocada a candidatización de actividades de reacondicionamiento y optimización de productividad en los activos | E24: Base de Datos – Informe de la Evaluación | F24: Digital | G24: 11 | H24: 2 | I24: =IFERROR(H24/G24,0) -> 0.18181818 | J24: =+H24+SEPTIEMBRE!J24 -> 7 | K24: =IFERROR(J24/G24,0) -> 0.63636364
... B30: 5 | C30: 5.11 | D30: Generar los análisis asociados a la ejecución de estudios de daño de formación empleando simulación numérica (análisis nodal y single well model, análisis de aguas, análisis de crudos, entre otros) | E30: Base de Datos – Informe de la Evaluación | F30: Digital | G30: 11 | H30: 3 | I30: =IFERROR(H30/G30,0) -> 0.27272727 | J30: =+H30+SEPTIEMBRE!J30 -> 6 | K30: =IFERROR(J30/G30,0) -> 0.54545455
G31: =+CONCATENATE("TOTAL A ",D7) -> TOTAL A OCTUBRE | J31: TOTAL ACUMULADO
G32: =+SUM(G13:G30) -> 198 | H32: =+SUM(H13:H30) -> 30 | I32: =IFERROR(H32/G32,0) -> 0.15151515 | J32: =+SUM(J13:J30) -> 138 | K32: =IFERROR(J32/G32,0) -> 0.6969697
B34: Observaciones: | D34: Describa en este espacio su observación
B35: ¿Se presentó algún aspecto o situación que afecte la ejecución y calidad de los entregables? (Marque con una X)
B37: PROFESIONAL
B38: SI | D38: Describa en este espacio su observación
B39: NO
B40: ¿Se presentó algún aspecto o situación que afecte la ejecución y calidad de los entregables? (Marque con una X)
B42: INTERVENTOR O LIDER
B43: SI | D43: Describa en este espacio su observación
B44: NO
B48: Revisa: | G48: Interventor: | H48: Luisa Margarita Uribe Corrales
A95: MES
A96: ENERO
A97: FEBRERO
...

Sheet NOVIEMBRE
P1: MES
B2: REPORTE DE AVANCE | P2: ENERO
B3: Fecha: 29/06/2022 | E3: Version: 01 | I3: GP-F-23
P4: FEBRERO
B5: Código Orden de servicio | D5: 90227898 | P5: MARZO
P6: ABRIL
B7: Mes a reportar | D7: NOVIEMBRE | P7: JULIO
P8: AGOSTO
B9: Fecha reporte | D9: 45991 | P9: SEPTIEMBRE
P10: OCTUBRE
B11: Clasificación del servicio | H11: Reporte mes por servicio | J11: Reporte acumulado por servicio | P11: NOVIEMBRE
B12: Ítem general | C12: ítem actividad | D12: Descripción de la actividad | E12: Soporte | F12: Medio de entrega | G12: Días contratados | H12: Días | I12: % avance | J12: Días | K12: % avance | P12: DICIEMBRE
B13: 3 | C13: 3.6 | D13: Generar Modelo analítico del yacimiento integrando la información disponible en un software específico | E13: Modelo Analítico – Perfiles de Producción – Informe del modelo | F13: Digital | G13: 11 | H13: 1 | I13: =IFERROR(H13/G13,0) -> 0.090909091 | J13: =+H13+OCTUBRE!J13 -> 9 | K13: =IFERROR(J13/G13,0) -> 0.81818182
B14: 3 | C14: 3.11 | D14: Análisis e interpretación de datos de pruebas de presión-producción (DSTs, PBU, Pruebas Extendidas Producción, Gradientes Estáticos-Dinámicos PT, etc.) o de presión inyección (Inyectividad, SRT, FOT) aplicadas ya sea en tiempo real, memorizadas o con sarta temporal DST. Integración Probador Formación – Registros Open Hole. | E14: Informe del análisis por pozo o prueba | F14: Digital | G14: 11 | H14: 1 | I14: =IFERROR(H14/G14,0) -> 0.090909091 | J14: =+H14+OCTUBRE!J14 -> 9 | K14: =IFERROR(J14/G14,0) -> 0.81818182
B15: 3 | C15: 3.13 | D15: Generar base de datos de producción (OFM o la que se requiera) | E15: Base de Datos | F15: Digital | G15: 11 | H15: 1 | I15: =IFERROR(H15/G15,0) -> 0.090909091 | J15: =+H15+OCTUBRE!J15 -> 10 | K15: =IFERROR(J15/G15,0) -> 0.90909091
B16: 3 | C16: 3.14 | D16: Generar Distribución de Producción por sub- unidades (allocation) | E16: Base de Datos | F16: Digital | G16: 11 | H16: 2 | I16: =IFERROR(H16/G16,0) -> 0.18181818 | J16: =+H16+OCTUBRE!J16 -> 10 | K16: =IFERROR(J16/G16,0) -> 0.90909091
B17: 3 | C17: 3.15 | D17: Generar Balance de Materia por campo y/o por subunidad y/o por compartimiento | E17: Base de Datos - Modelo de Balance - Informe del modelo | F17: Digital | G17: 11 | H17: 3 | I17: =IFERROR(H17/G17,0) -> 0.27272727 | J17: =+H17+OCTUBRE!J17 -> 10 | K17: =IFERROR(J17/G17,0) -> 0.90909091
B18: 3 | C18: 3.16 | D18: Análisis de Declinaciones por pozo y/o subunidad | E18: Base de Datos – Perfiles Generados – Informe del análisis | F18: Digital | G18: 11 | H18: 1 | I18: =IFERROR(H18/G18,0) -> 0.090909091 | J18: =+H18+OCTUBRE!J18 -> 9 | K18: =IFERROR(J18/G18,0) -> 0.81818182
B19: 3 | C19: 3.17 | D19: Analizar data histórica de producción, productividad y daño por pozo | E19: Base de Datos - Informe de la Evaluación | F19: Digital | G19: 11 | H19: 1 | I19: =IFERROR(H19/G19,0) -> 0.090909091 | J19: =+H19+OCTUBRE!J19 -> 10 | K19: =IFERROR(J19/G19,0) -> 0.90909091
B20: 3 | C20: 3.18 | D20: Generar perfiles de Producción por pozos para pozos existente en escenarios Bajo, Medio y Alto. | E20: Base de Datos – Informe de la Evaluación | F20: Digital | G20: 11 | H20: 1 | I20: =IFERROR(H20/G20,0) -> 0.090909091 | J20: =+H20+OCTUBRE!J20 -> 9 | K20: =IFERROR(J20/G20,0) -> 0.81818182
B21: 5 | C21: 5.2 | D21: Generación de oportunidades de intervención a Pozos | E21: Base de Datos - Informe de la Evaluación | F21: Digital | G21: 11 | H21: 3 | I21: =IFERROR(H21/G21,0) -> 0.27272727 | J21: =+H21+OCTUBRE!J21 -> 9 | K21: =IFERROR(J21/G21,0) -> 0.81818182
B22: 5 | C22: 5.3 | D22: Estimar restricciones de Presión y tasas para la generación de perfiles de producción | E22: Base de Datos – Informe de la Evaluación | F22: Digital | G22: 11 | H22: 1 | I22: =IFERROR(H22/G22,0) -> 0.090909091 | J22: =+H22+OCTUBRE!J22 -> 9 | K22: =IFERROR(J22/G22,0) -> 0.81818182
B23: 5 | C23: 5.4 | D23: Generar modelo de Pozos | E23: Base de Datos – Informe de la Evaluación | F23: Digital | G23: 11 | H23: 1 | I23: =IFERROR(H23/G23,0) -> 0.090909091 | J23: =+H23+OCTUBRE!J23 -> 9 | K23: =IFERROR(J23/G23,0) -> 0.81818182
B24: 5 | C24: 5.5 | D24: Adelantar la evaluación e interpretación de datos enfocada a candidatización de actividades de reacondicionamiento y optimización de productividad en los activos | E24: Base de Datos – Informe de la Evaluación | F24: Digital | G24: 11 | H24: 2 | I24: =IFERROR(H24/G24,0) -> 0.18181818 | J24: =+H24+OCTUBRE!J24 -> 9 | K24: =IFERROR(J24/G24,0) -> 0.81818182
... B30: 5 | C30: 5.11 | D30: Generar los análisis asociados a la ejecución de estudios de daño de formación empleando simulación numérica (análisis nodal y single well model, análisis de aguas, análisis de crudos, entre otros) | E30: Base de Datos – Informe de la Evaluación | F30: Digital | G30: 11 | H30: 3 | I30: =IFERROR(H30/G30,0) -> 0.27272727 | J30: =+H30+OCTUBRE!J30 -> 9 | K30: =IFERROR(J30/G30,0) -> 0.81818182
G31: =+CONCATENATE("TOTAL A ",D7) -> TOTAL A NOVIEMBRE | J31: TOTAL ACUMULADO
G32: =+SUM(G13:G30) -> 198 | H32: =+SUM(H13:H30) -> 30 | I32: =IFERROR(H32/G32,0) -> 0.15151515 | J32: =+SUM(J13:J30) -> 168 | K32: =IFERROR(J32/G32,0) -> 0.84848485
B34: Observaciones: | D34: Describa en este espacio su observación
B35: ¿Se presentó algún aspecto o situación que afecte la ejecución y calidad de los entregables? (Marque con una X)
B37: PROFESIONAL
B38: SI | D38: Describa en este espacio su observación
B39: NO
B40: ¿Se presentó algún aspecto o situación que afecte la ejecución y calidad de los entregables? (Marque con una X)
B42: INTERVENTOR O LIDER
B43: SI | D43: Describa en este espacio su observación
B44: NO
B48: Revisa: | G48: Interventor: | H48: Luisa Margarita Uribe Corrales
A95: MES
A96: ENERO
A97: FEBRERO
...

Sheet DICIEMBRE
P1: MES
B2: REPORTE DE AVANCE | P2: ENERO
B3: Fecha: 29/06/2022 | E3: Version: 01 | I3: GP-F-23
P4: FEBRERO
B5: Código Orden de servicio | D5: 90227898 | P5: MARZO
P6: ABRIL
B7: Mes a reportar | D7: DICIEMBRE | P7: JULIO
P8: AGOSTO
B9: Fecha reporte | D9: 46022 | P9: SEPTIEMBRE
P10: OCTUBRE
B11: Clasificación del servicio | H11: Reporte mes por servicio | J11: Reporte acumulado por servicio | P11: NOVIEMBRE
B12: Ítem general | C12: ítem actividad | D12: Descripción de la actividad | E12: Soporte | F12: Medio de entrega | G12: Días contratados | H12: Días | I12: % avance | J12: Días | K12: % avance | P12: DICIEMBRE
B13: 3 | C13: 3.6 | D13: Generar Modelo analítico del yacimiento integrando la información disponible en un software específico | E13: Modelo Analítico – Perfiles de Producción – Informe del modelo | F13: Digital | G13: 11 | H13: 2 | I13: =IFERROR(H13/G13,0) -> 0.18181818 | J13: =+H13+NOVIEMBRE!J13 -> 11 | K13: =IFERROR(J13/G13,0) -> 1
B14: 3 | C14: 3.11 | D14: Análisis e interpretación de datos de pruebas de presión-producción (DSTs, PBU, Pruebas Extendidas Producción, Gradientes Estáticos-Dinámicos PT, etc.) o de presión inyección (Inyectividad, SRT, FOT) aplicadas ya sea en tiempo real, memorizadas o con sarta temporal DST. Integración Probador Formación – Registros Open Hole. | E14: Informe del análisis por pozo o prueba | F14: Digital | G14: 11 | H14: 2 | I14: =IFERROR(H14/G14,0) -> 0.18181818 | J14: =+H14+NOVIEMBRE!J14 -> 11 | K14: =IFERROR(J14/G14,0) -> 1
B15: 3 | C15: 3.13 | D15: Generar base de datos de producción (OFM o la que se requiera) | E15: Base de Datos | F15: Digital | G15: 11 | H15: 1 | I15: =IFERROR(H15/G15,0) -> 0.090909091 | J15: =+H15+NOVIEMBRE!J15 -> 11 | K15: =IFERROR(J15/G15,0) -> 1
B16: 3 | C16: 3.14 | D16: Generar Distribución de Producción por sub- unidades (allocation) | E16: Base de Datos | F16: Digital | G16: 11 | H16: 1 | I16: =IFERROR(H16/G16,0) -> 0.090909091 | J16: =+H16+NOVIEMBRE!J16 -> 11 | K16: =IFERROR(J16/G16,0) -> 1
B17: 3 | C17: 3.15 | D17: Generar Balance de Materia por campo y/o por subunidad y/o por compartimiento | E17: Base de Datos - Modelo de Balance - Informe del modelo | F17: Digital | G17: 11 | H17: 1 | I17: =IFERROR(H17/G17,0) -> 0.090909091 | J17: =+H17+NOVIEMBRE!J17 -> 11 | K17: =IFERROR(J17/G17,0) -> 1
B18: 3 | C18: 3.16 | D18: Análisis de Declinaciones por pozo y/o subunidad | E18: Base de Datos – Perfiles Generados – Informe del análisis | F18: Digital | G18: 11 | H18: 2 | I18: =IFERROR(H18/G18,0) -> 0.18181818 | J18: =+H18+NOVIEMBRE!J18 -> 11 | K18: =IFERROR(J18/G18,0) -> 1
B19: 3 | C19: 3.17 | D19: Analizar data histórica de producción, productividad y daño por pozo | E19: Base de Datos - Informe de la Evaluación | F19: Digital | G19: 11 | H19: 1 | I19: =IFERROR(H19/G19,0) -> 0.090909091 | J19: =+H19+NOVIEMBRE!J19 -> 11 | K19: =IFERROR(J19/G19,0) -> 1
B20: 3 | C20: 3.18 | D20: Generar perfiles de Producción por pozos para pozos existente en escenarios Bajo, Medio y Alto. | E20: Base de Datos – Informe de la Evaluación | F20: Digital | G20: 11 | H20: 2 | I20: =IFERROR(H20/G20,0) -> 0.18181818 | J20: =+H20+NOVIEMBRE!J20 -> 11 | K20: =IFERROR(J20/G20,0) -> 1
B21: 5 | C21: 5.2 | D21: Generación de oportunidades de intervención a Pozos | E21: Base de Datos - Informe de la Evaluación | F21: Digital | G21: 11 | H21: 2 | I21: =IFERROR(H21/G21,0) -> 0.18181818 | J21: =+H21+NOVIEMBRE!J21 -> 11 | K21: =IFERROR(J21/G21,0) -> 1
B22: 5 | C22: 5.3 | D22: Estimar restricciones de Presión y tasas para la generación de perfiles de producción | E22: Base de Datos – Informe de la Evaluación | F22: Digital | G22: 11 | H22: 2 | I22: =IFERROR(H22/G22,0) -> 0.18181818 | J22: =+H22+NOVIEMBRE!J22 -> 11 | K22: =IFERROR(J22/G22,0) -> 1
B23: 5 | C23: 5.4 | D23: Generar modelo de Pozos | E23: Base de Datos – Informe de la Evaluación | F23: Digital | G23: 11 | H23: 2 | I23: =IFERROR(H23/G23,0) -> 0.18181818 | J23: =+H23+NOVIEMBRE!J23 -> 11 | K23: =IFERROR(J23/G23,0) -> 1
B24: 5 | C24: 5.5 | D24: Adelantar la evaluación e interpretación de datos enfocada a candidatización de actividades de reacondicionamiento y optimización de productividad en los activos | E24: Base de Datos – Informe de la Evaluación | F24: Digital | G24: 11 | H24: 2 | I24: =IFERROR(H24/G24,0) -> 0.18181818 | J24: =+H24+NOVIEMBRE!J24 -> 11 | K24: =IFERROR(J24/G24,0) -> 1
... B30: 5 | C30: 5.11 | D30: Generar los análisis asociados a la ejecución de estudios de daño de formación empleando simulación numérica (análisis nodal y single well model, análisis de aguas, análisis de crudos, entre otros) | E30: Base de Datos – Informe de la Evaluación | F30: Digital | G30: 11 | H30: 2 | I30: =IFERROR(H30/G30,0) -> 0.18181818 | J30: =+H30+NOVIEMBRE!J30 -> 11 | K30: =IFERROR(J30/G30,0) -> 1
G31: =+CONCATENATE("TOTAL A ",D7) -> TOTAL A DICIEMBRE | J31: TOTAL ACUMULADO
G32: =+SUM(G13:G30) -> 198 | H32: =+SUM(H13:H30) -> 30 | I32: =IFERROR(H32/G32,0) -> 0.15151515 | J32: =+SUM(J13:J30) -> 198 | K32: =IFERROR(J32/G32,0) -> 1
B34: Observaciones: | D34: Describa en este espacio su observación
B35: ¿Se presentó algún aspecto o situación que afecte la ejecución y calidad de los entregables? (Marque con una X)
B37: PROFESIONAL
B38: SI | D38: Describa en este espacio su observación
B39: NO
B40: ¿Se presentó algún aspecto o situación que afecte la ejecución y calidad de los entregables? (Marque con una X)
B42: INTERVENTOR O LIDER
B43: SI | D43: Describa en este espacio su observación
B44: NO
B48: Revisa: | G48: Interventor: | H48: Luisa Margarita Uribe Corrales
A95: MES
A96: ENERO
A97: FEBRERO
...

Sheet ENERO 2026
P1: MES
B2: REPORTE DE AVANCE | P2: ENERO
B3: Fecha: 29/06/2022 | E3: Version: 01 | I3: GP-F-23
P4: FEBRERO
B5: Código Orden de servicio | D5: 90227898 | P5: MARZO
P6: ABRIL
B7: Mes a reportar | D7: ENERO | P7: JULIO
P8: AGOSTO
B9: Fecha reporte | D9: 46053 | P9: SEPTIEMBRE
P10: OCTUBRE
B11: Clasificación del servicio | H11: Reporte mes por servicio | J11: Reporte acumulado por servicio | P11: NOVIEMBRE
B12: Ítem general | C12: ítem actividad | D12: Descripción de la actividad | E12: Soporte | F12: Medio de entrega | G12: Días contratados | H12: Días | I12: % avance | J12: Días | K12: % avance | P12: DICIEMBRE
B13: 3 | C13: 3.6 | D13: Generar Modelo analítico del yacimiento integrando la información disponible en un software específico | E13: Modelo Analítico – Perfiles de Producción – Informe del modelo | F13: Digital | G13: 16 | H13: 1 | I13: =IFERROR(H13/G13,0) -> 0.0625 | J13: =+H13+DICIEMBRE!J13 -> 12 | K13: =IFERROR(J13/G13,0) -> 0.75
B14: 3 | C14: 3.11 | D14: Análisis e interpretación de datos de pruebas de presión-producción (DSTs, PBU, Pruebas Extendidas Producción, Gradientes Estáticos-Dinámicos PT, etc.) o de presión inyección (Inyectividad, SRT, FOT) aplicadas ya sea en tiempo real, memorizadas o con sarta temporal DST. Integración Probador Formación – Registros Open Hole. | E14: Informe del análisis por pozo o prueba | F14: Digital | G14: 16 | H14: 1 | I14: =IFERROR(H14/G14,0) -> 0.0625 | J14: =+H14+DICIEMBRE!J14 -> 12 | K14: =IFERROR(J14/G14,0) -> 0.75
B15: 3 | C15: 3.13 | D15: Generar base de datos de producción (OFM o la que se requiera) | E15: Base de Datos | F15: Digital | G15: 16 | H15: 1 | I15: =IFERROR(H15/G15,0) -> 0.0625 | J15: =+H15+DICIEMBRE!J15 -> 12 | K15: =IFERROR(J15/G15,0) -> 0.75
B16: 3 | C16: 3.14 | D16: Generar Distribución de Producción por sub- unidades (allocation) | E16: Base de Datos | F16: Digital | G16: 16 | H16: 2 | I16: =IFERROR(H16/G16,0) -> 0.125 | J16: =+H16+DICIEMBRE!J16 -> 13 | K16: =IFERROR(J16/G16,0) -> 0.8125
B17: 3 | C17: 3.15 | D17: Generar Balance de Materia por campo y/o por subunidad y/o por compartimiento | E17: Base de Datos - Modelo de Balance - Informe del modelo | F17: Digital | G17: 16 | H17: 3 | I17: =IFERROR(H17/G17,0) -> 0.1875 | J17: =+H17+DICIEMBRE!J17 -> 14 | K17: =IFERROR(J17/G17,0) -> 0.875
B18: 3 | C18: 3.16 | D18: Análisis de Declinaciones por pozo y/o subunidad | E18: Base de Datos – Perfiles Generados – Informe del análisis | F18: Digital | G18: 16 | H18: 1 | I18: =IFERROR(H18/G18,0) -> 0.0625 | J18: =+H18+DICIEMBRE!J18 -> 12 | K18: =IFERROR(J18/G18,0) -> 0.75
B19: 3 | C19: 3.17 | D19: Analizar data histórica de producción, productividad y daño por pozo | E19: Base de Datos - Informe de la Evaluación | F19: Digital | G19: 16 | H19: 1 | I19: =IFERROR(H19/G19,0) -> 0.0625 | J19: =+H19+DICIEMBRE!J19 -> 12 | K19: =IFERROR(J19/G19,0) -> 0.75
B20: 3 | C20: 3.18 | D20: Generar perfiles de Producción por pozos para pozos existente en escenarios Bajo, Medio y Alto. | E20: Base de Datos – Informe de la Evaluación | F20: Digital | G20: 16 | H20: 1 | I20: =IFERROR(H20/G20,0) -> 0.0625 | J20: =+H20+DICIEMBRE!J20 -> 12 | K20: =IFERROR(J20/G20,0) -> 0.75
B21: 5 | C21: 5.2 | D21: Generación de oportunidades de intervención a Pozos | E21: Base de Datos - Informe de la Evaluación | F21: Digital | G21: 16 | H21: 3 | I21: =IFERROR(H21/G21,0) -> 0.1875 | J21: =+H21+DICIEMBRE!J21 -> 14 | K21: =IFERROR(J21/G21,0) -> 0.875
B22: 5 | C22: 5.3 | D22: Estimar restricciones de Presión y tasas para la generación de perfiles de producción | E22: Base de Datos – Informe de la Evaluación | F22: Digital | G22: 16 | H22: 1 | I22: =IFERROR(H22/G22,0) -> 0.0625 | J22: =+H22+DICIEMBRE!J22 -> 12 | K22: =IFERROR(J22/G22,0) -> 0.75
B23: 5 | C23: 5.4 | D23: Generar modelo de Pozos | E23: Base de Datos – Informe de la Evaluación | F23: Digital | G23: 16 | H23: 1 | I23: =IFERROR(H23/G23,0) -> 0.0625 | J23: =+H23+DICIEMBRE!J23 -> 12 | K23: =IFERROR(J23/G23,0) -> 0.75
B24: 5 | C24: 5.5 | D24: Adelantar la evaluación e interpretación de datos enfocada a candidatización de actividades de reacondicionamiento y optimización de productividad en los activos | E24: Base de Datos – Informe de la Evaluación | F24: Digital | G24: 16 | H24: 2 | I24: =IFERROR(H24/G24,0) -> 0.125 | J24: =+H24+DICIEMBRE!J24 -> 13 | K24: =IFERROR(J24/G24,0) -> 0.8125
... B30: 5 | C30: 5.11 | D30: Generar los análisis asociados a la ejecución de estudios de daño de formación empleando simulación numérica (análisis nodal y single well model, análisis de aguas, análisis de crudos, entre otros) | E30: Base de Datos – Informe de la Evaluación | F30: Digital | G30: 16 | H30: 3 | I30: =IFERROR(H30/G30,0) -> 0.1875 | J30: =+H30+DICIEMBRE!J30 -> 14 | K30: =IFERROR(J30/G30,0) -> 0.875
G31: =+CONCATENATE("TOTAL A ",D7) -> TOTAL A ENERO | J31: TOTAL ACUMULADO
G32: =+SUM(G13:G30) -> 288 | H32: =+SUM(H13:H30) -> 30 | I32: =IFERROR(H32/G32,0) -> 0.10416667 | J32: =+SUM(J13:J30) -> 228 | K32: =IFERROR(J32/G32,0) -> 0.79166667
B34: Observaciones: | D34: Describa en este espacio su observación
B35: ¿Se presentó algún aspecto o situación que afecte la ejecución y calidad de los entregables? (Marque con una X)
B37: PROFESIONAL
B38: SI | D38: Describa en este espacio su observación
B39: NO
B40: ¿Se presentó algún aspecto o situación que afecte la ejecución y calidad de los entregables? (Marque con una X)
B42: INTERVENTOR O LIDER
B43: SI | D43: Describa en este espacio su observación
B44: NO
B48: Revisa: | G48: Interventor: | H48: Luisa Margarita Uribe Corrales
A95: MES
A96: ENERO
A97: FEBRERO
...

Sheet FEBRERO 2026
P1: MES
B2: REPORTE DE AVANCE | P2: ENERO
B3: Fecha: 29/06/2022 | E3: Version: 01 | I3: GP-F-23
P4: FEBRERO
B5: Código Orden de servicio | D5: 90227898 | P5: MARZO
P6: ABRIL
B7: Mes a reportar | D7: FEBRERO | P7: JULIO
P8: AGOSTO
B9: Fecha reporte | D9: 46081 | P9: SEPTIEMBRE
P10: OCTUBRE
B11: Clasificación del servicio | H11: Reporte mes por servicio | J11: Reporte acumulado por servicio | P11: NOVIEMBRE
B12: Ítem general | C12: ítem actividad | D12: Descripción de la actividad | E12: Soporte | F12: Medio de entrega | G12: Días contratados | H12: Días | I12: % avance | J12: Días | K12: % avance | P12: DICIEMBRE
B13: 3 | C13: 3.6 | D13: Generar Modelo analítico del yacimiento integrando la información disponible en un software específico | E13: Modelo Analítico – Perfiles de Producción – Informe del modelo | F13: Digital | G13: 16 | H13: 2 | I13: =IFERROR(H13/G13,0) -> 0.125 | J13: =+H13+'ENERO 2026'!J13 -> 14 | K13: =IFERROR(J13/G13,0) -> 0.875
B14: 3 | C14: 3.11 | D14: Análisis e interpretación de datos de pruebas de presión-producción (DSTs, PBU, Pruebas Extendidas Producción, Gradientes Estáticos-Dinámicos PT, etc.) o de presión inyección (Inyectividad, SRT, FOT) aplicadas ya sea en tiempo real, memorizadas o con sarta temporal DST. Integración Probador Formación – Registros Open Hole. | E14: Informe del análisis por pozo o prueba | F14: Digital | G14: 16 | H14: 2 | I14: =IFERROR(H14/G14,0) -> 0.125 | J14: =+H14+'ENERO 2026'!J14 -> 14 | K14: =IFERROR(J14/G14,0) -> 0.875
B15: 3 | C15: 3.13 | D15: Generar base de datos de producción (OFM o la que se requiera) | E15: Base de Datos | F15: Digital | G15: 16 | H15: 2 | I15: =IFERROR(H15/G15,0) -> 0.125 | J15: =+H15+'ENERO 2026'!J15 -> 14 | K15: =IFERROR(J15/G15,0) -> 0.875
B16: 3 | C16: 3.14 | D16: Generar Distribución de Producción por sub- unidades (allocation) | E16: Base de Datos | F16: Digital | G16: 16 | H16: 2 | I16: =IFERROR(H16/G16,0) -> 0.125 | J16: =+H16+'ENERO 2026'!J16 -> 15 | K16: =IFERROR(J16/G16,0) -> 0.9375
B17: 3 | C17: 3.15 | D17: Generar Balance de Materia por campo y/o por subunidad y/o por compartimiento | E17: Base de Datos - Modelo de Balance - Informe del modelo | F17: Digital | G17: 16 | H17: 1 | I17: =IFERROR(H17/G17,0) -> 0.0625 | J17: =+H17+'ENERO 2026'!J17 -> 15 | K17: =IFERROR(J17/G17,0) -> 0.9375
B18: 3 | C18: 3.16 | D18: Análisis de Declinaciones por pozo y/o subunidad | E18: Base de Datos – Perfiles Generados – Informe del análisis | F18: Digital | G18: 16 | H18: 2 | I18: =IFERROR(H18/G18,0) -> 0.125 | J18: =+H18+'ENERO 2026'!J18 -> 14 | K18: =IFERROR(J18/G18,0) -> 0.875
B19: 3 | C19: 3.17 | D19: Analizar data histórica de producción, productividad y daño por pozo | E19: Base de Datos - Informe de la Evaluación | F19: Digital | G19: 16 | H19: 1 | I19: =IFERROR(H19/G19,0) -> 0.0625 | J19: =+H19+'ENERO 2026'!J19 -> 13 | K19: =IFERROR(J19/G19,0) -> 0.8125
B20: 3 | C20: 3.18 | D20: Generar perfiles de Producción por pozos para pozos existente en escenarios Bajo, Medio y Alto. | E20: Base de Datos – Informe de la Evaluación | F20: Digital | G20: 16 | H20: 2 | I20: =IFERROR(H20/G20,0) -> 0.125 | J20: =+H20+'ENERO 2026'!J20 -> 14 | K20: =IFERROR(J20/G20,0) -> 0.875
B21: 5 | C21: 5.2 | D21: Generación de oportunidades de intervención a Pozos | E21: Base de Datos - Informe de la Evaluación | F21: Digital | G21: 16 | H21: 1 | I21: =IFERROR(H21/G21,0) -> 0.0625 | J21: =+H21+'ENERO 2026'!J21 -> 15 | K21: =IFERROR(J21/G21,0) -> 0.9375
B22: 5 | C22: 5.3 | D22: Estimar restricciones de Presión y tasas para la generación de perfiles de producción | E22: Base de Datos – Informe de la Evaluación | F22: Digital | G22: 16 | H22: 2 | I22: =IFERROR(H22/G22,0) -> 0.125 | J22: =+H22+'ENERO 2026'!J22 -> 14 | K22: =IFERROR(J22/G22,0) -> 0.875
B23: 5 | C23: 5.4 | D23: Generar modelo de Pozos | E23: Base de Datos – Informe de la Evaluación | F23: Digital | G23: 16 | H23: 2 | I23: =IFERROR(H23/G23,0) -> 0.125 | J23: =+H23+'ENERO 2026'!J23 -> 14 | K23: =IFERROR(J23/G23,0) -> 0.875
B24: 5 | C24: 5.5 | D24: Adelantar la evaluación e interpretación de datos enfocada a candidatización de actividades de reacondicionamiento y optimización de productividad en los activos | E24: Base de Datos – Informe de la Evaluación | F24: Digital | G24: 16 | H24: 2 | I24: =IFERROR(H24/G24,0) -> 0.125 | J24: =+H24+'ENERO 2026'!J24 -> 15 | K24: =IFERROR(J24/G24,0) -> 0.9375
... B30: 5 | C30: 5.11 | D30: Generar los análisis asociados a la ejecución de estudios de daño de formación empleando simulación numérica (análisis nodal y single well model, análisis de aguas, análisis de crudos, entre otros) | E30: Base de Datos – Informe de la Evaluación | F30: Digital | G30: 16 | H30: 1 | I30: =IFERROR(H30/G30,0) -> 0.0625 | J30: =+H30+'ENERO 2026'!J30 -> 15 | K30: =IFERROR(J30/G30,0) -> 0.9375
G31: =+CONCATENATE("TOTAL A ",D7) -> TOTAL A FEBRERO | J31: TOTAL ACUMULADO
G32: =+SUM(G13:G30) -> 288 | H32: =+SUM(H13:H30) -> 30 | I32: =IFERROR(H32/G32,0) -> 0.10416667 | J32: =+SUM(J13:J30) -> 258 | K32: =IFERROR(J32/G32,0) -> 0.89583333
B34: Observaciones: | D34: Describa en este espacio su observación
B35: ¿Se presentó algún aspecto o situación que afecte la ejecución y calidad de los entregables? (Marque con una X)
B37: PROFESIONAL
B38: SI | D38: Describa en este espacio su observación
B39: NO
B40: ¿Se presentó algún aspecto o situación que afecte la ejecución y calidad de los entregables? (Marque con una X)
B42: INTERVENTOR O LIDER
B43: SI | D43: Describa en este espacio su observación
B44: NO
B48: Revisa: | G48: Interventor: | H48: Luisa Margarita Uribe Corrales
A95: MES
A96: ENERO
A97: FEBRERO
...
