Workbook

Sheet ENERO 2026
R1: MES
B2: REPORTE DE AVANCE | R2: ENERO
B3: Fecha: 29/06/2022 | G3: Version: 01 | K3: GP-F-23
R4: FEBRERO
B5: Código Orden de servicio | D5: 90598918 | R5: MARZO
R6: JUNIO
B7: Mes a reportar | D7: ENERO | R7: JULIO
R8: AGOSTO
B9: Fecha reporte | D9: 46053 | R9: SEPTIEMBRE
R10: OCTUBRE
B11: Clasificación del servicio | J11: Reporte mes por servicio | L11: Reporte acumulado por servicio | R11: NOVIEMBRE
B12: Ítem general | C12: ítem actividad | D12: Descripción de la actividad | E12: Profesional a cargo | F12: Nivel contratado | G12: Soporte | H12: Medio de entrega | I12: Días contratados Acta de Inicio | J12: Días | K12: % avance | L12: Días | M12: % avance | R12: DICIEMBRE
B13: 1 | C13: 1.1 | D13: Generar Modelo Estático del yacimiento integrando la información disponible. | E13: Jesus David Arenas Navarro | F13: Junior | G13: Modelo Estático - Informe de Modelo - Cálculo de Volúmenes in Place | H13: Digital | I13: 25 | J13: 3 | K13: =IFERROR(J13/I13,0) -> 0.12 | L13: =J13 -> 3 | M13: =IFERROR(L13/I13,0) -> 0.12
B14: 1 | C14: 1.15 | D14: Carga de información para poblar el modelo geocelular (direccionales, coordenadas, surveys, topes, data de presión, estados mecánicos, evento de pozos, etc.) | G14: Modelo poblado | H14: Digital | I14: 25 | J14: 3 | K14: =IFERROR(J14/I14,0) -> 0.12 | L14: =J14 -> 3 | M14: =IFERROR(L14/I14,0) -> 0.12
B15: 1 | C15: 1.16 | D15: Georeferenciación de Mapas, pozos, Imágenes satélite, etc. y Definición de CRS (Cordinates Reference System) | G15: Información georeferenciada | H15: Digital | I15: 25 | J15: 3 | K15: =IFERROR(J15/I15,0) -> 0.12 | L15: =J15 -> 3 | M15: =IFERROR(L15/I15,0) -> 0.12
B16: 1 | C16: 1.17 | D16: Calculo probabilístico de Volúmenes In situ. | G16: Calculo Volumétrico - Bases de Datos | H16: Digital | I16: 25 | J16: 3 | K16: =IFERROR(J16/I16,0) -> 0.12 | L16: =J16 -> 3 | M16: =IFERROR(L16/I16,0) -> 0.12
B17: 1 | C17: 1.24 | D17: Caracterización composicional de fluidos de hidrocarburos mediante técnicas geoquímicas. | G17: - | H17: - | I17: 25 | J17: 0 | K17: =IFERROR(J17/I17,0) -> 0 | L17: =J17 -> 0 | M17: =IFERROR(L17/I17,0) -> 0
B18: 1 | C18: 1.25 | D18: Análisis geoquímicos de Fingerprinting | G18: - | H18: - | I18: 25 | J18: 0 | K18: =IFERROR(J18/I18,0) -> 0 | L18: =J18 -> 0 | M18: =IFERROR(L18/I18,0) -> 0
B19: 1 | C19: 1.26 | D19: Análisis e interpretación de imágenes de satélite | G19: - | H19: - | I19: 25 | J19: 0 | K19: =IFERROR(J19/I19,0) -> 0 | L19: =J19 -> 0 | M19: =IFERROR(L19/I19,0) -> 0
B20: 2 | C20: 2.5 | D20: Realizar caracterización Scal (interpretación) | G20: Informe | H20: Digital | I20: 25 | J20: 3 | K20: =IFERROR(J20/I20,0) -> 0.12 | L20: =J20 -> 3 | M20: =IFERROR(L20/I20,0) -> 0.12
B21: 2 | C21: 2.11 | D21: Generación de Modelos de Física de Rocas | G21: - | H21: - | I21: 25 | J21: 0 | K21: =IFERROR(J21/I21,0) -> 0 | L21: =J21 -> 0 | M21: =IFERROR(L21/I21,0) -> 0
B22: 8 | C22: 8.1 | D22: Revisión bibliográfica de modelos / metodologías y sus aplicaciones existentes, así como refinación de objetivos si procede. | E22: Jorge Felipe Alarcon Torres | F22: Junior | G22: Informe | H22: Digital | I22: 37 | J22: 2 | K22: =IFERROR(J22/I22,0) -> 0.054054054 | L22: =J22 -> 2 | M22: =IFERROR(L22/I22,0) -> 0.054054054
B23: 8 | C23: 8.2 | D23: Carga de datos, procesamiento de datos, Análisis Estadístico descriptivo considerando hipótesis desde la teoría, y análisis descriptivo considerando hipótesis generadas desde la misma data (pasos 1, 2 y 3 teoría CRISP-DM). | G23: Informe, con estadísticas descriptivas, histogramas, pruebas de ajuste, etc. | H23: Digital | I23: 37 | J23: 3 | K23: =IFERROR(J23/I23,0) -> 0.081081081 | L23: =J23 -> 3 | M23: =IFERROR(L23/I23,0) -> 0.081081081
B24: 8 | C24: 8.3 | D24: Construcción de modelo matemático utilizando las técnicas pertinentes de Ciencia de Datos (e.g. Programación Matemática / Optimización / Investigación de Operaciones, Modelamiento Probabilístico, Machine Learning, etc.), con dominio de conocimiento petrotecnico. Si el modelo es supervisado y no paramétrico, se debe generar el sustento y razonamiento respectivo, arquitectura, calibración de parámetros adecuado, pruebas de validación, generalización, desempeño, etc. La fase de modelamiento debe incluir el razonamiento del modelo y como se relaciona con los modelos petrotecnicos convencionales o actuales, en que difiere y cuál es su innovación en términos de analítica de datos. Lo anterior | G24: Formulación matemática, razonamientos, seudocódigo, definiciones, supuestos, pruebas estadísticas, pruebas de generalización, etc. | H24: Digital | I24: 37 | J24: 2 | K24: =IFERROR(J24/I24,0) -> 0.054054054 | L24: =J24 -> 2 | M24: =IFERROR(L24/I24,0) -> 0.054054054
B25: 8 | C25: 8.4 | D25: Análisis de resultados y análisis Estadístico - descriptivo de los resultados obtenidos, así como de las pruebas implementadas. Ejemplificación de la interpretación de resultados y auto-critica de los mismos. Mapeo de conclusiones, recomendaciones y validación de los objetivos con enfoque de valor. Es clave generar nociones para que los resultados puedan ser bien utilizados y/o asociados con otras metodologías. Si procede, se debe validar los resultados con los expertos o dolientes respectivos. Etapa 5 de la metodología CRISP- DM. | G25: Informe y/o presentación | H25: Digital | I25: 38 | J25: 2 | K25: =IFERROR(J25/I25,0) -> 0.052631579 | L25: =J25 -> 2 | M25: =IFERROR(L25/I25,0) -> 0.052631579
B26: 8 | C26: 8.5 | D26: Programación del modelo matemático en las herramientas que se considere más adecuada, e.g. R, Python, SAS, C++, Java, Matlab, Visual, etc. Los scripts deben respetar los planteamientos y consideraciones contenidas en el informe, debe contener buenas prácticas de programación (e.g. comentarios, identación (anglicismo de “identation”), separación por métodos o funciones, etc. – el programa no necesariamente debe estar orientado a objetos y otros paradigmas, e.g. la programación funcional podría ser altamente recomendable). | G26: Código. | H26: Digital | I26: 38 | J26: 3 | K26: =IFERROR(J26/I26,0) -> 0.078947368 | L26: =J26 -> 3 | M26: =IFERROR(L26/I26,0) -> 0.078947368
B27: 8 | C27: 8.6 | D27: Diseño modelo de datos "satélite" para el modelo matemático o la metodología aplicada. Si es el caso, se debe implementar la base de datos, e.g. en SQL. Adicionalmente, si es el caso, revisión del flujo de información respecto a procesos y actividades, así como de posibles fuentes de error en las mediciones o captura de la data. También, de aplicar, un análisis del error acumulado que se pueda estar generando antes de alimentar el modelo o metodología propuesta con la data. | G27: Documentación del modelo de datos (E.g. diagrama relacional), definiciones, diccionarios, relaciones. | H27: Digital | I27: 38 | J27: 3 | K27: =IFERROR(J27/I27,0) -> 0.078947368 | L27: =J27 -> 3 | M27: =IFERROR(L27/I27,0) -> 0.078947368
B28: 8 | C28: 8.1 | D28: Revisión bibliográfica de modelos / metodologías y sus aplicaciones existentes, así como refinación de objetivos si procede. | E28: Oscar Ivan Jimenez Barandica | F28: Junior | G28: Informe | H28: Documento: https://ecopetrol.sharepoint.com/:w:/s/vde/get/IQCJGX51Kg7mSpPiZhl1_-jCAb39voiLO1z7cqcxzk0aqys?email=jhonfr.gonzalez%40ecopetrol.com.co&e=FLO6eU | I28: 30 | J28: 5 | K28: =IFERROR(J28/I28,0) -> 0.16666667 | L28: =J28 -> 5 | M28: =IFERROR(L28/I28,0) -> 0.16666667
B29: 8 | C29: 8.2 | D29: Carga de datos, procesamiento de datos, Análisis Estadístico descriptivo considerando hipótesis desde la teoría, y análisis descriptivo considerando hipótesis generadas desde la misma data (pasos 1, 2 y 3 teoría CRISP-DM). | G29: Informe, con estadísticas descriptivas, histogramas, pruebas de ajuste, etc. | H29: Carpeta: https://ecopetrol.sharepoint.com/:u:/s/vde/get/IQCOq_mKpPMTT6rU8OdRuOlaAfLBNKQDI3-j9sz-QO90zLw?email=jhonfr.gonzalez%40ecopetrol.com.co&e=H1thvC | I29: 30 | J29: 5 | K29: =IFERROR(J29/I29,0) -> 0.16666667 | L29: =J29 -> 5 | M29: =IFERROR(L29/I29,0) -> 0.16666667
B30: 8 | C30: 8.3 | D30: Construcción de modelo matemático utilizando las técnicas pertinentes de Ciencia de Datos (e.g. Programación Matemática / Optimización / Investigación de Operaciones, Modelamiento Probabilístico, Machine Learning, etc.), con dominio de conocimiento petrotecnico. Si el modelo es supervisado y no paramétrico, se debe generar el sustento y razonamiento respectivo, arquitectura, calibración de parámetros adecuado, pruebas de validación, generalización, desempeño, etc. La fase de modelamiento debe incluir el razonamiento del modelo y como se relaciona con los modelos petrotecnicos convencionales o actuales, en que difiere y cuál es su innovación en términos de analítica de datos. Lo anterior | G30: Formulación matemática, razonamientos, seudocódigo, definiciones, supuestos, pruebas estadísticas, pruebas de generalización, etc. | H30: Codigo: https://ecopetrol.sharepoint.com/:u:/s/vde/get/IQDB0O3kMc02RIGx7y_FEMvDATbak4CrloJVQgfgrhTqqWk?email=jhonfr.gonzalez%40ecopetrol.com.co&e=cwWTuf | I30: 60 | J30: 5 | K30: =IFERROR(J30/I30,0) -> 0.083333333 | L30: =J30 -> 5 | M30: =IFERROR(L30/I30,0) -> 0.083333333
B31: 8 | C31: 8.4 | D31: Análisis de resultados y análisis Estadístico - descriptivo de los resultados obtenidos, así como de las pruebas implementadas. Ejemplificación de la interpretación de resultados y auto-critica de los mismos. Mapeo de conclusiones, recomendaciones y validación de los objetivos con enfoque de valor. Es clave generar nociones para que los resultados puedan ser bien utilizados y/o asociados con otras metodologías. Si procede, se debe validar los resultados con los expertos o dolientes respectivos. Etapa 5 de la metodología CRISP- DM. | G31: - | H31: - | I31: 30 | J31: 0 | K31: =IFERROR(J31/I31,0) -> 0 | L31: =J31 -> 0 | M31: =IFERROR(L31/I31,0) -> 0
B32: 8 | C32: 8.5 | D32: Programación del modelo matemático en las herramientas que se considere más adecuada, e.g. R, Python, SAS, C++, Java, Matlab, Visual, etc. Los scripts deben respetar los planteamientos y consideraciones contenidas en el informe, debe contener buenas prácticas de programación (e.g. comentarios, identación (anglicismo de “identation”), separación por métodos o funciones, etc. – el programa no necesariamente debe estar orientado a objetos y otros paradigmas, e.g. la programación funcional podría ser altamente recomendable). | G32: - | H32: - | I32: 45 | J32: 0 | K32: =IFERROR(J32/I32,0) -> 0 | L32: =J32 -> 0 | M32: =IFERROR(L32/I32,0) -> 0
B33: 8 | C33: 8.6 | D33: Diseño modelo de datos "satélite" para el modelo matemático o la metodología aplicada. Si es el caso, se debe implementar la base de datos, e.g. en SQL. Adicionalmente, si es el caso, revisión del flujo de información respecto a procesos y actividades, así como de posibles fuentes de error en las mediciones o captura de la data. También, de aplicar, un análisis del error acumulado que se pueda estar generando antes de alimentar el modelo o metodología propuesta con la data. | G33: - | H33: - | I33: 30 | J33: 0 | K33: =IFERROR(J33/I33,0) -> 0 | L33: =J33 -> 0 | M33: =IFERROR(L33/I33,0) -> 0
B34: 8 | C34: 8.1 | D34: Revisión bibliográfica de modelos / metodologías y sus aplicaciones existentes, así como refinación de objetivos si procede. | E34: Alejandra Arbelaez Londoño | F34: Senior | G34: Informe | H34: Digital | I34: 45 | J34: 8 | K34: =IFERROR(J34/I34,0) -> 0.17777778 | L34: =J34 -> 8 | M34: =IFERROR(L34/I34,0) -> 0.17777778
B35: 8 | C35: 8.2 | D35: Carga de datos, procesamiento de datos, Análisis Estadístico descriptivo considerando hipótesis desde la teoría, y análisis descriptivo considerando hipótesis generadas desde la misma data (pasos 1, 2 y 3 teoría CRISP-DM). | G35: - | H35: - | I35: 40 | J35: 0 | K35: =IFERROR(J35/I35,0) -> 0 | L35: =J35 -> 0 | M35: =IFERROR(L35/I35,0) -> 0
B36: 8 | C36: 8.3 | D36: Construcción de modelo matemático utilizando las técnicas pertinentes de Ciencia de Datos (e.g. Programación Matemática / Optimización / Investigación de Operaciones, Modelamiento Probabilístico, Machine Learning, etc.), con dominio de conocimiento petrotecnico. Si el modelo es supervisado y no paramétrico, se debe generar el sustento y razonamiento respectivo, arquitectura, calibración de parámetros adecuado, pruebas de validación, generalización, desempeño, etc. La fase de modelamiento debe incluir el razonamiento del modelo y como se relaciona con los modelos petrotecnicos convencionales o actuales, en que difiere y cuál es su innovación en términos de analítica de datos. Lo anterior | G36: Formulación matemática, razonamientos, seudocódigo, definiciones, supuestos, pruebas estadísticas, pruebas de generalización, etc. | H36: Digital | I36: 40 | J36: 7 | K36: =IFERROR(J36/I36,0) -> 0.175 | L36: =J36 -> 7 | M36: =IFERROR(L36/I36,0) -> 0.175
B37: 8 | C37: 8.4 | D37: Análisis de resultados y análisis Estadístico - descriptivo de los resultados obtenidos, así como de las pruebas implementadas. Ejemplificación de la interpretación de resultados y auto-critica de los mismos. Mapeo de conclusiones, recomendaciones y validación de los objetivos con enfoque de valor. Es clave generar nociones para que los resultados puedan ser bien utilizados y/o asociados con otras metodologías. Si procede, se debe validar los resultados con los expertos o dolientes respectivos. Etapa 5 de la metodología CRISP- DM. | G37: - | H37: - | I37: 40 | J37: 0 | K37: =IFERROR(J37/I37,0) -> 0 | L37: =J37 -> 0 | M37: =IFERROR(L37/I37,0) -> 0
B38: 8 | C38: 8.5 | D38: Programación del modelo matemático en las herramientas que se considere más adecuada, e.g. R, Python, SAS, C++, Java, Matlab, Visual, etc. Los scripts deben respetar los planteamientos y consideraciones contenidas en el informe, debe contener buenas prácticas de programación (e.g. comentarios, identación (anglicismo de “identation”), separación por métodos o funciones, etc. – el programa no necesariamente debe estar orientado a objetos y otros paradigmas, e.g. la programación funcional podría ser altamente recomendable). | G38: - | H38: - | I38: 40 | J38: 0 | K38: =IFERROR(J38/I38,0) -> 0 | L38: =J38 -> 0 | M38: =IFERROR(L38/I38,0) -> 0
B39: 8 | C39: 8.6 | D39: Diseño modelo de datos "satélite" para el modelo matemático o la metodología aplicada. Si es el caso, se debe implementar la base de datos, e.g. en SQL. Adicionalmente, si es el caso, revisión del flujo de información respecto a procesos y actividades, así como de posibles fuentes de error en las mediciones o captura de la data. También, de aplicar, un análisis del error acumulado que se pueda estar generando antes de alimentar el modelo o metodología propuesta con la data. | G39: - | H39: - | I39: 20 | J39: 0 | K39: =IFERROR(J39/I39,0) -> 0 | L39: =J39 -> 0 | M39: =IFERROR(L39/I39,0) -> 0
B40: 4 | C40: 4.3 | D40: Evaluación e interpretación de información de fluidos | E40: Camilo Andres Santana Otalora | F40: Básico | G40: Comparación de propiedades fluidos Loma Larga 10 vs muestras formación Honda | H40: C:\Users\Usuario Meridian\OneDrive - Ecopetrol S.A\Camilo Santana\Ecopetrol 2026 | I40: 75 | J40: 5 | K40: =IFERROR(J40/I40,0) -> 0.066666667 | L40: =J40 -> 5 | M40: =IFERROR(L40/I40,0) -> 0.066666667
...

Sheet FEBRERO
R1: MES
B2: REPORTE DE AVANCE | R2: ENERO
B3: Fecha: 29/06/2022 | G3: Version: 01 | K3: GP-F-23
R4: FEBRERO
B5: Código Orden de servicio | D5: 90598918 | R5: MARZO
R6: JUNIO
B7: Mes a reportar | D7: FEBRERO | R7: JULIO
R8: AGOSTO
B9: Fecha reporte | D9: 46081 | R9: SEPTIEMBRE
R10: OCTUBRE
B11: Clasificación del servicio | J11: Reporte mes por servicio | L11: Reporte acumulado por servicio | R11: NOVIEMBRE
B12: Ítem general | C12: ítem actividad | D12: Descripción de la actividad | E12: Profesional a cargo | F12: Nivel contratado | G12: Soporte | H12: Medio de entrega | I12: Días contratados Acta de Inicio | J12: Días | K12: % avance | L12: Días | M12: % avance | R12: DICIEMBRE
B13: 1 | C13: 1.1 | D13: Generar Modelo Estático del yacimiento integrando la información disponible. | E13: Jesus David Arenas Navarro | F13: Junior | G13: Modelo Estático - Informe de Modelo - Cálculo de Volúmenes in Place | H13: Digital | I13: 25 | J13: 6 | K13: =IFERROR(J13/I13,0) -> 0.24 | L13: =+'ENERO 2026'!L13+J13 -> 9 | M13: =IFERROR(L13/I13,0) -> 0.36
B14: 1 | C14: 1.15 | D14: Carga de información para poblar el modelo geocelular (direccionales, coordenadas, surveys, topes, data de presión, estados mecánicos, evento de pozos, etc.) | G14: Modelo poblado | H14: Digital | I14: 25 | J14: 6 | K14: =IFERROR(J14/I14,0) -> 0.24 | L14: =+'ENERO 2026'!L14+J14 -> 9 | M14: =IFERROR(L14/I14,0) -> 0.36
B15: 1 | C15: 1.16 | D15: Georeferenciación de Mapas, pozos, Imágenes satélite, etc. y Definición de CRS (Cordinates Reference System) | G15: Información georeferenciada | H15: Digital | I15: 25 | J15: 6 | K15: =IFERROR(J15/I15,0) -> 0.24 | L15: =+'ENERO 2026'!L15+J15 -> 9 | M15: =IFERROR(L15/I15,0) -> 0.36
B16: 1 | C16: 1.17 | D16: Calculo probabilístico de Volúmenes In situ. | G16: Calculo Volumétrico - Bases de Datos | H16: Digital | I16: 25 | J16: 6 | K16: =IFERROR(J16/I16,0) -> 0.24 | L16: =+'ENERO 2026'!L16+J16 -> 9 | M16: =IFERROR(L16/I16,0) -> 0.36
B17: 1 | C17: 1.24 | D17: Caracterización composicional de fluidos de hidrocarburos mediante técnicas geoquímicas. | G17: - | H17: - | I17: 25 | J17: 0 | K17: =IFERROR(J17/I17,0) -> 0 | L17: =+'ENERO 2026'!L17+J17 -> 0 | M17: =IFERROR(L17/I17,0) -> 0
B18: 1 | C18: 1.25 | D18: Análisis geoquímicos de Fingerprinting | G18: - | H18: - | I18: 25 | J18: 0 | K18: =IFERROR(J18/I18,0) -> 0 | L18: =+'ENERO 2026'!L18+J18 -> 0 | M18: =IFERROR(L18/I18,0) -> 0
B19: 1 | C19: 1.26 | D19: Análisis e interpretación de imágenes de satélite | G19: - | H19: - | I19: 25 | J19: 0 | K19: =IFERROR(J19/I19,0) -> 0 | L19: =+'ENERO 2026'!L19+J19 -> 0 | M19: =IFERROR(L19/I19,0) -> 0
B20: 2 | C20: 2.5 | D20: Realizar caracterización Scal (interpretación) | G20: Informe | H20: Digital | I20: 25 | J20: 6 | K20: =IFERROR(J20/I20,0) -> 0.24 | L20: =+'ENERO 2026'!L20+J20 -> 9 | M20: =IFERROR(L20/I20,0) -> 0.36
B21: 2 | C21: 2.11 | D21: Generación de Modelos de Física de Rocas | G21: - | H21: - | I21: 25 | J21: 0 | K21: =IFERROR(J21/I21,0) -> 0 | L21: =+'ENERO 2026'!L21+J21 -> 0 | M21: =IFERROR(L21/I21,0) -> 0
B22: 8 | C22: 8.1 | D22: Revisión bibliográfica de modelos / metodologías y sus aplicaciones existentes, así como refinación de objetivos si procede. | E22: Jorge Felipe Alarcon Torres | F22: Junior | G22: Informe | H22: Digital | I22: 37 | J22: 5 | K22: =IFERROR(J22/I22,0) -> 0.13513514 | L22: =+'ENERO 2026'!L22+J22 -> 7 | M22: =IFERROR(L22/I22,0) -> 0.18918919
B23: 8 | C23: 8.2 | D23: Carga de datos, procesamiento de datos, Análisis Estadístico descriptivo considerando hipótesis desde la teoría, y análisis descriptivo considerando hipótesis generadas desde la misma data (pasos 1, 2 y 3 teoría CRISP-DM). | G23: Informe, con estadísticas descriptivas, histogramas, pruebas de ajuste, etc. | H23: Digital | I23: 37 | J23: 5 | K23: =IFERROR(J23/I23,0) -> 0.13513514 | L23: =+'ENERO 2026'!L23+J23 -> 8 | M23: =IFERROR(L23/I23,0) -> 0.21621622
B24: 8 | C24: 8.3 | D24: Construcción de modelo matemático utilizando las técnicas pertinentes de Ciencia de Datos (e.g. Programación Matemática / Optimización / Investigación de Operaciones, Modelamiento Probabilístico, Machine Learning, etc.), con dominio de conocimiento petrotecnico. Si el modelo es supervisado y no paramétrico, se debe generar el sustento y razonamiento respectivo, arquitectura, calibración de parámetros adecuado, pruebas de validación, generalización, desempeño, etc. La fase de modelamiento debe incluir el razonamiento del modelo y como se relaciona con los modelos petrotecnicos convencionales o actuales, en que difiere y cuál es su innovación en términos de analítica de datos. Lo anterior | G24: Formulación matemática, razonamientos, seudocódigo, definiciones, supuestos, pruebas estadísticas, pruebas de generalización, etc. | H24: Digital | I24: 37 | J24: 5 | K24: =IFERROR(J24/I24,0) -> 0.13513514 | L24: =+'ENERO 2026'!L24+J24 -> 7 | M24: =IFERROR(L24/I24,0) -> 0.18918919
B25: 8 | C25: 8.4 | D25: Análisis de resultados y análisis Estadístico - descriptivo de los resultados obtenidos, así como de las pruebas implementadas. Ejemplificación de la interpretación de resultados y auto-critica de los mismos. Mapeo de conclusiones, recomendaciones y validación de los objetivos con enfoque de valor. Es clave generar nociones para que los resultados puedan ser bien utilizados y/o asociados con otras metodologías. Si procede, se debe validar los resultados con los expertos o dolientes respectivos. Etapa 5 de la metodología CRISP- DM. | G25: Informe y/o presentación | H25: Digital | I25: 38 | J25: 5 | K25: =IFERROR(J25/I25,0) -> 0.13157895 | L25: =+'ENERO 2026'!L25+J25 -> 7 | M25: =IFERROR(L25/I25,0) -> 0.18421053
B26: 8 | C26: 8.5 | D26: Programación del modelo matemático en las herramientas que se considere más adecuada, e.g. R, Python, SAS, C++, Java, Matlab, Visual, etc. Los scripts deben respetar los planteamientos y consideraciones contenidas en el informe, debe contener buenas prácticas de programación (e.g. comentarios, identación (anglicismo de “identation”), separación por métodos o funciones, etc. – el programa no necesariamente debe estar orientado a objetos y otros paradigmas, e.g. la programación funcional podría ser altamente recomendable). | G26: Código. | H26: Digital | I26: 38 | J26: 5 | K26: =IFERROR(J26/I26,0) -> 0.13157895 | L26: =+'ENERO 2026'!L26+J26 -> 8 | M26: =IFERROR(L26/I26,0) -> 0.21052632
B27: 8 | C27: 8.6 | D27: Diseño modelo de datos "satélite" para el modelo matemático o la metodología aplicada. Si es el caso, se debe implementar la base de datos, e.g. en SQL. Adicionalmente, si es el caso, revisión del flujo de información respecto a procesos y actividades, así como de posibles fuentes de error en las mediciones o captura de la data. También, de aplicar, un análisis del error acumulado que se pueda estar generando antes de alimentar el modelo o metodología propuesta con la data. | G27: Documentación del modelo de datos (E.g. diagrama relacional), definiciones, diccionarios, relaciones. | H27: Digital | I27: 38 | J27: 5 | K27: =IFERROR(J27/I27,0) -> 0.13157895 | L27: =+'ENERO 2026'!L27+J27 -> 8 | M27: =IFERROR(L27/I27,0) -> 0.21052632
B28: 8 | C28: 8.1 | D28: Revisión bibliográfica de modelos / metodologías y sus aplicaciones existentes, así como refinación de objetivos si procede. | E28: Oscar Ivan Jimenez Barandica | F28: Junior | G28: - | H28: - | I28: 30 | J28: 0 | K28: =IFERROR(J28/I28,0) -> 0 | L28: =+'ENERO 2026'!L28+J28 -> 5 | M28: =IFERROR(L28/I28,0) -> 0.16666667
B29: 8 | C29: 8.2 | D29: Carga de datos, procesamiento de datos, Análisis Estadístico descriptivo considerando hipótesis desde la teoría, y análisis descriptivo considerando hipótesis generadas desde la misma data (pasos 1, 2 y 3 teoría CRISP-DM). | G29: https://ecopetrol.sharepoint.com/:u:/r/sites/vde/get/Analtica/0.%20SDPID/1_SDPID/12_Entregables/Oscar%20Ivan%20Jimenez%20Barandica/Meridian/2_Febrero/Llanito_Unificado.zip?csf=1&web=1&e=brV0rX | H29: Digital | I29: 30 | J29: 10 | K29: =IFERROR(J29/I29,0) -> 0.33333333 | L29: =+'ENERO 2026'!L29+J29 -> 15 | M29: =IFERROR(L29/I29,0) -> 0.5
B30: 8 | C30: 8.3 | D30: Construcción de modelo matemático utilizando las técnicas pertinentes de Ciencia de Datos (e.g. Programación Matemática / Optimización / Investigación de Operaciones, Modelamiento Probabilístico, Machine Learning, etc.), con dominio de conocimiento petrotecnico. Si el modelo es supervisado y no paramétrico, se debe generar el sustento y razonamiento respectivo, arquitectura, calibración de parámetros adecuado, pruebas de validación, generalización, desempeño, etc. La fase de modelamiento debe incluir el razonamiento del modelo y como se relaciona con los modelos petrotecnicos convencionales o actuales, en que difiere y cuál es su innovación en términos de analítica de datos. Lo anterior | G30: - | H30: - | I30: 60 | J30: 0 | K30: =IFERROR(J30/I30,0) -> 0 | L30: =+'ENERO 2026'!L30+J30 -> 5 | M30: =IFERROR(L30/I30,0) -> 0.083333333
B31: 8 | C31: 8.4 | D31: Análisis de resultados y análisis Estadístico - descriptivo de los resultados obtenidos, así como de las pruebas implementadas. Ejemplificación de la interpretación de resultados y auto-critica de los mismos. Mapeo de conclusiones, recomendaciones y validación de los objetivos con enfoque de valor. Es clave generar nociones para que los resultados puedan ser bien utilizados y/o asociados con otras metodologías. Si procede, se debe validar los resultados con los expertos o dolientes respectivos. Etapa 5 de la metodología CRISP- DM. | G31: https://ecopetrol.sharepoint.com/:x:/r/sites/vde/get/Analtica/0.%20SDPID/1_SDPID/12_Entregables/Oscar%20Ivan%20Jimenez%20Barandica/Meridian/2_Febrero/Comparacion%20prob.xlsx?d=wb276fba403c14550a923922320d0993f&csf=1&web=1&e=l8h5MC | H31: Digital | I31: 30 | J31: 10 | K31: =IFERROR(J31/I31,0) -> 0.33333333 | L31: =+'ENERO 2026'!L31+J31 -> 10 | M31: =IFERROR(L31/I31,0) -> 0.33333333
B32: 8 | C32: 8.5 | D32: Programación del modelo matemático en las herramientas que se considere más adecuada, e.g. R, Python, SAS, C++, Java, Matlab, Visual, etc. Los scripts deben respetar los planteamientos y consideraciones contenidas en el informe, debe contener buenas prácticas de programación (e.g. comentarios, identación (anglicismo de “identation”), separación por métodos o funciones, etc. – el programa no necesariamente debe estar orientado a objetos y otros paradigmas, e.g. la programación funcional podría ser altamente recomendable). | G32: https://ecopetrol.sharepoint.com/:u:/r/sites/vde/get/Analtica/0.%20SDPID/1_SDPID/12_Entregables/Oscar%20Ivan%20Jimenez%20Barandica/Meridian/2_Febrero/Llanito_proxy.ipynb?csf=1&web=1&e=Tgq9B4 | H32: Digital | I32: 45 | J32: 10 | K32: =IFERROR(J32/I32,0) -> 0.22222222 | L32: =+'ENERO 2026'!L32+J32 -> 10 | M32: =IFERROR(L32/I32,0) -> 0.22222222
B33: 8 | C33: 8.6 | D33: Diseño modelo de datos "satélite" para el modelo matemático o la metodología aplicada. Si es el caso, se debe implementar la base de datos, e.g. en SQL. Adicionalmente, si es el caso, revisión del flujo de información respecto a procesos y actividades, así como de posibles fuentes de error en las mediciones o captura de la data. También, de aplicar, un análisis del error acumulado que se pueda estar generando antes de alimentar el modelo o metodología propuesta con la data. | G33: - | H33: - | I33: 30 | J33: 0 | K33: =IFERROR(J33/I33,0) -> 0 | L33: =+'ENERO 2026'!L33+J33 -> 0 | M33: =IFERROR(L33/I33,0) -> 0
B34: 8 | C34: 8.1 | D34: Revisión bibliográfica de modelos / metodologías y sus aplicaciones existentes, así como refinación de objetivos si procede. | E34: Alejandra Arbelaez Londoño | F34: Senior | G34: Informe | H34: Digital | I34: 45 | J34: 8 | K34: =IFERROR(J34/I34,0) -> 0.17777778 | L34: =+'ENERO 2026'!L34+J34 -> 16 | M34: =IFERROR(L34/I34,0) -> 0.35555556
B35: 8 | C35: 8.2 | D35: Carga de datos, procesamiento de datos, Análisis Estadístico descriptivo considerando hipótesis desde la teoría, y análisis descriptivo considerando hipótesis generadas desde la misma data (pasos 1, 2 y 3 teoría CRISP-DM). | G35: - | H35: - | I35: 40 | J35: 0 | K35: =IFERROR(J35/I35,0) -> 0 | L35: =+'ENERO 2026'!L35+J35 -> 0 | M35: =IFERROR(L35/I35,0) -> 0
B36: 8 | C36: 8.3 | D36: Construcción de modelo matemático utilizando las técnicas pertinentes de Ciencia de Datos (e.g. Programación Matemática / Optimización / Investigación de Operaciones, Modelamiento Probabilístico, Machine Learning, etc.), con dominio de conocimiento petrotecnico. Si el modelo es supervisado y no paramétrico, se debe generar el sustento y razonamiento respectivo, arquitectura, calibración de parámetros adecuado, pruebas de validación, generalización, desempeño, etc. La fase de modelamiento debe incluir el razonamiento del modelo y como se relaciona con los modelos petrotecnicos convencionales o actuales, en que difiere y cuál es su innovación en términos de analítica de datos. | G36: Formulación matemática, razonamientos, seudocódigo, definiciones, supuestos, pruebas estadísticas, pruebas de generalización, etc. | H36: Digital | I36: 40 | J36: 8 | K36: =IFERROR(J36/I36,0) -> 0.2 | L36: =+'ENERO 2026'!L36+J36 -> 15 | M36: =IFERROR(L36/I36,0) -> 0.375
B37: 8 | C37: 8.4 | D37: Análisis de resultados y análisis Estadístico - descriptivo de los resultados obtenidos, así como de las pruebas implementadas. Ejemplificación de la interpretación de resultados y auto-critica de los mismos. Mapeo de conclusiones, recomendaciones y validación de los objetivos con enfoque de valor. Es clave generar nociones para que los resultados puedan ser bien utilizados y/o asociados con otras metodologías. Si procede, se debe validar los resultados con los expertos o dolientes respectivos. Etapa 5 de la metodología CRISP- DM. | G37: - | H37: - | I37: 40 | J37: 0 | K37: =IFERROR(J37/I37,0) -> 0 | L37: =+'ENERO 2026'!L37+J37 -> 0 | M37: =IFERROR(L37/I37,0) -> 0
B38: 8 | C38: 8.5 | D38: Programación del modelo matemático en las herramientas que se considere más adecuada, e.g. R, Python, SAS, C++, Java, Matlab, Visual, etc. Los scripts deben respetar los planteamientos y consideraciones contenidas en el informe, debe contener buenas prácticas de programación (e.g. comentarios, identación (anglicismo de “identation”), separación por métodos o funciones, etc. – el programa no necesariamente debe estar orientado a objetos y otros paradigmas, e.g. la programación funcional podría ser altamente recomendable). | G38: Código. | H38: Digital | I38: 40 | J38: 6 | K38: =IFERROR(J38/I38,0) -> 0.15 | L38: =+'ENERO 2026'!L38+J38 -> 6 | M38: =IFERROR(L38/I38,0) -> 0.15
B39: 8 | C39: 8.6 | D39: Diseño modelo de datos "satélite" para el modelo matemático o la metodología aplicada. Si es el caso, se debe implementar la base de datos, e.g. en SQL. Adicionalmente, si es el caso, revisión del flujo de información respecto a procesos y actividades, así como de posibles fuentes de error en las mediciones o captura de la data. También, de aplicar, un análisis del error acumulado que se pueda estar generando antes de alimentar el modelo o metodología propuesta con la data. | G39: Documentación del modelo de datos (E.g. diagrama relacional), definiciones, diccionarios, relaciones. | H39: Digital | I39: 20 | J39: 8 | K39: =IFERROR(J39/I39,0) -> 0.4 | L39: =+'ENERO 2026'!L39+J39 -> 8 | M39: =IFERROR(L39/I39,0) -> 0.4
B40: 4 | C40: 4.3 | D40: Evaluación e interpretación de información de fluidos | E40: Camilo Andres Santana Otalora | F40: Básico | G40: Comparación de propiedades fluidos Loma Larga 10 vs muestras formación Honda | H40: C:\Users\Usuario Meridian\OneDrive - Ecopetrol S.A\Camilo Santana\Ecopetrol 2026 | I40: 75 | J40: 10 | K40: =IFERROR(J40/I40,0) -> 0.13333333 | L40: =+'ENERO 2026'!L40+J40 -> 15 | M40: =IFERROR(L40/I40,0) -> 0.2
...
